package com.parzi.starwarsmod.world.gen;

import java.util.Random;

import net.minecraft.block.Block;
import net.minecraft.init.Blocks;
import net.minecraft.world.World;
import net.minecraft.world.chunk.IChunkProvider;
import net.minecraft.world.gen.feature.WorldGenerator;
import cpw.mods.fml.common.IWorldGenerator;

public class WorldGenEndorTree2 extends WorldGenerator implements IWorldGenerator
{
	public WorldGenEndorTree2()
	{
	}

	@Override
	public void generate(Random random, int chunkX, int chunkZ, World world, IChunkProvider chunkGenerator, IChunkProvider chunkProvider)
	{
	}

	@Override
	public boolean generate(World world, Random rand, int i, int j, int k)
	{
		// check that each corner is one of the valid spawn blocks
		if (!locationIsValidSpawn(world, i, j, k) || !locationIsValidSpawn(world, i + 36, j, k) || !locationIsValidSpawn(world, i + 36, j, k + 37) || !locationIsValidSpawn(world, i, j, k + 37)) { return false; }

		k = k - 10;
		i = i - 10;

		setBlock(world, i + 2, j + 39, k + 20, Blocks.log, 0);
		setBlock(world, i + 4, j + 42, k + 10, Blocks.log, 0);
		setBlock(world, i + 4, j + 42, k + 22, Blocks.log, 0);
		setBlock(world, i + 8, j + 39, k + 23, Blocks.log, 0);
		setBlock(world, i + 8, j + 40, k + 11, Blocks.log, 0);
		setBlock(world, i + 9, j + 40, k + 23, Blocks.log, 0);
		setBlock(world, i + 9, j + 42, k + 16, Blocks.log, 0);
		setBlock(world, i + 9, j + 46, k + 18, Blocks.log, 0);
		setBlock(world, i + 10, j + 40, k + 13, Blocks.log, 0);
		setBlock(world, i + 10, j + 40, k + 21, Blocks.log, 0);
		setBlock(world, i + 10, j + 44, k + 15, Blocks.log, 0);
		setBlock(world, i + 10, j + 45, k + 15, Blocks.log, 0);
		setBlock(world, i + 10, j + 45, k + 21, Blocks.log, 0);
		setBlock(world, i + 10, j + 46, k + 17, Blocks.log, 0);
		setBlock(world, i + 11, j + 42, k + 18, Blocks.log, 0);
		setBlock(world, i + 11, j + 42, k + 24, Blocks.log, 0);
		setBlock(world, i + 11, j + 43, k + 17, Blocks.log, 0);
		setBlock(world, i + 11, j + 43, k + 19, Blocks.log, 0);
		setBlock(world, i + 11, j + 45, k + 11, Blocks.log, 0);
		setBlock(world, i + 12, j + 41, k + 15, Blocks.log, 0);
		setBlock(world, i + 12, j + 42, k + 12, Blocks.log, 0);
		setBlock(world, i + 12, j + 42, k + 20, Blocks.log, 0);
		setBlock(world, i + 12, j + 45, k + 17, Blocks.log, 0);
		setBlock(world, i + 12, j + 46, k + 17, Blocks.log, 0);
		setBlock(world, i + 12, j + 47, k + 14, Blocks.log, 0);
		setBlock(world, i + 13, j + 40, k + 17, Blocks.log, 0);
		setBlock(world, i + 13, j + 40, k + 30, Blocks.log, 0);
		setBlock(world, i + 13, j + 41, k + 16, Blocks.log, 0);
		setBlock(world, i + 13, j + 42, k + 17, Blocks.log, 0);
		setBlock(world, i + 13, j + 43, k + 14, Blocks.log, 0);
		setBlock(world, i + 13, j + 43, k + 16, Blocks.log, 0);
		setBlock(world, i + 13, j + 44, k + 16, Blocks.log, 0);
		setBlock(world, i + 13, j + 44, k + 24, Blocks.log, 0);
		setBlock(world, i + 13, j + 45, k + 19, Blocks.log, 0);
		setBlock(world, i + 13, j + 47, k + 21, Blocks.log, 0);
		setBlock(world, i + 13, j + 48, k + 15, Blocks.log, 0);
		setBlock(world, i + 14, j + 39, k + 35, Blocks.log, 0);
		setBlock(world, i + 14, j + 40, k + 29, Blocks.log, 0);
		setBlock(world, i + 14, j + 41, k + 20, Blocks.log, 0);
		setBlock(world, i + 14, j + 41, k + 30, Blocks.log, 0);
		setBlock(world, i + 14, j + 43, k + 14, Blocks.log, 0);
		setBlock(world, i + 14, j + 45, k + 16, Blocks.log, 0);
		setBlock(world, i + 14, j + 45, k + 18, Blocks.log, 0);
		setBlock(world, i + 14, j + 47, k + 13, Blocks.log, 0);
		setBlock(world, i + 14, j + 47, k + 16, Blocks.log, 0);
		setBlock(world, i + 15, j + 38, k + 17, Blocks.log, 0);
		setBlock(world, i + 15, j + 44, k + 7, Blocks.log, 0);
		setBlock(world, i + 15, j + 45, k + 13, Blocks.log, 0);
		setBlock(world, i + 15, j + 45, k + 15, Blocks.log, 0);
		setBlock(world, i + 15, j + 45, k + 16, Blocks.log, 0);
		setBlock(world, i + 15, j + 46, k + 16, Blocks.log, 0);
		setBlock(world, i + 15, j + 46, k + 21, Blocks.log, 0);
		setBlock(world, i + 15, j + 47, k + 12, Blocks.log, 0);
		setBlock(world, i + 15, j + 47, k + 16, Blocks.log, 0);
		setBlock(world, i + 16, j + 37, k + 17, Blocks.log, 0);
		setBlock(world, i + 16, j + 41, k + 11, Blocks.log, 0);
		setBlock(world, i + 16, j + 41, k + 26, Blocks.log, 0);
		setBlock(world, i + 16, j + 42, k + 6, Blocks.log, 0);
		setBlock(world, i + 16, j + 42, k + 9, Blocks.log, 0);
		setBlock(world, i + 16, j + 42, k + 22, Blocks.log, 0);
		setBlock(world, i + 16, j + 43, k + 6, Blocks.log, 0);
		setBlock(world, i + 16, j + 43, k + 14, Blocks.log, 0);
		setBlock(world, i + 16, j + 43, k + 17, Blocks.log, 0);
		setBlock(world, i + 16, j + 43, k + 22, Blocks.log, 0);
		setBlock(world, i + 16, j + 43, k + 28, Blocks.log, 0);
		setBlock(world, i + 16, j + 44, k + 13, Blocks.log, 0);
		setBlock(world, i + 16, j + 45, k + 11, Blocks.log, 0);
		setBlock(world, i + 16, j + 45, k + 16, Blocks.log, 0);
		setBlock(world, i + 16, j + 45, k + 25, Blocks.log, 0);
		setBlock(world, i + 16, j + 46, k + 10, Blocks.log, 0);
		setBlock(world, i + 16, j + 46, k + 16, Blocks.log, 0);
		setBlock(world, i + 16, j + 46, k + 18, Blocks.log, 0);
		setBlock(world, i + 16, j + 46, k + 21, Blocks.log, 0);
		setBlock(world, i + 16, j + 47, k + 14, Blocks.log, 0);
		setBlock(world, i + 16, j + 47, k + 17, Blocks.log, 0);
		setBlock(world, i + 17, j + 42, k + 11, Blocks.log, 0);
		setBlock(world, i + 17, j + 42, k + 19, Blocks.log, 0);
		setBlock(world, i + 17, j + 42, k + 26, Blocks.log, 0);
		setBlock(world, i + 17, j + 43, k + 13, Blocks.log, 0);
		setBlock(world, i + 17, j + 44, k + 12, Blocks.log, 0);
		setBlock(world, i + 17, j + 44, k + 14, Blocks.log, 0);
		setBlock(world, i + 17, j + 44, k + 16, Blocks.log, 0);
		setBlock(world, i + 17, j + 44, k + 17, Blocks.log, 0);
		setBlock(world, i + 17, j + 44, k + 23, Blocks.log, 0);
		setBlock(world, i + 17, j + 45, k + 13, Blocks.log, 0);
		setBlock(world, i + 17, j + 45, k + 16, Blocks.log, 0);
		setBlock(world, i + 17, j + 46, k + 17, Blocks.log, 0);
		setBlock(world, i + 17, j + 47, k + 17, Blocks.log, 0);
		setBlock(world, i + 17, j + 48, k + 14, Blocks.log, 0);
		setBlock(world, i + 17, j + 48, k + 16, Blocks.log, 0);
		setBlock(world, i + 18, j + 0, k + 13, Blocks.log, 0);
		setBlock(world, i + 18, j + 0, k + 14, Blocks.log, 0);
		setBlock(world, i + 18, j + 0, k + 15, Blocks.log, 0);
		setBlock(world, i + 18, j + 0, k + 16, Blocks.log, 0);
		setBlock(world, i + 18, j + 1, k + 13, Blocks.log, 0);
		setBlock(world, i + 18, j + 1, k + 14, Blocks.log, 0);
		setBlock(world, i + 18, j + 1, k + 15, Blocks.log, 0);
		setBlock(world, i + 18, j + 1, k + 16, Blocks.log, 0);
		setBlock(world, i + 18, j + 2, k + 13, Blocks.log, 0);
		setBlock(world, i + 18, j + 2, k + 14, Blocks.log, 0);
		setBlock(world, i + 18, j + 2, k + 15, Blocks.log, 0);
		setBlock(world, i + 18, j + 2, k + 16, Blocks.log, 0);
		setBlock(world, i + 18, j + 3, k + 13, Blocks.log, 0);
		setBlock(world, i + 18, j + 3, k + 14, Blocks.log, 0);
		setBlock(world, i + 18, j + 3, k + 15, Blocks.log, 0);
		setBlock(world, i + 18, j + 3, k + 16, Blocks.log, 0);
		setBlock(world, i + 18, j + 4, k + 13, Blocks.log, 0);
		setBlock(world, i + 18, j + 4, k + 14, Blocks.log, 0);
		setBlock(world, i + 18, j + 4, k + 15, Blocks.log, 0);
		setBlock(world, i + 18, j + 4, k + 16, Blocks.log, 0);
		setBlock(world, i + 18, j + 5, k + 14, Blocks.log, 0);
		setBlock(world, i + 18, j + 5, k + 15, Blocks.log, 0);
		setBlock(world, i + 18, j + 5, k + 16, Blocks.log, 0);
		setBlock(world, i + 18, j + 6, k + 15, Blocks.log, 0);
		setBlock(world, i + 18, j + 14, k + 15, Blocks.log, 0);
		setBlock(world, i + 18, j + 14, k + 16, Blocks.log, 0);
		setBlock(world, i + 18, j + 15, k + 15, Blocks.log, 0);
		setBlock(world, i + 18, j + 15, k + 16, Blocks.log, 0);
		setBlock(world, i + 18, j + 16, k + 15, Blocks.log, 0);
		setBlock(world, i + 18, j + 16, k + 16, Blocks.log, 0);
		setBlock(world, i + 18, j + 16, k + 17, Blocks.log, 0);
		setBlock(world, i + 18, j + 17, k + 15, Blocks.log, 0);
		setBlock(world, i + 18, j + 17, k + 16, Blocks.log, 0);
		setBlock(world, i + 18, j + 17, k + 17, Blocks.log, 0);
		setBlock(world, i + 18, j + 18, k + 15, Blocks.log, 0);
		setBlock(world, i + 18, j + 18, k + 16, Blocks.log, 0);
		setBlock(world, i + 18, j + 18, k + 17, Blocks.log, 0);
		setBlock(world, i + 18, j + 19, k + 15, Blocks.log, 0);
		setBlock(world, i + 18, j + 19, k + 16, Blocks.log, 0);
		setBlock(world, i + 18, j + 19, k + 17, Blocks.log, 0);
		setBlock(world, i + 18, j + 20, k + 15, Blocks.log, 0);
		setBlock(world, i + 18, j + 20, k + 16, Blocks.log, 0);
		setBlock(world, i + 18, j + 20, k + 17, Blocks.log, 0);
		setBlock(world, i + 18, j + 21, k + 15, Blocks.log, 0);
		setBlock(world, i + 18, j + 21, k + 16, Blocks.log, 0);
		setBlock(world, i + 18, j + 21, k + 17, Blocks.log, 0);
		setBlock(world, i + 18, j + 22, k + 15, Blocks.log, 0);
		setBlock(world, i + 18, j + 22, k + 16, Blocks.log, 0);
		setBlock(world, i + 18, j + 22, k + 17, Blocks.log, 0);
		setBlock(world, i + 18, j + 23, k + 16, Blocks.log, 0);
		setBlock(world, i + 18, j + 24, k + 16, Blocks.log, 0);
		setBlock(world, i + 18, j + 25, k + 16, Blocks.log, 0);
		setBlock(world, i + 18, j + 26, k + 16, Blocks.log, 0);
		setBlock(world, i + 18, j + 35, k + 17, Blocks.log, 0);
		setBlock(world, i + 18, j + 41, k + 21, Blocks.log, 0);
		setBlock(world, i + 18, j + 42, k + 13, Blocks.log, 0);
		setBlock(world, i + 18, j + 42, k + 15, Blocks.log, 0);
		setBlock(world, i + 18, j + 42, k + 22, Blocks.log, 0);
		setBlock(world, i + 18, j + 43, k + 15, Blocks.log, 0);
		setBlock(world, i + 18, j + 43, k + 16, Blocks.log, 0);
		setBlock(world, i + 18, j + 43, k + 17, Blocks.log, 0);
		setBlock(world, i + 18, j + 43, k + 18, Blocks.log, 0);
		setBlock(world, i + 18, j + 44, k + 8, Blocks.log, 0);
		setBlock(world, i + 18, j + 45, k + 17, Blocks.log, 0);
		setBlock(world, i + 18, j + 46, k + 10, Blocks.log, 0);
		setBlock(world, i + 18, j + 46, k + 20, Blocks.log, 0);
		setBlock(world, i + 18, j + 47, k + 14, Blocks.log, 0);
		setBlock(world, i + 18, j + 47, k + 16, Blocks.log, 0);
		setBlock(world, i + 18, j + 48, k + 10, Blocks.log, 0);
		setBlock(world, i + 18, j + 48, k + 14, Blocks.log, 0);
		setBlock(world, i + 18, j + 48, k + 20, Blocks.log, 0);
		setBlock(world, i + 19, j + 0, k + 13, Blocks.log, 0);
		setBlock(world, i + 19, j + 0, k + 14, Blocks.log, 0);
		setBlock(world, i + 19, j + 0, k + 15, Blocks.log, 0);
		setBlock(world, i + 19, j + 0, k + 16, Blocks.log, 0);
		setBlock(world, i + 19, j + 0, k + 17, Blocks.log, 0);
		setBlock(world, i + 19, j + 1, k + 13, Blocks.log, 0);
		setBlock(world, i + 19, j + 1, k + 14, Blocks.log, 0);
		setBlock(world, i + 19, j + 1, k + 15, Blocks.log, 0);
		setBlock(world, i + 19, j + 1, k + 16, Blocks.log, 0);
		setBlock(world, i + 19, j + 1, k + 17, Blocks.log, 0);
		setBlock(world, i + 19, j + 2, k + 13, Blocks.log, 0);
		setBlock(world, i + 19, j + 2, k + 14, Blocks.log, 0);
		setBlock(world, i + 19, j + 2, k + 15, Blocks.log, 0);
		setBlock(world, i + 19, j + 2, k + 16, Blocks.log, 0);
		setBlock(world, i + 19, j + 2, k + 17, Blocks.log, 0);
		setBlock(world, i + 19, j + 3, k + 13, Blocks.log, 0);
		setBlock(world, i + 19, j + 3, k + 14, Blocks.log, 0);
		setBlock(world, i + 19, j + 3, k + 15, Blocks.log, 0);
		setBlock(world, i + 19, j + 3, k + 16, Blocks.log, 0);
		setBlock(world, i + 19, j + 3, k + 17, Blocks.log, 0);
		setBlock(world, i + 19, j + 4, k + 13, Blocks.log, 0);
		setBlock(world, i + 19, j + 4, k + 14, Blocks.log, 0);
		setBlock(world, i + 19, j + 4, k + 15, Blocks.log, 0);
		setBlock(world, i + 19, j + 4, k + 16, Blocks.log, 0);
		setBlock(world, i + 19, j + 4, k + 17, Blocks.log, 0);
		setBlock(world, i + 19, j + 5, k + 13, Blocks.log, 0);
		setBlock(world, i + 19, j + 5, k + 14, Blocks.log, 0);
		setBlock(world, i + 19, j + 5, k + 15, Blocks.log, 0);
		setBlock(world, i + 19, j + 5, k + 16, Blocks.log, 0);
		setBlock(world, i + 19, j + 5, k + 17, Blocks.log, 0);
		setBlock(world, i + 19, j + 6, k + 13, Blocks.log, 0);
		setBlock(world, i + 19, j + 6, k + 14, Blocks.log, 0);
		setBlock(world, i + 19, j + 6, k + 15, Blocks.log, 0);
		setBlock(world, i + 19, j + 6, k + 16, Blocks.log, 0);
		setBlock(world, i + 19, j + 7, k + 14, Blocks.log, 0);
		setBlock(world, i + 19, j + 7, k + 15, Blocks.log, 0);
		setBlock(world, i + 19, j + 8, k + 14, Blocks.log, 0);
		setBlock(world, i + 19, j + 8, k + 15, Blocks.log, 0);
		setBlock(world, i + 19, j + 9, k + 14, Blocks.log, 0);
		setBlock(world, i + 19, j + 9, k + 15, Blocks.log, 0);
		setBlock(world, i + 19, j + 10, k + 14, Blocks.log, 0);
		setBlock(world, i + 19, j + 10, k + 15, Blocks.log, 0);
		setBlock(world, i + 19, j + 11, k + 14, Blocks.log, 0);
		setBlock(world, i + 19, j + 11, k + 15, Blocks.log, 0);
		setBlock(world, i + 19, j + 11, k + 16, Blocks.log, 0);
		setBlock(world, i + 19, j + 12, k + 14, Blocks.log, 0);
		setBlock(world, i + 19, j + 12, k + 15, Blocks.log, 0);
		setBlock(world, i + 19, j + 12, k + 16, Blocks.log, 0);
		setBlock(world, i + 19, j + 13, k + 14, Blocks.log, 0);
		setBlock(world, i + 19, j + 13, k + 15, Blocks.log, 0);
		setBlock(world, i + 19, j + 13, k + 16, Blocks.log, 0);
		setBlock(world, i + 19, j + 14, k + 14, Blocks.log, 0);
		setBlock(world, i + 19, j + 14, k + 15, Blocks.log, 0);
		setBlock(world, i + 19, j + 14, k + 16, Blocks.log, 0);
		setBlock(world, i + 19, j + 15, k + 14, Blocks.log, 0);
		setBlock(world, i + 19, j + 15, k + 15, Blocks.log, 0);
		setBlock(world, i + 19, j + 15, k + 16, Blocks.log, 0);
		setBlock(world, i + 19, j + 15, k + 17, Blocks.log, 0);
		setBlock(world, i + 19, j + 15, k + 18, Blocks.log, 0);
		setBlock(world, i + 19, j + 16, k + 14, Blocks.log, 0);
		setBlock(world, i + 19, j + 16, k + 15, Blocks.log, 0);
		setBlock(world, i + 19, j + 16, k + 16, Blocks.log, 0);
		setBlock(world, i + 19, j + 16, k + 17, Blocks.log, 0);
		setBlock(world, i + 19, j + 16, k + 18, Blocks.log, 0);
		setBlock(world, i + 19, j + 17, k + 14, Blocks.log, 0);
		setBlock(world, i + 19, j + 17, k + 15, Blocks.log, 0);
		setBlock(world, i + 19, j + 17, k + 16, Blocks.log, 0);
		setBlock(world, i + 19, j + 17, k + 17, Blocks.log, 0);
		setBlock(world, i + 19, j + 17, k + 18, Blocks.log, 0);
		setBlock(world, i + 19, j + 18, k + 14, Blocks.log, 0);
		setBlock(world, i + 19, j + 18, k + 15, Blocks.log, 0);
		setBlock(world, i + 19, j + 18, k + 16, Blocks.log, 0);
		setBlock(world, i + 19, j + 18, k + 17, Blocks.log, 0);
		setBlock(world, i + 19, j + 18, k + 18, Blocks.log, 0);
		setBlock(world, i + 19, j + 19, k + 14, Blocks.log, 0);
		setBlock(world, i + 19, j + 19, k + 15, Blocks.log, 0);
		setBlock(world, i + 19, j + 19, k + 16, Blocks.log, 0);
		setBlock(world, i + 19, j + 19, k + 17, Blocks.log, 0);
		setBlock(world, i + 19, j + 19, k + 18, Blocks.log, 0);
		setBlock(world, i + 19, j + 20, k + 14, Blocks.log, 0);
		setBlock(world, i + 19, j + 20, k + 15, Blocks.log, 0);
		setBlock(world, i + 19, j + 20, k + 16, Blocks.log, 0);
		setBlock(world, i + 19, j + 20, k + 17, Blocks.log, 0);
		setBlock(world, i + 19, j + 20, k + 18, Blocks.log, 0);
		setBlock(world, i + 19, j + 21, k + 14, Blocks.log, 0);
		setBlock(world, i + 19, j + 21, k + 15, Blocks.log, 0);
		setBlock(world, i + 19, j + 21, k + 16, Blocks.log, 0);
		setBlock(world, i + 19, j + 21, k + 17, Blocks.log, 0);
		setBlock(world, i + 19, j + 21, k + 18, Blocks.log, 0);
		setBlock(world, i + 19, j + 22, k + 14, Blocks.log, 0);
		setBlock(world, i + 19, j + 22, k + 15, Blocks.log, 0);
		setBlock(world, i + 19, j + 22, k + 16, Blocks.log, 0);
		setBlock(world, i + 19, j + 22, k + 17, Blocks.log, 0);
		setBlock(world, i + 19, j + 22, k + 18, Blocks.log, 0);
		setBlock(world, i + 19, j + 23, k + 15, Blocks.log, 0);
		setBlock(world, i + 19, j + 23, k + 16, Blocks.log, 0);
		setBlock(world, i + 19, j + 23, k + 17, Blocks.log, 0);
		setBlock(world, i + 19, j + 24, k + 15, Blocks.log, 0);
		setBlock(world, i + 19, j + 24, k + 16, Blocks.log, 0);
		setBlock(world, i + 19, j + 24, k + 17, Blocks.log, 0);
		setBlock(world, i + 19, j + 25, k + 15, Blocks.log, 0);
		setBlock(world, i + 19, j + 25, k + 16, Blocks.log, 0);
		setBlock(world, i + 19, j + 25, k + 17, Blocks.log, 0);
		setBlock(world, i + 19, j + 26, k + 15, Blocks.log, 0);
		setBlock(world, i + 19, j + 26, k + 16, Blocks.log, 0);
		setBlock(world, i + 19, j + 26, k + 17, Blocks.log, 0);
		setBlock(world, i + 19, j + 27, k + 15, Blocks.log, 0);
		setBlock(world, i + 19, j + 27, k + 16, Blocks.log, 0);
		setBlock(world, i + 19, j + 27, k + 17, Blocks.log, 0);
		setBlock(world, i + 19, j + 28, k + 15, Blocks.log, 0);
		setBlock(world, i + 19, j + 28, k + 17, Blocks.log, 0);
		setBlock(world, i + 19, j + 33, k + 16, Blocks.log, 0);
		setBlock(world, i + 19, j + 34, k + 16, Blocks.log, 0);
		setBlock(world, i + 19, j + 35, k + 16, Blocks.log, 0);
		setBlock(world, i + 19, j + 36, k + 16, Blocks.log, 0);
		setBlock(world, i + 19, j + 40, k + 15, Blocks.log, 0);
		setBlock(world, i + 19, j + 41, k + 14, Blocks.log, 0);
		setBlock(world, i + 19, j + 42, k + 16, Blocks.log, 0);
		setBlock(world, i + 19, j + 43, k + 17, Blocks.log, 0);
		setBlock(world, i + 19, j + 44, k + 17, Blocks.log, 0);
		setBlock(world, i + 19, j + 44, k + 18, Blocks.log, 0);
		setBlock(world, i + 19, j + 44, k + 27, Blocks.log, 0);
		setBlock(world, i + 19, j + 45, k + 9, Blocks.log, 0);
		setBlock(world, i + 19, j + 45, k + 19, Blocks.log, 0);
		setBlock(world, i + 19, j + 46, k + 20, Blocks.log, 0);
		setBlock(world, i + 19, j + 46, k + 22, Blocks.log, 0);
		setBlock(world, i + 19, j + 47, k + 15, Blocks.log, 0);
		setBlock(world, i + 19, j + 47, k + 21, Blocks.log, 0);
		setBlock(world, i + 19, j + 48, k + 13, Blocks.log, 0);
		setBlock(world, i + 19, j + 48, k + 15, Blocks.log, 0);
		setBlock(world, i + 19, j + 48, k + 16, Blocks.log, 0);
		setBlock(world, i + 20, j + 0, k + 13, Blocks.log, 0);
		setBlock(world, i + 20, j + 0, k + 14, Blocks.log, 0);
		setBlock(world, i + 20, j + 0, k + 15, Blocks.log, 0);
		setBlock(world, i + 20, j + 0, k + 16, Blocks.log, 0);
		setBlock(world, i + 20, j + 0, k + 17, Blocks.log, 0);
		setBlock(world, i + 20, j + 1, k + 13, Blocks.log, 0);
		setBlock(world, i + 20, j + 1, k + 14, Blocks.log, 0);
		setBlock(world, i + 20, j + 1, k + 15, Blocks.log, 0);
		setBlock(world, i + 20, j + 1, k + 16, Blocks.log, 0);
		setBlock(world, i + 20, j + 1, k + 17, Blocks.log, 0);
		setBlock(world, i + 20, j + 2, k + 13, Blocks.log, 0);
		setBlock(world, i + 20, j + 2, k + 14, Blocks.log, 0);
		setBlock(world, i + 20, j + 2, k + 15, Blocks.log, 0);
		setBlock(world, i + 20, j + 2, k + 16, Blocks.log, 0);
		setBlock(world, i + 20, j + 2, k + 17, Blocks.log, 0);
		setBlock(world, i + 20, j + 3, k + 13, Blocks.log, 0);
		setBlock(world, i + 20, j + 3, k + 14, Blocks.log, 0);
		setBlock(world, i + 20, j + 3, k + 15, Blocks.log, 0);
		setBlock(world, i + 20, j + 3, k + 16, Blocks.log, 0);
		setBlock(world, i + 20, j + 3, k + 17, Blocks.log, 0);
		setBlock(world, i + 20, j + 4, k + 13, Blocks.log, 0);
		setBlock(world, i + 20, j + 4, k + 14, Blocks.log, 0);
		setBlock(world, i + 20, j + 4, k + 15, Blocks.log, 0);
		setBlock(world, i + 20, j + 4, k + 16, Blocks.log, 0);
		setBlock(world, i + 20, j + 4, k + 17, Blocks.log, 0);
		setBlock(world, i + 20, j + 5, k + 13, Blocks.log, 0);
		setBlock(world, i + 20, j + 5, k + 14, Blocks.log, 0);
		setBlock(world, i + 20, j + 5, k + 15, Blocks.log, 0);
		setBlock(world, i + 20, j + 5, k + 16, Blocks.log, 0);
		setBlock(world, i + 20, j + 5, k + 17, Blocks.log, 0);
		setBlock(world, i + 20, j + 6, k + 13, Blocks.log, 0);
		setBlock(world, i + 20, j + 6, k + 14, Blocks.log, 0);
		setBlock(world, i + 20, j + 6, k + 15, Blocks.log, 0);
		setBlock(world, i + 20, j + 6, k + 16, Blocks.log, 0);
		setBlock(world, i + 20, j + 7, k + 14, Blocks.log, 0);
		setBlock(world, i + 20, j + 7, k + 15, Blocks.log, 0);
		setBlock(world, i + 20, j + 7, k + 16, Blocks.log, 0);
		setBlock(world, i + 20, j + 8, k + 14, Blocks.log, 0);
		setBlock(world, i + 20, j + 8, k + 15, Blocks.log, 0);
		setBlock(world, i + 20, j + 8, k + 16, Blocks.log, 0);
		setBlock(world, i + 20, j + 9, k + 14, Blocks.log, 0);
		setBlock(world, i + 20, j + 9, k + 15, Blocks.log, 0);
		setBlock(world, i + 20, j + 9, k + 16, Blocks.log, 0);
		setBlock(world, i + 20, j + 10, k + 14, Blocks.log, 0);
		setBlock(world, i + 20, j + 10, k + 15, Blocks.log, 0);
		setBlock(world, i + 20, j + 10, k + 16, Blocks.log, 0);
		setBlock(world, i + 20, j + 11, k + 14, Blocks.log, 0);
		setBlock(world, i + 20, j + 11, k + 15, Blocks.log, 0);
		setBlock(world, i + 20, j + 11, k + 16, Blocks.log, 0);
		setBlock(world, i + 20, j + 12, k + 14, Blocks.log, 0);
		setBlock(world, i + 20, j + 12, k + 15, Blocks.log, 0);
		setBlock(world, i + 20, j + 12, k + 16, Blocks.log, 0);
		setBlock(world, i + 20, j + 13, k + 14, Blocks.log, 0);
		setBlock(world, i + 20, j + 13, k + 15, Blocks.log, 0);
		setBlock(world, i + 20, j + 13, k + 16, Blocks.log, 0);
		setBlock(world, i + 20, j + 13, k + 17, Blocks.log, 0);
		setBlock(world, i + 20, j + 14, k + 14, Blocks.log, 0);
		setBlock(world, i + 20, j + 14, k + 15, Blocks.log, 0);
		setBlock(world, i + 20, j + 14, k + 16, Blocks.log, 0);
		setBlock(world, i + 20, j + 14, k + 17, Blocks.log, 0);
		setBlock(world, i + 20, j + 15, k + 14, Blocks.log, 0);
		setBlock(world, i + 20, j + 15, k + 15, Blocks.log, 0);
		setBlock(world, i + 20, j + 15, k + 16, Blocks.log, 0);
		setBlock(world, i + 20, j + 15, k + 17, Blocks.log, 0);
		setBlock(world, i + 20, j + 15, k + 18, Blocks.log, 0);
		setBlock(world, i + 20, j + 16, k + 14, Blocks.log, 0);
		setBlock(world, i + 20, j + 16, k + 15, Blocks.log, 0);
		setBlock(world, i + 20, j + 16, k + 16, Blocks.log, 0);
		setBlock(world, i + 20, j + 16, k + 17, Blocks.log, 0);
		setBlock(world, i + 20, j + 16, k + 18, Blocks.log, 0);
		setBlock(world, i + 20, j + 17, k + 14, Blocks.log, 0);
		setBlock(world, i + 20, j + 17, k + 15, Blocks.log, 0);
		setBlock(world, i + 20, j + 17, k + 16, Blocks.log, 0);
		setBlock(world, i + 20, j + 17, k + 17, Blocks.log, 0);
		setBlock(world, i + 20, j + 17, k + 18, Blocks.log, 0);
		setBlock(world, i + 20, j + 18, k + 14, Blocks.log, 0);
		setBlock(world, i + 20, j + 18, k + 15, Blocks.log, 0);
		setBlock(world, i + 20, j + 18, k + 16, Blocks.log, 0);
		setBlock(world, i + 20, j + 18, k + 17, Blocks.log, 0);
		setBlock(world, i + 20, j + 18, k + 18, Blocks.log, 0);
		setBlock(world, i + 20, j + 19, k + 14, Blocks.log, 0);
		setBlock(world, i + 20, j + 19, k + 15, Blocks.log, 0);
		setBlock(world, i + 20, j + 19, k + 16, Blocks.log, 0);
		setBlock(world, i + 20, j + 19, k + 17, Blocks.log, 0);
		setBlock(world, i + 20, j + 19, k + 18, Blocks.log, 0);
		setBlock(world, i + 20, j + 20, k + 14, Blocks.log, 0);
		setBlock(world, i + 20, j + 20, k + 15, Blocks.log, 0);
		setBlock(world, i + 20, j + 20, k + 16, Blocks.log, 0);
		setBlock(world, i + 20, j + 20, k + 17, Blocks.log, 0);
		setBlock(world, i + 20, j + 20, k + 18, Blocks.log, 0);
		setBlock(world, i + 20, j + 21, k + 14, Blocks.log, 0);
		setBlock(world, i + 20, j + 21, k + 15, Blocks.log, 0);
		setBlock(world, i + 20, j + 21, k + 16, Blocks.log, 0);
		setBlock(world, i + 20, j + 21, k + 17, Blocks.log, 0);
		setBlock(world, i + 20, j + 21, k + 18, Blocks.log, 0);
		setBlock(world, i + 20, j + 22, k + 14, Blocks.log, 0);
		setBlock(world, i + 20, j + 22, k + 15, Blocks.log, 0);
		setBlock(world, i + 20, j + 22, k + 16, Blocks.log, 0);
		setBlock(world, i + 20, j + 22, k + 17, Blocks.log, 0);
		setBlock(world, i + 20, j + 22, k + 18, Blocks.log, 0);
		setBlock(world, i + 20, j + 23, k + 14, Blocks.log, 0);
		setBlock(world, i + 20, j + 23, k + 15, Blocks.log, 0);
		setBlock(world, i + 20, j + 23, k + 16, Blocks.log, 0);
		setBlock(world, i + 20, j + 23, k + 17, Blocks.log, 0);
		setBlock(world, i + 20, j + 23, k + 18, Blocks.log, 0);
		setBlock(world, i + 20, j + 24, k + 14, Blocks.log, 0);
		setBlock(world, i + 20, j + 24, k + 15, Blocks.log, 0);
		setBlock(world, i + 20, j + 24, k + 16, Blocks.log, 0);
		setBlock(world, i + 20, j + 24, k + 17, Blocks.log, 0);
		setBlock(world, i + 20, j + 24, k + 18, Blocks.log, 0);
		setBlock(world, i + 20, j + 25, k + 14, Blocks.log, 0);
		setBlock(world, i + 20, j + 25, k + 15, Blocks.log, 0);
		setBlock(world, i + 20, j + 25, k + 16, Blocks.log, 0);
		setBlock(world, i + 20, j + 25, k + 17, Blocks.log, 0);
		setBlock(world, i + 20, j + 25, k + 18, Blocks.log, 0);
		setBlock(world, i + 20, j + 26, k + 14, Blocks.log, 0);
		setBlock(world, i + 20, j + 26, k + 15, Blocks.log, 0);
		setBlock(world, i + 20, j + 26, k + 16, Blocks.log, 0);
		setBlock(world, i + 20, j + 26, k + 17, Blocks.log, 0);
		setBlock(world, i + 20, j + 26, k + 18, Blocks.log, 0);
		setBlock(world, i + 20, j + 27, k + 15, Blocks.log, 0);
		setBlock(world, i + 20, j + 27, k + 16, Blocks.log, 0);
		setBlock(world, i + 20, j + 27, k + 17, Blocks.log, 0);
		setBlock(world, i + 20, j + 28, k + 16, Blocks.log, 0);
		setBlock(world, i + 20, j + 28, k + 17, Blocks.log, 0);
		setBlock(world, i + 20, j + 31, k + 13, Blocks.log, 0);
		setBlock(world, i + 20, j + 31, k + 16, Blocks.log, 0);
		setBlock(world, i + 20, j + 32, k + 12, Blocks.log, 0);
		setBlock(world, i + 20, j + 33, k + 11, Blocks.log, 0);
		setBlock(world, i + 20, j + 35, k + 16, Blocks.log, 0);
		setBlock(world, i + 20, j + 36, k + 16, Blocks.log, 0);
		setBlock(world, i + 20, j + 38, k + 16, Blocks.log, 0);
		setBlock(world, i + 20, j + 39, k + 16, Blocks.log, 0);
		setBlock(world, i + 20, j + 40, k + 15, Blocks.log, 0);
		setBlock(world, i + 20, j + 40, k + 16, Blocks.log, 0);
		setBlock(world, i + 20, j + 41, k + 16, Blocks.log, 0);
		setBlock(world, i + 20, j + 42, k + 8, Blocks.log, 0);
		setBlock(world, i + 20, j + 42, k + 11, Blocks.log, 0);
		setBlock(world, i + 20, j + 42, k + 16, Blocks.log, 0);
		setBlock(world, i + 20, j + 43, k + 16, Blocks.log, 0);
		setBlock(world, i + 20, j + 43, k + 22, Blocks.log, 0);
		setBlock(world, i + 20, j + 43, k + 25, Blocks.log, 0);
		setBlock(world, i + 20, j + 43, k + 31, Blocks.log, 0);
		setBlock(world, i + 20, j + 44, k + 8, Blocks.log, 0);
		setBlock(world, i + 20, j + 44, k + 11, Blocks.log, 0);
		setBlock(world, i + 20, j + 44, k + 12, Blocks.log, 0);
		setBlock(world, i + 20, j + 44, k + 18, Blocks.log, 0);
		setBlock(world, i + 20, j + 44, k + 22, Blocks.log, 0);
		setBlock(world, i + 20, j + 45, k + 6, Blocks.log, 0);
		setBlock(world, i + 20, j + 45, k + 13, Blocks.log, 0);
		setBlock(world, i + 20, j + 46, k + 11, Blocks.log, 0);
		setBlock(world, i + 20, j + 47, k + 11, Blocks.log, 0);
		setBlock(world, i + 20, j + 47, k + 19, Blocks.log, 0);
		setBlock(world, i + 20, j + 48, k + 19, Blocks.log, 0);
		setBlock(world, i + 20, j + 48, k + 20, Blocks.log, 0);
		setBlock(world, i + 21, j + 0, k + 13, Blocks.log, 0);
		setBlock(world, i + 21, j + 0, k + 14, Blocks.log, 0);
		setBlock(world, i + 21, j + 0, k + 15, Blocks.log, 0);
		setBlock(world, i + 21, j + 0, k + 16, Blocks.log, 0);
		setBlock(world, i + 21, j + 0, k + 17, Blocks.log, 0);
		setBlock(world, i + 21, j + 1, k + 13, Blocks.log, 0);
		setBlock(world, i + 21, j + 1, k + 14, Blocks.log, 0);
		setBlock(world, i + 21, j + 1, k + 15, Blocks.log, 0);
		setBlock(world, i + 21, j + 1, k + 16, Blocks.log, 0);
		setBlock(world, i + 21, j + 1, k + 17, Blocks.log, 0);
		setBlock(world, i + 21, j + 2, k + 13, Blocks.log, 0);
		setBlock(world, i + 21, j + 2, k + 14, Blocks.log, 0);
		setBlock(world, i + 21, j + 2, k + 15, Blocks.log, 0);
		setBlock(world, i + 21, j + 2, k + 16, Blocks.log, 0);
		setBlock(world, i + 21, j + 2, k + 17, Blocks.log, 0);
		setBlock(world, i + 21, j + 3, k + 14, Blocks.log, 0);
		setBlock(world, i + 21, j + 3, k + 15, Blocks.log, 0);
		setBlock(world, i + 21, j + 3, k + 16, Blocks.log, 0);
		setBlock(world, i + 21, j + 3, k + 17, Blocks.log, 0);
		setBlock(world, i + 21, j + 4, k + 14, Blocks.log, 0);
		setBlock(world, i + 21, j + 4, k + 15, Blocks.log, 0);
		setBlock(world, i + 21, j + 4, k + 16, Blocks.log, 0);
		setBlock(world, i + 21, j + 4, k + 17, Blocks.log, 0);
		setBlock(world, i + 21, j + 5, k + 14, Blocks.log, 0);
		setBlock(world, i + 21, j + 5, k + 15, Blocks.log, 0);
		setBlock(world, i + 21, j + 5, k + 16, Blocks.log, 0);
		setBlock(world, i + 21, j + 5, k + 17, Blocks.log, 0);
		setBlock(world, i + 21, j + 6, k + 14, Blocks.log, 0);
		setBlock(world, i + 21, j + 6, k + 15, Blocks.log, 0);
		setBlock(world, i + 21, j + 6, k + 16, Blocks.log, 0);
		setBlock(world, i + 21, j + 6, k + 17, Blocks.log, 0);
		setBlock(world, i + 21, j + 7, k + 14, Blocks.log, 0);
		setBlock(world, i + 21, j + 7, k + 15, Blocks.log, 0);
		setBlock(world, i + 21, j + 7, k + 16, Blocks.log, 0);
		setBlock(world, i + 21, j + 8, k + 15, Blocks.log, 0);
		setBlock(world, i + 21, j + 8, k + 16, Blocks.log, 0);
		setBlock(world, i + 21, j + 9, k + 15, Blocks.log, 0);
		setBlock(world, i + 21, j + 9, k + 16, Blocks.log, 0);
		setBlock(world, i + 21, j + 10, k + 15, Blocks.log, 0);
		setBlock(world, i + 21, j + 10, k + 16, Blocks.log, 0);
		setBlock(world, i + 21, j + 11, k + 15, Blocks.log, 0);
		setBlock(world, i + 21, j + 11, k + 16, Blocks.log, 0);
		setBlock(world, i + 21, j + 11, k + 17, Blocks.log, 0);
		setBlock(world, i + 21, j + 12, k + 14, Blocks.log, 0);
		setBlock(world, i + 21, j + 12, k + 15, Blocks.log, 0);
		setBlock(world, i + 21, j + 12, k + 16, Blocks.log, 0);
		setBlock(world, i + 21, j + 12, k + 17, Blocks.log, 0);
		setBlock(world, i + 21, j + 13, k + 14, Blocks.log, 0);
		setBlock(world, i + 21, j + 13, k + 15, Blocks.log, 0);
		setBlock(world, i + 21, j + 13, k + 16, Blocks.log, 0);
		setBlock(world, i + 21, j + 13, k + 17, Blocks.log, 0);
		setBlock(world, i + 21, j + 13, k + 18, Blocks.log, 0);
		setBlock(world, i + 21, j + 14, k + 14, Blocks.log, 0);
		setBlock(world, i + 21, j + 14, k + 15, Blocks.log, 0);
		setBlock(world, i + 21, j + 14, k + 16, Blocks.log, 0);
		setBlock(world, i + 21, j + 14, k + 17, Blocks.log, 0);
		setBlock(world, i + 21, j + 14, k + 18, Blocks.log, 0);
		setBlock(world, i + 21, j + 15, k + 14, Blocks.log, 0);
		setBlock(world, i + 21, j + 15, k + 15, Blocks.log, 0);
		setBlock(world, i + 21, j + 15, k + 16, Blocks.log, 0);
		setBlock(world, i + 21, j + 15, k + 17, Blocks.log, 0);
		setBlock(world, i + 21, j + 15, k + 18, Blocks.log, 0);
		setBlock(world, i + 21, j + 16, k + 14, Blocks.log, 0);
		setBlock(world, i + 21, j + 16, k + 15, Blocks.log, 0);
		setBlock(world, i + 21, j + 16, k + 16, Blocks.log, 0);
		setBlock(world, i + 21, j + 16, k + 17, Blocks.log, 0);
		setBlock(world, i + 21, j + 16, k + 18, Blocks.log, 0);
		setBlock(world, i + 21, j + 17, k + 14, Blocks.log, 0);
		setBlock(world, i + 21, j + 17, k + 15, Blocks.log, 0);
		setBlock(world, i + 21, j + 17, k + 16, Blocks.log, 0);
		setBlock(world, i + 21, j + 17, k + 17, Blocks.log, 0);
		setBlock(world, i + 21, j + 17, k + 18, Blocks.log, 0);
		setBlock(world, i + 21, j + 18, k + 14, Blocks.log, 0);
		setBlock(world, i + 21, j + 18, k + 15, Blocks.log, 0);
		setBlock(world, i + 21, j + 18, k + 16, Blocks.log, 0);
		setBlock(world, i + 21, j + 18, k + 17, Blocks.log, 0);
		setBlock(world, i + 21, j + 18, k + 18, Blocks.log, 0);
		setBlock(world, i + 21, j + 19, k + 14, Blocks.log, 0);
		setBlock(world, i + 21, j + 19, k + 15, Blocks.log, 0);
		setBlock(world, i + 21, j + 19, k + 16, Blocks.log, 0);
		setBlock(world, i + 21, j + 19, k + 17, Blocks.log, 0);
		setBlock(world, i + 21, j + 19, k + 18, Blocks.log, 0);
		setBlock(world, i + 21, j + 20, k + 14, Blocks.log, 0);
		setBlock(world, i + 21, j + 20, k + 15, Blocks.log, 0);
		setBlock(world, i + 21, j + 20, k + 16, Blocks.log, 0);
		setBlock(world, i + 21, j + 20, k + 17, Blocks.log, 0);
		setBlock(world, i + 21, j + 20, k + 18, Blocks.log, 0);
		setBlock(world, i + 21, j + 21, k + 14, Blocks.log, 0);
		setBlock(world, i + 21, j + 21, k + 15, Blocks.log, 0);
		setBlock(world, i + 21, j + 21, k + 16, Blocks.log, 0);
		setBlock(world, i + 21, j + 21, k + 17, Blocks.log, 0);
		setBlock(world, i + 21, j + 21, k + 18, Blocks.log, 0);
		setBlock(world, i + 21, j + 22, k + 14, Blocks.log, 0);
		setBlock(world, i + 21, j + 22, k + 15, Blocks.log, 0);
		setBlock(world, i + 21, j + 22, k + 16, Blocks.log, 0);
		setBlock(world, i + 21, j + 22, k + 17, Blocks.log, 0);
		setBlock(world, i + 21, j + 22, k + 18, Blocks.log, 0);
		setBlock(world, i + 21, j + 23, k + 15, Blocks.log, 0);
		setBlock(world, i + 21, j + 23, k + 16, Blocks.log, 0);
		setBlock(world, i + 21, j + 23, k + 17, Blocks.log, 0);
		setBlock(world, i + 21, j + 24, k + 15, Blocks.log, 0);
		setBlock(world, i + 21, j + 24, k + 16, Blocks.log, 0);
		setBlock(world, i + 21, j + 24, k + 17, Blocks.log, 0);
		setBlock(world, i + 21, j + 25, k + 15, Blocks.log, 0);
		setBlock(world, i + 21, j + 25, k + 16, Blocks.log, 0);
		setBlock(world, i + 21, j + 25, k + 17, Blocks.log, 0);
		setBlock(world, i + 21, j + 26, k + 15, Blocks.log, 0);
		setBlock(world, i + 21, j + 26, k + 16, Blocks.log, 0);
		setBlock(world, i + 21, j + 26, k + 17, Blocks.log, 0);
		setBlock(world, i + 21, j + 27, k + 15, Blocks.log, 0);
		setBlock(world, i + 21, j + 27, k + 16, Blocks.log, 0);
		setBlock(world, i + 21, j + 27, k + 17, Blocks.log, 0);
		setBlock(world, i + 21, j + 28, k + 15, Blocks.log, 0);
		setBlock(world, i + 21, j + 28, k + 16, Blocks.log, 0);
		setBlock(world, i + 21, j + 28, k + 17, Blocks.log, 0);
		setBlock(world, i + 21, j + 29, k + 16, Blocks.log, 0);
		setBlock(world, i + 21, j + 29, k + 17, Blocks.log, 0);
		setBlock(world, i + 21, j + 30, k + 16, Blocks.log, 0);
		setBlock(world, i + 21, j + 34, k + 10, Blocks.log, 0);
		setBlock(world, i + 21, j + 35, k + 9, Blocks.log, 0);
		setBlock(world, i + 21, j + 36, k + 8, Blocks.log, 0);
		setBlock(world, i + 21, j + 36, k + 16, Blocks.log, 0);
		setBlock(world, i + 21, j + 37, k + 7, Blocks.log, 0);
		setBlock(world, i + 21, j + 38, k + 6, Blocks.log, 0);
		setBlock(world, i + 21, j + 38, k + 14, Blocks.log, 0);
		setBlock(world, i + 21, j + 38, k + 16, Blocks.log, 0);
		setBlock(world, i + 21, j + 39, k + 5, Blocks.log, 0);
		setBlock(world, i + 21, j + 40, k + 4, Blocks.log, 0);
		setBlock(world, i + 21, j + 40, k + 6, Blocks.log, 0);
		setBlock(world, i + 21, j + 40, k + 16, Blocks.log, 0);
		setBlock(world, i + 21, j + 41, k + 14, Blocks.log, 0);
		setBlock(world, i + 21, j + 41, k + 24, Blocks.log, 0);
		setBlock(world, i + 21, j + 41, k + 25, Blocks.log, 0);
		setBlock(world, i + 21, j + 42, k + 9, Blocks.log, 0);
		setBlock(world, i + 21, j + 42, k + 13, Blocks.log, 0);
		setBlock(world, i + 21, j + 42, k + 15, Blocks.log, 0);
		setBlock(world, i + 21, j + 42, k + 17, Blocks.log, 0);
		setBlock(world, i + 21, j + 43, k + 9, Blocks.log, 0);
		setBlock(world, i + 21, j + 43, k + 12, Blocks.log, 0);
		setBlock(world, i + 21, j + 43, k + 14, Blocks.log, 0);
		setBlock(world, i + 21, j + 44, k + 12, Blocks.log, 0);
		setBlock(world, i + 21, j + 46, k + 13, Blocks.log, 0);
		setBlock(world, i + 21, j + 47, k + 7, Blocks.log, 0);
		setBlock(world, i + 21, j + 47, k + 8, Blocks.log, 0);
		setBlock(world, i + 21, j + 47, k + 13, Blocks.log, 0);
		setBlock(world, i + 21, j + 47, k + 18, Blocks.log, 0);
		setBlock(world, i + 21, j + 48, k + 17, Blocks.log, 0);
		setBlock(world, i + 21, j + 48, k + 21, Blocks.log, 0);
		setBlock(world, i + 21, j + 48, k + 22, Blocks.log, 0);
		setBlock(world, i + 22, j + 0, k + 14, Blocks.log, 0);
		setBlock(world, i + 22, j + 0, k + 15, Blocks.log, 0);
		setBlock(world, i + 22, j + 0, k + 16, Blocks.log, 0);
		setBlock(world, i + 22, j + 1, k + 14, Blocks.log, 0);
		setBlock(world, i + 22, j + 1, k + 15, Blocks.log, 0);
		setBlock(world, i + 22, j + 1, k + 16, Blocks.log, 0);
		setBlock(world, i + 22, j + 2, k + 14, Blocks.log, 0);
		setBlock(world, i + 22, j + 2, k + 15, Blocks.log, 0);
		setBlock(world, i + 22, j + 2, k + 16, Blocks.log, 0);
		setBlock(world, i + 22, j + 3, k + 14, Blocks.log, 0);
		setBlock(world, i + 22, j + 3, k + 15, Blocks.log, 0);
		setBlock(world, i + 22, j + 3, k + 16, Blocks.log, 0);
		setBlock(world, i + 22, j + 4, k + 14, Blocks.log, 0);
		setBlock(world, i + 22, j + 4, k + 15, Blocks.log, 0);
		setBlock(world, i + 22, j + 4, k + 16, Blocks.log, 0);
		setBlock(world, i + 22, j + 5, k + 14, Blocks.log, 0);
		setBlock(world, i + 22, j + 5, k + 15, Blocks.log, 0);
		setBlock(world, i + 22, j + 5, k + 16, Blocks.log, 0);
		setBlock(world, i + 22, j + 6, k + 14, Blocks.log, 0);
		setBlock(world, i + 22, j + 6, k + 15, Blocks.log, 0);
		setBlock(world, i + 22, j + 6, k + 16, Blocks.log, 0);
		setBlock(world, i + 22, j + 7, k + 14, Blocks.log, 0);
		setBlock(world, i + 22, j + 7, k + 15, Blocks.log, 0);
		setBlock(world, i + 22, j + 7, k + 16, Blocks.log, 0);
		setBlock(world, i + 22, j + 8, k + 15, Blocks.log, 0);
		setBlock(world, i + 22, j + 8, k + 16, Blocks.log, 0);
		setBlock(world, i + 22, j + 9, k + 15, Blocks.log, 0);
		setBlock(world, i + 22, j + 9, k + 16, Blocks.log, 0);
		setBlock(world, i + 22, j + 10, k + 15, Blocks.log, 0);
		setBlock(world, i + 22, j + 10, k + 16, Blocks.log, 0);
		setBlock(world, i + 22, j + 10, k + 17, Blocks.log, 0);
		setBlock(world, i + 22, j + 11, k + 15, Blocks.log, 0);
		setBlock(world, i + 22, j + 11, k + 16, Blocks.log, 0);
		setBlock(world, i + 22, j + 11, k + 17, Blocks.log, 0);
		setBlock(world, i + 22, j + 12, k + 15, Blocks.log, 0);
		setBlock(world, i + 22, j + 12, k + 16, Blocks.log, 0);
		setBlock(world, i + 22, j + 12, k + 17, Blocks.log, 0);
		setBlock(world, i + 22, j + 13, k + 15, Blocks.log, 0);
		setBlock(world, i + 22, j + 13, k + 16, Blocks.log, 0);
		setBlock(world, i + 22, j + 13, k + 17, Blocks.log, 0);
		setBlock(world, i + 22, j + 13, k + 18, Blocks.log, 0);
		setBlock(world, i + 22, j + 14, k + 15, Blocks.log, 0);
		setBlock(world, i + 22, j + 14, k + 16, Blocks.log, 0);
		setBlock(world, i + 22, j + 14, k + 17, Blocks.log, 0);
		setBlock(world, i + 22, j + 14, k + 18, Blocks.log, 0);
		setBlock(world, i + 22, j + 15, k + 15, Blocks.log, 0);
		setBlock(world, i + 22, j + 15, k + 16, Blocks.log, 0);
		setBlock(world, i + 22, j + 15, k + 17, Blocks.log, 0);
		setBlock(world, i + 22, j + 15, k + 18, Blocks.log, 0);
		setBlock(world, i + 22, j + 16, k + 15, Blocks.log, 0);
		setBlock(world, i + 22, j + 16, k + 16, Blocks.log, 0);
		setBlock(world, i + 22, j + 16, k + 17, Blocks.log, 0);
		setBlock(world, i + 22, j + 17, k + 15, Blocks.log, 0);
		setBlock(world, i + 22, j + 17, k + 16, Blocks.log, 0);
		setBlock(world, i + 22, j + 17, k + 17, Blocks.log, 0);
		setBlock(world, i + 22, j + 18, k + 15, Blocks.log, 0);
		setBlock(world, i + 22, j + 18, k + 16, Blocks.log, 0);
		setBlock(world, i + 22, j + 18, k + 17, Blocks.log, 0);
		setBlock(world, i + 22, j + 19, k + 15, Blocks.log, 0);
		setBlock(world, i + 22, j + 19, k + 16, Blocks.log, 0);
		setBlock(world, i + 22, j + 19, k + 17, Blocks.log, 0);
		setBlock(world, i + 22, j + 20, k + 15, Blocks.log, 0);
		setBlock(world, i + 22, j + 20, k + 16, Blocks.log, 0);
		setBlock(world, i + 22, j + 20, k + 17, Blocks.log, 0);
		setBlock(world, i + 22, j + 21, k + 15, Blocks.log, 0);
		setBlock(world, i + 22, j + 21, k + 16, Blocks.log, 0);
		setBlock(world, i + 22, j + 21, k + 17, Blocks.log, 0);
		setBlock(world, i + 22, j + 22, k + 15, Blocks.log, 0);
		setBlock(world, i + 22, j + 22, k + 16, Blocks.log, 0);
		setBlock(world, i + 22, j + 22, k + 17, Blocks.log, 0);
		setBlock(world, i + 22, j + 23, k + 16, Blocks.log, 0);
		setBlock(world, i + 22, j + 24, k + 16, Blocks.log, 0);
		setBlock(world, i + 22, j + 25, k + 16, Blocks.log, 0);
		setBlock(world, i + 22, j + 26, k + 16, Blocks.log, 0);
		setBlock(world, i + 22, j + 30, k + 15, Blocks.log, 0);
		setBlock(world, i + 22, j + 31, k + 14, Blocks.log, 0);
		setBlock(world, i + 22, j + 40, k + 12, Blocks.log, 0);
		setBlock(world, i + 22, j + 41, k + 3, Blocks.log, 0);
		setBlock(world, i + 22, j + 42, k + 23, Blocks.log, 0);
		setBlock(world, i + 22, j + 42, k + 24, Blocks.log, 0);
		setBlock(world, i + 22, j + 43, k + 14, Blocks.log, 0);
		setBlock(world, i + 22, j + 43, k + 18, Blocks.log, 0);
		setBlock(world, i + 22, j + 44, k + 11, Blocks.log, 0);
		setBlock(world, i + 22, j + 44, k + 12, Blocks.log, 0);
		setBlock(world, i + 22, j + 44, k + 13, Blocks.log, 0);
		setBlock(world, i + 22, j + 46, k + 13, Blocks.log, 0);
		setBlock(world, i + 22, j + 47, k + 11, Blocks.log, 0);
		setBlock(world, i + 22, j + 47, k + 13, Blocks.log, 0);
		setBlock(world, i + 22, j + 47, k + 24, Blocks.log, 0);
		setBlock(world, i + 22, j + 48, k + 16, Blocks.log, 0);
		setBlock(world, i + 23, j + 40, k + 13, Blocks.log, 0);
		setBlock(world, i + 23, j + 41, k + 5, Blocks.log, 0);
		setBlock(world, i + 23, j + 41, k + 11, Blocks.log, 0);
		setBlock(world, i + 23, j + 41, k + 20, Blocks.log, 0);
		setBlock(world, i + 23, j + 41, k + 24, Blocks.log, 0);
		setBlock(world, i + 23, j + 43, k + 3, Blocks.log, 0);
		setBlock(world, i + 23, j + 43, k + 18, Blocks.log, 0);
		setBlock(world, i + 23, j + 44, k + 15, Blocks.log, 0);
		setBlock(world, i + 23, j + 44, k + 18, Blocks.log, 0);
		setBlock(world, i + 23, j + 44, k + 19, Blocks.log, 0);
		setBlock(world, i + 23, j + 45, k + 12, Blocks.log, 0);
		setBlock(world, i + 23, j + 45, k + 14, Blocks.log, 0);
		setBlock(world, i + 23, j + 45, k + 19, Blocks.log, 0);
		setBlock(world, i + 23, j + 46, k + 12, Blocks.log, 0);
		setBlock(world, i + 23, j + 47, k + 20, Blocks.log, 0);
		setBlock(world, i + 23, j + 48, k + 13, Blocks.log, 0);
		setBlock(world, i + 23, j + 48, k + 16, Blocks.log, 0);
		setBlock(world, i + 23, j + 48, k + 18, Blocks.log, 0);
		setBlock(world, i + 24, j + 43, k + 23, Blocks.log, 0);
		setBlock(world, i + 24, j + 44, k + 19, Blocks.log, 0);
		setBlock(world, i + 24, j + 44, k + 21, Blocks.log, 0);
		setBlock(world, i + 24, j + 45, k + 18, Blocks.log, 0);
		setBlock(world, i + 24, j + 46, k + 11, Blocks.log, 0);
		setBlock(world, i + 24, j + 46, k + 17, Blocks.log, 0);
		setBlock(world, i + 24, j + 46, k + 19, Blocks.log, 0);
		setBlock(world, i + 24, j + 47, k + 19, Blocks.log, 0);
		setBlock(world, i + 24, j + 48, k + 17, Blocks.log, 0);
		setBlock(world, i + 24, j + 48, k + 22, Blocks.log, 0);
		setBlock(world, i + 25, j + 35, k + 11, Blocks.log, 0);
		setBlock(world, i + 25, j + 41, k + 11, Blocks.log, 0);
		setBlock(world, i + 25, j + 41, k + 17, Blocks.log, 0);
		setBlock(world, i + 25, j + 45, k + 15, Blocks.log, 0);
		setBlock(world, i + 25, j + 45, k + 16, Blocks.log, 0);
		setBlock(world, i + 25, j + 45, k + 19, Blocks.log, 0);
		setBlock(world, i + 25, j + 46, k + 11, Blocks.log, 0);
		setBlock(world, i + 25, j + 47, k + 17, Blocks.log, 0);
		setBlock(world, i + 25, j + 48, k + 14, Blocks.log, 0);
		setBlock(world, i + 25, j + 48, k + 15, Blocks.log, 0);
		setBlock(world, i + 25, j + 48, k + 19, Blocks.log, 0);
		setBlock(world, i + 26, j + 40, k + 33, Blocks.log, 0);
		setBlock(world, i + 26, j + 41, k + 14, Blocks.log, 0);
		setBlock(world, i + 26, j + 42, k + 20, Blocks.log, 0);
		setBlock(world, i + 26, j + 43, k + 14, Blocks.log, 0);
		setBlock(world, i + 26, j + 43, k + 18, Blocks.log, 0);
		setBlock(world, i + 26, j + 45, k + 14, Blocks.log, 0);
		setBlock(world, i + 26, j + 46, k + 16, Blocks.log, 0);
		setBlock(world, i + 26, j + 47, k + 17, Blocks.log, 0);
		setBlock(world, i + 26, j + 48, k + 21, Blocks.log, 0);
		setBlock(world, i + 27, j + 38, k + 8, Blocks.log, 0);
		setBlock(world, i + 27, j + 41, k + 14, Blocks.log, 0);
		setBlock(world, i + 27, j + 41, k + 20, Blocks.log, 0);
		setBlock(world, i + 27, j + 41, k + 23, Blocks.log, 0);
		setBlock(world, i + 27, j + 42, k + 2, Blocks.log, 0);
		setBlock(world, i + 27, j + 42, k + 15, Blocks.log, 0);
		setBlock(world, i + 27, j + 43, k + 23, Blocks.log, 0);
		setBlock(world, i + 27, j + 45, k + 15, Blocks.log, 0);
		setBlock(world, i + 27, j + 45, k + 18, Blocks.log, 0);
		setBlock(world, i + 27, j + 46, k + 17, Blocks.log, 0);
		setBlock(world, i + 28, j + 39, k + 7, Blocks.log, 0);
		setBlock(world, i + 28, j + 40, k + 13, Blocks.log, 0);
		setBlock(world, i + 28, j + 42, k + 23, Blocks.log, 0);
		setBlock(world, i + 28, j + 43, k + 13, Blocks.log, 0);
		setBlock(world, i + 28, j + 46, k + 12, Blocks.log, 0);
		setBlock(world, i + 29, j + 39, k + 24, Blocks.log, 0);
		setBlock(world, i + 29, j + 41, k + 17, Blocks.log, 0);
		setBlock(world, i + 29, j + 41, k + 23, Blocks.log, 0);
		setBlock(world, i + 29, j + 43, k + 20, Blocks.log, 0);
		setBlock(world, i + 29, j + 44, k + 22, Blocks.log, 0);
		setBlock(world, i + 29, j + 47, k + 16, Blocks.log, 0);
		setBlock(world, i + 30, j + 39, k + 16, Blocks.log, 0);
		setBlock(world, i + 30, j + 42, k + 16, Blocks.log, 0);
		setBlock(world, i + 30, j + 44, k + 13, Blocks.log, 0);
		setBlock(world, i + 30, j + 44, k + 14, Blocks.log, 0);
		setBlock(world, i + 30, j + 44, k + 21, Blocks.log, 0);
		setBlock(world, i + 31, j + 39, k + 23, Blocks.log, 0);
		setBlock(world, i + 31, j + 42, k + 13, Blocks.log, 0);
		setBlock(world, i + 32, j + 40, k + 9, Blocks.log, 0);
		setBlock(world, i + 32, j + 40, k + 15, Blocks.log, 0);
		setBlock(world, i + 33, j + 40, k + 23, Blocks.log, 0);
		setBlock(world, i + 33, j + 43, k + 15, Blocks.log, 0);
		setBlock(world, i + 33, j + 43, k + 16, Blocks.log, 0);
		setBlock(world, i + 34, j + 40, k + 26, Blocks.log, 0);
		setBlock(world, i + 34, j + 41, k + 15, Blocks.log, 0);
		setBlock(world, i + 34, j + 42, k + 23, Blocks.log, 0);
		setBlock(world, i + 0, j + 37, k + 18, Blocks.leaves, 4);
		world.setBlockMetadataWithNotify(i + 0, j + 37, k + 18, 4, 2);
		setBlock(world, i + 0, j + 39, k + 19, Blocks.leaves, 4);
		world.setBlockMetadataWithNotify(i + 0, j + 39, k + 19, 4, 2);
		setBlock(world, i + 0, j + 39, k + 20, Blocks.leaves, 4);
		world.setBlockMetadataWithNotify(i + 0, j + 39, k + 20, 4, 2);
		setBlock(world, i + 0, j + 39, k + 21, Blocks.leaves, 4);
		world.setBlockMetadataWithNotify(i + 0, j + 39, k + 21, 4, 2);
		setBlock(world, i + 0, j + 40, k + 20, Blocks.leaves, 4);
		world.setBlockMetadataWithNotify(i + 0, j + 40, k + 20, 4, 2);
		setBlock(world, i + 1, j + 36, k + 18, Blocks.leaves, 4);
		world.setBlockMetadataWithNotify(i + 1, j + 36, k + 18, 4, 2);
		setBlock(world, i + 1, j + 37, k + 17, Blocks.leaves, 4);
		world.setBlockMetadataWithNotify(i + 1, j + 37, k + 17, 4, 2);
		setBlock(world, i + 1, j + 37, k + 18, Blocks.leaves, 4);
		world.setBlockMetadataWithNotify(i + 1, j + 37, k + 18, 4, 2);
		setBlock(world, i + 1, j + 37, k + 19, Blocks.leaves, 4);
		world.setBlockMetadataWithNotify(i + 1, j + 37, k + 19, 4, 2);
		setBlock(world, i + 1, j + 38, k + 18, Blocks.leaves, 4);
		world.setBlockMetadataWithNotify(i + 1, j + 38, k + 18, 4, 2);
		setBlock(world, i + 1, j + 39, k + 18, Blocks.leaves, 4);
		world.setBlockMetadataWithNotify(i + 1, j + 39, k + 18, 4, 2);
		setBlock(world, i + 1, j + 39, k + 19, Blocks.leaves, 4);
		world.setBlockMetadataWithNotify(i + 1, j + 39, k + 19, 4, 2);
		setBlock(world, i + 1, j + 39, k + 20, Blocks.leaves, 4);
		world.setBlockMetadataWithNotify(i + 1, j + 39, k + 20, 4, 2);
		setBlock(world, i + 1, j + 39, k + 21, Blocks.leaves, 4);
		world.setBlockMetadataWithNotify(i + 1, j + 39, k + 21, 4, 2);
		setBlock(world, i + 1, j + 39, k + 22, Blocks.leaves, 4);
		world.setBlockMetadataWithNotify(i + 1, j + 39, k + 22, 4, 2);
		setBlock(world, i + 1, j + 40, k + 19, Blocks.leaves, 4);
		world.setBlockMetadataWithNotify(i + 1, j + 40, k + 19, 4, 2);
		setBlock(world, i + 1, j + 40, k + 20, Blocks.leaves, 4);
		world.setBlockMetadataWithNotify(i + 1, j + 40, k + 20, 4, 2);
		setBlock(world, i + 1, j + 40, k + 21, Blocks.leaves, 4);
		world.setBlockMetadataWithNotify(i + 1, j + 40, k + 21, 4, 2);
		setBlock(world, i + 2, j + 36, k + 18, Blocks.leaves, 4);
		world.setBlockMetadataWithNotify(i + 2, j + 36, k + 18, 4, 2);
		setBlock(world, i + 2, j + 37, k + 17, Blocks.leaves, 4);
		world.setBlockMetadataWithNotify(i + 2, j + 37, k + 17, 4, 2);
		setBlock(world, i + 2, j + 37, k + 18, Blocks.leaves, 4);
		world.setBlockMetadataWithNotify(i + 2, j + 37, k + 18, 4, 2);
		setBlock(world, i + 2, j + 37, k + 19, Blocks.leaves, 4);
		world.setBlockMetadataWithNotify(i + 2, j + 37, k + 19, 4, 2);
		setBlock(world, i + 2, j + 38, k + 18, Blocks.leaves, 4);
		world.setBlockMetadataWithNotify(i + 2, j + 38, k + 18, 4, 2);
		setBlock(world, i + 2, j + 39, k + 18, Blocks.leaves, 4);
		world.setBlockMetadataWithNotify(i + 2, j + 39, k + 18, 4, 2);
		setBlock(world, i + 2, j + 39, k + 19, Blocks.leaves, 4);
		world.setBlockMetadataWithNotify(i + 2, j + 39, k + 19, 4, 2);
		setBlock(world, i + 2, j + 39, k + 21, Blocks.leaves, 4);
		world.setBlockMetadataWithNotify(i + 2, j + 39, k + 21, 4, 2);
		setBlock(world, i + 2, j + 39, k + 22, Blocks.leaves, 4);
		world.setBlockMetadataWithNotify(i + 2, j + 39, k + 22, 4, 2);
		setBlock(world, i + 2, j + 40, k + 18, Blocks.leaves, 4);
		world.setBlockMetadataWithNotify(i + 2, j + 40, k + 18, 4, 2);
		setBlock(world, i + 2, j + 40, k + 19, Blocks.leaves, 4);
		world.setBlockMetadataWithNotify(i + 2, j + 40, k + 19, 4, 2);
		setBlock(world, i + 2, j + 40, k + 20, Blocks.leaves, 4);
		world.setBlockMetadataWithNotify(i + 2, j + 40, k + 20, 4, 2);
		setBlock(world, i + 2, j + 40, k + 21, Blocks.leaves, 4);
		world.setBlockMetadataWithNotify(i + 2, j + 40, k + 21, 4, 2);
		setBlock(world, i + 2, j + 40, k + 22, Blocks.leaves, 4);
		world.setBlockMetadataWithNotify(i + 2, j + 40, k + 22, 4, 2);
		setBlock(world, i + 2, j + 42, k + 9, Blocks.leaves, 4);
		world.setBlockMetadataWithNotify(i + 2, j + 42, k + 9, 4, 2);
		setBlock(world, i + 2, j + 42, k + 10, Blocks.leaves, 4);
		world.setBlockMetadataWithNotify(i + 2, j + 42, k + 10, 4, 2);
		setBlock(world, i + 2, j + 42, k + 11, Blocks.leaves, 4);
		world.setBlockMetadataWithNotify(i + 2, j + 42, k + 11, 4, 2);
		setBlock(world, i + 2, j + 42, k + 21, Blocks.leaves, 4);
		world.setBlockMetadataWithNotify(i + 2, j + 42, k + 21, 4, 2);
		setBlock(world, i + 2, j + 42, k + 22, Blocks.leaves, 4);
		world.setBlockMetadataWithNotify(i + 2, j + 42, k + 22, 4, 2);
		setBlock(world, i + 2, j + 42, k + 23, Blocks.leaves, 4);
		world.setBlockMetadataWithNotify(i + 2, j + 42, k + 23, 4, 2);
		setBlock(world, i + 2, j + 43, k + 10, Blocks.leaves, 4);
		world.setBlockMetadataWithNotify(i + 2, j + 43, k + 10, 4, 2);
		setBlock(world, i + 2, j + 43, k + 22, Blocks.leaves, 4);
		world.setBlockMetadataWithNotify(i + 2, j + 43, k + 22, 4, 2);
		setBlock(world, i + 3, j + 36, k + 19, Blocks.leaves, 4);
		world.setBlockMetadataWithNotify(i + 3, j + 36, k + 19, 4, 2);
		setBlock(world, i + 3, j + 37, k + 18, Blocks.leaves, 4);
		world.setBlockMetadataWithNotify(i + 3, j + 37, k + 18, 4, 2);
		setBlock(world, i + 3, j + 37, k + 19, Blocks.leaves, 4);
		world.setBlockMetadataWithNotify(i + 3, j + 37, k + 19, 4, 2);
		setBlock(world, i + 3, j + 37, k + 20, Blocks.leaves, 4);
		world.setBlockMetadataWithNotify(i + 3, j + 37, k + 20, 4, 2);
		setBlock(world, i + 3, j + 38, k + 18, Blocks.leaves, 4);
		world.setBlockMetadataWithNotify(i + 3, j + 38, k + 18, 4, 2);
		setBlock(world, i + 3, j + 38, k + 19, Blocks.leaves, 4);
		world.setBlockMetadataWithNotify(i + 3, j + 38, k + 19, 4, 2);
		setBlock(world, i + 3, j + 39, k + 18, Blocks.leaves, 4);
		world.setBlockMetadataWithNotify(i + 3, j + 39, k + 18, 4, 2);
		setBlock(world, i + 3, j + 39, k + 19, Blocks.leaves, 4);
		world.setBlockMetadataWithNotify(i + 3, j + 39, k + 19, 4, 2);
		setBlock(world, i + 3, j + 39, k + 20, Blocks.leaves, 4);
		world.setBlockMetadataWithNotify(i + 3, j + 39, k + 20, 4, 2);
		setBlock(world, i + 3, j + 39, k + 21, Blocks.leaves, 4);
		world.setBlockMetadataWithNotify(i + 3, j + 39, k + 21, 4, 2);
		setBlock(world, i + 3, j + 39, k + 22, Blocks.leaves, 4);
		world.setBlockMetadataWithNotify(i + 3, j + 39, k + 22, 4, 2);
		setBlock(world, i + 3, j + 40, k + 17, Blocks.leaves, 4);
		world.setBlockMetadataWithNotify(i + 3, j + 40, k + 17, 4, 2);
		setBlock(world, i + 3, j + 40, k + 19, Blocks.leaves, 4);
		world.setBlockMetadataWithNotify(i + 3, j + 40, k + 19, 4, 2);
		setBlock(world, i + 3, j + 40, k + 20, Blocks.leaves, 4);
		world.setBlockMetadataWithNotify(i + 3, j + 40, k + 20, 4, 2);
		setBlock(world, i + 3, j + 40, k + 21, Blocks.leaves, 4);
		world.setBlockMetadataWithNotify(i + 3, j + 40, k + 21, 4, 2);
		setBlock(world, i + 3, j + 42, k + 8, Blocks.leaves, 4);
		world.setBlockMetadataWithNotify(i + 3, j + 42, k + 8, 4, 2);
		setBlock(world, i + 3, j + 42, k + 9, Blocks.leaves, 4);
		world.setBlockMetadataWithNotify(i + 3, j + 42, k + 9, 4, 2);
		setBlock(world, i + 3, j + 42, k + 10, Blocks.leaves, 4);
		world.setBlockMetadataWithNotify(i + 3, j + 42, k + 10, 4, 2);
		setBlock(world, i + 3, j + 42, k + 11, Blocks.leaves, 4);
		world.setBlockMetadataWithNotify(i + 3, j + 42, k + 11, 4, 2);
		setBlock(world, i + 3, j + 42, k + 12, Blocks.leaves, 4);
		world.setBlockMetadataWithNotify(i + 3, j + 42, k + 12, 4, 2);
		setBlock(world, i + 3, j + 42, k + 20, Blocks.leaves, 4);
		world.setBlockMetadataWithNotify(i + 3, j + 42, k + 20, 4, 2);
		setBlock(world, i + 3, j + 42, k + 21, Blocks.leaves, 4);
		world.setBlockMetadataWithNotify(i + 3, j + 42, k + 21, 4, 2);
		setBlock(world, i + 3, j + 42, k + 22, Blocks.leaves, 4);
		world.setBlockMetadataWithNotify(i + 3, j + 42, k + 22, 4, 2);
		setBlock(world, i + 3, j + 42, k + 23, Blocks.leaves, 4);
		world.setBlockMetadataWithNotify(i + 3, j + 42, k + 23, 4, 2);
		setBlock(world, i + 3, j + 42, k + 24, Blocks.leaves, 4);
		world.setBlockMetadataWithNotify(i + 3, j + 42, k + 24, 4, 2);
		setBlock(world, i + 3, j + 43, k + 9, Blocks.leaves, 4);
		world.setBlockMetadataWithNotify(i + 3, j + 43, k + 9, 4, 2);
		setBlock(world, i + 3, j + 43, k + 10, Blocks.leaves, 4);
		world.setBlockMetadataWithNotify(i + 3, j + 43, k + 10, 4, 2);
		setBlock(world, i + 3, j + 43, k + 11, Blocks.leaves, 4);
		world.setBlockMetadataWithNotify(i + 3, j + 43, k + 11, 4, 2);
		setBlock(world, i + 3, j + 43, k + 21, Blocks.leaves, 4);
		world.setBlockMetadataWithNotify(i + 3, j + 43, k + 21, 4, 2);
		setBlock(world, i + 3, j + 43, k + 22, Blocks.leaves, 4);
		world.setBlockMetadataWithNotify(i + 3, j + 43, k + 22, 4, 2);
		setBlock(world, i + 3, j + 43, k + 23, Blocks.leaves, 4);
		world.setBlockMetadataWithNotify(i + 3, j + 43, k + 23, 4, 2);
		setBlock(world, i + 3, j + 45, k + 11, Blocks.leaves, 4);
		world.setBlockMetadataWithNotify(i + 3, j + 45, k + 11, 4, 2);
		setBlock(world, i + 4, j + 36, k + 19, Blocks.leaves, 4);
		world.setBlockMetadataWithNotify(i + 4, j + 36, k + 19, 4, 2);
		setBlock(world, i + 4, j + 37, k + 18, Blocks.leaves, 4);
		world.setBlockMetadataWithNotify(i + 4, j + 37, k + 18, 4, 2);
		setBlock(world, i + 4, j + 37, k + 19, Blocks.leaves, 4);
		world.setBlockMetadataWithNotify(i + 4, j + 37, k + 19, 4, 2);
		setBlock(world, i + 4, j + 37, k + 20, Blocks.leaves, 4);
		world.setBlockMetadataWithNotify(i + 4, j + 37, k + 20, 4, 2);
		setBlock(world, i + 4, j + 38, k + 17, Blocks.leaves, 4);
		world.setBlockMetadataWithNotify(i + 4, j + 38, k + 17, 4, 2);
		setBlock(world, i + 4, j + 38, k + 18, Blocks.leaves, 4);
		world.setBlockMetadataWithNotify(i + 4, j + 38, k + 18, 4, 2);
		setBlock(world, i + 4, j + 38, k + 19, Blocks.leaves, 4);
		world.setBlockMetadataWithNotify(i + 4, j + 38, k + 19, 4, 2);
		setBlock(world, i + 4, j + 39, k + 17, Blocks.leaves, 4);
		world.setBlockMetadataWithNotify(i + 4, j + 39, k + 17, 4, 2);
		setBlock(world, i + 4, j + 39, k + 18, Blocks.leaves, 4);
		world.setBlockMetadataWithNotify(i + 4, j + 39, k + 18, 4, 2);
		setBlock(world, i + 4, j + 39, k + 19, Blocks.leaves, 4);
		world.setBlockMetadataWithNotify(i + 4, j + 39, k + 19, 4, 2);
		setBlock(world, i + 4, j + 39, k + 20, Blocks.leaves, 4);
		world.setBlockMetadataWithNotify(i + 4, j + 39, k + 20, 4, 2);
		setBlock(world, i + 4, j + 39, k + 21, Blocks.leaves, 4);
		world.setBlockMetadataWithNotify(i + 4, j + 39, k + 21, 4, 2);
		setBlock(world, i + 4, j + 40, k + 16, Blocks.leaves, 4);
		world.setBlockMetadataWithNotify(i + 4, j + 40, k + 16, 4, 2);
		setBlock(world, i + 4, j + 40, k + 17, Blocks.leaves, 4);
		world.setBlockMetadataWithNotify(i + 4, j + 40, k + 17, 4, 2);
		setBlock(world, i + 4, j + 40, k + 18, Blocks.leaves, 4);
		world.setBlockMetadataWithNotify(i + 4, j + 40, k + 18, 4, 2);
		setBlock(world, i + 4, j + 40, k + 20, Blocks.leaves, 4);
		world.setBlockMetadataWithNotify(i + 4, j + 40, k + 20, 4, 2);
		setBlock(world, i + 4, j + 41, k + 17, Blocks.leaves, 4);
		world.setBlockMetadataWithNotify(i + 4, j + 41, k + 17, 4, 2);
		setBlock(world, i + 4, j + 42, k + 8, Blocks.leaves, 4);
		world.setBlockMetadataWithNotify(i + 4, j + 42, k + 8, 4, 2);
		setBlock(world, i + 4, j + 42, k + 9, Blocks.leaves, 4);
		world.setBlockMetadataWithNotify(i + 4, j + 42, k + 9, 4, 2);
		setBlock(world, i + 4, j + 42, k + 11, Blocks.leaves, 4);
		world.setBlockMetadataWithNotify(i + 4, j + 42, k + 11, 4, 2);
		setBlock(world, i + 4, j + 42, k + 12, Blocks.leaves, 4);
		world.setBlockMetadataWithNotify(i + 4, j + 42, k + 12, 4, 2);
		setBlock(world, i + 4, j + 42, k + 20, Blocks.leaves, 4);
		world.setBlockMetadataWithNotify(i + 4, j + 42, k + 20, 4, 2);
		setBlock(world, i + 4, j + 42, k + 21, Blocks.leaves, 4);
		world.setBlockMetadataWithNotify(i + 4, j + 42, k + 21, 4, 2);
		setBlock(world, i + 4, j + 42, k + 23, Blocks.leaves, 4);
		world.setBlockMetadataWithNotify(i + 4, j + 42, k + 23, 4, 2);
		setBlock(world, i + 4, j + 42, k + 24, Blocks.leaves, 4);
		world.setBlockMetadataWithNotify(i + 4, j + 42, k + 24, 4, 2);
		setBlock(world, i + 4, j + 43, k + 8, Blocks.leaves, 4);
		world.setBlockMetadataWithNotify(i + 4, j + 43, k + 8, 4, 2);
		setBlock(world, i + 4, j + 43, k + 9, Blocks.leaves, 4);
		world.setBlockMetadataWithNotify(i + 4, j + 43, k + 9, 4, 2);
		setBlock(world, i + 4, j + 43, k + 10, Blocks.leaves, 4);
		world.setBlockMetadataWithNotify(i + 4, j + 43, k + 10, 4, 2);
		setBlock(world, i + 4, j + 43, k + 11, Blocks.leaves, 4);
		world.setBlockMetadataWithNotify(i + 4, j + 43, k + 11, 4, 2);
		setBlock(world, i + 4, j + 43, k + 12, Blocks.leaves, 4);
		world.setBlockMetadataWithNotify(i + 4, j + 43, k + 12, 4, 2);
		setBlock(world, i + 4, j + 43, k + 20, Blocks.leaves, 4);
		world.setBlockMetadataWithNotify(i + 4, j + 43, k + 20, 4, 2);
		setBlock(world, i + 4, j + 43, k + 21, Blocks.leaves, 4);
		world.setBlockMetadataWithNotify(i + 4, j + 43, k + 21, 4, 2);
		setBlock(world, i + 4, j + 43, k + 22, Blocks.leaves, 4);
		world.setBlockMetadataWithNotify(i + 4, j + 43, k + 22, 4, 2);
		setBlock(world, i + 4, j + 43, k + 23, Blocks.leaves, 4);
		world.setBlockMetadataWithNotify(i + 4, j + 43, k + 23, 4, 2);
		setBlock(world, i + 4, j + 43, k + 24, Blocks.leaves, 4);
		world.setBlockMetadataWithNotify(i + 4, j + 43, k + 24, 4, 2);
		setBlock(world, i + 4, j + 44, k + 11, Blocks.leaves, 4);
		world.setBlockMetadataWithNotify(i + 4, j + 44, k + 11, 4, 2);
		setBlock(world, i + 4, j + 45, k + 10, Blocks.leaves, 4);
		world.setBlockMetadataWithNotify(i + 4, j + 45, k + 10, 4, 2);
		setBlock(world, i + 4, j + 45, k + 11, Blocks.leaves, 4);
		world.setBlockMetadataWithNotify(i + 4, j + 45, k + 11, 4, 2);
		setBlock(world, i + 4, j + 45, k + 12, Blocks.leaves, 4);
		world.setBlockMetadataWithNotify(i + 4, j + 45, k + 12, 4, 2);
		setBlock(world, i + 4, j + 46, k + 11, Blocks.leaves, 4);
		world.setBlockMetadataWithNotify(i + 4, j + 46, k + 11, 4, 2);
		setBlock(world, i + 5, j + 35, k + 19, Blocks.leaves, 4);
		world.setBlockMetadataWithNotify(i + 5, j + 35, k + 19, 4, 2);
		setBlock(world, i + 5, j + 36, k + 15, Blocks.leaves, 4);
		world.setBlockMetadataWithNotify(i + 5, j + 36, k + 15, 4, 2);
		setBlock(world, i + 5, j + 36, k + 18, Blocks.leaves, 4);
		world.setBlockMetadataWithNotify(i + 5, j + 36, k + 18, 4, 2);
		setBlock(world, i + 5, j + 36, k + 19, Blocks.leaves, 4);
		world.setBlockMetadataWithNotify(i + 5, j + 36, k + 19, 4, 2);
		setBlock(world, i + 5, j + 36, k + 20, Blocks.leaves, 4);
		world.setBlockMetadataWithNotify(i + 5, j + 36, k + 20, 4, 2);
		setBlock(world, i + 5, j + 37, k + 17, Blocks.leaves, 4);
		world.setBlockMetadataWithNotify(i + 5, j + 37, k + 17, 4, 2);
		setBlock(world, i + 5, j + 37, k + 18, Blocks.leaves, 4);
		world.setBlockMetadataWithNotify(i + 5, j + 37, k + 18, 4, 2);
		setBlock(world, i + 5, j + 37, k + 19, Blocks.leaves, 4);
		world.setBlockMetadataWithNotify(i + 5, j + 37, k + 19, 4, 2);
		setBlock(world, i + 5, j + 37, k + 22, Blocks.leaves, 4);
		world.setBlockMetadataWithNotify(i + 5, j + 37, k + 22, 4, 2);
		setBlock(world, i + 5, j + 38, k + 10, Blocks.leaves, 4);
		world.setBlockMetadataWithNotify(i + 5, j + 38, k + 10, 4, 2);
		setBlock(world, i + 5, j + 38, k + 11, Blocks.leaves, 4);
		world.setBlockMetadataWithNotify(i + 5, j + 38, k + 11, 4, 2);
		setBlock(world, i + 5, j + 38, k + 16, Blocks.leaves, 4);
		world.setBlockMetadataWithNotify(i + 5, j + 38, k + 16, 4, 2);
		setBlock(world, i + 5, j + 38, k + 17, Blocks.leaves, 4);
		world.setBlockMetadataWithNotify(i + 5, j + 38, k + 17, 4, 2);
		setBlock(world, i + 5, j + 38, k + 18, Blocks.leaves, 4);
		world.setBlockMetadataWithNotify(i + 5, j + 38, k + 18, 4, 2);
		setBlock(world, i + 5, j + 39, k + 11, Blocks.leaves, 4);
		world.setBlockMetadataWithNotify(i + 5, j + 39, k + 11, 4, 2);
		setBlock(world, i + 5, j + 39, k + 17, Blocks.leaves, 4);
		world.setBlockMetadataWithNotify(i + 5, j + 39, k + 17, 4, 2);
		setBlock(world, i + 5, j + 40, k + 17, Blocks.leaves, 4);
		world.setBlockMetadataWithNotify(i + 5, j + 40, k + 17, 4, 2);
		setBlock(world, i + 5, j + 42, k + 8, Blocks.leaves, 4);
		world.setBlockMetadataWithNotify(i + 5, j + 42, k + 8, 4, 2);
		setBlock(world, i + 5, j + 42, k + 9, Blocks.leaves, 4);
		world.setBlockMetadataWithNotify(i + 5, j + 42, k + 9, 4, 2);
		setBlock(world, i + 5, j + 42, k + 10, Blocks.leaves, 4);
		world.setBlockMetadataWithNotify(i + 5, j + 42, k + 10, 4, 2);
		setBlock(world, i + 5, j + 42, k + 11, Blocks.leaves, 4);
		world.setBlockMetadataWithNotify(i + 5, j + 42, k + 11, 4, 2);
		setBlock(world, i + 5, j + 42, k + 12, Blocks.leaves, 4);
		world.setBlockMetadataWithNotify(i + 5, j + 42, k + 12, 4, 2);
		setBlock(world, i + 5, j + 42, k + 20, Blocks.leaves, 4);
		world.setBlockMetadataWithNotify(i + 5, j + 42, k + 20, 4, 2);
		setBlock(world, i + 5, j + 42, k + 21, Blocks.leaves, 4);
		world.setBlockMetadataWithNotify(i + 5, j + 42, k + 21, 4, 2);
		setBlock(world, i + 5, j + 42, k + 22, Blocks.leaves, 4);
		world.setBlockMetadataWithNotify(i + 5, j + 42, k + 22, 4, 2);
		setBlock(world, i + 5, j + 42, k + 23, Blocks.leaves, 4);
		world.setBlockMetadataWithNotify(i + 5, j + 42, k + 23, 4, 2);
		setBlock(world, i + 5, j + 42, k + 24, Blocks.leaves, 4);
		world.setBlockMetadataWithNotify(i + 5, j + 42, k + 24, 4, 2);
		setBlock(world, i + 5, j + 43, k + 9, Blocks.leaves, 4);
		world.setBlockMetadataWithNotify(i + 5, j + 43, k + 9, 4, 2);
		setBlock(world, i + 5, j + 43, k + 10, Blocks.leaves, 4);
		world.setBlockMetadataWithNotify(i + 5, j + 43, k + 10, 4, 2);
		setBlock(world, i + 5, j + 43, k + 11, Blocks.leaves, 4);
		world.setBlockMetadataWithNotify(i + 5, j + 43, k + 11, 4, 2);
		setBlock(world, i + 5, j + 43, k + 21, Blocks.leaves, 4);
		world.setBlockMetadataWithNotify(i + 5, j + 43, k + 21, 4, 2);
		setBlock(world, i + 5, j + 43, k + 22, Blocks.leaves, 4);
		world.setBlockMetadataWithNotify(i + 5, j + 43, k + 22, 4, 2);
		setBlock(world, i + 5, j + 43, k + 23, Blocks.leaves, 4);
		world.setBlockMetadataWithNotify(i + 5, j + 43, k + 23, 4, 2);
		setBlock(world, i + 5, j + 44, k + 9, Blocks.leaves, 4);
		world.setBlockMetadataWithNotify(i + 5, j + 44, k + 9, 4, 2);
		setBlock(world, i + 5, j + 45, k + 11, Blocks.leaves, 4);
		world.setBlockMetadataWithNotify(i + 5, j + 45, k + 11, 4, 2);
		setBlock(world, i + 6, j + 34, k + 19, Blocks.leaves, 4);
		world.setBlockMetadataWithNotify(i + 6, j + 34, k + 19, 4, 2);
		setBlock(world, i + 6, j + 35, k + 15, Blocks.leaves, 4);
		world.setBlockMetadataWithNotify(i + 6, j + 35, k + 15, 4, 2);
		setBlock(world, i + 6, j + 35, k + 18, Blocks.leaves, 4);
		world.setBlockMetadataWithNotify(i + 6, j + 35, k + 18, 4, 2);
		setBlock(world, i + 6, j + 35, k + 19, Blocks.leaves, 4);
		world.setBlockMetadataWithNotify(i + 6, j + 35, k + 19, 4, 2);
		setBlock(world, i + 6, j + 35, k + 20, Blocks.leaves, 4);
		world.setBlockMetadataWithNotify(i + 6, j + 35, k + 20, 4, 2);
		setBlock(world, i + 6, j + 36, k + 14, Blocks.leaves, 4);
		world.setBlockMetadataWithNotify(i + 6, j + 36, k + 14, 4, 2);
		setBlock(world, i + 6, j + 36, k + 15, Blocks.leaves, 4);
		world.setBlockMetadataWithNotify(i + 6, j + 36, k + 15, 4, 2);
		setBlock(world, i + 6, j + 36, k + 16, Blocks.leaves, 4);
		world.setBlockMetadataWithNotify(i + 6, j + 36, k + 16, 4, 2);
		setBlock(world, i + 6, j + 36, k + 17, Blocks.leaves, 4);
		world.setBlockMetadataWithNotify(i + 6, j + 36, k + 17, 4, 2);
		setBlock(world, i + 6, j + 36, k + 18, Blocks.leaves, 4);
		world.setBlockMetadataWithNotify(i + 6, j + 36, k + 18, 4, 2);
		setBlock(world, i + 6, j + 36, k + 19, Blocks.leaves, 4);
		world.setBlockMetadataWithNotify(i + 6, j + 36, k + 19, 4, 2);
		setBlock(world, i + 6, j + 36, k + 20, Blocks.leaves, 4);
		world.setBlockMetadataWithNotify(i + 6, j + 36, k + 20, 4, 2);
		setBlock(world, i + 6, j + 36, k + 21, Blocks.leaves, 4);
		world.setBlockMetadataWithNotify(i + 6, j + 36, k + 21, 4, 2);
		setBlock(world, i + 6, j + 36, k + 22, Blocks.leaves, 4);
		world.setBlockMetadataWithNotify(i + 6, j + 36, k + 22, 4, 2);
		setBlock(world, i + 6, j + 37, k + 10, Blocks.leaves, 4);
		world.setBlockMetadataWithNotify(i + 6, j + 37, k + 10, 4, 2);
		setBlock(world, i + 6, j + 37, k + 11, Blocks.leaves, 4);
		world.setBlockMetadataWithNotify(i + 6, j + 37, k + 11, 4, 2);
		setBlock(world, i + 6, j + 37, k + 15, Blocks.leaves, 4);
		world.setBlockMetadataWithNotify(i + 6, j + 37, k + 15, 4, 2);
		setBlock(world, i + 6, j + 37, k + 16, Blocks.leaves, 4);
		world.setBlockMetadataWithNotify(i + 6, j + 37, k + 16, 4, 2);
		setBlock(world, i + 6, j + 37, k + 17, Blocks.leaves, 4);
		world.setBlockMetadataWithNotify(i + 6, j + 37, k + 17, 4, 2);
		setBlock(world, i + 6, j + 37, k + 18, Blocks.leaves, 4);
		world.setBlockMetadataWithNotify(i + 6, j + 37, k + 18, 4, 2);
		setBlock(world, i + 6, j + 37, k + 19, Blocks.leaves, 4);
		world.setBlockMetadataWithNotify(i + 6, j + 37, k + 19, 4, 2);
		setBlock(world, i + 6, j + 37, k + 20, Blocks.leaves, 4);
		world.setBlockMetadataWithNotify(i + 6, j + 37, k + 20, 4, 2);
		setBlock(world, i + 6, j + 37, k + 21, Blocks.leaves, 4);
		world.setBlockMetadataWithNotify(i + 6, j + 37, k + 21, 4, 2);
		setBlock(world, i + 6, j + 37, k + 22, Blocks.leaves, 4);
		world.setBlockMetadataWithNotify(i + 6, j + 37, k + 22, 4, 2);
		setBlock(world, i + 6, j + 37, k + 23, Blocks.leaves, 4);
		world.setBlockMetadataWithNotify(i + 6, j + 37, k + 23, 4, 2);
		setBlock(world, i + 6, j + 38, k + 9, Blocks.leaves, 4);
		world.setBlockMetadataWithNotify(i + 6, j + 38, k + 9, 4, 2);
		setBlock(world, i + 6, j + 38, k + 10, Blocks.leaves, 4);
		world.setBlockMetadataWithNotify(i + 6, j + 38, k + 10, 4, 2);
		setBlock(world, i + 6, j + 38, k + 11, Blocks.leaves, 4);
		world.setBlockMetadataWithNotify(i + 6, j + 38, k + 11, 4, 2);
		setBlock(world, i + 6, j + 38, k + 12, Blocks.leaves, 4);
		world.setBlockMetadataWithNotify(i + 6, j + 38, k + 12, 4, 2);
		setBlock(world, i + 6, j + 38, k + 13, Blocks.leaves, 4);
		world.setBlockMetadataWithNotify(i + 6, j + 38, k + 13, 4, 2);
		setBlock(world, i + 6, j + 38, k + 17, Blocks.leaves, 4);
		world.setBlockMetadataWithNotify(i + 6, j + 38, k + 17, 4, 2);
		setBlock(world, i + 6, j + 38, k + 18, Blocks.leaves, 4);
		world.setBlockMetadataWithNotify(i + 6, j + 38, k + 18, 4, 2);
		setBlock(world, i + 6, j + 38, k + 22, Blocks.leaves, 4);
		world.setBlockMetadataWithNotify(i + 6, j + 38, k + 22, 4, 2);
		setBlock(world, i + 6, j + 38, k + 25, Blocks.leaves, 4);
		world.setBlockMetadataWithNotify(i + 6, j + 38, k + 25, 4, 2);
		setBlock(world, i + 6, j + 39, k + 10, Blocks.leaves, 4);
		world.setBlockMetadataWithNotify(i + 6, j + 39, k + 10, 4, 2);
		setBlock(world, i + 6, j + 39, k + 11, Blocks.leaves, 4);
		world.setBlockMetadataWithNotify(i + 6, j + 39, k + 11, 4, 2);
		setBlock(world, i + 6, j + 39, k + 12, Blocks.leaves, 4);
		world.setBlockMetadataWithNotify(i + 6, j + 39, k + 12, 4, 2);
		setBlock(world, i + 6, j + 39, k + 22, Blocks.leaves, 4);
		world.setBlockMetadataWithNotify(i + 6, j + 39, k + 22, 4, 2);
		setBlock(world, i + 6, j + 39, k + 23, Blocks.leaves, 4);
		world.setBlockMetadataWithNotify(i + 6, j + 39, k + 23, 4, 2);
		setBlock(world, i + 6, j + 39, k + 24, Blocks.leaves, 4);
		world.setBlockMetadataWithNotify(i + 6, j + 39, k + 24, 4, 2);
		setBlock(world, i + 6, j + 40, k + 10, Blocks.leaves, 4);
		world.setBlockMetadataWithNotify(i + 6, j + 40, k + 10, 4, 2);
		setBlock(world, i + 6, j + 40, k + 11, Blocks.leaves, 4);
		world.setBlockMetadataWithNotify(i + 6, j + 40, k + 11, 4, 2);
		setBlock(world, i + 6, j + 40, k + 12, Blocks.leaves, 4);
		world.setBlockMetadataWithNotify(i + 6, j + 40, k + 12, 4, 2);
		setBlock(world, i + 6, j + 40, k + 15, Blocks.leaves, 4);
		world.setBlockMetadataWithNotify(i + 6, j + 40, k + 15, 4, 2);
		setBlock(world, i + 6, j + 40, k + 16, Blocks.leaves, 4);
		world.setBlockMetadataWithNotify(i + 6, j + 40, k + 16, 4, 2);
		setBlock(world, i + 6, j + 40, k + 17, Blocks.leaves, 4);
		world.setBlockMetadataWithNotify(i + 6, j + 40, k + 17, 4, 2);
		setBlock(world, i + 6, j + 40, k + 21, Blocks.leaves, 4);
		world.setBlockMetadataWithNotify(i + 6, j + 40, k + 21, 4, 2);
		setBlock(world, i + 6, j + 40, k + 23, Blocks.leaves, 4);
		world.setBlockMetadataWithNotify(i + 6, j + 40, k + 23, 4, 2);
		setBlock(world, i + 6, j + 41, k + 11, Blocks.leaves, 4);
		world.setBlockMetadataWithNotify(i + 6, j + 41, k + 11, 4, 2);
		setBlock(world, i + 6, j + 41, k + 16, Blocks.leaves, 4);
		world.setBlockMetadataWithNotify(i + 6, j + 41, k + 16, 4, 2);
		setBlock(world, i + 6, j + 42, k + 9, Blocks.leaves, 4);
		world.setBlockMetadataWithNotify(i + 6, j + 42, k + 9, 4, 2);
		setBlock(world, i + 6, j + 42, k + 10, Blocks.leaves, 4);
		world.setBlockMetadataWithNotify(i + 6, j + 42, k + 10, 4, 2);
		setBlock(world, i + 6, j + 42, k + 11, Blocks.leaves, 4);
		world.setBlockMetadataWithNotify(i + 6, j + 42, k + 11, 4, 2);
		setBlock(world, i + 6, j + 42, k + 21, Blocks.leaves, 4);
		world.setBlockMetadataWithNotify(i + 6, j + 42, k + 21, 4, 2);
		setBlock(world, i + 6, j + 42, k + 22, Blocks.leaves, 4);
		world.setBlockMetadataWithNotify(i + 6, j + 42, k + 22, 4, 2);
		setBlock(world, i + 6, j + 42, k + 23, Blocks.leaves, 4);
		world.setBlockMetadataWithNotify(i + 6, j + 42, k + 23, 4, 2);
		setBlock(world, i + 6, j + 43, k + 9, Blocks.leaves, 4);
		world.setBlockMetadataWithNotify(i + 6, j + 43, k + 9, 4, 2);
		setBlock(world, i + 6, j + 43, k + 10, Blocks.leaves, 4);
		world.setBlockMetadataWithNotify(i + 6, j + 43, k + 10, 4, 2);
		setBlock(world, i + 6, j + 43, k + 22, Blocks.leaves, 4);
		world.setBlockMetadataWithNotify(i + 6, j + 43, k + 22, 4, 2);
		setBlock(world, i + 6, j + 44, k + 8, Blocks.leaves, 4);
		world.setBlockMetadataWithNotify(i + 6, j + 44, k + 8, 4, 2);
		setBlock(world, i + 6, j + 44, k + 9, Blocks.leaves, 4);
		world.setBlockMetadataWithNotify(i + 6, j + 44, k + 9, 4, 2);
		setBlock(world, i + 6, j + 44, k + 10, Blocks.leaves, 4);
		world.setBlockMetadataWithNotify(i + 6, j + 44, k + 10, 4, 2);
		setBlock(world, i + 6, j + 45, k + 9, Blocks.leaves, 4);
		world.setBlockMetadataWithNotify(i + 6, j + 45, k + 9, 4, 2);
		setBlock(world, i + 7, j + 35, k + 10, Blocks.leaves, 4);
		world.setBlockMetadataWithNotify(i + 7, j + 35, k + 10, 4, 2);
		setBlock(world, i + 7, j + 35, k + 17, Blocks.leaves, 4);
		world.setBlockMetadataWithNotify(i + 7, j + 35, k + 17, 4, 2);
		setBlock(world, i + 7, j + 35, k + 18, Blocks.leaves, 4);
		world.setBlockMetadataWithNotify(i + 7, j + 35, k + 18, 4, 2);
		setBlock(world, i + 7, j + 35, k + 19, Blocks.leaves, 4);
		world.setBlockMetadataWithNotify(i + 7, j + 35, k + 19, 4, 2);
		setBlock(world, i + 7, j + 35, k + 22, Blocks.leaves, 4);
		world.setBlockMetadataWithNotify(i + 7, j + 35, k + 22, 4, 2);
		setBlock(world, i + 7, j + 36, k + 15, Blocks.leaves, 4);
		world.setBlockMetadataWithNotify(i + 7, j + 36, k + 15, 4, 2);
		setBlock(world, i + 7, j + 36, k + 16, Blocks.leaves, 4);
		world.setBlockMetadataWithNotify(i + 7, j + 36, k + 16, 4, 2);
		setBlock(world, i + 7, j + 36, k + 17, Blocks.leaves, 4);
		world.setBlockMetadataWithNotify(i + 7, j + 36, k + 17, 4, 2);
		setBlock(world, i + 7, j + 36, k + 18, Blocks.leaves, 4);
		world.setBlockMetadataWithNotify(i + 7, j + 36, k + 18, 4, 2);
		setBlock(world, i + 7, j + 36, k + 19, Blocks.leaves, 4);
		world.setBlockMetadataWithNotify(i + 7, j + 36, k + 19, 4, 2);
		setBlock(world, i + 7, j + 36, k + 20, Blocks.leaves, 4);
		world.setBlockMetadataWithNotify(i + 7, j + 36, k + 20, 4, 2);
		setBlock(world, i + 7, j + 36, k + 21, Blocks.leaves, 4);
		world.setBlockMetadataWithNotify(i + 7, j + 36, k + 21, 4, 2);
		setBlock(world, i + 7, j + 37, k + 9, Blocks.leaves, 4);
		world.setBlockMetadataWithNotify(i + 7, j + 37, k + 9, 4, 2);
		setBlock(world, i + 7, j + 37, k + 11, Blocks.leaves, 4);
		world.setBlockMetadataWithNotify(i + 7, j + 37, k + 11, 4, 2);
		setBlock(world, i + 7, j + 37, k + 12, Blocks.leaves, 4);
		world.setBlockMetadataWithNotify(i + 7, j + 37, k + 12, 4, 2);
		setBlock(world, i + 7, j + 37, k + 13, Blocks.leaves, 4);
		world.setBlockMetadataWithNotify(i + 7, j + 37, k + 13, 4, 2);
		setBlock(world, i + 7, j + 37, k + 15, Blocks.leaves, 4);
		world.setBlockMetadataWithNotify(i + 7, j + 37, k + 15, 4, 2);
		setBlock(world, i + 7, j + 37, k + 16, Blocks.leaves, 4);
		world.setBlockMetadataWithNotify(i + 7, j + 37, k + 16, 4, 2);
		setBlock(world, i + 7, j + 37, k + 17, Blocks.leaves, 4);
		world.setBlockMetadataWithNotify(i + 7, j + 37, k + 17, 4, 2);
		setBlock(world, i + 7, j + 37, k + 18, Blocks.leaves, 4);
		world.setBlockMetadataWithNotify(i + 7, j + 37, k + 18, 4, 2);
		setBlock(world, i + 7, j + 37, k + 19, Blocks.leaves, 4);
		world.setBlockMetadataWithNotify(i + 7, j + 37, k + 19, 4, 2);
		setBlock(world, i + 7, j + 37, k + 20, Blocks.leaves, 4);
		world.setBlockMetadataWithNotify(i + 7, j + 37, k + 20, 4, 2);
		setBlock(world, i + 7, j + 37, k + 21, Blocks.leaves, 4);
		world.setBlockMetadataWithNotify(i + 7, j + 37, k + 21, 4, 2);
		setBlock(world, i + 7, j + 37, k + 22, Blocks.leaves, 4);
		world.setBlockMetadataWithNotify(i + 7, j + 37, k + 22, 4, 2);
		setBlock(world, i + 7, j + 37, k + 25, Blocks.leaves, 4);
		world.setBlockMetadataWithNotify(i + 7, j + 37, k + 25, 4, 2);
		setBlock(world, i + 7, j + 38, k + 8, Blocks.leaves, 4);
		world.setBlockMetadataWithNotify(i + 7, j + 38, k + 8, 4, 2);
		setBlock(world, i + 7, j + 38, k + 9, Blocks.leaves, 4);
		world.setBlockMetadataWithNotify(i + 7, j + 38, k + 9, 4, 2);
		setBlock(world, i + 7, j + 38, k + 10, Blocks.leaves, 4);
		world.setBlockMetadataWithNotify(i + 7, j + 38, k + 10, 4, 2);
		setBlock(world, i + 7, j + 38, k + 11, Blocks.leaves, 4);
		world.setBlockMetadataWithNotify(i + 7, j + 38, k + 11, 4, 2);
		setBlock(world, i + 7, j + 38, k + 12, Blocks.leaves, 4);
		world.setBlockMetadataWithNotify(i + 7, j + 38, k + 12, 4, 2);
		setBlock(world, i + 7, j + 38, k + 13, Blocks.leaves, 4);
		world.setBlockMetadataWithNotify(i + 7, j + 38, k + 13, 4, 2);
		setBlock(world, i + 7, j + 38, k + 14, Blocks.leaves, 4);
		world.setBlockMetadataWithNotify(i + 7, j + 38, k + 14, 4, 2);
		setBlock(world, i + 7, j + 38, k + 16, Blocks.leaves, 4);
		world.setBlockMetadataWithNotify(i + 7, j + 38, k + 16, 4, 2);
		setBlock(world, i + 7, j + 38, k + 17, Blocks.leaves, 4);
		world.setBlockMetadataWithNotify(i + 7, j + 38, k + 17, 4, 2);
		setBlock(world, i + 7, j + 38, k + 18, Blocks.leaves, 4);
		world.setBlockMetadataWithNotify(i + 7, j + 38, k + 18, 4, 2);
		setBlock(world, i + 7, j + 38, k + 19, Blocks.leaves, 4);
		world.setBlockMetadataWithNotify(i + 7, j + 38, k + 19, 4, 2);
		setBlock(world, i + 7, j + 38, k + 21, Blocks.leaves, 4);
		world.setBlockMetadataWithNotify(i + 7, j + 38, k + 21, 4, 2);
		setBlock(world, i + 7, j + 38, k + 24, Blocks.leaves, 4);
		world.setBlockMetadataWithNotify(i + 7, j + 38, k + 24, 4, 2);
		setBlock(world, i + 7, j + 38, k + 25, Blocks.leaves, 4);
		world.setBlockMetadataWithNotify(i + 7, j + 38, k + 25, 4, 2);
		setBlock(world, i + 7, j + 38, k + 26, Blocks.leaves, 4);
		world.setBlockMetadataWithNotify(i + 7, j + 38, k + 26, 4, 2);
		setBlock(world, i + 7, j + 39, k + 9, Blocks.leaves, 4);
		world.setBlockMetadataWithNotify(i + 7, j + 39, k + 9, 4, 2);
		setBlock(world, i + 7, j + 39, k + 11, Blocks.leaves, 4);
		world.setBlockMetadataWithNotify(i + 7, j + 39, k + 11, 4, 2);
		setBlock(world, i + 7, j + 39, k + 12, Blocks.leaves, 4);
		world.setBlockMetadataWithNotify(i + 7, j + 39, k + 12, 4, 2);
		setBlock(world, i + 7, j + 39, k + 13, Blocks.leaves, 4);
		world.setBlockMetadataWithNotify(i + 7, j + 39, k + 13, 4, 2);
		setBlock(world, i + 7, j + 39, k + 15, Blocks.leaves, 4);
		world.setBlockMetadataWithNotify(i + 7, j + 39, k + 15, 4, 2);
		setBlock(world, i + 7, j + 39, k + 16, Blocks.leaves, 4);
		world.setBlockMetadataWithNotify(i + 7, j + 39, k + 16, 4, 2);
		setBlock(world, i + 7, j + 39, k + 17, Blocks.leaves, 4);
		world.setBlockMetadataWithNotify(i + 7, j + 39, k + 17, 4, 2);
		setBlock(world, i + 7, j + 39, k + 18, Blocks.leaves, 4);
		world.setBlockMetadataWithNotify(i + 7, j + 39, k + 18, 4, 2);
		setBlock(world, i + 7, j + 39, k + 19, Blocks.leaves, 4);
		world.setBlockMetadataWithNotify(i + 7, j + 39, k + 19, 4, 2);
		setBlock(world, i + 7, j + 39, k + 21, Blocks.leaves, 4);
		world.setBlockMetadataWithNotify(i + 7, j + 39, k + 21, 4, 2);
		setBlock(world, i + 7, j + 39, k + 22, Blocks.leaves, 4);
		world.setBlockMetadataWithNotify(i + 7, j + 39, k + 22, 4, 2);
		setBlock(world, i + 7, j + 39, k + 23, Blocks.leaves, 4);
		world.setBlockMetadataWithNotify(i + 7, j + 39, k + 23, 4, 2);
		setBlock(world, i + 7, j + 39, k + 24, Blocks.leaves, 4);
		world.setBlockMetadataWithNotify(i + 7, j + 39, k + 24, 4, 2);
		setBlock(world, i + 7, j + 39, k + 25, Blocks.leaves, 4);
		world.setBlockMetadataWithNotify(i + 7, j + 39, k + 25, 4, 2);
		setBlock(world, i + 7, j + 40, k + 9, Blocks.leaves, 4);
		world.setBlockMetadataWithNotify(i + 7, j + 40, k + 9, 4, 2);
		setBlock(world, i + 7, j + 40, k + 10, Blocks.leaves, 4);
		world.setBlockMetadataWithNotify(i + 7, j + 40, k + 10, 4, 2);
		setBlock(world, i + 7, j + 40, k + 11, Blocks.leaves, 4);
		world.setBlockMetadataWithNotify(i + 7, j + 40, k + 11, 4, 2);
		setBlock(world, i + 7, j + 40, k + 12, Blocks.leaves, 4);
		world.setBlockMetadataWithNotify(i + 7, j + 40, k + 12, 4, 2);
		setBlock(world, i + 7, j + 40, k + 13, Blocks.leaves, 4);
		world.setBlockMetadataWithNotify(i + 7, j + 40, k + 13, 4, 2);
		setBlock(world, i + 7, j + 40, k + 14, Blocks.leaves, 4);
		world.setBlockMetadataWithNotify(i + 7, j + 40, k + 14, 4, 2);
		setBlock(world, i + 7, j + 40, k + 15, Blocks.leaves, 4);
		world.setBlockMetadataWithNotify(i + 7, j + 40, k + 15, 4, 2);
		setBlock(world, i + 7, j + 40, k + 16, Blocks.leaves, 4);
		world.setBlockMetadataWithNotify(i + 7, j + 40, k + 16, 4, 2);
		setBlock(world, i + 7, j + 40, k + 17, Blocks.leaves, 4);
		world.setBlockMetadataWithNotify(i + 7, j + 40, k + 17, 4, 2);
		setBlock(world, i + 7, j + 40, k + 18, Blocks.leaves, 4);
		world.setBlockMetadataWithNotify(i + 7, j + 40, k + 18, 4, 2);
		setBlock(world, i + 7, j + 40, k + 20, Blocks.leaves, 4);
		world.setBlockMetadataWithNotify(i + 7, j + 40, k + 20, 4, 2);
		setBlock(world, i + 7, j + 40, k + 21, Blocks.leaves, 4);
		world.setBlockMetadataWithNotify(i + 7, j + 40, k + 21, 4, 2);
		setBlock(world, i + 7, j + 40, k + 22, Blocks.leaves, 4);
		world.setBlockMetadataWithNotify(i + 7, j + 40, k + 22, 4, 2);
		setBlock(world, i + 7, j + 40, k + 23, Blocks.leaves, 4);
		world.setBlockMetadataWithNotify(i + 7, j + 40, k + 23, 4, 2);
		setBlock(world, i + 7, j + 40, k + 24, Blocks.leaves, 4);
		world.setBlockMetadataWithNotify(i + 7, j + 40, k + 24, 4, 2);
		setBlock(world, i + 7, j + 41, k + 10, Blocks.leaves, 4);
		world.setBlockMetadataWithNotify(i + 7, j + 41, k + 10, 4, 2);
		setBlock(world, i + 7, j + 41, k + 11, Blocks.leaves, 4);
		world.setBlockMetadataWithNotify(i + 7, j + 41, k + 11, 4, 2);
		setBlock(world, i + 7, j + 41, k + 12, Blocks.leaves, 4);
		world.setBlockMetadataWithNotify(i + 7, j + 41, k + 12, 4, 2);
		setBlock(world, i + 7, j + 41, k + 15, Blocks.leaves, 4);
		world.setBlockMetadataWithNotify(i + 7, j + 41, k + 15, 4, 2);
		setBlock(world, i + 7, j + 41, k + 16, Blocks.leaves, 4);
		world.setBlockMetadataWithNotify(i + 7, j + 41, k + 16, 4, 2);
		setBlock(world, i + 7, j + 41, k + 17, Blocks.leaves, 4);
		world.setBlockMetadataWithNotify(i + 7, j + 41, k + 17, 4, 2);
		setBlock(world, i + 7, j + 41, k + 21, Blocks.leaves, 4);
		world.setBlockMetadataWithNotify(i + 7, j + 41, k + 21, 4, 2);
		setBlock(world, i + 7, j + 41, k + 23, Blocks.leaves, 4);
		world.setBlockMetadataWithNotify(i + 7, j + 41, k + 23, 4, 2);
		setBlock(world, i + 7, j + 42, k + 10, Blocks.leaves, 4);
		world.setBlockMetadataWithNotify(i + 7, j + 42, k + 10, 4, 2);
		setBlock(world, i + 7, j + 42, k + 15, Blocks.leaves, 4);
		world.setBlockMetadataWithNotify(i + 7, j + 42, k + 15, 4, 2);
		setBlock(world, i + 7, j + 42, k + 16, Blocks.leaves, 4);
		world.setBlockMetadataWithNotify(i + 7, j + 42, k + 16, 4, 2);
		setBlock(world, i + 7, j + 42, k + 17, Blocks.leaves, 4);
		world.setBlockMetadataWithNotify(i + 7, j + 42, k + 17, 4, 2);
		setBlock(world, i + 7, j + 43, k + 9, Blocks.leaves, 4);
		world.setBlockMetadataWithNotify(i + 7, j + 43, k + 9, 4, 2);
		setBlock(world, i + 7, j + 43, k + 10, Blocks.leaves, 4);
		world.setBlockMetadataWithNotify(i + 7, j + 43, k + 10, 4, 2);
		setBlock(world, i + 7, j + 43, k + 11, Blocks.leaves, 4);
		world.setBlockMetadataWithNotify(i + 7, j + 43, k + 11, 4, 2);
		setBlock(world, i + 7, j + 43, k + 16, Blocks.leaves, 4);
		world.setBlockMetadataWithNotify(i + 7, j + 43, k + 16, 4, 2);
		setBlock(world, i + 7, j + 44, k + 9, Blocks.leaves, 4);
		world.setBlockMetadataWithNotify(i + 7, j + 44, k + 9, 4, 2);
		setBlock(world, i + 7, j + 44, k + 10, Blocks.leaves, 4);
		world.setBlockMetadataWithNotify(i + 7, j + 44, k + 10, 4, 2);
		setBlock(world, i + 7, j + 44, k + 13, Blocks.leaves, 4);
		world.setBlockMetadataWithNotify(i + 7, j + 44, k + 13, 4, 2);
		setBlock(world, i + 7, j + 44, k + 17, Blocks.leaves, 4);
		world.setBlockMetadataWithNotify(i + 7, j + 44, k + 17, 4, 2);
		setBlock(world, i + 7, j + 45, k + 15, Blocks.leaves, 4);
		world.setBlockMetadataWithNotify(i + 7, j + 45, k + 15, 4, 2);
		setBlock(world, i + 7, j + 46, k + 17, Blocks.leaves, 4);
		world.setBlockMetadataWithNotify(i + 7, j + 46, k + 17, 4, 2);
		setBlock(world, i + 7, j + 46, k + 18, Blocks.leaves, 4);
		world.setBlockMetadataWithNotify(i + 7, j + 46, k + 18, 4, 2);
		setBlock(world, i + 7, j + 46, k + 19, Blocks.leaves, 4);
		world.setBlockMetadataWithNotify(i + 7, j + 46, k + 19, 4, 2);
		setBlock(world, i + 7, j + 47, k + 18, Blocks.leaves, 4);
		world.setBlockMetadataWithNotify(i + 7, j + 47, k + 18, 4, 2);
		setBlock(world, i + 7, j + 48, k + 16, Blocks.leaves, 4);
		world.setBlockMetadataWithNotify(i + 7, j + 48, k + 16, 4, 2);
		setBlock(world, i + 7, j + 49, k + 17, Blocks.leaves, 4);
		world.setBlockMetadataWithNotify(i + 7, j + 49, k + 17, 4, 2);
		setBlock(world, i + 8, j + 34, k + 10, Blocks.leaves, 4);
		world.setBlockMetadataWithNotify(i + 8, j + 34, k + 10, 4, 2);
		setBlock(world, i + 8, j + 34, k + 18, Blocks.leaves, 4);
		world.setBlockMetadataWithNotify(i + 8, j + 34, k + 18, 4, 2);
		setBlock(world, i + 8, j + 34, k + 22, Blocks.leaves, 4);
		world.setBlockMetadataWithNotify(i + 8, j + 34, k + 22, 4, 2);
		setBlock(world, i + 8, j + 35, k + 9, Blocks.leaves, 4);
		world.setBlockMetadataWithNotify(i + 8, j + 35, k + 9, 4, 2);
		setBlock(world, i + 8, j + 35, k + 10, Blocks.leaves, 4);
		world.setBlockMetadataWithNotify(i + 8, j + 35, k + 10, 4, 2);
		setBlock(world, i + 8, j + 35, k + 11, Blocks.leaves, 4);
		world.setBlockMetadataWithNotify(i + 8, j + 35, k + 11, 4, 2);
		setBlock(world, i + 8, j + 35, k + 17, Blocks.leaves, 4);
		world.setBlockMetadataWithNotify(i + 8, j + 35, k + 17, 4, 2);
		setBlock(world, i + 8, j + 35, k + 18, Blocks.leaves, 4);
		world.setBlockMetadataWithNotify(i + 8, j + 35, k + 18, 4, 2);
		setBlock(world, i + 8, j + 35, k + 19, Blocks.leaves, 4);
		world.setBlockMetadataWithNotify(i + 8, j + 35, k + 19, 4, 2);
		setBlock(world, i + 8, j + 35, k + 21, Blocks.leaves, 4);
		world.setBlockMetadataWithNotify(i + 8, j + 35, k + 21, 4, 2);
		setBlock(world, i + 8, j + 35, k + 22, Blocks.leaves, 4);
		world.setBlockMetadataWithNotify(i + 8, j + 35, k + 22, 4, 2);
		setBlock(world, i + 8, j + 35, k + 23, Blocks.leaves, 4);
		world.setBlockMetadataWithNotify(i + 8, j + 35, k + 23, 4, 2);
		setBlock(world, i + 8, j + 36, k + 10, Blocks.leaves, 4);
		world.setBlockMetadataWithNotify(i + 8, j + 36, k + 10, 4, 2);
		setBlock(world, i + 8, j + 36, k + 11, Blocks.leaves, 4);
		world.setBlockMetadataWithNotify(i + 8, j + 36, k + 11, 4, 2);
		setBlock(world, i + 8, j + 36, k + 12, Blocks.leaves, 4);
		world.setBlockMetadataWithNotify(i + 8, j + 36, k + 12, 4, 2);
		setBlock(world, i + 8, j + 36, k + 13, Blocks.leaves, 4);
		world.setBlockMetadataWithNotify(i + 8, j + 36, k + 13, 4, 2);
		setBlock(world, i + 8, j + 36, k + 15, Blocks.leaves, 4);
		world.setBlockMetadataWithNotify(i + 8, j + 36, k + 15, 4, 2);
		setBlock(world, i + 8, j + 36, k + 16, Blocks.leaves, 4);
		world.setBlockMetadataWithNotify(i + 8, j + 36, k + 16, 4, 2);
		setBlock(world, i + 8, j + 36, k + 17, Blocks.leaves, 4);
		world.setBlockMetadataWithNotify(i + 8, j + 36, k + 17, 4, 2);
		setBlock(world, i + 8, j + 36, k + 18, Blocks.leaves, 4);
		world.setBlockMetadataWithNotify(i + 8, j + 36, k + 18, 4, 2);
		setBlock(world, i + 8, j + 36, k + 19, Blocks.leaves, 4);
		world.setBlockMetadataWithNotify(i + 8, j + 36, k + 19, 4, 2);
		setBlock(world, i + 8, j + 36, k + 20, Blocks.leaves, 4);
		world.setBlockMetadataWithNotify(i + 8, j + 36, k + 20, 4, 2);
		setBlock(world, i + 8, j + 36, k + 22, Blocks.leaves, 4);
		world.setBlockMetadataWithNotify(i + 8, j + 36, k + 22, 4, 2);
		setBlock(world, i + 8, j + 36, k + 23, Blocks.leaves, 4);
		world.setBlockMetadataWithNotify(i + 8, j + 36, k + 23, 4, 2);
		setBlock(world, i + 8, j + 37, k + 9, Blocks.leaves, 4);
		world.setBlockMetadataWithNotify(i + 8, j + 37, k + 9, 4, 2);
		setBlock(world, i + 8, j + 37, k + 10, Blocks.leaves, 4);
		world.setBlockMetadataWithNotify(i + 8, j + 37, k + 10, 4, 2);
		setBlock(world, i + 8, j + 37, k + 11, Blocks.leaves, 4);
		world.setBlockMetadataWithNotify(i + 8, j + 37, k + 11, 4, 2);
		setBlock(world, i + 8, j + 37, k + 12, Blocks.leaves, 4);
		world.setBlockMetadataWithNotify(i + 8, j + 37, k + 12, 4, 2);
		setBlock(world, i + 8, j + 37, k + 13, Blocks.leaves, 4);
		world.setBlockMetadataWithNotify(i + 8, j + 37, k + 13, 4, 2);
		setBlock(world, i + 8, j + 37, k + 14, Blocks.leaves, 4);
		world.setBlockMetadataWithNotify(i + 8, j + 37, k + 14, 4, 2);
		setBlock(world, i + 8, j + 37, k + 16, Blocks.leaves, 4);
		world.setBlockMetadataWithNotify(i + 8, j + 37, k + 16, 4, 2);
		setBlock(world, i + 8, j + 37, k + 17, Blocks.leaves, 4);
		world.setBlockMetadataWithNotify(i + 8, j + 37, k + 17, 4, 2);
		setBlock(world, i + 8, j + 37, k + 18, Blocks.leaves, 4);
		world.setBlockMetadataWithNotify(i + 8, j + 37, k + 18, 4, 2);
		setBlock(world, i + 8, j + 37, k + 19, Blocks.leaves, 4);
		world.setBlockMetadataWithNotify(i + 8, j + 37, k + 19, 4, 2);
		setBlock(world, i + 8, j + 37, k + 20, Blocks.leaves, 4);
		world.setBlockMetadataWithNotify(i + 8, j + 37, k + 20, 4, 2);
		setBlock(world, i + 8, j + 37, k + 21, Blocks.leaves, 4);
		world.setBlockMetadataWithNotify(i + 8, j + 37, k + 21, 4, 2);
		setBlock(world, i + 8, j + 37, k + 22, Blocks.leaves, 4);
		world.setBlockMetadataWithNotify(i + 8, j + 37, k + 22, 4, 2);
		setBlock(world, i + 8, j + 37, k + 23, Blocks.leaves, 4);
		world.setBlockMetadataWithNotify(i + 8, j + 37, k + 23, 4, 2);
		setBlock(world, i + 8, j + 38, k + 9, Blocks.leaves, 4);
		world.setBlockMetadataWithNotify(i + 8, j + 38, k + 9, 4, 2);
		setBlock(world, i + 8, j + 38, k + 10, Blocks.leaves, 4);
		world.setBlockMetadataWithNotify(i + 8, j + 38, k + 10, 4, 2);
		setBlock(world, i + 8, j + 38, k + 11, Blocks.leaves, 4);
		world.setBlockMetadataWithNotify(i + 8, j + 38, k + 11, 4, 2);
		setBlock(world, i + 8, j + 38, k + 12, Blocks.leaves, 4);
		world.setBlockMetadataWithNotify(i + 8, j + 38, k + 12, 4, 2);
		setBlock(world, i + 8, j + 38, k + 13, Blocks.leaves, 4);
		world.setBlockMetadataWithNotify(i + 8, j + 38, k + 13, 4, 2);
		setBlock(world, i + 8, j + 38, k + 15, Blocks.leaves, 4);
		world.setBlockMetadataWithNotify(i + 8, j + 38, k + 15, 4, 2);
		setBlock(world, i + 8, j + 38, k + 16, Blocks.leaves, 4);
		world.setBlockMetadataWithNotify(i + 8, j + 38, k + 16, 4, 2);
		setBlock(world, i + 8, j + 38, k + 18, Blocks.leaves, 4);
		world.setBlockMetadataWithNotify(i + 8, j + 38, k + 18, 4, 2);
		setBlock(world, i + 8, j + 38, k + 19, Blocks.leaves, 4);
		world.setBlockMetadataWithNotify(i + 8, j + 38, k + 19, 4, 2);
		setBlock(world, i + 8, j + 38, k + 20, Blocks.leaves, 4);
		world.setBlockMetadataWithNotify(i + 8, j + 38, k + 20, 4, 2);
		setBlock(world, i + 8, j + 38, k + 22, Blocks.leaves, 4);
		world.setBlockMetadataWithNotify(i + 8, j + 38, k + 22, 4, 2);
		setBlock(world, i + 8, j + 38, k + 25, Blocks.leaves, 4);
		world.setBlockMetadataWithNotify(i + 8, j + 38, k + 25, 4, 2);
		setBlock(world, i + 8, j + 39, k + 8, Blocks.leaves, 4);
		world.setBlockMetadataWithNotify(i + 8, j + 39, k + 8, 4, 2);
		setBlock(world, i + 8, j + 39, k + 10, Blocks.leaves, 4);
		world.setBlockMetadataWithNotify(i + 8, j + 39, k + 10, 4, 2);
		setBlock(world, i + 8, j + 39, k + 12, Blocks.leaves, 4);
		world.setBlockMetadataWithNotify(i + 8, j + 39, k + 12, 4, 2);
		setBlock(world, i + 8, j + 39, k + 13, Blocks.leaves, 4);
		world.setBlockMetadataWithNotify(i + 8, j + 39, k + 13, 4, 2);
		setBlock(world, i + 8, j + 39, k + 14, Blocks.leaves, 4);
		world.setBlockMetadataWithNotify(i + 8, j + 39, k + 14, 4, 2);
		setBlock(world, i + 8, j + 39, k + 17, Blocks.leaves, 4);
		world.setBlockMetadataWithNotify(i + 8, j + 39, k + 17, 4, 2);
		setBlock(world, i + 8, j + 39, k + 18, Blocks.leaves, 4);
		world.setBlockMetadataWithNotify(i + 8, j + 39, k + 18, 4, 2);
		setBlock(world, i + 8, j + 39, k + 19, Blocks.leaves, 4);
		world.setBlockMetadataWithNotify(i + 8, j + 39, k + 19, 4, 2);
		setBlock(world, i + 8, j + 39, k + 20, Blocks.leaves, 4);
		world.setBlockMetadataWithNotify(i + 8, j + 39, k + 20, 4, 2);

		generate2(world, rand, i, j, k);
		return true;
	}

	public boolean generate10(World world, Random rand, int i, int j, int k)
	{
		setBlock(world, i + 29, j + 43, k + 18, Blocks.leaves, 4);
		world.setBlockMetadataWithNotify(i + 29, j + 43, k + 18, 4, 2);
		setBlock(world, i + 29, j + 43, k + 19, Blocks.leaves, 4);
		world.setBlockMetadataWithNotify(i + 29, j + 43, k + 19, 4, 2);
		setBlock(world, i + 29, j + 43, k + 21, Blocks.leaves, 4);
		world.setBlockMetadataWithNotify(i + 29, j + 43, k + 21, 4, 2);
		setBlock(world, i + 29, j + 43, k + 22, Blocks.leaves, 4);
		world.setBlockMetadataWithNotify(i + 29, j + 43, k + 22, 4, 2);
		setBlock(world, i + 29, j + 43, k + 23, Blocks.leaves, 4);
		world.setBlockMetadataWithNotify(i + 29, j + 43, k + 23, 4, 2);
		setBlock(world, i + 29, j + 43, k + 24, Blocks.leaves, 4);
		world.setBlockMetadataWithNotify(i + 29, j + 43, k + 24, 4, 2);
		setBlock(world, i + 29, j + 44, k + 9, Blocks.leaves, 4);
		world.setBlockMetadataWithNotify(i + 29, j + 44, k + 9, 4, 2);
		setBlock(world, i + 29, j + 44, k + 10, Blocks.leaves, 4);
		world.setBlockMetadataWithNotify(i + 29, j + 44, k + 10, 4, 2);
		setBlock(world, i + 29, j + 44, k + 11, Blocks.leaves, 4);
		world.setBlockMetadataWithNotify(i + 29, j + 44, k + 11, 4, 2);
		setBlock(world, i + 29, j + 44, k + 12, Blocks.leaves, 4);
		world.setBlockMetadataWithNotify(i + 29, j + 44, k + 12, 4, 2);
		setBlock(world, i + 29, j + 44, k + 13, Blocks.leaves, 4);
		world.setBlockMetadataWithNotify(i + 29, j + 44, k + 13, 4, 2);
		setBlock(world, i + 29, j + 44, k + 14, Blocks.leaves, 4);
		world.setBlockMetadataWithNotify(i + 29, j + 44, k + 14, 4, 2);
		setBlock(world, i + 29, j + 44, k + 15, Blocks.leaves, 4);
		world.setBlockMetadataWithNotify(i + 29, j + 44, k + 15, 4, 2);
		setBlock(world, i + 29, j + 44, k + 16, Blocks.leaves, 4);
		world.setBlockMetadataWithNotify(i + 29, j + 44, k + 16, 4, 2);
		setBlock(world, i + 29, j + 44, k + 18, Blocks.leaves, 4);
		world.setBlockMetadataWithNotify(i + 29, j + 44, k + 18, 4, 2);
		setBlock(world, i + 29, j + 44, k + 19, Blocks.leaves, 4);
		world.setBlockMetadataWithNotify(i + 29, j + 44, k + 19, 4, 2);
		setBlock(world, i + 29, j + 44, k + 20, Blocks.leaves, 4);
		world.setBlockMetadataWithNotify(i + 29, j + 44, k + 20, 4, 2);
		setBlock(world, i + 29, j + 44, k + 21, Blocks.leaves, 4);
		world.setBlockMetadataWithNotify(i + 29, j + 44, k + 21, 4, 2);
		setBlock(world, i + 29, j + 44, k + 23, Blocks.leaves, 4);
		world.setBlockMetadataWithNotify(i + 29, j + 44, k + 23, 4, 2);
		setBlock(world, i + 29, j + 44, k + 24, Blocks.leaves, 4);
		world.setBlockMetadataWithNotify(i + 29, j + 44, k + 24, 4, 2);
		setBlock(world, i + 29, j + 45, k + 11, Blocks.leaves, 4);
		world.setBlockMetadataWithNotify(i + 29, j + 45, k + 11, 4, 2);
		setBlock(world, i + 29, j + 45, k + 12, Blocks.leaves, 4);
		world.setBlockMetadataWithNotify(i + 29, j + 45, k + 12, 4, 2);
		setBlock(world, i + 29, j + 45, k + 13, Blocks.leaves, 4);
		world.setBlockMetadataWithNotify(i + 29, j + 45, k + 13, 4, 2);
		setBlock(world, i + 29, j + 45, k + 14, Blocks.leaves, 4);
		world.setBlockMetadataWithNotify(i + 29, j + 45, k + 14, 4, 2);
		setBlock(world, i + 29, j + 45, k + 15, Blocks.leaves, 4);
		world.setBlockMetadataWithNotify(i + 29, j + 45, k + 15, 4, 2);
		setBlock(world, i + 29, j + 45, k + 16, Blocks.leaves, 4);
		world.setBlockMetadataWithNotify(i + 29, j + 45, k + 16, 4, 2);
		setBlock(world, i + 29, j + 45, k + 17, Blocks.leaves, 4);
		world.setBlockMetadataWithNotify(i + 29, j + 45, k + 17, 4, 2);
		setBlock(world, i + 29, j + 45, k + 18, Blocks.leaves, 4);
		world.setBlockMetadataWithNotify(i + 29, j + 45, k + 18, 4, 2);
		setBlock(world, i + 29, j + 45, k + 19, Blocks.leaves, 4);
		world.setBlockMetadataWithNotify(i + 29, j + 45, k + 19, 4, 2);
		setBlock(world, i + 29, j + 45, k + 20, Blocks.leaves, 4);
		world.setBlockMetadataWithNotify(i + 29, j + 45, k + 20, 4, 2);
		setBlock(world, i + 29, j + 45, k + 21, Blocks.leaves, 4);
		world.setBlockMetadataWithNotify(i + 29, j + 45, k + 21, 4, 2);
		setBlock(world, i + 29, j + 45, k + 22, Blocks.leaves, 4);
		world.setBlockMetadataWithNotify(i + 29, j + 45, k + 22, 4, 2);
		setBlock(world, i + 29, j + 45, k + 23, Blocks.leaves, 4);
		world.setBlockMetadataWithNotify(i + 29, j + 45, k + 23, 4, 2);
		setBlock(world, i + 29, j + 45, k + 24, Blocks.leaves, 4);
		world.setBlockMetadataWithNotify(i + 29, j + 45, k + 24, 4, 2);
		setBlock(world, i + 29, j + 46, k + 10, Blocks.leaves, 4);
		world.setBlockMetadataWithNotify(i + 29, j + 46, k + 10, 4, 2);
		setBlock(world, i + 29, j + 46, k + 11, Blocks.leaves, 4);
		world.setBlockMetadataWithNotify(i + 29, j + 46, k + 11, 4, 2);
		setBlock(world, i + 29, j + 46, k + 12, Blocks.leaves, 4);
		world.setBlockMetadataWithNotify(i + 29, j + 46, k + 12, 4, 2);
		setBlock(world, i + 29, j + 46, k + 13, Blocks.leaves, 4);
		world.setBlockMetadataWithNotify(i + 29, j + 46, k + 13, 4, 2);
		setBlock(world, i + 29, j + 46, k + 14, Blocks.leaves, 4);
		world.setBlockMetadataWithNotify(i + 29, j + 46, k + 14, 4, 2);
		setBlock(world, i + 29, j + 46, k + 15, Blocks.leaves, 4);
		world.setBlockMetadataWithNotify(i + 29, j + 46, k + 15, 4, 2);
		setBlock(world, i + 29, j + 46, k + 16, Blocks.leaves, 4);
		world.setBlockMetadataWithNotify(i + 29, j + 46, k + 16, 4, 2);
		setBlock(world, i + 29, j + 46, k + 17, Blocks.leaves, 4);
		world.setBlockMetadataWithNotify(i + 29, j + 46, k + 17, 4, 2);
		setBlock(world, i + 29, j + 46, k + 18, Blocks.leaves, 4);
		world.setBlockMetadataWithNotify(i + 29, j + 46, k + 18, 4, 2);
		setBlock(world, i + 29, j + 46, k + 23, Blocks.leaves, 4);
		world.setBlockMetadataWithNotify(i + 29, j + 46, k + 23, 4, 2);
		setBlock(world, i + 29, j + 47, k + 11, Blocks.leaves, 4);
		world.setBlockMetadataWithNotify(i + 29, j + 47, k + 11, 4, 2);
		setBlock(world, i + 29, j + 47, k + 12, Blocks.leaves, 4);
		world.setBlockMetadataWithNotify(i + 29, j + 47, k + 12, 4, 2);
		setBlock(world, i + 29, j + 47, k + 13, Blocks.leaves, 4);
		world.setBlockMetadataWithNotify(i + 29, j + 47, k + 13, 4, 2);
		setBlock(world, i + 29, j + 47, k + 14, Blocks.leaves, 4);
		world.setBlockMetadataWithNotify(i + 29, j + 47, k + 14, 4, 2);
		setBlock(world, i + 29, j + 47, k + 15, Blocks.leaves, 4);
		world.setBlockMetadataWithNotify(i + 29, j + 47, k + 15, 4, 2);
		setBlock(world, i + 29, j + 47, k + 17, Blocks.leaves, 4);
		world.setBlockMetadataWithNotify(i + 29, j + 47, k + 17, 4, 2);
		setBlock(world, i + 29, j + 47, k + 18, Blocks.leaves, 4);
		world.setBlockMetadataWithNotify(i + 29, j + 47, k + 18, 4, 2);
		setBlock(world, i + 29, j + 48, k + 12, Blocks.leaves, 4);
		world.setBlockMetadataWithNotify(i + 29, j + 48, k + 12, 4, 2);
		setBlock(world, i + 29, j + 48, k + 14, Blocks.leaves, 4);
		world.setBlockMetadataWithNotify(i + 29, j + 48, k + 14, 4, 2);
		setBlock(world, i + 29, j + 48, k + 15, Blocks.leaves, 4);
		world.setBlockMetadataWithNotify(i + 29, j + 48, k + 15, 4, 2);
		setBlock(world, i + 29, j + 48, k + 16, Blocks.leaves, 4);
		world.setBlockMetadataWithNotify(i + 29, j + 48, k + 16, 4, 2);
		setBlock(world, i + 29, j + 48, k + 17, Blocks.leaves, 4);
		world.setBlockMetadataWithNotify(i + 29, j + 48, k + 17, 4, 2);
		setBlock(world, i + 29, j + 48, k + 18, Blocks.leaves, 4);
		world.setBlockMetadataWithNotify(i + 29, j + 48, k + 18, 4, 2);
		setBlock(world, i + 29, j + 49, k + 11, Blocks.leaves, 4);
		world.setBlockMetadataWithNotify(i + 29, j + 49, k + 11, 4, 2);
		setBlock(world, i + 29, j + 49, k + 12, Blocks.leaves, 4);
		world.setBlockMetadataWithNotify(i + 29, j + 49, k + 12, 4, 2);
		setBlock(world, i + 29, j + 49, k + 13, Blocks.leaves, 4);
		world.setBlockMetadataWithNotify(i + 29, j + 49, k + 13, 4, 2);
		setBlock(world, i + 29, j + 49, k + 15, Blocks.leaves, 4);
		world.setBlockMetadataWithNotify(i + 29, j + 49, k + 15, 4, 2);
		setBlock(world, i + 29, j + 49, k + 18, Blocks.leaves, 4);
		world.setBlockMetadataWithNotify(i + 29, j + 49, k + 18, 4, 2);
		setBlock(world, i + 29, j + 50, k + 12, Blocks.leaves, 4);
		world.setBlockMetadataWithNotify(i + 29, j + 50, k + 12, 4, 2);
		setBlock(world, i + 29, j + 50, k + 14, Blocks.leaves, 4);
		world.setBlockMetadataWithNotify(i + 29, j + 50, k + 14, 4, 2);
		setBlock(world, i + 29, j + 50, k + 15, Blocks.leaves, 4);
		world.setBlockMetadataWithNotify(i + 29, j + 50, k + 15, 4, 2);
		setBlock(world, i + 29, j + 50, k + 16, Blocks.leaves, 4);
		world.setBlockMetadataWithNotify(i + 29, j + 50, k + 16, 4, 2);
		setBlock(world, i + 29, j + 50, k + 17, Blocks.leaves, 4);
		world.setBlockMetadataWithNotify(i + 29, j + 50, k + 17, 4, 2);
		setBlock(world, i + 29, j + 50, k + 18, Blocks.leaves, 4);
		world.setBlockMetadataWithNotify(i + 29, j + 50, k + 18, 4, 2);
		setBlock(world, i + 29, j + 50, k + 19, Blocks.leaves, 4);
		world.setBlockMetadataWithNotify(i + 29, j + 50, k + 19, 4, 2);
		setBlock(world, i + 29, j + 51, k + 15, Blocks.leaves, 4);
