package com.parzi.starwarsmod.world.gen;

import java.util.Random;

import net.minecraft.block.Block;
import net.minecraft.init.Blocks;
import net.minecraft.world.World;
import net.minecraft.world.chunk.IChunkProvider;
import net.minecraft.world.gen.feature.WorldGenerator;
import cpw.mods.fml.common.IWorldGenerator;

public class WorldGenEndorTree3 extends WorldGenerator implements IWorldGenerator
{
	public WorldGenEndorTree3()
	{
	}

	@Override
	public void generate(Random random, int chunkX, int chunkZ, World world, IChunkProvider chunkGenerator, IChunkProvider chunkProvider)
	{
	}

	@Override
	public boolean generate(World world, Random rand, int i, int j, int k)
	{
		// check that each corner is one of the valid spawn blocks
		if (!locationIsValidSpawn(world, i, j, k) || !locationIsValidSpawn(world, i + 36, j, k) || !locationIsValidSpawn(world, i + 36, j, k + 31) || !locationIsValidSpawn(world, i, j, k + 31)) { return false; }

		k = k - 10;
		i = i - 10;

		setBlock(world, i + 2, j + 40, k + 8, Blocks.log, 0);
		setBlock(world, i + 2, j + 40, k + 23, Blocks.log, 0);
		setBlock(world, i + 4, j + 39, k + 10, Blocks.log, 0);
		setBlock(world, i + 4, j + 42, k + 16, Blocks.log, 0);
		setBlock(world, i + 5, j + 40, k + 20, Blocks.log, 0);
		setBlock(world, i + 5, j + 41, k + 16, Blocks.log, 0);
		setBlock(world, i + 6, j + 39, k + 17, Blocks.log, 0);
		setBlock(world, i + 6, j + 40, k + 16, Blocks.log, 0);
		setBlock(world, i + 6, j + 42, k + 11, Blocks.log, 0);
		setBlock(world, i + 7, j + 39, k + 10, Blocks.log, 0);
		setBlock(world, i + 7, j + 39, k + 16, Blocks.log, 0);
		setBlock(world, i + 7, j + 42, k + 8, Blocks.log, 0);
		setBlock(world, i + 8, j + 41, k + 23, Blocks.log, 0);
		setBlock(world, i + 9, j + 41, k + 22, Blocks.log, 0);
		setBlock(world, i + 9, j + 43, k + 11, Blocks.log, 0);
		setBlock(world, i + 10, j + 39, k + 10, Blocks.log, 0);
		setBlock(world, i + 10, j + 39, k + 16, Blocks.log, 0);
		setBlock(world, i + 10, j + 43, k + 7, Blocks.log, 0);
		setBlock(world, i + 10, j + 43, k + 8, Blocks.log, 0);
		setBlock(world, i + 10, j + 44, k + 21, Blocks.log, 0);
		setBlock(world, i + 11, j + 40, k + 21, Blocks.log, 0);
		setBlock(world, i + 11, j + 41, k + 17, Blocks.log, 0);
		setBlock(world, i + 11, j + 42, k + 10, Blocks.log, 0);
		setBlock(world, i + 11, j + 42, k + 15, Blocks.log, 0);
		setBlock(world, i + 11, j + 45, k + 19, Blocks.log, 0);
		setBlock(world, i + 11, j + 45, k + 21, Blocks.log, 0);
		setBlock(world, i + 12, j + 40, k + 15, Blocks.log, 0);
		setBlock(world, i + 12, j + 40, k + 16, Blocks.log, 0);
		setBlock(world, i + 12, j + 40, k + 17, Blocks.log, 0);
		setBlock(world, i + 12, j + 41, k + 11, Blocks.log, 0);
		setBlock(world, i + 12, j + 42, k + 10, Blocks.log, 0);
		setBlock(world, i + 12, j + 43, k + 9, Blocks.log, 0);
		setBlock(world, i + 12, j + 46, k + 13, Blocks.log, 0);
		setBlock(world, i + 12, j + 47, k + 16, Blocks.log, 0);
		setBlock(world, i + 13, j + 39, k + 17, Blocks.log, 0);
		setBlock(world, i + 13, j + 39, k + 18, Blocks.log, 0);
		setBlock(world, i + 13, j + 39, k + 24, Blocks.log, 0);
		setBlock(world, i + 13, j + 40, k + 8, Blocks.log, 0);
		setBlock(world, i + 13, j + 40, k + 12, Blocks.log, 0);
		setBlock(world, i + 13, j + 41, k + 14, Blocks.log, 0);
		setBlock(world, i + 13, j + 41, k + 18, Blocks.log, 0);
		setBlock(world, i + 13, j + 43, k + 6, Blocks.log, 0);
		setBlock(world, i + 13, j + 43, k + 7, Blocks.log, 0);
		setBlock(world, i + 13, j + 43, k + 11, Blocks.log, 0);
		setBlock(world, i + 13, j + 44, k + 22, Blocks.log, 0);
		setBlock(world, i + 13, j + 46, k + 13, Blocks.log, 0);
		setBlock(world, i + 13, j + 46, k + 14, Blocks.log, 0);
		setBlock(world, i + 13, j + 47, k + 14, Blocks.log, 0);
		setBlock(world, i + 13, j + 47, k + 16, Blocks.log, 0);
		setBlock(world, i + 14, j + 40, k + 7, Blocks.log, 0);
		setBlock(world, i + 14, j + 44, k + 16, Blocks.log, 0);
		setBlock(world, i + 14, j + 45, k + 18, Blocks.log, 0);
		setBlock(world, i + 14, j + 45, k + 19, Blocks.log, 0);
		setBlock(world, i + 14, j + 46, k + 13, Blocks.log, 0);
		setBlock(world, i + 14, j + 46, k + 19, Blocks.log, 0);
		setBlock(world, i + 14, j + 47, k + 15, Blocks.log, 0);
		setBlock(world, i + 15, j + 39, k + 6, Blocks.log, 0);
		setBlock(world, i + 15, j + 39, k + 19, Blocks.log, 0);
		setBlock(world, i + 15, j + 40, k + 2, Blocks.log, 0);
		setBlock(world, i + 15, j + 42, k + 23, Blocks.log, 0);
		setBlock(world, i + 15, j + 43, k + 10, Blocks.log, 0);
		setBlock(world, i + 15, j + 43, k + 19, Blocks.log, 0);
		setBlock(world, i + 15, j + 44, k + 13, Blocks.log, 0);
		setBlock(world, i + 15, j + 44, k + 16, Blocks.log, 0);
		setBlock(world, i + 15, j + 44, k + 20, Blocks.log, 0);
		setBlock(world, i + 15, j + 45, k + 18, Blocks.log, 0);
		setBlock(world, i + 15, j + 45, k + 22, Blocks.log, 0);
		setBlock(world, i + 15, j + 46, k + 15, Blocks.log, 0);
		setBlock(world, i + 15, j + 47, k + 15, Blocks.log, 0);
		setBlock(world, i + 15, j + 47, k + 18, Blocks.log, 0);
		setBlock(world, i + 16, j + 40, k + 29, Blocks.log, 0);
		setBlock(world, i + 16, j + 41, k + 6, Blocks.log, 0);
		setBlock(world, i + 16, j + 41, k + 10, Blocks.log, 0);
		setBlock(world, i + 16, j + 42, k + 14, Blocks.log, 0);
		setBlock(world, i + 16, j + 42, k + 21, Blocks.log, 0);
		setBlock(world, i + 16, j + 43, k + 16, Blocks.log, 0);
		setBlock(world, i + 16, j + 44, k + 9, Blocks.log, 0);
		setBlock(world, i + 16, j + 44, k + 16, Blocks.log, 0);
		setBlock(world, i + 16, j + 45, k + 13, Blocks.log, 0);
		setBlock(world, i + 16, j + 45, k + 20, Blocks.log, 0);
		setBlock(world, i + 16, j + 46, k + 16, Blocks.log, 0);
		setBlock(world, i + 16, j + 47, k + 13, Blocks.log, 0);
		setBlock(world, i + 16, j + 48, k + 11, Blocks.log, 0);
		setBlock(world, i + 17, j + 0, k + 15, Blocks.log, 0);
		setBlock(world, i + 17, j + 0, k + 16, Blocks.log, 0);
		setBlock(world, i + 17, j + 0, k + 17, Blocks.log, 0);
		setBlock(world, i + 17, j + 0, k + 18, Blocks.log, 0);
		setBlock(world, i + 17, j + 1, k + 15, Blocks.log, 0);
		setBlock(world, i + 17, j + 1, k + 16, Blocks.log, 0);
		setBlock(world, i + 17, j + 1, k + 17, Blocks.log, 0);
		setBlock(world, i + 17, j + 1, k + 18, Blocks.log, 0);
		setBlock(world, i + 17, j + 2, k + 15, Blocks.log, 0);
		setBlock(world, i + 17, j + 2, k + 16, Blocks.log, 0);
		setBlock(world, i + 17, j + 2, k + 17, Blocks.log, 0);
		setBlock(world, i + 17, j + 2, k + 18, Blocks.log, 0);
		setBlock(world, i + 17, j + 3, k + 15, Blocks.log, 0);
		setBlock(world, i + 17, j + 3, k + 16, Blocks.log, 0);
		setBlock(world, i + 17, j + 3, k + 17, Blocks.log, 0);
		setBlock(world, i + 17, j + 3, k + 18, Blocks.log, 0);
		setBlock(world, i + 17, j + 4, k + 15, Blocks.log, 0);
		setBlock(world, i + 17, j + 4, k + 16, Blocks.log, 0);
		setBlock(world, i + 17, j + 4, k + 17, Blocks.log, 0);
		setBlock(world, i + 17, j + 4, k + 18, Blocks.log, 0);
		setBlock(world, i + 17, j + 5, k + 15, Blocks.log, 0);
		setBlock(world, i + 17, j + 5, k + 16, Blocks.log, 0);
		setBlock(world, i + 17, j + 5, k + 17, Blocks.log, 0);
		setBlock(world, i + 17, j + 5, k + 18, Blocks.log, 0);
		setBlock(world, i + 17, j + 6, k + 15, Blocks.log, 0);
		setBlock(world, i + 17, j + 6, k + 16, Blocks.log, 0);
		setBlock(world, i + 17, j + 6, k + 17, Blocks.log, 0);
		setBlock(world, i + 17, j + 6, k + 18, Blocks.log, 0);
		setBlock(world, i + 17, j + 7, k + 15, Blocks.log, 0);
		setBlock(world, i + 17, j + 7, k + 16, Blocks.log, 0);
		setBlock(world, i + 17, j + 7, k + 17, Blocks.log, 0);
		setBlock(world, i + 17, j + 7, k + 18, Blocks.log, 0);
		setBlock(world, i + 17, j + 8, k + 15, Blocks.log, 0);
		setBlock(world, i + 17, j + 8, k + 18, Blocks.log, 0);
		setBlock(world, i + 17, j + 39, k + 6, Blocks.log, 0);
		setBlock(world, i + 17, j + 40, k + 13, Blocks.log, 0);
		setBlock(world, i + 17, j + 40, k + 23, Blocks.log, 0);
		setBlock(world, i + 17, j + 41, k + 10, Blocks.log, 0);
		setBlock(world, i + 17, j + 41, k + 11, Blocks.log, 0);
		setBlock(world, i + 17, j + 41, k + 20, Blocks.log, 0);
		setBlock(world, i + 17, j + 42, k + 15, Blocks.log, 0);
		setBlock(world, i + 17, j + 42, k + 29, Blocks.log, 0);
		setBlock(world, i + 17, j + 43, k + 3, Blocks.log, 0);
		setBlock(world, i + 17, j + 43, k + 4, Blocks.log, 0);
		setBlock(world, i + 17, j + 43, k + 9, Blocks.log, 0);
		setBlock(world, i + 17, j + 43, k + 19, Blocks.log, 0);
		setBlock(world, i + 17, j + 43, k + 22, Blocks.log, 0);
		setBlock(world, i + 17, j + 45, k + 19, Blocks.log, 0);
		setBlock(world, i + 17, j + 46, k + 15, Blocks.log, 0);
		setBlock(world, i + 17, j + 47, k + 9, Blocks.log, 0);
		setBlock(world, i + 17, j + 47, k + 14, Blocks.log, 0);
		setBlock(world, i + 17, j + 47, k + 20, Blocks.log, 0);
		setBlock(world, i + 17, j + 48, k + 13, Blocks.log, 0);
		setBlock(world, i + 17, j + 48, k + 19, Blocks.log, 0);
		setBlock(world, i + 18, j + 0, k + 14, Blocks.log, 0);
		setBlock(world, i + 18, j + 0, k + 15, Blocks.log, 0);
		setBlock(world, i + 18, j + 0, k + 16, Blocks.log, 0);
		setBlock(world, i + 18, j + 0, k + 17, Blocks.log, 0);
		setBlock(world, i + 18, j + 0, k + 18, Blocks.log, 0);
		setBlock(world, i + 18, j + 1, k + 14, Blocks.log, 0);
		setBlock(world, i + 18, j + 1, k + 15, Blocks.log, 0);
		setBlock(world, i + 18, j + 1, k + 16, Blocks.log, 0);
		setBlock(world, i + 18, j + 1, k + 17, Blocks.log, 0);
		setBlock(world, i + 18, j + 1, k + 18, Blocks.log, 0);
		setBlock(world, i + 18, j + 2, k + 14, Blocks.log, 0);
		setBlock(world, i + 18, j + 2, k + 15, Blocks.log, 0);
		setBlock(world, i + 18, j + 2, k + 16, Blocks.log, 0);
		setBlock(world, i + 18, j + 2, k + 17, Blocks.log, 0);
		setBlock(world, i + 18, j + 2, k + 18, Blocks.log, 0);
		setBlock(world, i + 18, j + 3, k + 14, Blocks.log, 0);
		setBlock(world, i + 18, j + 3, k + 15, Blocks.log, 0);
		setBlock(world, i + 18, j + 3, k + 16, Blocks.log, 0);
		setBlock(world, i + 18, j + 3, k + 17, Blocks.log, 0);
		setBlock(world, i + 18, j + 3, k + 18, Blocks.log, 0);
		setBlock(world, i + 18, j + 4, k + 14, Blocks.log, 0);
		setBlock(world, i + 18, j + 4, k + 15, Blocks.log, 0);
		setBlock(world, i + 18, j + 4, k + 16, Blocks.log, 0);
		setBlock(world, i + 18, j + 4, k + 17, Blocks.log, 0);
		setBlock(world, i + 18, j + 4, k + 18, Blocks.log, 0);
		setBlock(world, i + 18, j + 5, k + 14, Blocks.log, 0);
		setBlock(world, i + 18, j + 5, k + 15, Blocks.log, 0);
		setBlock(world, i + 18, j + 5, k + 16, Blocks.log, 0);
		setBlock(world, i + 18, j + 5, k + 17, Blocks.log, 0);
		setBlock(world, i + 18, j + 5, k + 18, Blocks.log, 0);
		setBlock(world, i + 18, j + 6, k + 14, Blocks.log, 0);
		setBlock(world, i + 18, j + 6, k + 15, Blocks.log, 0);
		setBlock(world, i + 18, j + 6, k + 16, Blocks.log, 0);
		setBlock(world, i + 18, j + 6, k + 17, Blocks.log, 0);
		setBlock(world, i + 18, j + 6, k + 18, Blocks.log, 0);
		setBlock(world, i + 18, j + 7, k + 14, Blocks.log, 0);
		setBlock(world, i + 18, j + 7, k + 15, Blocks.log, 0);
		setBlock(world, i + 18, j + 7, k + 16, Blocks.log, 0);
		setBlock(world, i + 18, j + 7, k + 17, Blocks.log, 0);
		setBlock(world, i + 18, j + 7, k + 18, Blocks.log, 0);
		setBlock(world, i + 18, j + 8, k + 14, Blocks.log, 0);
		setBlock(world, i + 18, j + 8, k + 15, Blocks.log, 0);
		setBlock(world, i + 18, j + 8, k + 16, Blocks.log, 0);
		setBlock(world, i + 18, j + 8, k + 17, Blocks.log, 0);
		setBlock(world, i + 18, j + 8, k + 18, Blocks.log, 0);
		setBlock(world, i + 18, j + 9, k + 14, Blocks.log, 0);
		setBlock(world, i + 18, j + 9, k + 15, Blocks.log, 0);
		setBlock(world, i + 18, j + 9, k + 16, Blocks.log, 0);
		setBlock(world, i + 18, j + 9, k + 17, Blocks.log, 0);
		setBlock(world, i + 18, j + 10, k + 14, Blocks.log, 0);
		setBlock(world, i + 18, j + 10, k + 15, Blocks.log, 0);
		setBlock(world, i + 18, j + 10, k + 16, Blocks.log, 0);
		setBlock(world, i + 18, j + 10, k + 17, Blocks.log, 0);
		setBlock(world, i + 18, j + 11, k + 14, Blocks.log, 0);
		setBlock(world, i + 18, j + 11, k + 15, Blocks.log, 0);
		setBlock(world, i + 18, j + 11, k + 16, Blocks.log, 0);
		setBlock(world, i + 18, j + 11, k + 17, Blocks.log, 0);
		setBlock(world, i + 18, j + 12, k + 14, Blocks.log, 0);
		setBlock(world, i + 18, j + 12, k + 15, Blocks.log, 0);
		setBlock(world, i + 18, j + 12, k + 16, Blocks.log, 0);
		setBlock(world, i + 18, j + 12, k + 17, Blocks.log, 0);
		setBlock(world, i + 18, j + 13, k + 14, Blocks.log, 0);
		setBlock(world, i + 18, j + 13, k + 15, Blocks.log, 0);
		setBlock(world, i + 18, j + 13, k + 16, Blocks.log, 0);
		setBlock(world, i + 18, j + 13, k + 17, Blocks.log, 0);
		setBlock(world, i + 18, j + 14, k + 14, Blocks.log, 0);
		setBlock(world, i + 18, j + 14, k + 15, Blocks.log, 0);
		setBlock(world, i + 18, j + 14, k + 16, Blocks.log, 0);
		setBlock(world, i + 18, j + 14, k + 17, Blocks.log, 0);
		setBlock(world, i + 18, j + 15, k + 14, Blocks.log, 0);
		setBlock(world, i + 18, j + 15, k + 15, Blocks.log, 0);
		setBlock(world, i + 18, j + 15, k + 16, Blocks.log, 0);
		setBlock(world, i + 18, j + 15, k + 17, Blocks.log, 0);
		setBlock(world, i + 18, j + 16, k + 15, Blocks.log, 0);
		setBlock(world, i + 18, j + 16, k + 16, Blocks.log, 0);
		setBlock(world, i + 18, j + 16, k + 17, Blocks.log, 0);
		setBlock(world, i + 18, j + 17, k + 15, Blocks.log, 0);
		setBlock(world, i + 18, j + 17, k + 16, Blocks.log, 0);
		setBlock(world, i + 18, j + 17, k + 17, Blocks.log, 0);
		setBlock(world, i + 18, j + 18, k + 15, Blocks.log, 0);
		setBlock(world, i + 18, j + 18, k + 16, Blocks.log, 0);
		setBlock(world, i + 18, j + 18, k + 17, Blocks.log, 0);
		setBlock(world, i + 18, j + 19, k + 15, Blocks.log, 0);
		setBlock(world, i + 18, j + 19, k + 16, Blocks.log, 0);
		setBlock(world, i + 18, j + 19, k + 17, Blocks.log, 0);
		setBlock(world, i + 18, j + 20, k + 15, Blocks.log, 0);
		setBlock(world, i + 18, j + 20, k + 16, Blocks.log, 0);
		setBlock(world, i + 18, j + 20, k + 17, Blocks.log, 0);
		setBlock(world, i + 18, j + 21, k + 15, Blocks.log, 0);
		setBlock(world, i + 18, j + 21, k + 16, Blocks.log, 0);
		setBlock(world, i + 18, j + 21, k + 17, Blocks.log, 0);
		setBlock(world, i + 18, j + 22, k + 15, Blocks.log, 0);
		setBlock(world, i + 18, j + 22, k + 16, Blocks.log, 0);
		setBlock(world, i + 18, j + 22, k + 17, Blocks.log, 0);
		setBlock(world, i + 18, j + 23, k + 16, Blocks.log, 0);
		setBlock(world, i + 18, j + 24, k + 16, Blocks.log, 0);
		setBlock(world, i + 18, j + 25, k + 16, Blocks.log, 0);
		setBlock(world, i + 18, j + 26, k + 16, Blocks.log, 0);
		setBlock(world, i + 18, j + 27, k + 16, Blocks.log, 0);
		setBlock(world, i + 18, j + 39, k + 27, Blocks.log, 0);
		setBlock(world, i + 18, j + 40, k + 11, Blocks.log, 0);
		setBlock(world, i + 18, j + 40, k + 22, Blocks.log, 0);
		setBlock(world, i + 18, j + 40, k + 27, Blocks.log, 0);
		setBlock(world, i + 18, j + 42, k + 20, Blocks.log, 0);
		setBlock(world, i + 18, j + 43, k + 21, Blocks.log, 0);
		setBlock(world, i + 18, j + 44, k + 14, Blocks.log, 0);
		setBlock(world, i + 18, j + 44, k + 22, Blocks.log, 0);
		setBlock(world, i + 18, j + 45, k + 9, Blocks.log, 0);
		setBlock(world, i + 18, j + 45, k + 14, Blocks.log, 0);
		setBlock(world, i + 18, j + 45, k + 16, Blocks.log, 0);
		setBlock(world, i + 18, j + 45, k + 22, Blocks.log, 0);
		setBlock(world, i + 18, j + 46, k + 9, Blocks.log, 0);
		setBlock(world, i + 18, j + 46, k + 17, Blocks.log, 0);
		setBlock(world, i + 18, j + 47, k + 15, Blocks.log, 0);
		setBlock(world, i + 18, j + 47, k + 16, Blocks.log, 0);
		setBlock(world, i + 18, j + 48, k + 17, Blocks.log, 0);
		setBlock(world, i + 18, j + 48, k + 18, Blocks.log, 0);
		setBlock(world, i + 19, j + 0, k + 14, Blocks.log, 0);
		setBlock(world, i + 19, j + 0, k + 15, Blocks.log, 0);
		setBlock(world, i + 19, j + 0, k + 16, Blocks.log, 0);
		setBlock(world, i + 19, j + 0, k + 17, Blocks.log, 0);
		setBlock(world, i + 19, j + 0, k + 18, Blocks.log, 0);
		setBlock(world, i + 19, j + 1, k + 14, Blocks.log, 0);
		setBlock(world, i + 19, j + 1, k + 15, Blocks.log, 0);
		setBlock(world, i + 19, j + 1, k + 16, Blocks.log, 0);
		setBlock(world, i + 19, j + 1, k + 17, Blocks.log, 0);
		setBlock(world, i + 19, j + 1, k + 18, Blocks.log, 0);
		setBlock(world, i + 19, j + 2, k + 14, Blocks.log, 0);
		setBlock(world, i + 19, j + 2, k + 15, Blocks.log, 0);
		setBlock(world, i + 19, j + 2, k + 16, Blocks.log, 0);
		setBlock(world, i + 19, j + 2, k + 17, Blocks.log, 0);
		setBlock(world, i + 19, j + 2, k + 18, Blocks.log, 0);
		setBlock(world, i + 19, j + 3, k + 14, Blocks.log, 0);
		setBlock(world, i + 19, j + 3, k + 15, Blocks.log, 0);
		setBlock(world, i + 19, j + 3, k + 16, Blocks.log, 0);
		setBlock(world, i + 19, j + 3, k + 17, Blocks.log, 0);
		setBlock(world, i + 19, j + 3, k + 18, Blocks.log, 0);
		setBlock(world, i + 19, j + 4, k + 14, Blocks.log, 0);
		setBlock(world, i + 19, j + 4, k + 15, Blocks.log, 0);
		setBlock(world, i + 19, j + 4, k + 16, Blocks.log, 0);
		setBlock(world, i + 19, j + 4, k + 17, Blocks.log, 0);
		setBlock(world, i + 19, j + 4, k + 18, Blocks.log, 0);
		setBlock(world, i + 19, j + 5, k + 14, Blocks.log, 0);
		setBlock(world, i + 19, j + 5, k + 15, Blocks.log, 0);
		setBlock(world, i + 19, j + 5, k + 16, Blocks.log, 0);
		setBlock(world, i + 19, j + 5, k + 17, Blocks.log, 0);
		setBlock(world, i + 19, j + 5, k + 18, Blocks.log, 0);
		setBlock(world, i + 19, j + 6, k + 14, Blocks.log, 0);
		setBlock(world, i + 19, j + 6, k + 15, Blocks.log, 0);
		setBlock(world, i + 19, j + 6, k + 16, Blocks.log, 0);
		setBlock(world, i + 19, j + 6, k + 17, Blocks.log, 0);
		setBlock(world, i + 19, j + 6, k + 18, Blocks.log, 0);
		setBlock(world, i + 19, j + 7, k + 14, Blocks.log, 0);
		setBlock(world, i + 19, j + 7, k + 15, Blocks.log, 0);
		setBlock(world, i + 19, j + 7, k + 16, Blocks.log, 0);
		setBlock(world, i + 19, j + 7, k + 17, Blocks.log, 0);
		setBlock(world, i + 19, j + 7, k + 18, Blocks.log, 0);
		setBlock(world, i + 19, j + 8, k + 14, Blocks.log, 0);
		setBlock(world, i + 19, j + 8, k + 15, Blocks.log, 0);
		setBlock(world, i + 19, j + 8, k + 16, Blocks.log, 0);
		setBlock(world, i + 19, j + 8, k + 17, Blocks.log, 0);
		setBlock(world, i + 19, j + 8, k + 18, Blocks.log, 0);
		setBlock(world, i + 19, j + 9, k + 14, Blocks.log, 0);
		setBlock(world, i + 19, j + 9, k + 15, Blocks.log, 0);
		setBlock(world, i + 19, j + 9, k + 16, Blocks.log, 0);
		setBlock(world, i + 19, j + 9, k + 17, Blocks.log, 0);
		setBlock(world, i + 19, j + 9, k + 18, Blocks.log, 0);
		setBlock(world, i + 19, j + 10, k + 14, Blocks.log, 0);
		setBlock(world, i + 19, j + 10, k + 15, Blocks.log, 0);
		setBlock(world, i + 19, j + 10, k + 16, Blocks.log, 0);
		setBlock(world, i + 19, j + 10, k + 17, Blocks.log, 0);
		setBlock(world, i + 19, j + 10, k + 18, Blocks.log, 0);
		setBlock(world, i + 19, j + 11, k + 14, Blocks.log, 0);
		setBlock(world, i + 19, j + 11, k + 15, Blocks.log, 0);
		setBlock(world, i + 19, j + 11, k + 16, Blocks.log, 0);
		setBlock(world, i + 19, j + 11, k + 17, Blocks.log, 0);
		setBlock(world, i + 19, j + 12, k + 14, Blocks.log, 0);
		setBlock(world, i + 19, j + 12, k + 15, Blocks.log, 0);
		setBlock(world, i + 19, j + 12, k + 16, Blocks.log, 0);
		setBlock(world, i + 19, j + 12, k + 17, Blocks.log, 0);
		setBlock(world, i + 19, j + 13, k + 14, Blocks.log, 0);
		setBlock(world, i + 19, j + 13, k + 15, Blocks.log, 0);
		setBlock(world, i + 19, j + 13, k + 16, Blocks.log, 0);
		setBlock(world, i + 19, j + 13, k + 17, Blocks.log, 0);
		setBlock(world, i + 19, j + 14, k + 14, Blocks.log, 0);
		setBlock(world, i + 19, j + 14, k + 15, Blocks.log, 0);
		setBlock(world, i + 19, j + 14, k + 16, Blocks.log, 0);
		setBlock(world, i + 19, j + 14, k + 17, Blocks.log, 0);
		setBlock(world, i + 19, j + 15, k + 14, Blocks.log, 0);
		setBlock(world, i + 19, j + 15, k + 15, Blocks.log, 0);
		setBlock(world, i + 19, j + 15, k + 16, Blocks.log, 0);
		setBlock(world, i + 19, j + 15, k + 17, Blocks.log, 0);
		setBlock(world, i + 19, j + 15, k + 18, Blocks.log, 0);
		setBlock(world, i + 19, j + 16, k + 14, Blocks.log, 0);
		setBlock(world, i + 19, j + 16, k + 15, Blocks.log, 0);
		setBlock(world, i + 19, j + 16, k + 16, Blocks.log, 0);
		setBlock(world, i + 19, j + 16, k + 17, Blocks.log, 0);
		setBlock(world, i + 19, j + 16, k + 18, Blocks.log, 0);
		setBlock(world, i + 19, j + 17, k + 14, Blocks.log, 0);
		setBlock(world, i + 19, j + 17, k + 15, Blocks.log, 0);
		setBlock(world, i + 19, j + 17, k + 16, Blocks.log, 0);
		setBlock(world, i + 19, j + 17, k + 17, Blocks.log, 0);
		setBlock(world, i + 19, j + 17, k + 18, Blocks.log, 0);
		setBlock(world, i + 19, j + 18, k + 14, Blocks.log, 0);
		setBlock(world, i + 19, j + 18, k + 15, Blocks.log, 0);
		setBlock(world, i + 19, j + 18, k + 16, Blocks.log, 0);
		setBlock(world, i + 19, j + 18, k + 17, Blocks.log, 0);
		setBlock(world, i + 19, j + 18, k + 18, Blocks.log, 0);
		setBlock(world, i + 19, j + 19, k + 14, Blocks.log, 0);
		setBlock(world, i + 19, j + 19, k + 15, Blocks.log, 0);
		setBlock(world, i + 19, j + 19, k + 16, Blocks.log, 0);
		setBlock(world, i + 19, j + 19, k + 17, Blocks.log, 0);
		setBlock(world, i + 19, j + 19, k + 18, Blocks.log, 0);
		setBlock(world, i + 19, j + 20, k + 14, Blocks.log, 0);
		setBlock(world, i + 19, j + 20, k + 15, Blocks.log, 0);
		setBlock(world, i + 19, j + 20, k + 16, Blocks.log, 0);
		setBlock(world, i + 19, j + 20, k + 17, Blocks.log, 0);
		setBlock(world, i + 19, j + 20, k + 18, Blocks.log, 0);
		setBlock(world, i + 19, j + 21, k + 14, Blocks.log, 0);
		setBlock(world, i + 19, j + 21, k + 15, Blocks.log, 0);
		setBlock(world, i + 19, j + 21, k + 16, Blocks.log, 0);
		setBlock(world, i + 19, j + 21, k + 17, Blocks.log, 0);
		setBlock(world, i + 19, j + 21, k + 18, Blocks.log, 0);
		setBlock(world, i + 19, j + 22, k + 14, Blocks.log, 0);
		setBlock(world, i + 19, j + 22, k + 15, Blocks.log, 0);
		setBlock(world, i + 19, j + 22, k + 16, Blocks.log, 0);
		setBlock(world, i + 19, j + 22, k + 17, Blocks.log, 0);
		setBlock(world, i + 19, j + 22, k + 18, Blocks.log, 0);
		setBlock(world, i + 19, j + 23, k + 15, Blocks.log, 0);
		setBlock(world, i + 19, j + 23, k + 16, Blocks.log, 0);
		setBlock(world, i + 19, j + 23, k + 17, Blocks.log, 0);
		setBlock(world, i + 19, j + 24, k + 15, Blocks.log, 0);
		setBlock(world, i + 19, j + 24, k + 16, Blocks.log, 0);
		setBlock(world, i + 19, j + 24, k + 17, Blocks.log, 0);
		setBlock(world, i + 19, j + 25, k + 15, Blocks.log, 0);
		setBlock(world, i + 19, j + 25, k + 16, Blocks.log, 0);
		setBlock(world, i + 19, j + 25, k + 17, Blocks.log, 0);
		setBlock(world, i + 19, j + 26, k + 15, Blocks.log, 0);
		setBlock(world, i + 19, j + 26, k + 16, Blocks.log, 0);
		setBlock(world, i + 19, j + 26, k + 17, Blocks.log, 0);
		setBlock(world, i + 19, j + 27, k + 15, Blocks.log, 0);
		setBlock(world, i + 19, j + 27, k + 16, Blocks.log, 0);
		setBlock(world, i + 19, j + 27, k + 17, Blocks.log, 0);
		setBlock(world, i + 19, j + 28, k + 15, Blocks.log, 0);
		setBlock(world, i + 19, j + 28, k + 16, Blocks.log, 0);
		setBlock(world, i + 19, j + 28, k + 17, Blocks.log, 0);
		setBlock(world, i + 19, j + 29, k + 15, Blocks.log, 0);
		setBlock(world, i + 19, j + 29, k + 16, Blocks.log, 0);
		setBlock(world, i + 19, j + 29, k + 17, Blocks.log, 0);
		setBlock(world, i + 19, j + 30, k + 15, Blocks.log, 0);
		setBlock(world, i + 19, j + 30, k + 16, Blocks.log, 0);
		setBlock(world, i + 19, j + 30, k + 17, Blocks.log, 0);
		setBlock(world, i + 19, j + 31, k + 15, Blocks.log, 0);
		setBlock(world, i + 19, j + 31, k + 16, Blocks.log, 0);
		setBlock(world, i + 19, j + 31, k + 17, Blocks.log, 0);
		setBlock(world, i + 19, j + 32, k + 15, Blocks.log, 0);
		setBlock(world, i + 19, j + 32, k + 16, Blocks.log, 0);
		setBlock(world, i + 19, j + 32, k + 17, Blocks.log, 0);
		setBlock(world, i + 19, j + 33, k + 15, Blocks.log, 0);
		setBlock(world, i + 19, j + 33, k + 16, Blocks.log, 0);
		setBlock(world, i + 19, j + 33, k + 17, Blocks.log, 0);
		setBlock(world, i + 19, j + 34, k + 15, Blocks.log, 0);
		setBlock(world, i + 19, j + 34, k + 16, Blocks.log, 0);
		setBlock(world, i + 19, j + 35, k + 15, Blocks.log, 0);
		setBlock(world, i + 19, j + 35, k + 16, Blocks.log, 0);
		setBlock(world, i + 19, j + 36, k + 15, Blocks.log, 0);
		setBlock(world, i + 19, j + 36, k + 16, Blocks.log, 0);
		setBlock(world, i + 19, j + 37, k + 15, Blocks.log, 0);
		setBlock(world, i + 19, j + 37, k + 16, Blocks.log, 0);
		setBlock(world, i + 19, j + 38, k + 15, Blocks.log, 0);
		setBlock(world, i + 19, j + 38, k + 16, Blocks.log, 0);
		setBlock(world, i + 19, j + 39, k + 5, Blocks.log, 0);
		setBlock(world, i + 19, j + 41, k + 8, Blocks.log, 0);
		setBlock(world, i + 19, j + 41, k + 24, Blocks.log, 0);
		setBlock(world, i + 19, j + 42, k + 6, Blocks.log, 0);
		setBlock(world, i + 19, j + 42, k + 11, Blocks.log, 0);
		setBlock(world, i + 19, j + 42, k + 22, Blocks.log, 0);
		setBlock(world, i + 19, j + 43, k + 9, Blocks.log, 0);
		setBlock(world, i + 19, j + 43, k + 12, Blocks.log, 0);
		setBlock(world, i + 19, j + 43, k + 23, Blocks.log, 0);
		setBlock(world, i + 19, j + 44, k + 16, Blocks.log, 0);
		setBlock(world, i + 19, j + 45, k + 6, Blocks.log, 0);
		setBlock(world, i + 19, j + 45, k + 13, Blocks.log, 0);
		setBlock(world, i + 19, j + 46, k + 6, Blocks.log, 0);
		setBlock(world, i + 19, j + 46, k + 12, Blocks.log, 0);
		setBlock(world, i + 19, j + 46, k + 15, Blocks.log, 0);
		setBlock(world, i + 19, j + 47, k + 14, Blocks.log, 0);
		setBlock(world, i + 19, j + 48, k + 9, Blocks.log, 0);
		setBlock(world, i + 19, j + 48, k + 13, Blocks.log, 0);
		setBlock(world, i + 20, j + 0, k + 14, Blocks.log, 0);
		setBlock(world, i + 20, j + 0, k + 15, Blocks.log, 0);
		setBlock(world, i + 20, j + 0, k + 16, Blocks.log, 0);
		setBlock(world, i + 20, j + 0, k + 17, Blocks.log, 0);
		setBlock(world, i + 20, j + 0, k + 18, Blocks.log, 0);
		setBlock(world, i + 20, j + 1, k + 14, Blocks.log, 0);
		setBlock(world, i + 20, j + 1, k + 15, Blocks.log, 0);
		setBlock(world, i + 20, j + 1, k + 16, Blocks.log, 0);
		setBlock(world, i + 20, j + 1, k + 17, Blocks.log, 0);
		setBlock(world, i + 20, j + 1, k + 18, Blocks.log, 0);
		setBlock(world, i + 20, j + 2, k + 14, Blocks.log, 0);
		setBlock(world, i + 20, j + 2, k + 15, Blocks.log, 0);
		setBlock(world, i + 20, j + 2, k + 16, Blocks.log, 0);
		setBlock(world, i + 20, j + 2, k + 17, Blocks.log, 0);
		setBlock(world, i + 20, j + 2, k + 18, Blocks.log, 0);
		setBlock(world, i + 20, j + 3, k + 14, Blocks.log, 0);
		setBlock(world, i + 20, j + 3, k + 15, Blocks.log, 0);
		setBlock(world, i + 20, j + 3, k + 16, Blocks.log, 0);
		setBlock(world, i + 20, j + 3, k + 17, Blocks.log, 0);
		setBlock(world, i + 20, j + 3, k + 18, Blocks.log, 0);
		setBlock(world, i + 20, j + 4, k + 14, Blocks.log, 0);
		setBlock(world, i + 20, j + 4, k + 15, Blocks.log, 0);
		setBlock(world, i + 20, j + 4, k + 16, Blocks.log, 0);
		setBlock(world, i + 20, j + 4, k + 17, Blocks.log, 0);
		setBlock(world, i + 20, j + 4, k + 18, Blocks.log, 0);
		setBlock(world, i + 20, j + 5, k + 14, Blocks.log, 0);
		setBlock(world, i + 20, j + 5, k + 15, Blocks.log, 0);
		setBlock(world, i + 20, j + 5, k + 16, Blocks.log, 0);
		setBlock(world, i + 20, j + 5, k + 17, Blocks.log, 0);
		setBlock(world, i + 20, j + 5, k + 18, Blocks.log, 0);
		setBlock(world, i + 20, j + 6, k + 14, Blocks.log, 0);
		setBlock(world, i + 20, j + 6, k + 15, Blocks.log, 0);
		setBlock(world, i + 20, j + 6, k + 16, Blocks.log, 0);
		setBlock(world, i + 20, j + 6, k + 17, Blocks.log, 0);
		setBlock(world, i + 20, j + 6, k + 18, Blocks.log, 0);
		setBlock(world, i + 20, j + 7, k + 14, Blocks.log, 0);
		setBlock(world, i + 20, j + 7, k + 15, Blocks.log, 0);
		setBlock(world, i + 20, j + 7, k + 16, Blocks.log, 0);
		setBlock(world, i + 20, j + 7, k + 17, Blocks.log, 0);
		setBlock(world, i + 20, j + 7, k + 18, Blocks.log, 0);
		setBlock(world, i + 20, j + 8, k + 14, Blocks.log, 0);
		setBlock(world, i + 20, j + 8, k + 15, Blocks.log, 0);
		setBlock(world, i + 20, j + 8, k + 16, Blocks.log, 0);
		setBlock(world, i + 20, j + 8, k + 17, Blocks.log, 0);
		setBlock(world, i + 20, j + 8, k + 18, Blocks.log, 0);
		setBlock(world, i + 20, j + 9, k + 14, Blocks.log, 0);
		setBlock(world, i + 20, j + 9, k + 15, Blocks.log, 0);
		setBlock(world, i + 20, j + 9, k + 16, Blocks.log, 0);
		setBlock(world, i + 20, j + 9, k + 17, Blocks.log, 0);
		setBlock(world, i + 20, j + 9, k + 18, Blocks.log, 0);
		setBlock(world, i + 20, j + 10, k + 14, Blocks.log, 0);
		setBlock(world, i + 20, j + 10, k + 15, Blocks.log, 0);
		setBlock(world, i + 20, j + 10, k + 16, Blocks.log, 0);
		setBlock(world, i + 20, j + 10, k + 17, Blocks.log, 0);
		setBlock(world, i + 20, j + 10, k + 18, Blocks.log, 0);
		setBlock(world, i + 20, j + 11, k + 14, Blocks.log, 0);
		setBlock(world, i + 20, j + 11, k + 15, Blocks.log, 0);
		setBlock(world, i + 20, j + 11, k + 16, Blocks.log, 0);
		setBlock(world, i + 20, j + 11, k + 17, Blocks.log, 0);
		setBlock(world, i + 20, j + 11, k + 18, Blocks.log, 0);
		setBlock(world, i + 20, j + 12, k + 14, Blocks.log, 0);
		setBlock(world, i + 20, j + 12, k + 15, Blocks.log, 0);
		setBlock(world, i + 20, j + 12, k + 16, Blocks.log, 0);
		setBlock(world, i + 20, j + 12, k + 17, Blocks.log, 0);
		setBlock(world, i + 20, j + 13, k + 14, Blocks.log, 0);
		setBlock(world, i + 20, j + 13, k + 15, Blocks.log, 0);
		setBlock(world, i + 20, j + 13, k + 16, Blocks.log, 0);
		setBlock(world, i + 20, j + 13, k + 17, Blocks.log, 0);
		setBlock(world, i + 20, j + 14, k + 14, Blocks.log, 0);
		setBlock(world, i + 20, j + 14, k + 15, Blocks.log, 0);
		setBlock(world, i + 20, j + 14, k + 16, Blocks.log, 0);
		setBlock(world, i + 20, j + 14, k + 17, Blocks.log, 0);
		setBlock(world, i + 20, j + 14, k + 18, Blocks.log, 0);
		setBlock(world, i + 20, j + 15, k + 14, Blocks.log, 0);
		setBlock(world, i + 20, j + 15, k + 15, Blocks.log, 0);
		setBlock(world, i + 20, j + 15, k + 16, Blocks.log, 0);
		setBlock(world, i + 20, j + 15, k + 17, Blocks.log, 0);
		setBlock(world, i + 20, j + 15, k + 18, Blocks.log, 0);
		setBlock(world, i + 20, j + 16, k + 14, Blocks.log, 0);
		setBlock(world, i + 20, j + 16, k + 15, Blocks.log, 0);
		setBlock(world, i + 20, j + 16, k + 16, Blocks.log, 0);
		setBlock(world, i + 20, j + 16, k + 17, Blocks.log, 0);
		setBlock(world, i + 20, j + 16, k + 18, Blocks.log, 0);
		setBlock(world, i + 20, j + 17, k + 14, Blocks.log, 0);
		setBlock(world, i + 20, j + 17, k + 15, Blocks.log, 0);
		setBlock(world, i + 20, j + 17, k + 16, Blocks.log, 0);
		setBlock(world, i + 20, j + 17, k + 17, Blocks.log, 0);
		setBlock(world, i + 20, j + 17, k + 18, Blocks.log, 0);
		setBlock(world, i + 20, j + 18, k + 14, Blocks.log, 0);
		setBlock(world, i + 20, j + 18, k + 15, Blocks.log, 0);
		setBlock(world, i + 20, j + 18, k + 16, Blocks.log, 0);
		setBlock(world, i + 20, j + 18, k + 17, Blocks.log, 0);
		setBlock(world, i + 20, j + 18, k + 18, Blocks.log, 0);
		setBlock(world, i + 20, j + 19, k + 14, Blocks.log, 0);
		setBlock(world, i + 20, j + 19, k + 15, Blocks.log, 0);
		setBlock(world, i + 20, j + 19, k + 16, Blocks.log, 0);
		setBlock(world, i + 20, j + 19, k + 17, Blocks.log, 0);
		setBlock(world, i + 20, j + 19, k + 18, Blocks.log, 0);
		setBlock(world, i + 20, j + 20, k + 14, Blocks.log, 0);
		setBlock(world, i + 20, j + 20, k + 15, Blocks.log, 0);
		setBlock(world, i + 20, j + 20, k + 16, Blocks.log, 0);
		setBlock(world, i + 20, j + 20, k + 17, Blocks.log, 0);
		setBlock(world, i + 20, j + 20, k + 18, Blocks.log, 0);
		setBlock(world, i + 20, j + 21, k + 14, Blocks.log, 0);
		setBlock(world, i + 20, j + 21, k + 15, Blocks.log, 0);
		setBlock(world, i + 20, j + 21, k + 16, Blocks.log, 0);
		setBlock(world, i + 20, j + 21, k + 17, Blocks.log, 0);
		setBlock(world, i + 20, j + 21, k + 18, Blocks.log, 0);
		setBlock(world, i + 20, j + 22, k + 14, Blocks.log, 0);
		setBlock(world, i + 20, j + 22, k + 15, Blocks.log, 0);
		setBlock(world, i + 20, j + 22, k + 16, Blocks.log, 0);
		setBlock(world, i + 20, j + 22, k + 17, Blocks.log, 0);
		setBlock(world, i + 20, j + 22, k + 18, Blocks.log, 0);
		setBlock(world, i + 20, j + 23, k + 14, Blocks.log, 0);
		setBlock(world, i + 20, j + 23, k + 15, Blocks.log, 0);
		setBlock(world, i + 20, j + 23, k + 16, Blocks.log, 0);
		setBlock(world, i + 20, j + 23, k + 17, Blocks.log, 0);
		setBlock(world, i + 20, j + 23, k + 18, Blocks.log, 0);
		setBlock(world, i + 20, j + 24, k + 14, Blocks.log, 0);
		setBlock(world, i + 20, j + 24, k + 15, Blocks.log, 0);
		setBlock(world, i + 20, j + 24, k + 16, Blocks.log, 0);
		setBlock(world, i + 20, j + 24, k + 17, Blocks.log, 0);
		setBlock(world, i + 20, j + 24, k + 18, Blocks.log, 0);
		setBlock(world, i + 20, j + 25, k + 14, Blocks.log, 0);
		setBlock(world, i + 20, j + 25, k + 15, Blocks.log, 0);
		setBlock(world, i + 20, j + 25, k + 16, Blocks.log, 0);
		setBlock(world, i + 20, j + 25, k + 17, Blocks.log, 0);
		setBlock(world, i + 20, j + 25, k + 18, Blocks.log, 0);
		setBlock(world, i + 20, j + 26, k + 14, Blocks.log, 0);
		setBlock(world, i + 20, j + 26, k + 15, Blocks.log, 0);
		setBlock(world, i + 20, j + 26, k + 16, Blocks.log, 0);
		setBlock(world, i + 20, j + 26, k + 17, Blocks.log, 0);
		setBlock(world, i + 20, j + 26, k + 18, Blocks.log, 0);
		setBlock(world, i + 20, j + 27, k + 14, Blocks.log, 0);
		setBlock(world, i + 20, j + 27, k + 15, Blocks.log, 0);
		setBlock(world, i + 20, j + 27, k + 16, Blocks.log, 0);
		setBlock(world, i + 20, j + 27, k + 17, Blocks.log, 0);
		setBlock(world, i + 20, j + 28, k + 14, Blocks.log, 0);
		setBlock(world, i + 20, j + 28, k + 15, Blocks.log, 0);
		setBlock(world, i + 20, j + 28, k + 16, Blocks.log, 0);
		setBlock(world, i + 20, j + 28, k + 17, Blocks.log, 0);
		setBlock(world, i + 20, j + 29, k + 14, Blocks.log, 0);
		setBlock(world, i + 20, j + 29, k + 15, Blocks.log, 0);
		setBlock(world, i + 20, j + 29, k + 16, Blocks.log, 0);
		setBlock(world, i + 20, j + 29, k + 17, Blocks.log, 0);
		setBlock(world, i + 20, j + 30, k + 14, Blocks.log, 0);
		setBlock(world, i + 20, j + 30, k + 15, Blocks.log, 0);
		setBlock(world, i + 20, j + 30, k + 16, Blocks.log, 0);
		setBlock(world, i + 20, j + 30, k + 17, Blocks.log, 0);
		setBlock(world, i + 20, j + 31, k + 14, Blocks.log, 0);
		setBlock(world, i + 20, j + 31, k + 15, Blocks.log, 0);
		setBlock(world, i + 20, j + 31, k + 16, Blocks.log, 0);
		setBlock(world, i + 20, j + 31, k + 17, Blocks.log, 0);
		setBlock(world, i + 20, j + 32, k + 14, Blocks.log, 0);
		setBlock(world, i + 20, j + 32, k + 15, Blocks.log, 0);
		setBlock(world, i + 20, j + 32, k + 16, Blocks.log, 0);
		setBlock(world, i + 20, j + 32, k + 17, Blocks.log, 0);
		setBlock(world, i + 20, j + 33, k + 14, Blocks.log, 0);
		setBlock(world, i + 20, j + 33, k + 15, Blocks.log, 0);
		setBlock(world, i + 20, j + 33, k + 16, Blocks.log, 0);
		setBlock(world, i + 20, j + 33, k + 17, Blocks.log, 0);
		setBlock(world, i + 20, j + 34, k + 14, Blocks.log, 0);
		setBlock(world, i + 20, j + 34, k + 15, Blocks.log, 0);
		setBlock(world, i + 20, j + 34, k + 16, Blocks.log, 0);
		setBlock(world, i + 20, j + 34, k + 17, Blocks.log, 0);
		setBlock(world, i + 20, j + 35, k + 14, Blocks.log, 0);
		setBlock(world, i + 20, j + 35, k + 15, Blocks.log, 0);
		setBlock(world, i + 20, j + 35, k + 16, Blocks.log, 0);
		setBlock(world, i + 20, j + 35, k + 17, Blocks.log, 0);
		setBlock(world, i + 20, j + 36, k + 14, Blocks.log, 0);
		setBlock(world, i + 20, j + 36, k + 15, Blocks.log, 0);
		setBlock(world, i + 20, j + 36, k + 16, Blocks.log, 0);
		setBlock(world, i + 20, j + 36, k + 17, Blocks.log, 0);
		setBlock(world, i + 20, j + 37, k + 14, Blocks.log, 0);
		setBlock(world, i + 20, j + 37, k + 15, Blocks.log, 0);
		setBlock(world, i + 20, j + 37, k + 16, Blocks.log, 0);
		setBlock(world, i + 20, j + 38, k + 14, Blocks.log, 0);
		setBlock(world, i + 20, j + 38, k + 15, Blocks.log, 0);
		setBlock(world, i + 20, j + 38, k + 16, Blocks.log, 0);
		setBlock(world, i + 20, j + 39, k + 14, Blocks.log, 0);
		setBlock(world, i + 20, j + 39, k + 15, Blocks.log, 0);
		setBlock(world, i + 20, j + 39, k + 16, Blocks.log, 0);
		setBlock(world, i + 20, j + 39, k + 21, Blocks.log, 0);
		setBlock(world, i + 20, j + 40, k + 15, Blocks.log, 0);
		setBlock(world, i + 20, j + 40, k + 16, Blocks.log, 0);
		setBlock(world, i + 20, j + 40, k + 29, Blocks.log, 0);
		setBlock(world, i + 20, j + 41, k + 6, Blocks.log, 0);
		setBlock(world, i + 20, j + 41, k + 10, Blocks.log, 0);
		setBlock(world, i + 20, j + 41, k + 16, Blocks.log, 0);
		setBlock(world, i + 20, j + 41, k + 22, Blocks.log, 0);
		setBlock(world, i + 20, j + 42, k + 16, Blocks.log, 0);
		setBlock(world, i + 20, j + 42, k + 23, Blocks.log, 0);
		setBlock(world, i + 20, j + 43, k + 16, Blocks.log, 0);
		setBlock(world, i + 20, j + 43, k + 18, Blocks.log, 0);
		setBlock(world, i + 20, j + 44, k + 9, Blocks.log, 0);
		setBlock(world, i + 20, j + 44, k + 11, Blocks.log, 0);
		setBlock(world, i + 20, j + 45, k + 10, Blocks.log, 0);
		setBlock(world, i + 20, j + 46, k + 11, Blocks.log, 0);
		setBlock(world, i + 20, j + 47, k + 18, Blocks.log, 0);
		setBlock(world, i + 20, j + 47, k + 20, Blocks.log, 0);
		setBlock(world, i + 20, j + 47, k + 21, Blocks.log, 0);
		setBlock(world, i + 20, j + 48, k + 12, Blocks.log, 0);
		setBlock(world, i + 20, j + 48, k + 13, Blocks.log, 0);
		setBlock(world, i + 20, j + 48, k + 17, Blocks.log, 0);
		setBlock(world, i + 21, j + 0, k + 14, Blocks.log, 0);
		setBlock(world, i + 21, j + 0, k + 15, Blocks.log, 0);
		setBlock(world, i + 21, j + 0, k + 16, Blocks.log, 0);
		setBlock(world, i + 21, j + 0, k + 17, Blocks.log, 0);
		setBlock(world, i + 21, j + 0, k + 18, Blocks.log, 0);
		setBlock(world, i + 21, j + 1, k + 14, Blocks.log, 0);
		setBlock(world, i + 21, j + 1, k + 15, Blocks.log, 0);
		setBlock(world, i + 21, j + 1, k + 16, Blocks.log, 0);
		setBlock(world, i + 21, j + 1, k + 17, Blocks.log, 0);
		setBlock(world, i + 21, j + 1, k + 18, Blocks.log, 0);
		setBlock(world, i + 21, j + 2, k + 14, Blocks.log, 0);
		setBlock(world, i + 21, j + 2, k + 15, Blocks.log, 0);
		setBlock(world, i + 21, j + 2, k + 16, Blocks.log, 0);
		setBlock(world, i + 21, j + 2, k + 17, Blocks.log, 0);
		setBlock(world, i + 21, j + 2, k + 18, Blocks.log, 0);
		setBlock(world, i + 21, j + 3, k + 14, Blocks.log, 0);
		setBlock(world, i + 21, j + 3, k + 15, Blocks.log, 0);
		setBlock(world, i + 21, j + 3, k + 16, Blocks.log, 0);
		setBlock(world, i + 21, j + 3, k + 17, Blocks.log, 0);
		setBlock(world, i + 21, j + 3, k + 18, Blocks.log, 0);
		setBlock(world, i + 21, j + 4, k + 14, Blocks.log, 0);
		setBlock(world, i + 21, j + 4, k + 15, Blocks.log, 0);
		setBlock(world, i + 21, j + 4, k + 16, Blocks.log, 0);
		setBlock(world, i + 21, j + 4, k + 17, Blocks.log, 0);
		setBlock(world, i + 21, j + 4, k + 18, Blocks.log, 0);
		setBlock(world, i + 21, j + 5, k + 14, Blocks.log, 0);
		setBlock(world, i + 21, j + 5, k + 15, Blocks.log, 0);
		setBlock(world, i + 21, j + 5, k + 16, Blocks.log, 0);
		setBlock(world, i + 21, j + 5, k + 17, Blocks.log, 0);
		setBlock(world, i + 21, j + 5, k + 18, Blocks.log, 0);
		setBlock(world, i + 21, j + 6, k + 14, Blocks.log, 0);
		setBlock(world, i + 21, j + 6, k + 15, Blocks.log, 0);
		setBlock(world, i + 21, j + 6, k + 16, Blocks.log, 0);
		setBlock(world, i + 21, j + 6, k + 17, Blocks.log, 0);
		setBlock(world, i + 21, j + 6, k + 18, Blocks.log, 0);
		setBlock(world, i + 21, j + 7, k + 14, Blocks.log, 0);
		setBlock(world, i + 21, j + 7, k + 15, Blocks.log, 0);
		setBlock(world, i + 21, j + 7, k + 16, Blocks.log, 0);
		setBlock(world, i + 21, j + 7, k + 17, Blocks.log, 0);
		setBlock(world, i + 21, j + 7, k + 18, Blocks.log, 0);
		setBlock(world, i + 21, j + 8, k + 14, Blocks.log, 0);
		setBlock(world, i + 21, j + 8, k + 15, Blocks.log, 0);
		setBlock(world, i + 21, j + 8, k + 16, Blocks.log, 0);
		setBlock(world, i + 21, j + 8, k + 17, Blocks.log, 0);
		setBlock(world, i + 21, j + 8, k + 18, Blocks.log, 0);
		setBlock(world, i + 21, j + 9, k + 14, Blocks.log, 0);
		setBlock(world, i + 21, j + 9, k + 15, Blocks.log, 0);
		setBlock(world, i + 21, j + 9, k + 16, Blocks.log, 0);
		setBlock(world, i + 21, j + 9, k + 17, Blocks.log, 0);
		setBlock(world, i + 21, j + 9, k + 18, Blocks.log, 0);
		setBlock(world, i + 21, j + 10, k + 14, Blocks.log, 0);
		setBlock(world, i + 21, j + 10, k + 15, Blocks.log, 0);
		setBlock(world, i + 21, j + 10, k + 16, Blocks.log, 0);
		setBlock(world, i + 21, j + 10, k + 17, Blocks.log, 0);
		setBlock(world, i + 21, j + 10, k + 18, Blocks.log, 0);
		setBlock(world, i + 21, j + 11, k + 14, Blocks.log, 0);
		setBlock(world, i + 21, j + 11, k + 15, Blocks.log, 0);
		setBlock(world, i + 21, j + 11, k + 16, Blocks.log, 0);
		setBlock(world, i + 21, j + 11, k + 17, Blocks.log, 0);
		setBlock(world, i + 21, j + 11, k + 18, Blocks.log, 0);
		setBlock(world, i + 21, j + 12, k + 14, Blocks.log, 0);
		setBlock(world, i + 21, j + 12, k + 15, Blocks.log, 0);
		setBlock(world, i + 21, j + 12, k + 16, Blocks.log, 0);
		setBlock(world, i + 21, j + 12, k + 17, Blocks.log, 0);
		setBlock(world, i + 21, j + 12, k + 18, Blocks.log, 0);
		setBlock(world, i + 21, j + 13, k + 14, Blocks.log, 0);
		setBlock(world, i + 21, j + 13, k + 15, Blocks.log, 0);
		setBlock(world, i + 21, j + 13, k + 16, Blocks.log, 0);
		setBlock(world, i + 21, j + 13, k + 17, Blocks.log, 0);
		setBlock(world, i + 21, j + 13, k + 18, Blocks.log, 0);
		setBlock(world, i + 21, j + 14, k + 14, Blocks.log, 0);
		setBlock(world, i + 21, j + 14, k + 15, Blocks.log, 0);
		setBlock(world, i + 21, j + 14, k + 16, Blocks.log, 0);
		setBlock(world, i + 21, j + 14, k + 17, Blocks.log, 0);
		setBlock(world, i + 21, j + 14, k + 18, Blocks.log, 0);
		setBlock(world, i + 21, j + 15, k + 14, Blocks.log, 0);
		setBlock(world, i + 21, j + 15, k + 15, Blocks.log, 0);
		setBlock(world, i + 21, j + 15, k + 16, Blocks.log, 0);
		setBlock(world, i + 21, j + 15, k + 17, Blocks.log, 0);
		setBlock(world, i + 21, j + 15, k + 18, Blocks.log, 0);
		setBlock(world, i + 21, j + 16, k + 14, Blocks.log, 0);
		setBlock(world, i + 21, j + 16, k + 15, Blocks.log, 0);
		setBlock(world, i + 21, j + 16, k + 16, Blocks.log, 0);
		setBlock(world, i + 21, j + 16, k + 17, Blocks.log, 0);
		setBlock(world, i + 21, j + 16, k + 18, Blocks.log, 0);
		setBlock(world, i + 21, j + 17, k + 14, Blocks.log, 0);
		setBlock(world, i + 21, j + 17, k + 15, Blocks.log, 0);
		setBlock(world, i + 21, j + 17, k + 16, Blocks.log, 0);
		setBlock(world, i + 21, j + 17, k + 17, Blocks.log, 0);
		setBlock(world, i + 21, j + 17, k + 18, Blocks.log, 0);
		setBlock(world, i + 21, j + 18, k + 14, Blocks.log, 0);
		setBlock(world, i + 21, j + 18, k + 15, Blocks.log, 0);
		setBlock(world, i + 21, j + 18, k + 16, Blocks.log, 0);
		setBlock(world, i + 21, j + 18, k + 17, Blocks.log, 0);
		setBlock(world, i + 21, j + 18, k + 18, Blocks.log, 0);
		setBlock(world, i + 21, j + 19, k + 14, Blocks.log, 0);
		setBlock(world, i + 21, j + 19, k + 15, Blocks.log, 0);
		setBlock(world, i + 21, j + 19, k + 16, Blocks.log, 0);
		setBlock(world, i + 21, j + 19, k + 17, Blocks.log, 0);
		setBlock(world, i + 21, j + 19, k + 18, Blocks.log, 0);
		setBlock(world, i + 21, j + 20, k + 14, Blocks.log, 0);
		setBlock(world, i + 21, j + 20, k + 15, Blocks.log, 0);
		setBlock(world, i + 21, j + 20, k + 16, Blocks.log, 0);
		setBlock(world, i + 21, j + 20, k + 17, Blocks.log, 0);
		setBlock(world, i + 21, j + 20, k + 18, Blocks.log, 0);
		setBlock(world, i + 21, j + 21, k + 14, Blocks.log, 0);
		setBlock(world, i + 21, j + 21, k + 15, Blocks.log, 0);
		setBlock(world, i + 21, j + 21, k + 16, Blocks.log, 0);
		setBlock(world, i + 21, j + 21, k + 17, Blocks.log, 0);
		setBlock(world, i + 21, j + 21, k + 18, Blocks.log, 0);
		setBlock(world, i + 21, j + 22, k + 14, Blocks.log, 0);
		setBlock(world, i + 21, j + 22, k + 15, Blocks.log, 0);
		setBlock(world, i + 21, j + 22, k + 16, Blocks.log, 0);
		setBlock(world, i + 21, j + 22, k + 17, Blocks.log, 0);
		setBlock(world, i + 21, j + 22, k + 18, Blocks.log, 0);
		setBlock(world, i + 21, j + 23, k + 15, Blocks.log, 0);
		setBlock(world, i + 21, j + 23, k + 16, Blocks.log, 0);
		setBlock(world, i + 21, j + 23, k + 17, Blocks.log, 0);
		setBlock(world, i + 21, j + 23, k + 18, Blocks.log, 0);
		setBlock(world, i + 21, j + 24, k + 15, Blocks.log, 0);
		setBlock(world, i + 21, j + 24, k + 16, Blocks.log, 0);
		setBlock(world, i + 21, j + 24, k + 17, Blocks.log, 0);
		setBlock(world, i + 21, j + 24, k + 18, Blocks.log, 0);
		setBlock(world, i + 21, j + 25, k + 15, Blocks.log, 0);
		setBlock(world, i + 21, j + 25, k + 16, Blocks.log, 0);
		setBlock(world, i + 21, j + 25, k + 17, Blocks.log, 0);
		setBlock(world, i + 21, j + 25, k + 18, Blocks.log, 0);
		setBlock(world, i + 21, j + 26, k + 15, Blocks.log, 0);
		setBlock(world, i + 21, j + 26, k + 16, Blocks.log, 0);
		setBlock(world, i + 21, j + 26, k + 17, Blocks.log, 0);
		setBlock(world, i + 21, j + 26, k + 18, Blocks.log, 0);
		setBlock(world, i + 21, j + 27, k + 15, Blocks.log, 0);
		setBlock(world, i + 21, j + 27, k + 16, Blocks.log, 0);
		setBlock(world, i + 21, j + 27, k + 17, Blocks.log, 0);
		setBlock(world, i + 21, j + 27, k + 18, Blocks.log, 0);
		setBlock(world, i + 21, j + 28, k + 14, Blocks.log, 0);
		setBlock(world, i + 21, j + 28, k + 15, Blocks.log, 0);
		setBlock(world, i + 21, j + 28, k + 16, Blocks.log, 0);
		setBlock(world, i + 21, j + 28, k + 17, Blocks.log, 0);
		setBlock(world, i + 21, j + 28, k + 18, Blocks.log, 0);
		setBlock(world, i + 21, j + 29, k + 14, Blocks.log, 0);
		setBlock(world, i + 21, j + 29, k + 15, Blocks.log, 0);
		setBlock(world, i + 21, j + 29, k + 16, Blocks.log, 0);
		setBlock(world, i + 21, j + 29, k + 17, Blocks.log, 0);
		setBlock(world, i + 21, j + 29, k + 18, Blocks.log, 0);
		setBlock(world, i + 21, j + 30, k + 14, Blocks.log, 0);
		setBlock(world, i + 21, j + 30, k + 15, Blocks.log, 0);
		setBlock(world, i + 21, j + 30, k + 16, Blocks.log, 0);
		setBlock(world, i + 21, j + 30, k + 17, Blocks.log, 0);
		setBlock(world, i + 21, j + 30, k + 18, Blocks.log, 0);
		setBlock(world, i + 21, j + 31, k + 14, Blocks.log, 0);
		setBlock(world, i + 21, j + 31, k + 15, Blocks.log, 0);
		setBlock(world, i + 21, j + 31, k + 16, Blocks.log, 0);
		setBlock(world, i + 21, j + 31, k + 17, Blocks.log, 0);
		setBlock(world, i + 21, j + 32, k + 14, Blocks.log, 0);
		setBlock(world, i + 21, j + 32, k + 15, Blocks.log, 0);
		setBlock(world, i + 21, j + 32, k + 16, Blocks.log, 0);
		setBlock(world, i + 21, j + 32, k + 17, Blocks.log, 0);
		setBlock(world, i + 21, j + 33, k + 14, Blocks.log, 0);
		setBlock(world, i + 21, j + 33, k + 15, Blocks.log, 0);
		setBlock(world, i + 21, j + 33, k + 16, Blocks.log, 0);
		setBlock(world, i + 21, j + 33, k + 17, Blocks.log, 0);
		setBlock(world, i + 21, j + 34, k + 14, Blocks.log, 0);
		setBlock(world, i + 21, j + 34, k + 15, Blocks.log, 0);
		setBlock(world, i + 21, j + 34, k + 16, Blocks.log, 0);
		setBlock(world, i + 21, j + 34, k + 17, Blocks.log, 0);
		setBlock(world, i + 21, j + 35, k + 14, Blocks.log, 0);
		setBlock(world, i + 21, j + 35, k + 15, Blocks.log, 0);
		setBlock(world, i + 21, j + 35, k + 16, Blocks.log, 0);
		setBlock(world, i + 21, j + 35, k + 17, Blocks.log, 0);
		setBlock(world, i + 21, j + 36, k + 14, Blocks.log, 0);
		setBlock(world, i + 21, j + 36, k + 15, Blocks.log, 0);
		setBlock(world, i + 21, j + 36, k + 16, Blocks.log, 0);
		setBlock(world, i + 21, j + 36, k + 17, Blocks.log, 0);
		setBlock(world, i + 21, j + 37, k + 14, Blocks.log, 0);
		setBlock(world, i + 21, j + 37, k + 15, Blocks.log, 0);
		setBlock(world, i + 21, j + 37, k + 16, Blocks.log, 0);
		setBlock(world, i + 21, j + 37, k + 17, Blocks.log, 0);
		setBlock(world, i + 21, j + 38, k + 14, Blocks.log, 0);
		setBlock(world, i + 21, j + 38, k + 15, Blocks.log, 0);
		setBlock(world, i + 21, j + 38, k + 16, Blocks.log, 0);
		setBlock(world, i + 21, j + 38, k + 17, Blocks.log, 0);
		setBlock(world, i + 21, j + 39, k + 14, Blocks.log, 0);
		setBlock(world, i + 21, j + 39, k + 15, Blocks.log, 0);
		setBlock(world, i + 21, j + 39, k + 16, Blocks.log, 0);
		setBlock(world, i + 21, j + 39, k + 17, Blocks.log, 0);
		setBlock(world, i + 21, j + 40, k + 7, Blocks.log, 0);
		setBlock(world, i + 21, j + 40, k + 8, Blocks.log, 0);
		setBlock(world, i + 21, j + 40, k + 9, Blocks.log, 0);
		setBlock(world, i + 21, j + 40, k + 14, Blocks.log, 0);
		setBlock(world, i + 21, j + 40, k + 15, Blocks.log, 0);
		setBlock(world, i + 21, j + 40, k + 16, Blocks.log, 0);
		setBlock(world, i + 21, j + 40, k + 17, Blocks.log, 0);
		setBlock(world, i + 21, j + 41, k + 9, Blocks.log, 0);
		setBlock(world, i + 21, j + 41, k + 15, Blocks.log, 0);
		setBlock(world, i + 21, j + 41, k + 16, Blocks.log, 0);
		setBlock(world, i + 21, j + 42, k + 9, Blocks.log, 0);
		setBlock(world, i + 21, j + 42, k + 24, Blocks.log, 0);
		setBlock(world, i + 21, j + 42, k + 28, Blocks.log, 0);
		setBlock(world, i + 21, j + 44, k + 7, Blocks.log, 0);
		setBlock(world, i + 21, j + 44, k + 16, Blocks.log, 0);
		setBlock(world, i + 21, j + 44, k + 22, Blocks.log, 0);
		setBlock(world, i + 21, j + 45, k + 14, Blocks.log, 0);
		setBlock(world, i + 21, j + 46, k + 9, Blocks.log, 0);
		setBlock(world, i + 21, j + 46, k + 23, Blocks.log, 0);
		setBlock(world, i + 21, j + 47, k + 16, Blocks.log, 0);
		setBlock(world, i + 21, j + 47, k + 20, Blocks.log, 0);
		setBlock(world, i + 21, j + 48, k + 13, Blocks.log, 0);
		setBlock(world, i + 21, j + 48, k + 18, Blocks.log, 0);
		setBlock(world, i + 21, j + 48, k + 19, Blocks.log, 0);
		setBlock(world, i + 22, j + 0, k + 14, Blocks.log, 0);
		setBlock(world, i + 22, j + 0, k + 15, Blocks.log, 0);
		setBlock(world, i + 22, j + 0, k + 16, Blocks.log, 0);
		setBlock(world, i + 22, j + 0, k + 17, Blocks.log, 0);
		setBlock(world, i + 22, j + 1, k + 14, Blocks.log, 0);
		setBlock(world, i + 22, j + 1, k + 15, Blocks.log, 0);
		setBlock(world, i + 22, j + 1, k + 16, Blocks.log, 0);
		setBlock(world, i + 22, j + 1, k + 17, Blocks.log, 0);
		setBlock(world, i + 22, j + 2, k + 14, Blocks.log, 0);
		setBlock(world, i + 22, j + 2, k + 15, Blocks.log, 0);
		setBlock(world, i + 22, j + 2, k + 16, Blocks.log, 0);
		setBlock(world, i + 22, j + 2, k + 17, Blocks.log, 0);
		setBlock(world, i + 22, j + 3, k + 14, Blocks.log, 0);
		setBlock(world, i + 22, j + 3, k + 15, Blocks.log, 0);
		setBlock(world, i + 22, j + 3, k + 16, Blocks.log, 0);
		setBlock(world, i + 22, j + 3, k + 17, Blocks.log, 0);
		setBlock(world, i + 22, j + 4, k + 14, Blocks.log, 0);
		setBlock(world, i + 22, j + 4, k + 15, Blocks.log, 0);
		setBlock(world, i + 22, j + 4, k + 16, Blocks.log, 0);
		setBlock(world, i + 22, j + 4, k + 17, Blocks.log, 0);
		setBlock(world, i + 22, j + 5, k + 14, Blocks.log, 0);
		setBlock(world, i + 22, j + 5, k + 15, Blocks.log, 0);
		setBlock(world, i + 22, j + 5, k + 16, Blocks.log, 0);
		setBlock(world, i + 22, j + 5, k + 17, Blocks.log, 0);
		setBlock(world, i + 22, j + 6, k + 14, Blocks.log, 0);
		setBlock(world, i + 22, j + 6, k + 15, Blocks.log, 0);
		setBlock(world, i + 22, j + 6, k + 16, Blocks.log, 0);
		setBlock(world, i + 22, j + 6, k + 17, Blocks.log, 0);
		setBlock(world, i + 22, j + 7, k + 14, Blocks.log, 0);
		setBlock(world, i + 22, j + 7, k + 15, Blocks.log, 0);
		setBlock(world, i + 22, j + 7, k + 16, Blocks.log, 0);
		setBlock(world, i + 22, j + 7, k + 17, Blocks.log, 0);
		setBlock(world, i + 22, j + 8, k + 15, Blocks.log, 0);
		setBlock(world, i + 22, j + 8, k + 16, Blocks.log, 0);
		setBlock(world, i + 22, j + 8, k + 17, Blocks.log, 0);
		setBlock(world, i + 22, j + 8, k + 18, Blocks.log, 0);
		setBlock(world, i + 22, j + 9, k + 15, Blocks.log, 0);
		setBlock(world, i + 22, j + 9, k + 16, Blocks.log, 0);
		setBlock(world, i + 22, j + 9, k + 17, Blocks.log, 0);
		setBlock(world, i + 22, j + 9, k + 18, Blocks.log, 0);
		setBlock(world, i + 22, j + 10, k + 16, Blocks.log, 0);
		setBlock(world, i + 22, j + 10, k + 17, Blocks.log, 0);
		setBlock(world, i + 22, j + 10, k + 18, Blocks.log, 0);
		setBlock(world, i + 22, j + 11, k + 17, Blocks.log, 0);
		setBlock(world, i + 22, j + 11, k + 18, Blocks.log, 0);
		setBlock(world, i + 22, j + 12, k + 17, Blocks.log, 0);
		setBlock(world, i + 22, j + 12, k + 18, Blocks.log, 0);
		setBlock(world, i + 22, j + 13, k + 17, Blocks.log, 0);
		setBlock(world, i + 22, j + 13, k + 18, Blocks.log, 0);
		setBlock(world, i + 22, j + 14, k + 16, Blocks.log, 0);
		setBlock(world, i + 22, j + 14, k + 17, Blocks.log, 0);
		setBlock(world, i + 22, j + 14, k + 18, Blocks.log, 0);
		setBlock(world, i + 22, j + 15, k + 15, Blocks.log, 0);
		setBlock(world, i + 22, j + 15, k + 16, Blocks.log, 0);
		setBlock(world, i + 22, j + 15, k + 17, Blocks.log, 0);
		setBlock(world, i + 22, j + 15, k + 18, Blocks.log, 0);
		setBlock(world, i + 22, j + 16, k + 15, Blocks.log, 0);
		setBlock(world, i + 22, j + 16, k + 16, Blocks.log, 0);
		setBlock(world, i + 22, j + 16, k + 17, Blocks.log, 0);
		setBlock(world, i + 22, j + 16, k + 18, Blocks.log, 0);
		setBlock(world, i + 22, j + 17, k + 15, Blocks.log, 0);
		setBlock(world, i + 22, j + 17, k + 16, Blocks.log, 0);
		setBlock(world, i + 22, j + 17, k + 17, Blocks.log, 0);
		setBlock(world, i + 22, j + 17, k + 18, Blocks.log, 0);
		setBlock(world, i + 22, j + 18, k + 15, Blocks.log, 0);
		setBlock(world, i + 22, j + 18, k + 16, Blocks.log, 0);
		setBlock(world, i + 22, j + 18, k + 17, Blocks.log, 0);
		setBlock(world, i + 22, j + 18, k + 18, Blocks.log, 0);
		setBlock(world, i + 22, j + 19, k + 15, Blocks.log, 0);
		setBlock(world, i + 22, j + 19, k + 16, Blocks.log, 0);
		setBlock(world, i + 22, j + 19, k + 17, Blocks.log, 0);
		setBlock(world, i + 22, j + 19, k + 18, Blocks.log, 0);
		setBlock(world, i + 22, j + 20, k + 15, Blocks.log, 0);
		setBlock(world, i + 22, j + 20, k + 16, Blocks.log, 0);
		setBlock(world, i + 22, j + 20, k + 17, Blocks.log, 0);
		setBlock(world, i + 22, j + 20, k + 18, Blocks.log, 0);
		setBlock(world, i + 22, j + 21, k + 15, Blocks.log, 0);
		setBlock(world, i + 22, j + 21, k + 16, Blocks.log, 0);
		setBlock(world, i + 22, j + 21, k + 17, Blocks.log, 0);
		setBlock(world, i + 22, j + 21, k + 18, Blocks.log, 0);
		setBlock(world, i + 22, j + 22, k + 15, Blocks.log, 0);
		setBlock(world, i + 22, j + 22, k + 16, Blocks.log, 0);
		setBlock(world, i + 22, j + 22, k + 17, Blocks.log, 0);
		setBlock(world, i + 22, j + 22, k + 18, Blocks.log, 0);
		setBlock(world, i + 22, j + 23, k + 15, Blocks.log, 0);
		setBlock(world, i + 22, j + 23, k + 16, Blocks.log, 0);
		setBlock(world, i + 22, j + 23, k + 17, Blocks.log, 0);
		setBlock(world, i + 22, j + 23, k + 18, Blocks.log, 0);
		setBlock(world, i + 22, j + 24, k + 15, Blocks.log, 0);
		setBlock(world, i + 22, j + 24, k + 16, Blocks.log, 0);
		setBlock(world, i + 22, j + 24, k + 17, Blocks.log, 0);
		setBlock(world, i + 22, j + 24, k + 18, Blocks.log, 0);
		setBlock(world, i + 22, j + 25, k + 15, Blocks.log, 0);
		setBlock(world, i + 22, j + 25, k + 16, Blocks.log, 0);
		setBlock(world, i + 22, j + 25, k + 17, Blocks.log, 0);
		setBlock(world, i + 22, j + 25, k + 18, Blocks.log, 0);
		setBlock(world, i + 22, j + 26, k + 15, Blocks.log, 0);
		setBlock(world, i + 22, j + 26, k + 16, Blocks.log, 0);
		setBlock(world, i + 22, j + 26, k + 17, Blocks.log, 0);
		setBlock(world, i + 22, j + 26, k + 18, Blocks.log, 0);
		setBlock(world, i + 22, j + 27, k + 15, Blocks.log, 0);
		setBlock(world, i + 22, j + 27, k + 16, Blocks.log, 0);
		setBlock(world, i + 22, j + 27, k + 17, Blocks.log, 0);
		setBlock(world, i + 22, j + 27, k + 18, Blocks.log, 0);
		setBlock(world, i + 22, j + 28, k + 15, Blocks.log, 0);
		setBlock(world, i + 22, j + 28, k + 16, Blocks.log, 0);
		setBlock(world, i + 22, j + 28, k + 17, Blocks.log, 0);
		setBlock(world, i + 22, j + 28, k + 18, Blocks.log, 0);
		setBlock(world, i + 22, j + 29, k + 14, Blocks.log, 0);
		setBlock(world, i + 22, j + 29, k + 15, Blocks.log, 0);
		setBlock(world, i + 22, j + 29, k + 16, Blocks.log, 0);
		setBlock(world, i + 22, j + 29, k + 17, Blocks.log, 0);
		setBlock(world, i + 22, j + 29, k + 18, Blocks.log, 0);
		setBlock(world, i + 22, j + 30, k + 14, Blocks.log, 0);
		setBlock(world, i + 22, j + 30, k + 15, Blocks.log, 0);
		setBlock(world, i + 22, j + 30, k + 16, Blocks.log, 0);
		setBlock(world, i + 22, j + 30, k + 17, Blocks.log, 0);
		setBlock(world, i + 22, j + 30, k + 18, Blocks.log, 0);
		setBlock(world, i + 22, j + 31, k + 14, Blocks.log, 0);
		setBlock(world, i + 22, j + 31, k + 15, Blocks.log, 0);
		setBlock(world, i + 22, j + 31, k + 16, Blocks.log, 0);
		setBlock(world, i + 22, j + 31, k + 17, Blocks.log, 0);
		setBlock(world, i + 22, j + 31, k + 18, Blocks.log, 0);
		setBlock(world, i + 22, j + 32, k + 14, Blocks.log, 0);
		setBlock(world, i + 22, j + 32, k + 15, Blocks.log, 0);
		setBlock(world, i + 22, j + 32, k + 16, Blocks.log, 0);
		setBlock(world, i + 22, j + 32, k + 17, Blocks.log, 0);
		setBlock(world, i + 22, j + 32, k + 18, Blocks.log, 0);
		setBlock(world, i + 22, j + 33, k + 14, Blocks.log, 0);
		setBlock(world, i + 22, j + 33, k + 15, Blocks.log, 0);
		setBlock(world, i + 22, j + 33, k + 16, Blocks.log, 0);
		setBlock(world, i + 22, j + 33, k + 17, Blocks.log, 0);
		setBlock(world, i + 22, j + 33, k + 18, Blocks.log, 0);
		setBlock(world, i + 22, j + 34, k + 14, Blocks.log, 0);
		setBlock(world, i + 22, j + 34, k + 15, Blocks.log, 0);
		setBlock(world, i + 22, j + 34, k + 16, Blocks.log, 0);
		setBlock(world, i + 22, j + 34, k + 17, Blocks.log, 0);
		setBlock(world, i + 22, j + 34, k + 18, Blocks.log, 0);
		setBlock(world, i + 22, j + 35, k + 14, Blocks.log, 0);
		setBlock(world, i + 22, j + 35, k + 15, Blocks.log, 0);
		setBlock(world, i + 22, j + 35, k + 16, Blocks.log, 0);
		setBlock(world, i + 22, j + 35, k + 17, Blocks.log, 0);
		setBlock(world, i + 22, j + 36, k + 14, Blocks.log, 0);
		setBlock(world, i + 22, j + 36, k + 15, Blocks.log, 0);
		setBlock(world, i + 22, j + 36, k + 16, Blocks.log, 0);
		setBlock(world, i + 22, j + 36, k + 17, Blocks.log, 0);
		setBlock(world, i + 22, j + 37, k + 14, Blocks.log, 0);
		setBlock(world, i + 22, j + 37, k + 15, Blocks.log, 0);
		setBlock(world, i + 22, j + 37, k + 16, Blocks.log, 0);
		setBlock(world, i + 22, j + 37, k + 17, Blocks.log, 0);
		setBlock(world, i + 22, j + 38, k + 14, Blocks.log, 0);
		setBlock(world, i + 22, j + 38, k + 15, Blocks.log, 0);
		setBlock(world, i + 22, j + 38, k + 16, Blocks.log, 0);
		setBlock(world, i + 22, j + 38, k + 17, Blocks.log, 0);
		setBlock(world, i + 22, j + 39, k + 4, Blocks.log, 0);
		setBlock(world, i + 22, j + 39, k + 14, Blocks.log, 0);
		setBlock(world, i + 22, j + 39, k + 15, Blocks.log, 0);
		setBlock(world, i + 22, j + 39, k + 16, Blocks.log, 0);
		setBlock(world, i + 22, j + 39, k + 17, Blocks.log, 0);
		setBlock(world, i + 22, j + 40, k + 14, Blocks.log, 0);
		setBlock(world, i + 22, j + 40, k + 15, Blocks.log, 0);
		setBlock(world, i + 22, j + 40, k + 16, Blocks.log, 0);
		setBlock(world, i + 22, j + 40, k + 17, Blocks.log, 0);
		setBlock(world, i + 22, j + 41, k + 8, Blocks.log, 0);
		setBlock(world, i + 22, j + 41, k + 15, Blocks.log, 0);
		setBlock(world, i + 22, j + 41, k + 16, Blocks.log, 0);
		setBlock(world, i + 22, j + 43, k + 10, Blocks.log, 0);
		setBlock(world, i + 22, j + 44, k + 20, Blocks.log, 0);
		setBlock(world, i + 22, j + 45, k + 16, Blocks.log, 0);
		setBlock(world, i + 22, j + 45, k + 18, Blocks.log, 0);
		setBlock(world, i + 22, j + 45, k + 19, Blocks.log, 0);
		setBlock(world, i + 22, j + 46, k + 15, Blocks.log, 0);
		setBlock(world, i + 22, j + 46, k + 19, Blocks.log, 0);
		setBlock(world, i + 22, j + 46, k + 20, Blocks.log, 0);
		setBlock(world, i + 22, j + 47, k + 18, Blocks.log, 0);
		setBlock(world, i + 22, j + 47, k + 19, Blocks.log, 0);
		setBlock(world, i + 22, j + 48, k + 11, Blocks.log, 0);
		setBlock(world, i + 22, j + 48, k + 16, Blocks.log, 0);
		setBlock(world, i + 23, j + 21, k + 16, Blocks.log, 0);
		setBlock(world, i + 23, j + 21, k + 17, Blocks.log, 0);
		setBlock(world, i + 23, j + 22, k + 15, Blocks.log, 0);
		setBlock(world, i + 23, j + 22, k + 16, Blocks.log, 0);
		setBlock(world, i + 23, j + 22, k + 17, Blocks.log, 0);
		setBlock(world, i + 23, j + 22, k + 18, Blocks.log, 0);
		setBlock(world, i + 23, j + 23, k + 15, Blocks.log, 0);
		setBlock(world, i + 23, j + 23, k + 16, Blocks.log, 0);
		setBlock(world, i + 23, j + 23, k + 17, Blocks.log, 0);
		setBlock(world, i + 23, j + 23, k + 18, Blocks.log, 0);
		setBlock(world, i + 23, j + 24, k + 15, Blocks.log, 0);
		setBlock(world, i + 23, j + 24, k + 16, Blocks.log, 0);
		setBlock(world, i + 23, j + 24, k + 17, Blocks.log, 0);
		setBlock(world, i + 23, j + 24, k + 18, Blocks.log, 0);
		setBlock(world, i + 23, j + 25, k + 15, Blocks.log, 0);
		setBlock(world, i + 23, j + 25, k + 16, Blocks.log, 0);
		setBlock(world, i + 23, j + 25, k + 17, Blocks.log, 0);
		setBlock(world, i + 23, j + 25, k + 18, Blocks.log, 0);
		setBlock(world, i + 23, j + 26, k + 15, Blocks.log, 0);
		setBlock(world, i + 23, j + 26, k + 16, Blocks.log, 0);
		setBlock(world, i + 23, j + 26, k + 17, Blocks.log, 0);
		setBlock(world, i + 23, j + 26, k + 18, Blocks.log, 0);
		setBlock(world, i + 23, j + 27, k + 15, Blocks.log, 0);
		setBlock(world, i + 23, j + 27, k + 16, Blocks.log, 0);
		setBlock(world, i + 23, j + 27, k + 17, Blocks.log, 0);
		setBlock(world, i + 23, j + 27, k + 18, Blocks.log, 0);
		setBlock(world, i + 23, j + 28, k + 15, Blocks.log, 0);
		setBlock(world, i + 23, j + 28, k + 16, Blocks.log, 0);
		setBlock(world, i + 23, j + 28, k + 17, Blocks.log, 0);
		setBlock(world, i + 23, j + 28, k + 18, Blocks.log, 0);
		setBlock(world, i + 23, j + 29, k + 15, Blocks.log, 0);
		setBlock(world, i + 23, j + 29, k + 16, Blocks.log, 0);
		setBlock(world, i + 23, j + 29, k + 17, Blocks.log, 0);
		setBlock(world, i + 23, j + 29, k + 18, Blocks.log, 0);
		setBlock(world, i + 23, j + 30, k + 14, Blocks.log, 0);
		setBlock(world, i + 23, j + 30, k + 15, Blocks.log, 0);
		setBlock(world, i + 23, j + 30, k + 16, Blocks.log, 0);
		setBlock(world, i + 23, j + 30, k + 17, Blocks.log, 0);
		setBlock(world, i + 23, j + 30, k + 18, Blocks.log, 0);
		setBlock(world, i + 23, j + 31, k + 14, Blocks.log, 0);
		setBlock(world, i + 23, j + 31, k + 15, Blocks.log, 0);
		setBlock(world, i + 23, j + 31, k + 16, Blocks.log, 0);
		setBlock(world, i + 23, j + 31, k + 17, Blocks.log, 0);
		setBlock(world, i + 23, j + 31, k + 18, Blocks.log, 0);
		setBlock(world, i + 23, j + 32, k + 14, Blocks.log, 0);
		setBlock(world, i + 23, j + 32, k + 15, Blocks.log, 0);
		setBlock(world, i + 23, j + 32, k + 16, Blocks.log, 0);
		setBlock(world, i + 23, j + 32, k + 17, Blocks.log, 0);
		setBlock(world, i + 23, j + 32, k + 18, Blocks.log, 0);
		setBlock(world, i + 23, j + 33, k + 14, Blocks.log, 0);
		setBlock(world, i + 23, j + 33, k + 15, Blocks.log, 0);
		setBlock(world, i + 23, j + 33, k + 16, Blocks.log, 0);
		setBlock(world, i + 23, j + 33, k + 17, Blocks.log, 0);
		setBlock(world, i + 23, j + 33, k + 18, Blocks.log, 0);
		setBlock(world, i + 23, j + 34, k + 14, Blocks.log, 0);
		setBlock(world, i + 23, j + 34, k + 15, Blocks.log, 0);
		setBlock(world, i + 23, j + 34, k + 16, Blocks.log, 0);
		setBlock(world, i + 23, j + 34, k + 17, Blocks.log, 0);
		setBlock(world, i + 23, j + 34, k + 18, Blocks.log, 0);
		setBlock(world, i + 23, j + 35, k + 14, Blocks.log, 0);
		setBlock(world, i + 23, j + 35, k + 15, Blocks.log, 0);
		setBlock(world, i + 23, j + 35, k + 16, Blocks.log, 0);
		setBlock(world, i + 23, j + 35, k + 17, Blocks.log, 0);
		setBlock(world, i + 23, j + 36, k + 14, Blocks.log, 0);
		setBlock(world, i + 23, j + 36, k + 15, Blocks.log, 0);
		setBlock(world, i + 23, j + 36, k + 16, Blocks.log, 0);
		setBlock(world, i + 23, j + 36, k + 17, Blocks.log, 0);
		setBlock(world, i + 23, j + 37, k + 15, Blocks.log, 0);
		setBlock(world, i + 23, j + 37, k + 16, Blocks.log, 0);
		setBlock(world, i + 23, j + 38, k + 15, Blocks.log, 0);
		setBlock(world, i + 23, j + 38, k + 16, Blocks.log, 0);
		setBlock(world, i + 23, j + 39, k + 15, Blocks.log, 0);
		setBlock(world, i + 23, j + 39, k + 16, Blocks.log, 0);
		setBlock(world, i + 23, j + 39, k + 22, Blocks.log, 0);
		setBlock(world, i + 23, j + 40, k + 15, Blocks.log, 0);
		setBlock(world, i + 23, j + 40, k + 16, Blocks.log, 0);
		setBlock(world, i + 23, j + 41, k + 11, Blocks.log, 0);
		setBlock(world, i + 23, j + 41, k + 21, Blocks.log, 0);
		setBlock(world, i + 23, j + 42, k + 22, Blocks.log, 0);
		setBlock(world, i + 23, j + 45, k + 9, Blocks.log, 0);
		setBlock(world, i + 23, j + 45, k + 15, Blocks.log, 0);
		setBlock(world, i + 23, j + 46, k + 13, Blocks.log, 0);
		setBlock(world, i + 23, j + 46, k + 16, Blocks.log, 0);
		setBlock(world, i + 23, j + 47, k + 14, Blocks.log, 0);
		setBlock(world, i + 23, j + 47, k + 17, Blocks.log, 0);
		setBlock(world, i + 23, j + 48, k + 11, Blocks.log, 0);
		setBlock(world, i + 24, j + 22, k + 16, Blocks.log, 0);
		setBlock(world, i + 24, j + 22, k + 17, Blocks.log, 0);
		setBlock(world, i + 24, j + 23, k + 16, Blocks.log, 0);
		setBlock(world, i + 24, j + 23, k + 17, Blocks.log, 0);
		setBlock(world, i + 24, j + 24, k + 16, Blocks.log, 0);
		setBlock(world, i + 24, j + 24, k + 17, Blocks.log, 0);
		setBlock(world, i + 24, j + 25, k + 16, Blocks.log, 0);
		setBlock(world, i + 24, j + 25, k + 17, Blocks.log, 0);
		setBlock(world, i + 24, j + 26, k + 16, Blocks.log, 0);
		setBlock(world, i + 24, j + 26, k + 17, Blocks.log, 0);
		setBlock(world, i + 24, j + 27, k + 16, Blocks.log, 0);
		setBlock(world, i + 24, j + 27, k + 17, Blocks.log, 0);
		setBlock(world, i + 24, j + 28, k + 16, Blocks.log, 0);
		setBlock(world, i + 24, j + 28, k + 17, Blocks.log, 0);
		setBlock(world, i + 24, j + 29, k + 16, Blocks.log, 0);
		setBlock(world, i + 24, j + 29, k + 17, Blocks.log, 0);
		setBlock(world, i + 24, j + 30, k + 15, Blocks.log, 0);
		setBlock(world, i + 24, j + 30, k + 16, Blocks.log, 0);
		setBlock(world, i + 24, j + 30, k + 17, Blocks.log, 0);
		setBlock(world, i + 24, j + 31, k + 15, Blocks.log, 0);
		setBlock(world, i + 24, j + 31, k + 16, Blocks.log, 0);
		setBlock(world, i + 24, j + 32, k + 15, Blocks.log, 0);
		setBlock(world, i + 24, j + 32, k + 16, Blocks.log, 0);
		setBlock(world, i + 24, j + 33, k + 15, Blocks.log, 0);
		setBlock(world, i + 24, j + 33, k + 16, Blocks.log, 0);
		setBlock(world, i + 24, j + 34, k + 15, Blocks.log, 0);
		setBlock(world, i + 24, j + 34, k + 16, Blocks.log, 0);
		setBlock(world, i + 24, j + 35, k + 15, Blocks.log, 0);
		setBlock(world, i + 24, j + 35, k + 16, Blocks.log, 0);
		setBlock(world, i + 24, j + 36, k + 15, Blocks.log, 0);
		setBlock(world, i + 24, j + 36, k + 16, Blocks.log, 0);
		setBlock(world, i + 24, j + 39, k + 25, Blocks.log, 0);
		setBlock(world, i + 24, j + 40, k + 18, Blocks.log, 0);
		setBlock(world, i + 24, j + 42, k + 19, Blocks.log, 0);
		setBlock(world, i + 24, j + 43, k + 16, Blocks.log, 0);
		setBlock(world, i + 24, j + 43, k + 21, Blocks.log, 0);
		setBlock(world, i + 24, j + 44, k + 15, Blocks.log, 0);
		setBlock(world, i + 24, j + 45, k + 5, Blocks.log, 0);
		setBlock(world, i + 24, j + 45, k + 12, Blocks.log, 0);
		setBlock(world, i + 24, j + 47, k + 11, Blocks.log, 0);
		setBlock(world, i + 24, j + 47, k + 14, Blocks.log, 0);
		setBlock(world, i + 24, j + 47, k + 16, Blocks.log, 0);
		setBlock(world, i + 24, j + 48, k + 15, Blocks.log, 0);
		setBlock(world, i + 24, j + 48, k + 19, Blocks.log, 0);
		setBlock(world, i + 24, j + 48, k + 22, Blocks.log, 0);
		setBlock(world, i + 25, j + 39, k + 21, Blocks.log, 0);
		setBlock(world, i + 25, j + 40, k + 22, Blocks.log, 0);
		setBlock(world, i + 25, j + 43, k + 10, Blocks.log, 0);
		setBlock(world, i + 25, j + 44, k + 19, Blocks.log, 0);
		setBlock(world, i + 25, j + 45, k + 15, Blocks.log, 0);
		setBlock(world, i + 25, j + 46, k + 10, Blocks.log, 0);
		setBlock(world, i + 25, j + 46, k + 15, Blocks.log, 0);
		setBlock(world, i + 25, j + 46, k + 20, Blocks.log, 0);
		setBlock(world, i + 25, j + 48, k + 16, Blocks.log, 0);
		setBlock(world, i + 25, j + 48, k + 18, Blocks.log, 0);
		setBlock(world, i + 25, j + 48, k + 21, Blocks.log, 0);
		setBlock(world, i + 26, j + 39, k + 12, Blocks.log, 0);
		setBlock(world, i + 26, j + 39, k + 23, Blocks.log, 0);
		setBlock(world, i + 26, j + 40, k + 16, Blocks.log, 0);
		setBlock(world, i + 26, j + 41, k + 23, Blocks.log, 0);
		setBlock(world, i + 26, j + 43, k + 14, Blocks.log, 0);
		setBlock(world, i + 26, j + 44, k + 12, Blocks.log, 0);
		setBlock(world, i + 26, j + 44, k + 19, Blocks.log, 0);
		setBlock(world, i + 26, j + 47, k + 13, Blocks.log, 0);
		setBlock(world, i + 27, j + 39, k + 8, Blocks.log, 0);
		setBlock(world, i + 27, j + 41, k + 16, Blocks.log, 0);
		setBlock(world, i + 27, j + 41, k + 24, Blocks.log, 0);
		setBlock(world, i + 27, j + 42, k + 12, Blocks.log, 0);
		setBlock(world, i + 27, j + 44, k + 18, Blocks.log, 0);
		setBlock(world, i + 27, j + 45, k + 13, Blocks.log, 0);
		setBlock(world, i + 27, j + 45, k + 16, Blocks.log, 0);
		setBlock(world, i + 27, j + 46, k + 17, Blocks.log, 0);
		setBlock(world, i + 27, j + 46, k + 19, Blocks.log, 0);
		setBlock(world, i + 27, j + 48, k + 18, Blocks.log, 0);
		setBlock(world, i + 28, j + 40, k + 22, Blocks.log, 0);
		setBlock(world, i + 28, j + 41, k + 5, Blocks.log, 0);
		setBlock(world, i + 28, j + 44, k + 13, Blocks.log, 0);
		setBlock(world, i + 28, j + 44, k + 17, Blocks.log, 0);
		setBlock(world, i + 28, j + 47, k + 20, Blocks.log, 0);
		setBlock(world, i + 29, j + 44, k + 13, Blocks.log, 0);
		setBlock(world, i + 29, j + 44, k + 16, Blocks.log, 0);
		setBlock(world, i + 29, j + 44, k + 23, Blocks.log, 0);
		setBlock(world, i + 30, j + 39, k + 22, Blocks.log, 0);
		setBlock(world, i + 30, j + 42, k + 12, Blocks.log, 0);
		setBlock(world, i + 30, j + 42, k + 14, Blocks.log, 0);
		setBlock(world, i + 30, j + 42, k + 21, Blocks.log, 0);
		setBlock(world, i + 30, j + 43, k + 10, Blocks.log, 0);
		setBlock(world, i + 31, j + 39, k + 17, Blocks.log, 0);
		setBlock(world, i + 31, j + 41, k + 8, Blocks.log, 0);
		setBlock(world, i + 31, j + 42, k + 21, Blocks.log, 0);
		setBlock(world, i + 31, j + 43, k + 25, Blocks.log, 0);
		setBlock(world, i + 31, j + 44, k + 21, Blocks.log, 0);
		setBlock(world, i + 32, j + 39, k + 19, Blocks.log, 0);
		setBlock(world, i + 32, j + 40, k + 16, Blocks.log, 0);
		setBlock(world, i + 33, j + 40, k + 4, Blocks.log, 0);
		setBlock(world, i + 33, j + 40, k + 18, Blocks.log, 0);
		setBlock(world, i + 33, j + 41, k + 9, Blocks.log, 0);
		setBlock(world, i + 33, j + 42, k + 6, Blocks.log, 0);
		setBlock(world, i + 34, j + 41, k + 7, Blocks.log, 0);
		setBlock(world, i + 0, j + 40, k + 9, Blocks.leaves, 12);
		world.setBlockMetadataWithNotify(i + 0, j + 40, k + 9, 12, 2);
		setBlock(world, i + 0, j + 40, k + 22, Blocks.leaves, 12);
		world.setBlockMetadataWithNotify(i + 0, j + 40, k + 22, 12, 2);
		setBlock(world, i + 0, j + 40, k + 23, Blocks.leaves, 12);
		world.setBlockMetadataWithNotify(i + 0, j + 40, k + 23, 12, 2);
		setBlock(world, i + 0, j + 41, k + 8, Blocks.leaves, 12);
		world.setBlockMetadataWithNotify(i + 0, j + 41, k + 8, 12, 2);
		setBlock(world, i + 0, j + 41, k + 23, Blocks.leaves, 12);
		world.setBlockMetadataWithNotify(i + 0, j + 41, k + 23, 12, 2);
		setBlock(world, i + 1, j + 40, k + 7, Blocks.leaves, 12);
		world.setBlockMetadataWithNotify(i + 1, j + 40, k + 7, 12, 2);
		setBlock(world, i + 1, j + 40, k + 8, Blocks.leaves, 12);
		world.setBlockMetadataWithNotify(i + 1, j + 40, k + 8, 12, 2);
		setBlock(world, i + 1, j + 40, k + 22, Blocks.leaves, 12);
		world.setBlockMetadataWithNotify(i + 1, j + 40, k + 22, 12, 2);
		setBlock(world, i + 1, j + 40, k + 23, Blocks.leaves, 12);
		world.setBlockMetadataWithNotify(i + 1, j + 40, k + 23, 12, 2);
		setBlock(world, i + 1, j + 40, k + 24, Blocks.leaves, 12);
		world.setBlockMetadataWithNotify(i + 1, j + 40, k + 24, 12, 2);
		setBlock(world, i + 1, j + 41, k + 7, Blocks.leaves, 12);
		world.setBlockMetadataWithNotify(i + 1, j + 41, k + 7, 12, 2);
		setBlock(world, i + 1, j + 41, k + 8, Blocks.leaves, 12);
		world.setBlockMetadataWithNotify(i + 1, j + 41, k + 8, 12, 2);
		setBlock(world, i + 1, j + 41, k + 9, Blocks.leaves, 12);
		world.setBlockMetadataWithNotify(i + 1, j + 41, k + 9, 12, 2);
		setBlock(world, i + 1, j + 41, k + 22, Blocks.leaves, 12);
		world.setBlockMetadataWithNotify(i + 1, j + 41, k + 22, 12, 2);
		setBlock(world, i + 1, j + 41, k + 23, Blocks.leaves, 12);
		world.setBlockMetadataWithNotify(i + 1, j + 41, k + 23, 12, 2);
		setBlock(world, i + 1, j + 41, k + 24, Blocks.leaves, 12);
		world.setBlockMetadataWithNotify(i + 1, j + 41, k + 24, 12, 2);
		setBlock(world, i + 2, j + 39, k + 9, Blocks.leaves, 12);
		world.setBlockMetadataWithNotify(i + 2, j + 39, k + 9, 12, 2);
		setBlock(world, i + 2, j + 39, k + 10, Blocks.leaves, 12);
		world.setBlockMetadataWithNotify(i + 2, j + 39, k + 10, 12, 2);
		setBlock(world, i + 2, j + 39, k + 11, Blocks.leaves, 12);
		world.setBlockMetadataWithNotify(i + 2, j + 39, k + 11, 12, 2);
		setBlock(world, i + 2, j + 40, k + 6, Blocks.leaves, 12);
		world.setBlockMetadataWithNotify(i + 2, j + 40, k + 6, 12, 2);
		setBlock(world, i + 2, j + 40, k + 7, Blocks.leaves, 12);
		world.setBlockMetadataWithNotify(i + 2, j + 40, k + 7, 12, 2);
		setBlock(world, i + 2, j + 40, k + 9, Blocks.leaves, 12);
		world.setBlockMetadataWithNotify(i + 2, j + 40, k + 9, 12, 2);
		setBlock(world, i + 2, j + 40, k + 21, Blocks.leaves, 12);
		world.setBlockMetadataWithNotify(i + 2, j + 40, k + 21, 12, 2);
		setBlock(world, i + 2, j + 40, k + 22, Blocks.leaves, 12);
		world.setBlockMetadataWithNotify(i + 2, j + 40, k + 22, 12, 2);
		setBlock(world, i + 2, j + 41, k + 6, Blocks.leaves, 12);
		world.setBlockMetadataWithNotify(i + 2, j + 41, k + 6, 12, 2);
		setBlock(world, i + 2, j + 41, k + 7, Blocks.leaves, 12);
		world.setBlockMetadataWithNotify(i + 2, j + 41, k + 7, 12, 2);
		setBlock(world, i + 2, j + 41, k + 8, Blocks.leaves, 12);
		world.setBlockMetadataWithNotify(i + 2, j + 41, k + 8, 12, 2);
		setBlock(world, i + 2, j + 41, k + 9, Blocks.leaves, 12);
		world.setBlockMetadataWithNotify(i + 2, j + 41, k + 9, 12, 2);
		setBlock(world, i + 2, j + 41, k + 10, Blocks.leaves, 12);
		world.setBlockMetadataWithNotify(i + 2, j + 41, k + 10, 12, 2);
		setBlock(world, i + 2, j + 41, k + 21, Blocks.leaves, 12);
		world.setBlockMetadataWithNotify(i + 2, j + 41, k + 21, 12, 2);
		setBlock(world, i + 2, j + 41, k + 22, Blocks.leaves, 12);
		world.setBlockMetadataWithNotify(i + 2, j + 41, k + 22, 12, 2);
		setBlock(world, i + 2, j + 41, k + 23, Blocks.leaves, 12);
		world.setBlockMetadataWithNotify(i + 2, j + 41, k + 23, 12, 2);
		setBlock(world, i + 2, j + 42, k + 16, Blocks.leaves, 12);
		world.setBlockMetadataWithNotify(i + 2, j + 42, k + 16, 12, 2);
		setBlock(world, i + 2, j + 42, k + 17, Blocks.leaves, 12);
		world.setBlockMetadataWithNotify(i + 2, j + 42, k + 17, 12, 2);
		setBlock(world, i + 3, j + 39, k + 9, Blocks.leaves, 12);
		world.setBlockMetadataWithNotify(i + 3, j + 39, k + 9, 12, 2);
		setBlock(world, i + 3, j + 39, k + 10, Blocks.leaves, 12);
		world.setBlockMetadataWithNotify(i + 3, j + 39, k + 10, 12, 2);
		setBlock(world, i + 3, j + 39, k + 11, Blocks.leaves, 12);
		world.setBlockMetadataWithNotify(i + 3, j + 39, k + 11, 12, 2);
		setBlock(world, i + 3, j + 39, k + 12, Blocks.leaves, 4);
		world.setBlockMetadataWithNotify(i + 3, j + 39, k + 12, 4, 2);
		setBlock(world, i + 3, j + 40, k + 6, Blocks.leaves, 4);
		world.setBlockMetadataWithNotify(i + 3, j + 40, k + 6, 4, 2);
		setBlock(world, i + 3, j + 40, k + 7, Blocks.leaves, 12);
		world.setBlockMetadataWithNotify(i + 3, j + 40, k + 7, 12, 2);
		setBlock(world, i + 3, j + 40, k + 8, Blocks.leaves, 12);
		world.setBlockMetadataWithNotify(i + 3, j + 40, k + 8, 12, 2);
		setBlock(world, i + 3, j + 40, k + 9, Blocks.leaves, 12);
		world.setBlockMetadataWithNotify(i + 3, j + 40, k + 9, 12, 2);
		setBlock(world, i + 3, j + 40, k + 10, Blocks.leaves, 12);
		world.setBlockMetadataWithNotify(i + 3, j + 40, k + 10, 12, 2);
		setBlock(world, i + 3, j + 40, k + 11, Blocks.leaves, 12);
		world.setBlockMetadataWithNotify(i + 3, j + 40, k + 11, 12, 2);
		setBlock(world, i + 3, j + 40, k + 20, Blocks.leaves, 12);
		world.setBlockMetadataWithNotify(i + 3, j + 40, k + 20, 12, 2);
		setBlock(world, i + 3, j + 40, k + 21, Blocks.leaves, 12);
		world.setBlockMetadataWithNotify(i + 3, j + 40, k + 21, 12, 2);
		setBlock(world, i + 3, j + 40, k + 22, Blocks.leaves, 12);
		world.setBlockMetadataWithNotify(i + 3, j + 40, k + 22, 12, 2);
		setBlock(world, i + 3, j + 40, k + 23, Blocks.leaves, 12);
		world.setBlockMetadataWithNotify(i + 3, j + 40, k + 23, 12, 2);
		setBlock(world, i + 3, j + 40, k + 24, Blocks.leaves, 12);
		world.setBlockMetadataWithNotify(i + 3, j + 40, k + 24, 12, 2);
		setBlock(world, i + 3, j + 40, k + 25, Blocks.leaves, 12);
		world.setBlockMetadataWithNotify(i + 3, j + 40, k + 25, 12, 2);
		setBlock(world, i + 3, j + 41, k + 7, Blocks.leaves, 4);
		world.setBlockMetadataWithNotify(i + 3, j + 41, k + 7, 4, 2);
		setBlock(world, i + 3, j + 41, k + 8, Blocks.leaves, 4);
		world.setBlockMetadataWithNotify(i + 3, j + 41, k + 8, 4, 2);
		setBlock(world, i + 3, j + 41, k + 9, Blocks.leaves, 12);
		world.setBlockMetadataWithNotify(i + 3, j + 41, k + 9, 12, 2);
		setBlock(world, i + 3, j + 41, k + 22, Blocks.leaves, 12);
		world.setBlockMetadataWithNotify(i + 3, j + 41, k + 22, 12, 2);
		setBlock(world, i + 3, j + 41, k + 24, Blocks.leaves, 12);
		world.setBlockMetadataWithNotify(i + 3, j + 41, k + 24, 12, 2);
		setBlock(world, i + 3, j + 42, k + 14, Blocks.leaves, 12);
		world.setBlockMetadataWithNotify(i + 3, j + 42, k + 14, 12, 2);
		setBlock(world, i + 3, j + 42, k + 15, Blocks.leaves, 12);
		world.setBlockMetadataWithNotify(i + 3, j + 42, k + 15, 12, 2);
		setBlock(world, i + 3, j + 42, k + 16, Blocks.leaves, 12);
		world.setBlockMetadataWithNotify(i + 3, j + 42, k + 16, 12, 2);
		setBlock(world, i + 3, j + 42, k + 17, Blocks.leaves, 12);
		world.setBlockMetadataWithNotify(i + 3, j + 42, k + 17, 12, 2);
		setBlock(world, i + 3, j + 42, k + 18, Blocks.leaves, 4);
		world.setBlockMetadataWithNotify(i + 3, j + 42, k + 18, 4, 2);
		setBlock(world, i + 3, j + 43, k + 16, Blocks.leaves, 12);
		world.setBlockMetadataWithNotify(i + 3, j + 43, k + 16, 12, 2);
		setBlock(world, i + 3, j + 43, k + 17, Blocks.leaves, 12);
		world.setBlockMetadataWithNotify(i + 3, j + 43, k + 17, 12, 2);
		setBlock(world, i + 4, j + 39, k + 8, Blocks.leaves, 12);
		world.setBlockMetadataWithNotify(i + 4, j + 39, k + 8, 12, 2);
		setBlock(world, i + 4, j + 39, k + 9, Blocks.leaves, 12);
		world.setBlockMetadataWithNotify(i + 4, j + 39, k + 9, 12, 2);
		setBlock(world, i + 4, j + 39, k + 11, Blocks.leaves, 4);
		world.setBlockMetadataWithNotify(i + 4, j + 39, k + 11, 4, 2);
		setBlock(world, i + 4, j + 39, k + 12, Blocks.leaves, 4);
		world.setBlockMetadataWithNotify(i + 4, j + 39, k + 12, 4, 2);
		setBlock(world, i + 4, j + 39, k + 17, Blocks.leaves, 12);
		world.setBlockMetadataWithNotify(i + 4, j + 39, k + 17, 12, 2);
		setBlock(world, i + 4, j + 39, k + 18, Blocks.leaves, 12);
		world.setBlockMetadataWithNotify(i + 4, j + 39, k + 18, 12, 2);
		setBlock(world, i + 4, j + 40, k + 7, Blocks.leaves, 12);
		world.setBlockMetadataWithNotify(i + 4, j + 40, k + 7, 12, 2);
		setBlock(world, i + 4, j + 40, k + 8, Blocks.leaves, 12);
		world.setBlockMetadataWithNotify(i + 4, j + 40, k + 8, 12, 2);
		setBlock(world, i + 4, j + 40, k + 9, Blocks.leaves, 12);
		world.setBlockMetadataWithNotify(i + 4, j + 40, k + 9, 12, 2);
		setBlock(world, i + 4, j + 40, k + 10, Blocks.leaves, 4);
		world.setBlockMetadataWithNotify(i + 4, j + 40, k + 10, 4, 2);
		setBlock(world, i + 4, j + 40, k + 11, Blocks.leaves, 4);
		world.setBlockMetadataWithNotify(i + 4, j + 40, k + 11, 4, 2);
		setBlock(world, i + 4, j + 40, k + 12, Blocks.leaves, 4);
		world.setBlockMetadataWithNotify(i + 4, j + 40, k + 12, 4, 2);
		setBlock(world, i + 4, j + 40, k + 17, Blocks.leaves, 12);
		world.setBlockMetadataWithNotify(i + 4, j + 40, k + 17, 12, 2);
		setBlock(world, i + 4, j + 40, k + 18, Blocks.leaves, 12);
		world.setBlockMetadataWithNotify(i + 4, j + 40, k + 18, 12, 2);
		setBlock(world, i + 4, j + 40, k + 19, Blocks.leaves, 12);
		world.setBlockMetadataWithNotify(i + 4, j + 40, k + 19, 12, 2);
		setBlock(world, i + 4, j + 40, k + 20, Blocks.leaves, 12);
		world.setBlockMetadataWithNotify(i + 4, j + 40, k + 20, 12, 2);
		setBlock(world, i + 4, j + 40, k + 21, Blocks.leaves, 12);
		world.setBlockMetadataWithNotify(i + 4, j + 40, k + 21, 12, 2);
		setBlock(world, i + 4, j + 40, k + 23, Blocks.leaves, 12);
		world.setBlockMetadataWithNotify(i + 4, j + 40, k + 23, 12, 2);
		setBlock(world, i + 4, j + 41, k + 8, Blocks.leaves, 4);
		world.setBlockMetadataWithNotify(i + 4, j + 41, k + 8, 4, 2);
		setBlock(world, i + 4, j + 41, k + 19, Blocks.leaves, 12);
		world.setBlockMetadataWithNotify(i + 4, j + 41, k + 19, 12, 2);
		setBlock(world, i + 4, j + 41, k + 20, Blocks.leaves, 12);
		world.setBlockMetadataWithNotify(i + 4, j + 41, k + 20, 12, 2);
		setBlock(world, i + 4, j + 41, k + 21, Blocks.leaves, 12);
		world.setBlockMetadataWithNotify(i + 4, j + 41, k + 21, 12, 2);
		setBlock(world, i + 4, j + 42, k + 10, Blocks.leaves, 4);
		world.setBlockMetadataWithNotify(i + 4, j + 42, k + 10, 4, 2);
		setBlock(world, i + 4, j + 42, k + 11, Blocks.leaves, 4);
		world.setBlockMetadataWithNotify(i + 4, j + 42, k + 11, 4, 2);
		setBlock(world, i + 4, j + 42, k + 12, Blocks.leaves, 4);
		world.setBlockMetadataWithNotify(i + 4, j + 42, k + 12, 4, 2);
		setBlock(world, i + 4, j + 42, k + 14, Blocks.leaves, 12);
		world.setBlockMetadataWithNotify(i + 4, j + 42, k + 14, 12, 2);
		setBlock(world, i + 4, j + 42, k + 15, Blocks.leaves, 12);
		world.setBlockMetadataWithNotify(i + 4, j + 42, k + 15, 12, 2);
		setBlock(world, i + 4, j + 42, k + 17, Blocks.leaves, 4);
		world.setBlockMetadataWithNotify(i + 4, j + 42, k + 17, 4, 2);
		setBlock(world, i + 4, j + 42, k + 18, Blocks.leaves, 4);
		world.setBlockMetadataWithNotify(i + 4, j + 42, k + 18, 4, 2);
		setBlock(world, i + 4, j + 43, k + 11, Blocks.leaves, 4);
		world.setBlockMetadataWithNotify(i + 4, j + 43, k + 11, 4, 2);
		setBlock(world, i + 4, j + 43, k + 14, Blocks.leaves, 12);
		world.setBlockMetadataWithNotify(i + 4, j + 43, k + 14, 12, 2);
		setBlock(world, i + 4, j + 43, k + 16, Blocks.leaves, 12);
		world.setBlockMetadataWithNotify(i + 4, j + 43, k + 16, 12, 2);
		setBlock(world, i + 4, j + 43, k + 17, Blocks.leaves, 4);
		world.setBlockMetadataWithNotify(i + 4, j + 43, k + 17, 4, 2);
		setBlock(world, i + 4, j + 43, k + 18, Blocks.leaves, 4);
		world.setBlockMetadataWithNotify(i + 4, j + 43, k + 18, 4, 2);
		setBlock(world, i + 5, j + 39, k + 8, Blocks.leaves, 4);
		world.setBlockMetadataWithNotify(i + 5, j + 39, k + 8, 4, 2);
		setBlock(world, i + 5, j + 39, k + 9, Blocks.leaves, 4);
		world.setBlockMetadataWithNotify(i + 5, j + 39, k + 9, 4, 2);
		setBlock(world, i + 5, j + 39, k + 10, Blocks.leaves, 4);
		world.setBlockMetadataWithNotify(i + 5, j + 39, k + 10, 4, 2);
		setBlock(world, i + 5, j + 39, k + 11, Blocks.leaves, 4);
		world.setBlockMetadataWithNotify(i + 5, j + 39, k + 11, 4, 2);
		setBlock(world, i + 5, j + 39, k + 12, Blocks.leaves, 4);
		world.setBlockMetadataWithNotify(i + 5, j + 39, k + 12, 4, 2);
		setBlock(world, i + 5, j + 39, k + 15, Blocks.leaves, 12);
		world.setBlockMetadataWithNotify(i + 5, j + 39, k + 15, 12, 2);
		setBlock(world, i + 5, j + 39, k + 16, Blocks.leaves, 12);
		world.setBlockMetadataWithNotify(i + 5, j + 39, k + 16, 12, 2);
		setBlock(world, i + 5, j + 39, k + 17, Blocks.leaves, 12);
		world.setBlockMetadataWithNotify(i + 5, j + 39, k + 17, 12, 2);
		setBlock(world, i + 5, j + 39, k + 18, Blocks.leaves, 4);
		world.setBlockMetadataWithNotify(i + 5, j + 39, k + 18, 4, 2);
		setBlock(world, i + 5, j + 39, k + 19, Blocks.leaves, 4);
		world.setBlockMetadataWithNotify(i + 5, j + 39, k + 19, 4, 2);
		setBlock(world, i + 5, j + 40, k + 9, Blocks.leaves, 4);
		world.setBlockMetadataWithNotify(i + 5, j + 40, k + 9, 4, 2);
		setBlock(world, i + 5, j + 40, k + 10, Blocks.leaves, 4);
		world.setBlockMetadataWithNotify(i + 5, j + 40, k + 10, 4, 2);
		setBlock(world, i + 5, j + 40, k + 11, Blocks.leaves, 4);
		world.setBlockMetadataWithNotify(i + 5, j + 40, k + 11, 4, 2);
		setBlock(world, i + 5, j + 40, k + 16, Blocks.leaves, 12);
		world.setBlockMetadataWithNotify(i + 5, j + 40, k + 16, 12, 2);
		setBlock(world, i + 5, j + 40, k + 17, Blocks.leaves, 12);
		world.setBlockMetadataWithNotify(i + 5, j + 40, k + 17, 12, 2);
		setBlock(world, i + 5, j + 40, k + 18, Blocks.leaves, 4);
		world.setBlockMetadataWithNotify(i + 5, j + 40, k + 18, 4, 2);
		setBlock(world, i + 5, j + 40, k + 19, Blocks.leaves, 4);
		world.setBlockMetadataWithNotify(i + 5, j + 40, k + 19, 4, 2);
		setBlock(world, i + 5, j + 40, k + 21, Blocks.leaves, 12);
		world.setBlockMetadataWithNotify(i + 5, j + 40, k + 21, 12, 2);
		setBlock(world, i + 5, j + 40, k + 22, Blocks.leaves, 12);
		world.setBlockMetadataWithNotify(i + 5, j + 40, k + 22, 12, 2);
		setBlock(world, i + 5, j + 41, k + 18, Blocks.leaves, 4);
		world.setBlockMetadataWithNotify(i + 5, j + 41, k + 18, 4, 2);
		setBlock(world, i + 5, j + 41, k + 19, Blocks.leaves, 4);
		world.setBlockMetadataWithNotify(i + 5, j + 41, k + 19, 4, 2);
		setBlock(world, i + 5, j + 41, k + 20, Blocks.leaves, 12);
		world.setBlockMetadataWithNotify(i + 5, j + 41, k + 20, 12, 2);
		setBlock(world, i + 5, j + 41, k + 21, Blocks.leaves, 12);
		world.setBlockMetadataWithNotify(i + 5, j + 41, k + 21, 12, 2);
		setBlock(world, i + 5, j + 41, k + 22, Blocks.leaves, 12);
		world.setBlockMetadataWithNotify(i + 5, j + 41, k + 22, 12, 2);
		setBlock(world, i + 5, j + 42, k + 7, Blocks.leaves, 12);
		world.setBlockMetadataWithNotify(i + 5, j + 42, k + 7, 12, 2);
		setBlock(world, i + 5, j + 42, k + 8, Blocks.leaves, 12);
		world.setBlockMetadataWithNotify(i + 5, j + 42, k + 8, 12, 2);
		setBlock(world, i + 5, j + 42, k + 9, Blocks.leaves, 4);
		world.setBlockMetadataWithNotify(i + 5, j + 42, k + 9, 4, 2);
		setBlock(world, i + 5, j + 42, k + 10, Blocks.leaves, 4);
		world.setBlockMetadataWithNotify(i + 5, j + 42, k + 10, 4, 2);
		setBlock(world, i + 5, j + 42, k + 11, Blocks.leaves, 4);
		world.setBlockMetadataWithNotify(i + 5, j + 42, k + 11, 4, 2);
		setBlock(world, i + 5, j + 42, k + 12, Blocks.leaves, 4);
		world.setBlockMetadataWithNotify(i + 5, j + 42, k + 12, 4, 2);
		setBlock(world, i + 5, j + 42, k + 13, Blocks.leaves, 4);
		world.setBlockMetadataWithNotify(i + 5, j + 42, k + 13, 4, 2);
		setBlock(world, i + 5, j + 42, k + 14, Blocks.leaves, 12);
		world.setBlockMetadataWithNotify(i + 5, j + 42, k + 14, 12, 2);
		setBlock(world, i + 5, j + 42, k + 15, Blocks.leaves, 12);
		world.setBlockMetadataWithNotify(i + 5, j + 42, k + 15, 12, 2);
		setBlock(world, i + 5, j + 42, k + 16, Blocks.leaves, 12);
		world.setBlockMetadataWithNotify(i + 5, j + 42, k + 16, 12, 2);
		setBlock(world, i + 5, j + 42, k + 17, Blocks.leaves, 4);
		world.setBlockMetadataWithNotify(i + 5, j + 42, k + 17, 4, 2);
		setBlock(world, i + 5, j + 42, k + 18, Blocks.leaves, 4);
		world.setBlockMetadataWithNotify(i + 5, j + 42, k + 18, 4, 2);
		setBlock(world, i + 5, j + 43, k + 8, Blocks.leaves, 12);
		world.setBlockMetadataWithNotify(i + 5, j + 43, k + 8, 12, 2);
		setBlock(world, i + 5, j + 43, k + 10, Blocks.leaves, 4);
		world.setBlockMetadataWithNotify(i + 5, j + 43, k + 10, 4, 2);
		setBlock(world, i + 5, j + 43, k + 11, Blocks.leaves, 4);
		world.setBlockMetadataWithNotify(i + 5, j + 43, k + 11, 4, 2);
		setBlock(world, i + 5, j + 43, k + 12, Blocks.leaves, 4);
		world.setBlockMetadataWithNotify(i + 5, j + 43, k + 12, 4, 2);
		setBlock(world, i + 5, j + 43, k + 15, Blocks.leaves, 12);
		world.setBlockMetadataWithNotify(i + 5, j + 43, k + 15, 12, 2);
		setBlock(world, i + 5, j + 43, k + 16, Blocks.leaves, 12);
		world.setBlockMetadataWithNotify(i + 5, j + 43, k + 16, 12, 2);
		setBlock(world, i + 5, j + 43, k + 17, Blocks.leaves, 4);
		world.setBlockMetadataWithNotify(i + 5, j + 43, k + 17, 4, 2);
		setBlock(world, i + 6, j + 39, k + 8, Blocks.leaves, 4);
		world.setBlockMetadataWithNotify(i + 6, j + 39, k + 8, 4, 2);
		setBlock(world, i + 6, j + 39, k + 9, Blocks.leaves, 4);
		world.setBlockMetadataWithNotify(i + 6, j + 39, k + 9, 4, 2);
		setBlock(world, i + 6, j + 39, k + 10, Blocks.leaves, 4);
		world.setBlockMetadataWithNotify(i + 6, j + 39, k + 10, 4, 2);
		setBlock(world, i + 6, j + 39, k + 11, Blocks.leaves, 4);
		world.setBlockMetadataWithNotify(i + 6, j + 39, k + 11, 4, 2);
		setBlock(world, i + 6, j + 39, k + 12, Blocks.leaves, 4);
		world.setBlockMetadataWithNotify(i + 6, j + 39, k + 12, 4, 2);
		setBlock(world, i + 6, j + 39, k + 15, Blocks.leaves, 4);
		world.setBlockMetadataWithNotify(i + 6, j + 39, k + 15, 4, 2);
		setBlock(world, i + 6, j + 39, k + 16, Blocks.leaves, 4);
		world.setBlockMetadataWithNotify(i + 6, j + 39, k + 16, 4, 2);
		setBlock(world, i + 6, j + 39, k + 18, Blocks.leaves, 4);
		world.setBlockMetadataWithNotify(i + 6, j + 39, k + 18, 4, 2);
		setBlock(world, i + 6, j + 39, k + 19, Blocks.leaves, 4);
		world.setBlockMetadataWithNotify(i + 6, j + 39, k + 19, 4, 2);
		setBlock(world, i + 6, j + 40, k + 9, Blocks.leaves, 4);
		world.setBlockMetadataWithNotify(i + 6, j + 40, k + 9, 4, 2);
		setBlock(world, i + 6, j + 40, k + 10, Blocks.leaves, 4);
		world.setBlockMetadataWithNotify(i + 6, j + 40, k + 10, 4, 2);
		setBlock(world, i + 6, j + 40, k + 11, Blocks.leaves, 4);
		world.setBlockMetadataWithNotify(i + 6, j + 40, k + 11, 4, 2);
		setBlock(world, i + 6, j + 40, k + 15, Blocks.leaves, 4);
		world.setBlockMetadataWithNotify(i + 6, j + 40, k + 15, 4, 2);
		setBlock(world, i + 6, j + 40, k + 17, Blocks.leaves, 4);
		world.setBlockMetadataWithNotify(i + 6, j + 40, k + 17, 4, 2);
		setBlock(world, i + 6, j + 40, k + 18, Blocks.leaves, 4);
		world.setBlockMetadataWithNotify(i + 6, j + 40, k + 18, 4, 2);
		setBlock(world, i + 6, j + 40, k + 19, Blocks.leaves, 4);
		world.setBlockMetadataWithNotify(i + 6, j + 40, k + 19, 4, 2);
		setBlock(world, i + 6, j + 40, k + 20, Blocks.leaves, 12);
		world.setBlockMetadataWithNotify(i + 6, j + 40, k + 20, 12, 2);
		setBlock(world, i + 6, j + 40, k + 21, Blocks.leaves, 12);
		world.setBlockMetadataWithNotify(i + 6, j + 40, k + 21, 12, 2);
		setBlock(world, i + 6, j + 40, k + 22, Blocks.leaves, 12);
		world.setBlockMetadataWithNotify(i + 6, j + 40, k + 22, 12, 2);
		setBlock(world, i + 6, j + 41, k + 19, Blocks.leaves, 4);
		world.setBlockMetadataWithNotify(i + 6, j + 41, k + 19, 4, 2);
		setBlock(world, i + 6, j + 41, k + 20, Blocks.leaves, 12);
		world.setBlockMetadataWithNotify(i + 6, j + 41, k + 20, 12, 2);
		setBlock(world, i + 6, j + 41, k + 22, Blocks.leaves, 12);
		world.setBlockMetadataWithNotify(i + 6, j + 41, k + 22, 12, 2);
		setBlock(world, i + 6, j + 41, k + 23, Blocks.leaves, 12);
		world.setBlockMetadataWithNotify(i + 6, j + 41, k + 23, 12, 2);
		setBlock(world, i + 6, j + 41, k + 24, Blocks.leaves, 12);
		world.setBlockMetadataWithNotify(i + 6, j + 41, k + 24, 12, 2);
		setBlock(world, i + 6, j + 42, k + 6, Blocks.leaves, 12);
		world.setBlockMetadataWithNotify(i + 6, j + 42, k + 6, 12, 2);
		setBlock(world, i + 6, j + 42, k + 7, Blocks.leaves, 12);
		world.setBlockMetadataWithNotify(i + 6, j + 42, k + 7, 12, 2);
		setBlock(world, i + 6, j + 42, k + 8, Blocks.leaves, 12);
		world.setBlockMetadataWithNotify(i + 6, j + 42, k + 8, 12, 2);
		setBlock(world, i + 6, j + 42, k + 9, Blocks.leaves, 4);
		world.setBlockMetadataWithNotify(i + 6, j + 42, k + 9, 4, 2);
		setBlock(world, i + 6, j + 42, k + 10, Blocks.leaves, 4);
		world.setBlockMetadataWithNotify(i + 6, j + 42, k + 10, 4, 2);
		setBlock(world, i + 6, j + 42, k + 12, Blocks.leaves, 4);
		world.setBlockMetadataWithNotify(i + 6, j + 42, k + 12, 4, 2);
		setBlock(world, i + 6, j + 42, k + 13, Blocks.leaves, 4);
		world.setBlockMetadataWithNotify(i + 6, j + 42, k + 13, 4, 2);
		setBlock(world, i + 6, j + 42, k + 15, Blocks.leaves, 4);
		world.setBlockMetadataWithNotify(i + 6, j + 42, k + 15, 4, 2);
		setBlock(world, i + 6, j + 42, k + 16, Blocks.leaves, 4);
		world.setBlockMetadataWithNotify(i + 6, j + 42, k + 16, 4, 2);
		setBlock(world, i + 6, j + 42, k + 17, Blocks.leaves, 4);
		world.setBlockMetadataWithNotify(i + 6, j + 42, k + 17, 4, 2);
		setBlock(world, i + 6, j + 42, k + 23, Blocks.leaves, 12);
		world.setBlockMetadataWithNotify(i + 6, j + 42, k + 23, 12, 2);
		setBlock(world, i + 6, j + 43, k + 8, Blocks.leaves, 12);
		world.setBlockMetadataWithNotify(i + 6, j + 43, k + 8, 12, 2);
		setBlock(world, i + 6, j + 43, k + 9, Blocks.leaves, 4);
		world.setBlockMetadataWithNotify(i + 6, j + 43, k + 9, 4, 2);
		setBlock(world, i + 6, j + 43, k + 10, Blocks.leaves, 4);
		world.setBlockMetadataWithNotify(i + 6, j + 43, k + 10, 4, 2);
		setBlock(world, i + 6, j + 43, k + 11, Blocks.leaves, 4);
		world.setBlockMetadataWithNotify(i + 6, j + 43, k + 11, 4, 2);
		setBlock(world, i + 6, j + 43, k + 12, Blocks.leaves, 4);
		world.setBlockMetadataWithNotify(i + 6, j + 43, k + 12, 4, 2);
		setBlock(world, i + 6, j + 43, k + 13, Blocks.leaves, 4);
		world.setBlockMetadataWithNotify(i + 6, j + 43, k + 13, 4, 2);
		setBlock(world, i + 6, j + 43, k + 16, Blocks.leaves, 4);
		world.setBlockMetadataWithNotify(i + 6, j + 43, k + 16, 4, 2);
		setBlock(world, i + 7, j + 39, k + 8, Blocks.leaves, 4);
		world.setBlockMetadataWithNotify(i + 7, j + 39, k + 8, 4, 2);
		setBlock(world, i + 7, j + 39, k + 9, Blocks.leaves, 4);
		world.setBlockMetadataWithNotify(i + 7, j + 39, k + 9, 4, 2);
		setBlock(world, i + 7, j + 39, k + 11, Blocks.leaves, 4);
		world.setBlockMetadataWithNotify(i + 7, j + 39, k + 11, 4, 2);
		setBlock(world, i + 7, j + 39, k + 12, Blocks.leaves, 4);
		world.setBlockMetadataWithNotify(i + 7, j + 39, k + 12, 4, 2);
		setBlock(world, i + 7, j + 39, k + 15, Blocks.leaves, 4);
		world.setBlockMetadataWithNotify(i + 7, j + 39, k + 15, 4, 2);
		setBlock(world, i + 7, j + 39, k + 17, Blocks.leaves, 4);
		world.setBlockMetadataWithNotify(i + 7, j + 39, k + 17, 4, 2);
		setBlock(world, i + 7, j + 39, k + 18, Blocks.leaves, 4);
		world.setBlockMetadataWithNotify(i + 7, j + 39, k + 18, 4, 2);
		setBlock(world, i + 7, j + 39, k + 19, Blocks.leaves, 4);
		world.setBlockMetadataWithNotify(i + 7, j + 39, k + 19, 4, 2);
		setBlock(world, i + 7, j + 40, k + 8, Blocks.leaves, 4);
		world.setBlockMetadataWithNotify(i + 7, j + 40, k + 8, 4, 2);
		setBlock(world, i + 7, j + 40, k + 9, Blocks.leaves, 4);
		world.setBlockMetadataWithNotify(i + 7, j + 40, k + 9, 4, 2);
		setBlock(world, i + 7, j + 40, k + 10, Blocks.leaves, 4);
		world.setBlockMetadataWithNotify(i + 7, j + 40, k + 10, 4, 2);
		setBlock(world, i + 7, j + 40, k + 11, Blocks.leaves, 4);
		world.setBlockMetadataWithNotify(i + 7, j + 40, k + 11, 4, 2);
		setBlock(world, i + 7, j + 40, k + 12, Blocks.leaves, 4);
		world.setBlockMetadataWithNotify(i + 7, j + 40, k + 12, 4, 2);
		setBlock(world, i + 7, j + 40, k + 16, Blocks.leaves, 4);
		world.setBlockMetadataWithNotify(i + 7, j + 40, k + 16, 4, 2);
		setBlock(world, i + 7, j + 40, k + 17, Blocks.leaves, 4);
		world.setBlockMetadataWithNotify(i + 7, j + 40, k + 17, 4, 2);
		setBlock(world, i + 7, j + 40, k + 18, Blocks.leaves, 4);
		world.setBlockMetadataWithNotify(i + 7, j + 40, k + 18, 4, 2);
		setBlock(world, i + 7, j + 40, k + 19, Blocks.leaves, 4);
		world.setBlockMetadataWithNotify(i + 7, j + 40, k + 19, 4, 2);
		setBlock(world, i + 7, j + 40, k + 20, Blocks.leaves, 12);
		world.setBlockMetadataWithNotify(i + 7, j + 40, k + 20, 12, 2);
		setBlock(world, i + 7, j + 40, k + 21, Blocks.leaves, 12);
		world.setBlockMetadataWithNotify(i + 7, j + 40, k + 21, 12, 2);
		setBlock(world, i + 7, j + 41, k + 20, Blocks.leaves, 12);
		world.setBlockMetadataWithNotify(i + 7, j + 41, k + 20, 12, 2);
		setBlock(world, i + 7, j + 41, k + 21, Blocks.leaves, 12);
		world.setBlockMetadataWithNotify(i + 7, j + 41, k + 21, 12, 2);
		setBlock(world, i + 7, j + 41, k + 22, Blocks.leaves, 12);
		world.setBlockMetadataWithNotify(i + 7, j + 41, k + 22, 12, 2);
		setBlock(world, i + 7, j + 41, k + 23, Blocks.leaves, 12);
		world.setBlockMetadataWithNotify(i + 7, j + 41, k + 23, 12, 2);
		setBlock(world, i + 7, j + 41, k + 24, Blocks.leaves, 12);
		world.setBlockMetadataWithNotify(i + 7, j + 41, k + 24, 12, 2);
		setBlock(world, i + 7, j + 41, k + 25, Blocks.leaves, 12);
		world.setBlockMetadataWithNotify(i + 7, j + 41, k + 25, 12, 2);
		setBlock(world, i + 7, j + 42, k + 6, Blocks.leaves, 12);
		world.setBlockMetadataWithNotify(i + 7, j + 42, k + 6, 12, 2);
		setBlock(world, i + 7, j + 42, k + 7, Blocks.leaves, 12);
		world.setBlockMetadataWithNotify(i + 7, j + 42, k + 7, 12, 2);
		setBlock(world, i + 7, j + 42, k + 9, Blocks.leaves, 4);
		world.setBlockMetadataWithNotify(i + 7, j + 42, k + 9, 4, 2);
		setBlock(world, i + 7, j + 42, k + 10, Blocks.leaves, 4);
		world.setBlockMetadataWithNotify(i + 7, j + 42, k + 10, 4, 2);
		setBlock(world, i + 7, j + 42, k + 11, Blocks.leaves, 4);
		world.setBlockMetadataWithNotify(i + 7, j + 42, k + 11, 4, 2);
		setBlock(world, i + 7, j + 42, k + 12, Blocks.leaves, 4);
		generate5(world, rand, i, j, k);
		return true;
	}

	public void generate2(World world, Random rand, int i, int j, int k)
	{
		world.setBlockMetadataWithNotify(i + 19, j + 44, k + 3, 12, 2);
		setBlock(world, i + 19, j + 44, k + 4, Blocks.leaves, 12);
		world.setBlockMetadataWithNotify(i + 19, j + 44, k + 4, 12, 2);
		setBlock(world, i + 19, j + 44, k + 6, Blocks.leaves, 4);
		world.setBlockMetadataWithNotify(i + 19, j + 44, k + 6, 4, 2);
		setBlock(world, i + 19, j + 44, k + 7, Blocks.leaves, 4);
		world.setBlockMetadataWithNotify(i + 19, j + 44, k + 7, 4, 2);
		setBlock(world, i + 19, j + 44, k + 8, Blocks.leaves, 4);
		world.setBlockMetadataWithNotify(i + 19, j + 44, k + 8, 4, 2);
		setBlock(world, i + 19, j + 44, k + 9, Blocks.leaves, 4);
		world.setBlockMetadataWithNotify(i + 19, j + 44, k + 9, 4, 2);
		setBlock(world, i + 19, j + 44, k + 10, Blocks.leaves, 4);
		world.setBlockMetadataWithNotify(i + 19, j + 44, k + 10, 4, 2);
		setBlock(world, i + 19, j + 44, k + 11, Blocks.leaves, 4);
		world.setBlockMetadataWithNotify(i + 19, j + 44, k + 11, 4, 2);
		setBlock(world, i + 19, j + 44, k + 12, Blocks.leaves, 4);
		world.setBlockMetadataWithNotify(i + 19, j + 44, k + 12, 4, 2);
		setBlock(world, i + 19, j + 44, k + 13, Blocks.leaves, 4);
		world.setBlockMetadataWithNotify(i + 19, j + 44, k + 13, 4, 2);
		setBlock(world, i + 19, j + 44, k + 14, Blocks.leaves, 4);
		world.setBlockMetadataWithNotify(i + 19, j + 44, k + 14, 4, 2);
		setBlock(world, i + 19, j + 44, k + 15, Blocks.leaves, 4);
		world.setBlockMetadataWithNotify(i + 19, j + 44, k + 15, 4, 2);
		setBlock(world, i + 19, j + 44, k + 17, Blocks.leaves, 4);
		world.setBlockMetadataWithNotify(i + 19, j + 44, k + 17, 4, 2);
		setBlock(world, i + 19, j + 44, k + 18, Blocks.leaves, 4);
		world.setBlockMetadataWithNotify(i + 19, j + 44, k + 18, 4, 2);
		setBlock(world, i + 19, j + 44, k + 19, Blocks.leaves, 4);
		world.setBlockMetadataWithNotify(i + 19, j + 44, k + 19, 4, 2);
		setBlock(world, i + 19, j + 44, k + 20, Blocks.leaves, 4);
		world.setBlockMetadataWithNotify(i + 19, j + 44, k + 20, 4, 2);
		setBlock(world, i + 19, j + 44, k + 21, Blocks.leaves, 4);
		world.setBlockMetadataWithNotify(i + 19, j + 44, k + 21, 4, 2);
		setBlock(world, i + 19, j + 44, k + 22, Blocks.leaves, 4);
		world.setBlockMetadataWithNotify(i + 19, j + 44, k + 22, 4, 2);
		setBlock(world, i + 19, j + 44, k + 23, Blocks.leaves, 4);
		world.setBlockMetadataWithNotify(i + 19, j + 44, k + 23, 4, 2);
		setBlock(world, i + 19, j + 44, k + 24, Blocks.leaves, 4);
		world.setBlockMetadataWithNotify(i + 19, j + 44, k + 24, 4, 2);
		setBlock(world, i + 19, j + 44, k + 25, Blocks.leaves, 4);
		world.setBlockMetadataWithNotify(i + 19, j + 44, k + 25, 4, 2);
		setBlock(world, i + 19, j + 45, k + 4, Blocks.leaves, 12);
		world.setBlockMetadataWithNotify(i + 19, j + 45, k + 4, 12, 2);
		setBlock(world, i + 19, j + 45, k + 5, Blocks.leaves, 12);
		world.setBlockMetadataWithNotify(i + 19, j + 45, k + 5, 12, 2);
