package com.parzi.starwarsmod.world.gen;

import java.util.Random;

import net.minecraft.block.Block;
import net.minecraft.init.Blocks;
import net.minecraft.world.World;
import net.minecraft.world.chunk.IChunkProvider;
import net.minecraft.world.gen.feature.WorldGenerator;
import cpw.mods.fml.common.IWorldGenerator;

public class WorldGenEndorTree1 extends WorldGenerator implements IWorldGenerator
{
	public WorldGenEndorTree1()
	{
	}

	@Override
	public void generate(Random random, int chunkX, int chunkZ, World world, IChunkProvider chunkGenerator, IChunkProvider chunkProvider)
	{
	}

	@Override
	public boolean generate(World world, Random rand, int i, int j, int k)
	{
		// check that each corner is one of the valid spawn blocks
		if (!locationIsValidSpawn(world, i, j, k) || !locationIsValidSpawn(world, i + 15, j, k) || !locationIsValidSpawn(world, i + 15, j, k + 15) || !locationIsValidSpawn(world, i, j, k + 15)) { return false; }

		k = k - 10;
		i = i - 10;

		setBlock(world, i + 1, j + 22, k + 3, Blocks.log, 0);
		setBlock(world, i + 2, j + 16, k + 2, Blocks.log, 0);
		setBlock(world, i + 2, j + 21, k + 4, Blocks.log, 0);
		setBlock(world, i + 2, j + 31, k + 8, Blocks.log, 0);
		setBlock(world, i + 3, j + 15, k + 3, Blocks.log, 0);
		setBlock(world, i + 3, j + 19, k + 6, Blocks.log, 0);
		setBlock(world, i + 3, j + 21, k + 5, Blocks.log, 0);
		setBlock(world, i + 3, j + 30, k + 8, Blocks.log, 0);
		setBlock(world, i + 4, j + 15, k + 4, Blocks.log, 0);
		setBlock(world, i + 4, j + 18, k + 6, Blocks.log, 0);
		setBlock(world, i + 4, j + 18, k + 7, Blocks.log, 0);
		setBlock(world, i + 4, j + 21, k + 5, Blocks.log, 0);
		setBlock(world, i + 4, j + 30, k + 8, Blocks.log, 0);
		setBlock(world, i + 4, j + 39, k + 8, Blocks.log, 0);
		setBlock(world, i + 5, j + 15, k + 5, Blocks.log, 0);
		setBlock(world, i + 5, j + 17, k + 7, Blocks.log, 0);
		setBlock(world, i + 5, j + 18, k + 6, Blocks.log, 0);
		setBlock(world, i + 5, j + 18, k + 7, Blocks.log, 0);
		setBlock(world, i + 5, j + 19, k + 5, Blocks.log, 0);
		setBlock(world, i + 5, j + 20, k + 2, Blocks.log, 0);
		setBlock(world, i + 5, j + 20, k + 3, Blocks.log, 0);
		setBlock(world, i + 5, j + 21, k + 1, Blocks.log, 0);
		setBlock(world, i + 5, j + 21, k + 6, Blocks.log, 0);
		setBlock(world, i + 5, j + 30, k + 8, Blocks.log, 0);
		setBlock(world, i + 5, j + 35, k + 11, Blocks.log, 0);
		setBlock(world, i + 5, j + 36, k + 7, Blocks.log, 0);
		setBlock(world, i + 5, j + 40, k + 7, Blocks.log, 0);
		setBlock(world, i + 6, j + 0, k + 6, Blocks.log, 0);
		setBlock(world, i + 6, j + 0, k + 7, Blocks.log, 0);
		setBlock(world, i + 6, j + 0, k + 8, Blocks.log, 0);
		setBlock(world, i + 6, j + 0, k + 9, Blocks.log, 0);
		setBlock(world, i + 6, j + 1, k + 6, Blocks.log, 0);
		setBlock(world, i + 6, j + 1, k + 7, Blocks.log, 0);
		setBlock(world, i + 6, j + 1, k + 8, Blocks.log, 0);
		setBlock(world, i + 6, j + 1, k + 9, Blocks.log, 0);
		setBlock(world, i + 6, j + 2, k + 6, Blocks.log, 0);
		setBlock(world, i + 6, j + 2, k + 7, Blocks.log, 0);
		setBlock(world, i + 6, j + 2, k + 8, Blocks.log, 0);
		setBlock(world, i + 6, j + 2, k + 9, Blocks.log, 0);
		setBlock(world, i + 6, j + 3, k + 6, Blocks.log, 0);
		setBlock(world, i + 6, j + 3, k + 7, Blocks.log, 0);
		setBlock(world, i + 6, j + 3, k + 8, Blocks.log, 0);
		setBlock(world, i + 6, j + 3, k + 9, Blocks.log, 0);
		setBlock(world, i + 6, j + 4, k + 7, Blocks.log, 0);
		setBlock(world, i + 6, j + 4, k + 8, Blocks.log, 0);
		setBlock(world, i + 6, j + 4, k + 9, Blocks.log, 0);
		setBlock(world, i + 6, j + 5, k + 7, Blocks.log, 0);
		setBlock(world, i + 6, j + 5, k + 8, Blocks.log, 0);
		setBlock(world, i + 6, j + 6, k + 8, Blocks.log, 0);
		setBlock(world, i + 6, j + 14, k + 6, Blocks.log, 0);
		setBlock(world, i + 6, j + 17, k + 7, Blocks.log, 0);
		setBlock(world, i + 6, j + 18, k + 7, Blocks.log, 0);
		setBlock(world, i + 6, j + 18, k + 8, Blocks.log, 0);
		setBlock(world, i + 6, j + 20, k + 4, Blocks.log, 0);
		setBlock(world, i + 6, j + 20, k + 5, Blocks.log, 0);
		setBlock(world, i + 6, j + 20, k + 6, Blocks.log, 0);
		setBlock(world, i + 6, j + 20, k + 7, Blocks.log, 0);
		setBlock(world, i + 6, j + 29, k + 8, Blocks.log, 0);
		setBlock(world, i + 6, j + 33, k + 12, Blocks.log, 0);
		setBlock(world, i + 6, j + 34, k + 2, Blocks.log, 0);
		setBlock(world, i + 6, j + 34, k + 6, Blocks.log, 0);
		setBlock(world, i + 6, j + 34, k + 10, Blocks.log, 0);
		setBlock(world, i + 6, j + 39, k + 7, Blocks.log, 0);
		setBlock(world, i + 6, j + 39, k + 8, Blocks.log, 0);
		setBlock(world, i + 6, j + 40, k + 10, Blocks.log, 0);
		setBlock(world, i + 7, j + 0, k + 7, Blocks.log, 0);
		setBlock(world, i + 7, j + 0, k + 8, Blocks.log, 0);
		setBlock(world, i + 7, j + 0, k + 9, Blocks.log, 0);
		setBlock(world, i + 7, j + 1, k + 6, Blocks.log, 0);
		setBlock(world, i + 7, j + 1, k + 7, Blocks.log, 0);
		setBlock(world, i + 7, j + 1, k + 8, Blocks.log, 0);
		setBlock(world, i + 7, j + 1, k + 9, Blocks.log, 0);
		setBlock(world, i + 7, j + 2, k + 6, Blocks.log, 0);
		setBlock(world, i + 7, j + 2, k + 7, Blocks.log, 0);
		setBlock(world, i + 7, j + 2, k + 8, Blocks.log, 0);
		setBlock(world, i + 7, j + 2, k + 9, Blocks.log, 0);
		setBlock(world, i + 7, j + 3, k + 6, Blocks.log, 0);
		setBlock(world, i + 7, j + 3, k + 7, Blocks.log, 0);
		setBlock(world, i + 7, j + 3, k + 8, Blocks.log, 0);
		setBlock(world, i + 7, j + 3, k + 9, Blocks.log, 0);
		setBlock(world, i + 7, j + 4, k + 6, Blocks.log, 0);
		setBlock(world, i + 7, j + 4, k + 7, Blocks.log, 0);
		setBlock(world, i + 7, j + 4, k + 8, Blocks.log, 0);
		setBlock(world, i + 7, j + 4, k + 9, Blocks.log, 0);
		setBlock(world, i + 7, j + 5, k + 7, Blocks.log, 0);
		setBlock(world, i + 7, j + 5, k + 8, Blocks.log, 0);
		setBlock(world, i + 7, j + 5, k + 9, Blocks.log, 0);
		setBlock(world, i + 7, j + 6, k + 7, Blocks.log, 0);
		setBlock(world, i + 7, j + 6, k + 8, Blocks.log, 0);
		setBlock(world, i + 7, j + 6, k + 9, Blocks.log, 0);
		setBlock(world, i + 7, j + 7, k + 7, Blocks.log, 0);
		setBlock(world, i + 7, j + 7, k + 8, Blocks.log, 0);
		setBlock(world, i + 7, j + 7, k + 9, Blocks.log, 0);
		setBlock(world, i + 7, j + 8, k + 7, Blocks.log, 0);
		setBlock(world, i + 7, j + 8, k + 8, Blocks.log, 0);
		setBlock(world, i + 7, j + 8, k + 9, Blocks.log, 0);
		setBlock(world, i + 7, j + 9, k + 7, Blocks.log, 0);
		setBlock(world, i + 7, j + 9, k + 8, Blocks.log, 0);
		setBlock(world, i + 7, j + 9, k + 9, Blocks.log, 0);
		setBlock(world, i + 7, j + 10, k + 7, Blocks.log, 0);
		setBlock(world, i + 7, j + 10, k + 8, Blocks.log, 0);
		setBlock(world, i + 7, j + 10, k + 9, Blocks.log, 0);
		setBlock(world, i + 7, j + 11, k + 7, Blocks.log, 0);
		setBlock(world, i + 7, j + 11, k + 8, Blocks.log, 0);
		setBlock(world, i + 7, j + 11, k + 9, Blocks.log, 0);
		setBlock(world, i + 7, j + 12, k + 7, Blocks.log, 0);
		setBlock(world, i + 7, j + 12, k + 8, Blocks.log, 0);
		setBlock(world, i + 7, j + 12, k + 9, Blocks.log, 0);
		setBlock(world, i + 7, j + 13, k + 7, Blocks.log, 0);
		setBlock(world, i + 7, j + 13, k + 8, Blocks.log, 0);
		setBlock(world, i + 7, j + 13, k + 9, Blocks.log, 0);
		setBlock(world, i + 7, j + 14, k + 4, Blocks.log, 0);
		setBlock(world, i + 7, j + 14, k + 5, Blocks.log, 0);
		setBlock(world, i + 7, j + 14, k + 6, Blocks.log, 0);
		setBlock(world, i + 7, j + 14, k + 7, Blocks.log, 0);
		setBlock(world, i + 7, j + 14, k + 8, Blocks.log, 0);
		setBlock(world, i + 7, j + 15, k + 3, Blocks.log, 0);
		setBlock(world, i + 7, j + 15, k + 8, Blocks.log, 0);
		setBlock(world, i + 7, j + 16, k + 8, Blocks.log, 0);
		setBlock(world, i + 7, j + 17, k + 8, Blocks.log, 0);
		setBlock(world, i + 7, j + 18, k + 8, Blocks.log, 0);
		setBlock(world, i + 7, j + 19, k + 8, Blocks.log, 0);
		setBlock(world, i + 7, j + 20, k + 7, Blocks.log, 0);
		setBlock(world, i + 7, j + 20, k + 8, Blocks.log, 0);
		setBlock(world, i + 7, j + 21, k + 8, Blocks.log, 0);
		setBlock(world, i + 7, j + 22, k + 8, Blocks.log, 0);
		setBlock(world, i + 7, j + 29, k + 8, Blocks.log, 0);
		setBlock(world, i + 7, j + 33, k + 7, Blocks.log, 0);
		setBlock(world, i + 7, j + 34, k + 9, Blocks.log, 0);
		setBlock(world, i + 7, j + 36, k + 6, Blocks.log, 0);
		setBlock(world, i + 7, j + 36, k + 7, Blocks.log, 0);
		setBlock(world, i + 7, j + 37, k + 5, Blocks.log, 0);
		setBlock(world, i + 7, j + 38, k + 8, Blocks.log, 0);
		setBlock(world, i + 7, j + 38, k + 10, Blocks.log, 0);
		setBlock(world, i + 7, j + 39, k + 9, Blocks.log, 0);
		setBlock(world, i + 7, j + 40, k + 10, Blocks.log, 0);
		setBlock(world, i + 7, j + 41, k + 7, Blocks.log, 0);
		setBlock(world, i + 7, j + 42, k + 8, Blocks.log, 0);
		setBlock(world, i + 7, j + 44, k + 8, Blocks.log, 0);
		setBlock(world, i + 7, j + 45, k + 8, Blocks.log, 0);
		setBlock(world, i + 8, j + 0, k + 6, Blocks.log, 0);
		setBlock(world, i + 8, j + 0, k + 7, Blocks.log, 0);
		setBlock(world, i + 8, j + 0, k + 8, Blocks.log, 0);
		setBlock(world, i + 8, j + 0, k + 9, Blocks.log, 0);
		setBlock(world, i + 8, j + 0, k + 10, Blocks.log, 0);
		setBlock(world, i + 8, j + 1, k + 6, Blocks.log, 0);
		setBlock(world, i + 8, j + 1, k + 7, Blocks.log, 0);
		setBlock(world, i + 8, j + 1, k + 8, Blocks.log, 0);
		setBlock(world, i + 8, j + 1, k + 9, Blocks.log, 0);
		setBlock(world, i + 8, j + 1, k + 10, Blocks.log, 0);
		setBlock(world, i + 8, j + 2, k + 6, Blocks.log, 0);
		setBlock(world, i + 8, j + 2, k + 7, Blocks.log, 0);
		setBlock(world, i + 8, j + 2, k + 8, Blocks.log, 0);
		setBlock(world, i + 8, j + 2, k + 9, Blocks.log, 0);
		setBlock(world, i + 8, j + 2, k + 10, Blocks.log, 0);
		setBlock(world, i + 8, j + 3, k + 6, Blocks.log, 0);
		setBlock(world, i + 8, j + 3, k + 7, Blocks.log, 0);
		setBlock(world, i + 8, j + 3, k + 8, Blocks.log, 0);
		setBlock(world, i + 8, j + 3, k + 9, Blocks.log, 0);
		setBlock(world, i + 8, j + 3, k + 10, Blocks.log, 0);
		setBlock(world, i + 8, j + 4, k + 6, Blocks.log, 0);
		setBlock(world, i + 8, j + 4, k + 7, Blocks.log, 0);
		setBlock(world, i + 8, j + 4, k + 8, Blocks.log, 0);
		setBlock(world, i + 8, j + 4, k + 9, Blocks.log, 0);
		setBlock(world, i + 8, j + 4, k + 10, Blocks.log, 0);
		setBlock(world, i + 8, j + 5, k + 6, Blocks.log, 0);
		setBlock(world, i + 8, j + 5, k + 7, Blocks.log, 0);
		setBlock(world, i + 8, j + 5, k + 8, Blocks.log, 0);
		setBlock(world, i + 8, j + 5, k + 9, Blocks.log, 0);
		setBlock(world, i + 8, j + 5, k + 10, Blocks.log, 0);
		setBlock(world, i + 8, j + 6, k + 6, Blocks.log, 0);
		setBlock(world, i + 8, j + 6, k + 7, Blocks.log, 0);
		setBlock(world, i + 8, j + 6, k + 8, Blocks.log, 0);
		setBlock(world, i + 8, j + 6, k + 9, Blocks.log, 0);
		setBlock(world, i + 8, j + 6, k + 10, Blocks.log, 0);
		setBlock(world, i + 8, j + 7, k + 6, Blocks.log, 0);
		setBlock(world, i + 8, j + 7, k + 7, Blocks.log, 0);
		setBlock(world, i + 8, j + 7, k + 8, Blocks.log, 0);
		setBlock(world, i + 8, j + 7, k + 9, Blocks.log, 0);
		setBlock(world, i + 8, j + 7, k + 10, Blocks.log, 0);
		setBlock(world, i + 8, j + 8, k + 6, Blocks.log, 0);
		setBlock(world, i + 8, j + 8, k + 7, Blocks.log, 0);
		setBlock(world, i + 8, j + 8, k + 8, Blocks.log, 0);
		setBlock(world, i + 8, j + 8, k + 9, Blocks.log, 0);
		setBlock(world, i + 8, j + 8, k + 10, Blocks.log, 0);
		setBlock(world, i + 8, j + 9, k + 6, Blocks.log, 0);
		setBlock(world, i + 8, j + 9, k + 7, Blocks.log, 0);
		setBlock(world, i + 8, j + 9, k + 8, Blocks.log, 0);
		setBlock(world, i + 8, j + 9, k + 9, Blocks.log, 0);
		setBlock(world, i + 8, j + 10, k + 7, Blocks.log, 0);
		setBlock(world, i + 8, j + 10, k + 8, Blocks.log, 0);
		setBlock(world, i + 8, j + 10, k + 9, Blocks.log, 0);
		setBlock(world, i + 8, j + 11, k + 7, Blocks.log, 0);
		setBlock(world, i + 8, j + 11, k + 8, Blocks.log, 0);
		setBlock(world, i + 8, j + 11, k + 9, Blocks.log, 0);
		setBlock(world, i + 8, j + 12, k + 7, Blocks.log, 0);
		setBlock(world, i + 8, j + 12, k + 8, Blocks.log, 0);
		setBlock(world, i + 8, j + 12, k + 9, Blocks.log, 0);
		setBlock(world, i + 8, j + 13, k + 7, Blocks.log, 0);
		setBlock(world, i + 8, j + 13, k + 8, Blocks.log, 0);
		setBlock(world, i + 8, j + 13, k + 9, Blocks.log, 0);
		setBlock(world, i + 8, j + 14, k + 7, Blocks.log, 0);
		setBlock(world, i + 8, j + 14, k + 8, Blocks.log, 0);
		setBlock(world, i + 8, j + 14, k + 9, Blocks.log, 0);
		setBlock(world, i + 8, j + 15, k + 7, Blocks.log, 0);
		setBlock(world, i + 8, j + 15, k + 8, Blocks.log, 0);
		setBlock(world, i + 8, j + 15, k + 9, Blocks.log, 0);
		setBlock(world, i + 8, j + 16, k + 7, Blocks.log, 0);
		setBlock(world, i + 8, j + 16, k + 8, Blocks.log, 0);
		setBlock(world, i + 8, j + 16, k + 9, Blocks.log, 0);
		setBlock(world, i + 8, j + 17, k + 7, Blocks.log, 0);
		setBlock(world, i + 8, j + 17, k + 8, Blocks.log, 0);
		setBlock(world, i + 8, j + 17, k + 9, Blocks.log, 0);
		setBlock(world, i + 8, j + 18, k + 7, Blocks.log, 0);
		setBlock(world, i + 8, j + 18, k + 8, Blocks.log, 0);
		setBlock(world, i + 8, j + 18, k + 9, Blocks.log, 0);
		setBlock(world, i + 8, j + 19, k + 7, Blocks.log, 0);
		setBlock(world, i + 8, j + 19, k + 8, Blocks.log, 0);
		setBlock(world, i + 8, j + 19, k + 9, Blocks.log, 0);
		setBlock(world, i + 8, j + 20, k + 7, Blocks.log, 0);
		setBlock(world, i + 8, j + 20, k + 8, Blocks.log, 0);
		setBlock(world, i + 8, j + 20, k + 9, Blocks.log, 0);
		setBlock(world, i + 8, j + 21, k + 7, Blocks.log, 0);
		setBlock(world, i + 8, j + 21, k + 8, Blocks.log, 0);
		setBlock(world, i + 8, j + 21, k + 9, Blocks.log, 0);
		setBlock(world, i + 8, j + 22, k + 7, Blocks.log, 0);
		setBlock(world, i + 8, j + 22, k + 8, Blocks.log, 0);
		setBlock(world, i + 8, j + 22, k + 9, Blocks.log, 0);
		setBlock(world, i + 8, j + 23, k + 6, Blocks.log, 0);
		setBlock(world, i + 8, j + 23, k + 8, Blocks.log, 0);
		setBlock(world, i + 8, j + 24, k + 8, Blocks.log, 0);
		setBlock(world, i + 8, j + 25, k + 8, Blocks.log, 0);
		setBlock(world, i + 8, j + 25, k + 9, Blocks.log, 0);
		setBlock(world, i + 8, j + 26, k + 8, Blocks.log, 0);
		setBlock(world, i + 8, j + 27, k + 8, Blocks.log, 0);
		setBlock(world, i + 8, j + 27, k + 9, Blocks.log, 0);
		setBlock(world, i + 8, j + 28, k + 8, Blocks.log, 0);
		setBlock(world, i + 8, j + 28, k + 9, Blocks.log, 0);
		setBlock(world, i + 8, j + 29, k + 8, Blocks.log, 0);
		setBlock(world, i + 8, j + 30, k + 8, Blocks.log, 0);
		setBlock(world, i + 8, j + 30, k + 9, Blocks.log, 0);
		setBlock(world, i + 8, j + 30, k + 10, Blocks.log, 0);
		setBlock(world, i + 8, j + 31, k + 8, Blocks.log, 0);
		setBlock(world, i + 8, j + 31, k + 9, Blocks.log, 0);
		setBlock(world, i + 8, j + 31, k + 10, Blocks.log, 0);
		setBlock(world, i + 8, j + 31, k + 11, Blocks.log, 0);
		setBlock(world, i + 8, j + 32, k + 3, Blocks.log, 0);
		setBlock(world, i + 8, j + 32, k + 4, Blocks.log, 0);
		setBlock(world, i + 8, j + 32, k + 5, Blocks.log, 0);
		setBlock(world, i + 8, j + 32, k + 6, Blocks.log, 0);
		setBlock(world, i + 8, j + 32, k + 7, Blocks.log, 0);
		setBlock(world, i + 8, j + 32, k + 8, Blocks.log, 0);
		setBlock(world, i + 8, j + 32, k + 11, Blocks.log, 0);
		setBlock(world, i + 8, j + 33, k + 8, Blocks.log, 0);
		setBlock(world, i + 8, j + 34, k + 8, Blocks.log, 0);
		setBlock(world, i + 8, j + 35, k + 6, Blocks.log, 0);
		setBlock(world, i + 8, j + 35, k + 7, Blocks.log, 0);
		setBlock(world, i + 8, j + 35, k + 8, Blocks.log, 0);
		setBlock(world, i + 8, j + 36, k + 8, Blocks.log, 0);
		setBlock(world, i + 8, j + 37, k + 3, Blocks.log, 0);
		setBlock(world, i + 8, j + 37, k + 5, Blocks.log, 0);
		setBlock(world, i + 8, j + 37, k + 6, Blocks.log, 0);
		setBlock(world, i + 8, j + 37, k + 7, Blocks.log, 0);
		setBlock(world, i + 8, j + 37, k + 8, Blocks.log, 0);
		setBlock(world, i + 8, j + 37, k + 9, Blocks.log, 0);
		setBlock(world, i + 8, j + 38, k + 8, Blocks.log, 0);
		setBlock(world, i + 8, j + 39, k + 4, Blocks.log, 0);
		setBlock(world, i + 8, j + 39, k + 8, Blocks.log, 0);
		setBlock(world, i + 8, j + 39, k + 9, Blocks.log, 0);
		setBlock(world, i + 8, j + 40, k + 8, Blocks.log, 0);
		setBlock(world, i + 8, j + 41, k + 8, Blocks.log, 0);
		setBlock(world, i + 8, j + 42, k + 7, Blocks.log, 0);
		setBlock(world, i + 8, j + 42, k + 8, Blocks.log, 0);
		setBlock(world, i + 8, j + 43, k + 7, Blocks.log, 0);
		setBlock(world, i + 8, j + 43, k + 8, Blocks.log, 0);
		setBlock(world, i + 8, j + 43, k + 9, Blocks.log, 0);
		setBlock(world, i + 8, j + 44, k + 8, Blocks.log, 0);
		setBlock(world, i + 8, j + 44, k + 9, Blocks.log, 0);
		setBlock(world, i + 8, j + 45, k + 8, Blocks.log, 0);
		setBlock(world, i + 8, j + 46, k + 8, Blocks.log, 0);
		setBlock(world, i + 8, j + 47, k + 8, Blocks.log, 0);
		setBlock(world, i + 8, j + 48, k + 8, Blocks.log, 0);
		setBlock(world, i + 9, j + 0, k + 6, Blocks.log, 0);
		setBlock(world, i + 9, j + 0, k + 7, Blocks.log, 0);
		setBlock(world, i + 9, j + 0, k + 8, Blocks.log, 0);
		setBlock(world, i + 9, j + 0, k + 9, Blocks.log, 0);
		setBlock(world, i + 9, j + 0, k + 10, Blocks.log, 0);
		setBlock(world, i + 9, j + 1, k + 6, Blocks.log, 0);
		setBlock(world, i + 9, j + 1, k + 7, Blocks.log, 0);
		setBlock(world, i + 9, j + 1, k + 8, Blocks.log, 0);
		setBlock(world, i + 9, j + 1, k + 9, Blocks.log, 0);
		setBlock(world, i + 9, j + 1, k + 10, Blocks.log, 0);
		setBlock(world, i + 9, j + 2, k + 6, Blocks.log, 0);
		setBlock(world, i + 9, j + 2, k + 7, Blocks.log, 0);
		setBlock(world, i + 9, j + 2, k + 8, Blocks.log, 0);
		setBlock(world, i + 9, j + 2, k + 9, Blocks.log, 0);
		setBlock(world, i + 9, j + 2, k + 10, Blocks.log, 0);
		setBlock(world, i + 9, j + 3, k + 6, Blocks.log, 0);
		setBlock(world, i + 9, j + 3, k + 7, Blocks.log, 0);
		setBlock(world, i + 9, j + 3, k + 8, Blocks.log, 0);
		setBlock(world, i + 9, j + 3, k + 9, Blocks.log, 0);
		setBlock(world, i + 9, j + 3, k + 10, Blocks.log, 0);
		setBlock(world, i + 9, j + 4, k + 6, Blocks.log, 0);
		setBlock(world, i + 9, j + 4, k + 7, Blocks.log, 0);
		setBlock(world, i + 9, j + 4, k + 8, Blocks.log, 0);
		setBlock(world, i + 9, j + 4, k + 9, Blocks.log, 0);
		setBlock(world, i + 9, j + 4, k + 10, Blocks.log, 0);
		setBlock(world, i + 9, j + 5, k + 6, Blocks.log, 0);
		setBlock(world, i + 9, j + 5, k + 7, Blocks.log, 0);
		setBlock(world, i + 9, j + 5, k + 8, Blocks.log, 0);
		setBlock(world, i + 9, j + 5, k + 9, Blocks.log, 0);
		setBlock(world, i + 9, j + 5, k + 10, Blocks.log, 0);
		setBlock(world, i + 9, j + 6, k + 6, Blocks.log, 0);
		setBlock(world, i + 9, j + 6, k + 7, Blocks.log, 0);
		setBlock(world, i + 9, j + 6, k + 8, Blocks.log, 0);
		setBlock(world, i + 9, j + 6, k + 9, Blocks.log, 0);
		setBlock(world, i + 9, j + 6, k + 10, Blocks.log, 0);
		setBlock(world, i + 9, j + 7, k + 6, Blocks.log, 0);
		setBlock(world, i + 9, j + 7, k + 7, Blocks.log, 0);
		setBlock(world, i + 9, j + 7, k + 8, Blocks.log, 0);
		setBlock(world, i + 9, j + 7, k + 9, Blocks.log, 0);
		setBlock(world, i + 9, j + 8, k + 6, Blocks.log, 0);
		setBlock(world, i + 9, j + 8, k + 7, Blocks.log, 0);
		setBlock(world, i + 9, j + 8, k + 8, Blocks.log, 0);
		setBlock(world, i + 9, j + 8, k + 9, Blocks.log, 0);
		setBlock(world, i + 9, j + 9, k + 6, Blocks.log, 0);
		setBlock(world, i + 9, j + 9, k + 7, Blocks.log, 0);
		setBlock(world, i + 9, j + 9, k + 8, Blocks.log, 0);
		setBlock(world, i + 9, j + 9, k + 9, Blocks.log, 0);
		setBlock(world, i + 9, j + 10, k + 6, Blocks.log, 0);
		setBlock(world, i + 9, j + 10, k + 7, Blocks.log, 0);
		setBlock(world, i + 9, j + 10, k + 8, Blocks.log, 0);
		setBlock(world, i + 9, j + 10, k + 9, Blocks.log, 0);
		setBlock(world, i + 9, j + 11, k + 6, Blocks.log, 0);
		setBlock(world, i + 9, j + 11, k + 7, Blocks.log, 0);
		setBlock(world, i + 9, j + 11, k + 8, Blocks.log, 0);
		setBlock(world, i + 9, j + 11, k + 9, Blocks.log, 0);
		setBlock(world, i + 9, j + 12, k + 7, Blocks.log, 0);
		setBlock(world, i + 9, j + 12, k + 8, Blocks.log, 0);
		setBlock(world, i + 9, j + 12, k + 9, Blocks.log, 0);
		setBlock(world, i + 9, j + 13, k + 7, Blocks.log, 0);
		setBlock(world, i + 9, j + 13, k + 8, Blocks.log, 0);
		setBlock(world, i + 9, j + 13, k + 9, Blocks.log, 0);
		setBlock(world, i + 9, j + 14, k + 8, Blocks.log, 0);
		setBlock(world, i + 9, j + 15, k + 8, Blocks.log, 0);
		setBlock(world, i + 9, j + 16, k + 8, Blocks.log, 0);
		setBlock(world, i + 9, j + 17, k + 8, Blocks.log, 0);
		setBlock(world, i + 9, j + 18, k + 8, Blocks.log, 0);
		setBlock(world, i + 9, j + 18, k + 9, Blocks.log, 0);
		setBlock(world, i + 9, j + 19, k + 8, Blocks.log, 0);
		setBlock(world, i + 9, j + 20, k + 8, Blocks.log, 0);
		setBlock(world, i + 9, j + 21, k + 8, Blocks.log, 0);
		setBlock(world, i + 9, j + 22, k + 8, Blocks.log, 0);
		setBlock(world, i + 9, j + 25, k + 8, Blocks.log, 0);
		setBlock(world, i + 9, j + 25, k + 9, Blocks.log, 0);
		setBlock(world, i + 9, j + 27, k + 10, Blocks.log, 0);
		setBlock(world, i + 9, j + 28, k + 7, Blocks.log, 0);
		setBlock(world, i + 9, j + 28, k + 8, Blocks.log, 0);
		setBlock(world, i + 9, j + 28, k + 9, Blocks.log, 0);
		setBlock(world, i + 9, j + 33, k + 2, Blocks.log, 0);
		setBlock(world, i + 9, j + 33, k + 9, Blocks.log, 0);
		setBlock(world, i + 9, j + 34, k + 3, Blocks.log, 0);
		setBlock(world, i + 9, j + 35, k + 4, Blocks.log, 0);
		setBlock(world, i + 9, j + 35, k + 5, Blocks.log, 0);
		setBlock(world, i + 9, j + 35, k + 8, Blocks.log, 0);
		setBlock(world, i + 9, j + 35, k + 9, Blocks.log, 0);
		setBlock(world, i + 9, j + 35, k + 10, Blocks.log, 0);
		setBlock(world, i + 9, j + 35, k + 11, Blocks.log, 0);
		setBlock(world, i + 9, j + 36, k + 8, Blocks.log, 0);
		setBlock(world, i + 9, j + 36, k + 12, Blocks.log, 0);
		setBlock(world, i + 9, j + 37, k + 6, Blocks.log, 0);
		setBlock(world, i + 9, j + 37, k + 7, Blocks.log, 0);
		setBlock(world, i + 9, j + 37, k + 8, Blocks.log, 0);
		setBlock(world, i + 9, j + 38, k + 4, Blocks.log, 0);
		setBlock(world, i + 9, j + 41, k + 8, Blocks.log, 0);
		setBlock(world, i + 9, j + 42, k + 9, Blocks.log, 0);
		setBlock(world, i + 9, j + 43, k + 8, Blocks.log, 0);
		setBlock(world, i + 9, j + 44, k + 8, Blocks.log, 0);
		setBlock(world, i + 9, j + 45, k + 8, Blocks.log, 0);
		setBlock(world, i + 10, j + 0, k + 7, Blocks.log, 0);
		setBlock(world, i + 10, j + 0, k + 8, Blocks.log, 0);
		setBlock(world, i + 10, j + 0, k + 9, Blocks.log, 0);
		setBlock(world, i + 10, j + 0, k + 10, Blocks.log, 0);
		setBlock(world, i + 10, j + 1, k + 7, Blocks.log, 0);
		setBlock(world, i + 10, j + 1, k + 8, Blocks.log, 0);
		setBlock(world, i + 10, j + 1, k + 9, Blocks.log, 0);
		setBlock(world, i + 10, j + 1, k + 10, Blocks.log, 0);
		setBlock(world, i + 10, j + 2, k + 7, Blocks.log, 0);
		setBlock(world, i + 10, j + 2, k + 8, Blocks.log, 0);
		setBlock(world, i + 10, j + 2, k + 9, Blocks.log, 0);
		setBlock(world, i + 10, j + 2, k + 10, Blocks.log, 0);
		setBlock(world, i + 10, j + 3, k + 8, Blocks.log, 0);
		setBlock(world, i + 10, j + 3, k + 9, Blocks.log, 0);
		setBlock(world, i + 10, j + 3, k + 10, Blocks.log, 0);
		setBlock(world, i + 10, j + 4, k + 8, Blocks.log, 0);
		setBlock(world, i + 10, j + 4, k + 9, Blocks.log, 0);
		setBlock(world, i + 10, j + 4, k + 10, Blocks.log, 0);
		setBlock(world, i + 10, j + 5, k + 9, Blocks.log, 0);
		setBlock(world, i + 10, j + 5, k + 10, Blocks.log, 0);
		setBlock(world, i + 10, j + 6, k + 9, Blocks.log, 0);
		setBlock(world, i + 10, j + 18, k + 8, Blocks.log, 0);
		setBlock(world, i + 10, j + 25, k + 7, Blocks.log, 0);
		setBlock(world, i + 10, j + 25, k + 8, Blocks.log, 0);
		setBlock(world, i + 10, j + 27, k + 11, Blocks.log, 0);
		setBlock(world, i + 10, j + 28, k + 9, Blocks.log, 0);
		setBlock(world, i + 10, j + 29, k + 5, Blocks.log, 0);
		setBlock(world, i + 10, j + 29, k + 6, Blocks.log, 0);
		setBlock(world, i + 10, j + 36, k + 3, Blocks.log, 0);
		setBlock(world, i + 10, j + 36, k + 8, Blocks.log, 0);
		setBlock(world, i + 10, j + 38, k + 5, Blocks.log, 0);
		setBlock(world, i + 11, j + 18, k + 7, Blocks.log, 0);
		setBlock(world, i + 11, j + 25, k + 6, Blocks.log, 0);
		setBlock(world, i + 11, j + 25, k + 8, Blocks.log, 0);
		setBlock(world, i + 11, j + 27, k + 12, Blocks.log, 0);
		setBlock(world, i + 11, j + 28, k + 9, Blocks.log, 0);
		setBlock(world, i + 11, j + 30, k + 4, Blocks.log, 0);
		setBlock(world, i + 11, j + 36, k + 8, Blocks.log, 0);
		setBlock(world, i + 12, j + 18, k + 6, Blocks.log, 0);
		setBlock(world, i + 12, j + 25, k + 7, Blocks.log, 0);
		setBlock(world, i + 12, j + 26, k + 5, Blocks.log, 0);
		setBlock(world, i + 12, j + 27, k + 13, Blocks.log, 0);
		setBlock(world, i + 12, j + 28, k + 9, Blocks.log, 0);
		setBlock(world, i + 12, j + 37, k + 8, Blocks.log, 0);
		setBlock(world, i + 13, j + 19, k + 5, Blocks.log, 0);
		setBlock(world, i + 13, j + 26, k + 6, Blocks.log, 0);
		setBlock(world, i + 13, j + 28, k + 13, Blocks.log, 0);
		setBlock(world, i + 13, j + 29, k + 8, Blocks.log, 0);
		setBlock(world, i + 13, j + 35, k + 9, Blocks.log, 0);
		setBlock(world, i + 0, j + 16, k + 1, Blocks.leaves, 4);
		world.setBlockMetadataWithNotify(i + 0, j + 16, k + 1, 4, 2);
		setBlock(world, i + 0, j + 16, k + 2, Blocks.leaves, 4);
		world.setBlockMetadataWithNotify(i + 0, j + 16, k + 2, 4, 2);
		setBlock(world, i + 0, j + 16, k + 3, Blocks.leaves, 4);
		world.setBlockMetadataWithNotify(i + 0, j + 16, k + 3, 4, 2);
		setBlock(world, i + 0, j + 17, k + 2, Blocks.leaves, 4);
		world.setBlockMetadataWithNotify(i + 0, j + 17, k + 2, 4, 2);
		setBlock(world, i + 0, j + 22, k + 1, Blocks.leaves, 4);
		world.setBlockMetadataWithNotify(i + 0, j + 22, k + 1, 4, 2);
		setBlock(world, i + 0, j + 22, k + 2, Blocks.leaves, 4);
		world.setBlockMetadataWithNotify(i + 0, j + 22, k + 2, 4, 2);
		setBlock(world, i + 0, j + 22, k + 3, Blocks.leaves, 4);
		world.setBlockMetadataWithNotify(i + 0, j + 22, k + 3, 4, 2);
		setBlock(world, i + 0, j + 22, k + 4, Blocks.leaves, 4);
		world.setBlockMetadataWithNotify(i + 0, j + 22, k + 4, 4, 2);
		setBlock(world, i + 0, j + 22, k + 5, Blocks.leaves, 4);
		world.setBlockMetadataWithNotify(i + 0, j + 22, k + 5, 4, 2);
		setBlock(world, i + 0, j + 23, k + 2, Blocks.leaves, 4);
		world.setBlockMetadataWithNotify(i + 0, j + 23, k + 2, 4, 2);
		setBlock(world, i + 0, j + 23, k + 3, Blocks.leaves, 4);
		world.setBlockMetadataWithNotify(i + 0, j + 23, k + 3, 4, 2);
		setBlock(world, i + 0, j + 23, k + 4, Blocks.leaves, 4);
		world.setBlockMetadataWithNotify(i + 0, j + 23, k + 4, 4, 2);
		setBlock(world, i + 0, j + 24, k + 3, Blocks.leaves, 4);
		world.setBlockMetadataWithNotify(i + 0, j + 24, k + 3, 4, 2);
		setBlock(world, i + 0, j + 31, k + 7, Blocks.leaves, 4);
		world.setBlockMetadataWithNotify(i + 0, j + 31, k + 7, 4, 2);
		setBlock(world, i + 0, j + 31, k + 8, Blocks.leaves, 4);
		world.setBlockMetadataWithNotify(i + 0, j + 31, k + 8, 4, 2);
		setBlock(world, i + 0, j + 31, k + 9, Blocks.leaves, 4);
		world.setBlockMetadataWithNotify(i + 0, j + 31, k + 9, 4, 2);
		setBlock(world, i + 0, j + 32, k + 8, Blocks.leaves, 4);
		world.setBlockMetadataWithNotify(i + 0, j + 32, k + 8, 4, 2);
		setBlock(world, i + 1, j + 16, k + 0, Blocks.leaves, 4);
		world.setBlockMetadataWithNotify(i + 1, j + 16, k + 0, 4, 2);
		setBlock(world, i + 1, j + 16, k + 1, Blocks.leaves, 4);
		world.setBlockMetadataWithNotify(i + 1, j + 16, k + 1, 4, 2);
		setBlock(world, i + 1, j + 16, k + 2, Blocks.leaves, 4);
		world.setBlockMetadataWithNotify(i + 1, j + 16, k + 2, 4, 2);
		setBlock(world, i + 1, j + 16, k + 3, Blocks.leaves, 4);
		world.setBlockMetadataWithNotify(i + 1, j + 16, k + 3, 4, 2);
		setBlock(world, i + 1, j + 16, k + 4, Blocks.leaves, 4);
		world.setBlockMetadataWithNotify(i + 1, j + 16, k + 4, 4, 2);
		setBlock(world, i + 1, j + 17, k + 1, Blocks.leaves, 4);
		world.setBlockMetadataWithNotify(i + 1, j + 17, k + 1, 4, 2);
		setBlock(world, i + 1, j + 17, k + 2, Blocks.leaves, 4);
		world.setBlockMetadataWithNotify(i + 1, j + 17, k + 2, 4, 2);
		setBlock(world, i + 1, j + 17, k + 3, Blocks.leaves, 4);
		world.setBlockMetadataWithNotify(i + 1, j + 17, k + 3, 4, 2);
		setBlock(world, i + 1, j + 18, k + 2, Blocks.leaves, 4);
		world.setBlockMetadataWithNotify(i + 1, j + 18, k + 2, 4, 2);
		setBlock(world, i + 1, j + 19, k + 5, Blocks.leaves, 4);
		world.setBlockMetadataWithNotify(i + 1, j + 19, k + 5, 4, 2);
		setBlock(world, i + 1, j + 19, k + 6, Blocks.leaves, 4);
		world.setBlockMetadataWithNotify(i + 1, j + 19, k + 6, 4, 2);
		setBlock(world, i + 1, j + 19, k + 7, Blocks.leaves, 4);
		world.setBlockMetadataWithNotify(i + 1, j + 19, k + 7, 4, 2);
		setBlock(world, i + 1, j + 20, k + 6, Blocks.leaves, 4);
		world.setBlockMetadataWithNotify(i + 1, j + 20, k + 6, 4, 2);
		setBlock(world, i + 1, j + 22, k + 1, Blocks.leaves, 4);
		world.setBlockMetadataWithNotify(i + 1, j + 22, k + 1, 4, 2);
		setBlock(world, i + 1, j + 22, k + 2, Blocks.leaves, 4);
		world.setBlockMetadataWithNotify(i + 1, j + 22, k + 2, 4, 2);
		setBlock(world, i + 1, j + 22, k + 4, Blocks.leaves, 4);
		world.setBlockMetadataWithNotify(i + 1, j + 22, k + 4, 4, 2);
		setBlock(world, i + 1, j + 22, k + 5, Blocks.leaves, 4);
		world.setBlockMetadataWithNotify(i + 1, j + 22, k + 5, 4, 2);
		setBlock(world, i + 1, j + 23, k + 1, Blocks.leaves, 4);
		world.setBlockMetadataWithNotify(i + 1, j + 23, k + 1, 4, 2);
		setBlock(world, i + 1, j + 23, k + 2, Blocks.leaves, 4);
		world.setBlockMetadataWithNotify(i + 1, j + 23, k + 2, 4, 2);
		setBlock(world, i + 1, j + 23, k + 3, Blocks.leaves, 4);
		world.setBlockMetadataWithNotify(i + 1, j + 23, k + 3, 4, 2);
		setBlock(world, i + 1, j + 23, k + 4, Blocks.leaves, 4);
		world.setBlockMetadataWithNotify(i + 1, j + 23, k + 4, 4, 2);
		setBlock(world, i + 1, j + 23, k + 5, Blocks.leaves, 4);
		world.setBlockMetadataWithNotify(i + 1, j + 23, k + 5, 4, 2);
		setBlock(world, i + 1, j + 24, k + 2, Blocks.leaves, 4);
		world.setBlockMetadataWithNotify(i + 1, j + 24, k + 2, 4, 2);
		setBlock(world, i + 1, j + 24, k + 3, Blocks.leaves, 4);
		world.setBlockMetadataWithNotify(i + 1, j + 24, k + 3, 4, 2);
		setBlock(world, i + 1, j + 24, k + 4, Blocks.leaves, 4);
		world.setBlockMetadataWithNotify(i + 1, j + 24, k + 4, 4, 2);
		setBlock(world, i + 1, j + 25, k + 3, Blocks.leaves, 4);
		world.setBlockMetadataWithNotify(i + 1, j + 25, k + 3, 4, 2);
		setBlock(world, i + 1, j + 31, k + 6, Blocks.leaves, 4);
		world.setBlockMetadataWithNotify(i + 1, j + 31, k + 6, 4, 2);
		setBlock(world, i + 1, j + 31, k + 7, Blocks.leaves, 4);
		world.setBlockMetadataWithNotify(i + 1, j + 31, k + 7, 4, 2);
		setBlock(world, i + 1, j + 31, k + 8, Blocks.leaves, 4);
		world.setBlockMetadataWithNotify(i + 1, j + 31, k + 8, 4, 2);
		setBlock(world, i + 1, j + 31, k + 9, Blocks.leaves, 4);
		world.setBlockMetadataWithNotify(i + 1, j + 31, k + 9, 4, 2);
		setBlock(world, i + 1, j + 31, k + 10, Blocks.leaves, 4);
		world.setBlockMetadataWithNotify(i + 1, j + 31, k + 10, 4, 2);
		setBlock(world, i + 1, j + 32, k + 7, Blocks.leaves, 4);
		world.setBlockMetadataWithNotify(i + 1, j + 32, k + 7, 4, 2);
		setBlock(world, i + 1, j + 32, k + 8, Blocks.leaves, 4);
		world.setBlockMetadataWithNotify(i + 1, j + 32, k + 8, 4, 2);
		setBlock(world, i + 1, j + 32, k + 9, Blocks.leaves, 4);
		world.setBlockMetadataWithNotify(i + 1, j + 32, k + 9, 4, 2);
		setBlock(world, i + 1, j + 33, k + 8, Blocks.leaves, 4);
		world.setBlockMetadataWithNotify(i + 1, j + 33, k + 8, 4, 2);
		setBlock(world, i + 2, j + 16, k + 0, Blocks.leaves, 4);
		world.setBlockMetadataWithNotify(i + 2, j + 16, k + 0, 4, 2);
		setBlock(world, i + 2, j + 16, k + 1, Blocks.leaves, 4);
		world.setBlockMetadataWithNotify(i + 2, j + 16, k + 1, 4, 2);
		setBlock(world, i + 2, j + 16, k + 3, Blocks.leaves, 4);
		world.setBlockMetadataWithNotify(i + 2, j + 16, k + 3, 4, 2);
		setBlock(world, i + 2, j + 16, k + 4, Blocks.leaves, 4);
		world.setBlockMetadataWithNotify(i + 2, j + 16, k + 4, 4, 2);
		setBlock(world, i + 2, j + 17, k + 0, Blocks.leaves, 4);
		world.setBlockMetadataWithNotify(i + 2, j + 17, k + 0, 4, 2);
		setBlock(world, i + 2, j + 17, k + 1, Blocks.leaves, 4);
		world.setBlockMetadataWithNotify(i + 2, j + 17, k + 1, 4, 2);
		setBlock(world, i + 2, j + 17, k + 2, Blocks.leaves, 4);
		world.setBlockMetadataWithNotify(i + 2, j + 17, k + 2, 4, 2);
		setBlock(world, i + 2, j + 17, k + 3, Blocks.leaves, 4);
		world.setBlockMetadataWithNotify(i + 2, j + 17, k + 3, 4, 2);
		setBlock(world, i + 2, j + 17, k + 4, Blocks.leaves, 4);
		world.setBlockMetadataWithNotify(i + 2, j + 17, k + 4, 4, 2);
		setBlock(world, i + 2, j + 18, k + 1, Blocks.leaves, 4);
		world.setBlockMetadataWithNotify(i + 2, j + 18, k + 1, 4, 2);
		setBlock(world, i + 2, j + 18, k + 2, Blocks.leaves, 4);
		world.setBlockMetadataWithNotify(i + 2, j + 18, k + 2, 4, 2);
		setBlock(world, i + 2, j + 18, k + 3, Blocks.leaves, 4);
		world.setBlockMetadataWithNotify(i + 2, j + 18, k + 3, 4, 2);
		setBlock(world, i + 2, j + 18, k + 5, Blocks.leaves, 4);
		world.setBlockMetadataWithNotify(i + 2, j + 18, k + 5, 4, 2);
		setBlock(world, i + 2, j + 18, k + 6, Blocks.leaves, 4);
		world.setBlockMetadataWithNotify(i + 2, j + 18, k + 6, 4, 2);
		setBlock(world, i + 2, j + 18, k + 7, Blocks.leaves, 4);
		world.setBlockMetadataWithNotify(i + 2, j + 18, k + 7, 4, 2);
		setBlock(world, i + 2, j + 19, k + 2, Blocks.leaves, 4);
		world.setBlockMetadataWithNotify(i + 2, j + 19, k + 2, 4, 2);
		setBlock(world, i + 2, j + 19, k + 4, Blocks.leaves, 4);
		world.setBlockMetadataWithNotify(i + 2, j + 19, k + 4, 4, 2);
		setBlock(world, i + 2, j + 19, k + 5, Blocks.leaves, 4);
		world.setBlockMetadataWithNotify(i + 2, j + 19, k + 5, 4, 2);
		setBlock(world, i + 2, j + 19, k + 6, Blocks.leaves, 4);
		world.setBlockMetadataWithNotify(i + 2, j + 19, k + 6, 4, 2);
		setBlock(world, i + 2, j + 19, k + 7, Blocks.leaves, 4);
		world.setBlockMetadataWithNotify(i + 2, j + 19, k + 7, 4, 2);
		setBlock(world, i + 2, j + 19, k + 8, Blocks.leaves, 4);
		world.setBlockMetadataWithNotify(i + 2, j + 19, k + 8, 4, 2);
		setBlock(world, i + 2, j + 20, k + 5, Blocks.leaves, 4);
		world.setBlockMetadataWithNotify(i + 2, j + 20, k + 5, 4, 2);
		setBlock(world, i + 2, j + 20, k + 6, Blocks.leaves, 4);
		world.setBlockMetadataWithNotify(i + 2, j + 20, k + 6, 4, 2);
		setBlock(world, i + 2, j + 20, k + 7, Blocks.leaves, 4);
		world.setBlockMetadataWithNotify(i + 2, j + 20, k + 7, 4, 2);
		setBlock(world, i + 2, j + 21, k + 6, Blocks.leaves, 4);
		world.setBlockMetadataWithNotify(i + 2, j + 21, k + 6, 4, 2);
		setBlock(world, i + 2, j + 22, k + 1, Blocks.leaves, 4);
		world.setBlockMetadataWithNotify(i + 2, j + 22, k + 1, 4, 2);
		setBlock(world, i + 2, j + 22, k + 2, Blocks.leaves, 4);
		world.setBlockMetadataWithNotify(i + 2, j + 22, k + 2, 4, 2);
		setBlock(world, i + 2, j + 22, k + 3, Blocks.leaves, 4);
		world.setBlockMetadataWithNotify(i + 2, j + 22, k + 3, 4, 2);
		setBlock(world, i + 2, j + 22, k + 4, Blocks.leaves, 4);
		world.setBlockMetadataWithNotify(i + 2, j + 22, k + 4, 4, 2);
		setBlock(world, i + 2, j + 22, k + 5, Blocks.leaves, 4);
		world.setBlockMetadataWithNotify(i + 2, j + 22, k + 5, 4, 2);
		setBlock(world, i + 2, j + 23, k + 2, Blocks.leaves, 4);
		world.setBlockMetadataWithNotify(i + 2, j + 23, k + 2, 4, 2);
		setBlock(world, i + 2, j + 23, k + 3, Blocks.leaves, 4);
		world.setBlockMetadataWithNotify(i + 2, j + 23, k + 3, 4, 2);
		setBlock(world, i + 2, j + 23, k + 4, Blocks.leaves, 4);
		world.setBlockMetadataWithNotify(i + 2, j + 23, k + 4, 4, 2);
		setBlock(world, i + 2, j + 24, k + 3, Blocks.leaves, 4);
		world.setBlockMetadataWithNotify(i + 2, j + 24, k + 3, 4, 2);
		setBlock(world, i + 2, j + 31, k + 6, Blocks.leaves, 4);
		world.setBlockMetadataWithNotify(i + 2, j + 31, k + 6, 4, 2);
		setBlock(world, i + 2, j + 31, k + 7, Blocks.leaves, 4);
		world.setBlockMetadataWithNotify(i + 2, j + 31, k + 7, 4, 2);
		setBlock(world, i + 2, j + 31, k + 9, Blocks.leaves, 4);
		world.setBlockMetadataWithNotify(i + 2, j + 31, k + 9, 4, 2);
		setBlock(world, i + 2, j + 31, k + 10, Blocks.leaves, 4);
		world.setBlockMetadataWithNotify(i + 2, j + 31, k + 10, 4, 2);
		setBlock(world, i + 2, j + 32, k + 6, Blocks.leaves, 4);
		world.setBlockMetadataWithNotify(i + 2, j + 32, k + 6, 4, 2);
		setBlock(world, i + 2, j + 32, k + 7, Blocks.leaves, 4);
		world.setBlockMetadataWithNotify(i + 2, j + 32, k + 7, 4, 2);
		setBlock(world, i + 2, j + 32, k + 8, Blocks.leaves, 4);
		world.setBlockMetadataWithNotify(i + 2, j + 32, k + 8, 4, 2);
		setBlock(world, i + 2, j + 32, k + 9, Blocks.leaves, 4);
		world.setBlockMetadataWithNotify(i + 2, j + 32, k + 9, 4, 2);
		setBlock(world, i + 2, j + 32, k + 10, Blocks.leaves, 4);
		world.setBlockMetadataWithNotify(i + 2, j + 32, k + 10, 4, 2);
		setBlock(world, i + 2, j + 33, k + 7, Blocks.leaves, 4);
		world.setBlockMetadataWithNotify(i + 2, j + 33, k + 7, 4, 2);
		setBlock(world, i + 2, j + 33, k + 8, Blocks.leaves, 4);
		world.setBlockMetadataWithNotify(i + 2, j + 33, k + 8, 4, 2);
		setBlock(world, i + 2, j + 33, k + 9, Blocks.leaves, 4);
		world.setBlockMetadataWithNotify(i + 2, j + 33, k + 9, 4, 2);
		setBlock(world, i + 2, j + 34, k + 8, Blocks.leaves, 4);
		world.setBlockMetadataWithNotify(i + 2, j + 34, k + 8, 4, 2);
		setBlock(world, i + 2, j + 39, k + 7, Blocks.leaves, 4);
		world.setBlockMetadataWithNotify(i + 2, j + 39, k + 7, 4, 2);
		setBlock(world, i + 2, j + 39, k + 8, Blocks.leaves, 4);
		world.setBlockMetadataWithNotify(i + 2, j + 39, k + 8, 4, 2);
		setBlock(world, i + 2, j + 39, k + 9, Blocks.leaves, 4);
		world.setBlockMetadataWithNotify(i + 2, j + 39, k + 9, 4, 2);
		setBlock(world, i + 2, j + 40, k + 8, Blocks.leaves, 4);
		world.setBlockMetadataWithNotify(i + 2, j + 40, k + 8, 4, 2);
		setBlock(world, i + 3, j + 16, k + 0, Blocks.leaves, 4);
		world.setBlockMetadataWithNotify(i + 3, j + 16, k + 0, 4, 2);
		setBlock(world, i + 3, j + 16, k + 1, Blocks.leaves, 4);
		world.setBlockMetadataWithNotify(i + 3, j + 16, k + 1, 4, 2);
		setBlock(world, i + 3, j + 16, k + 2, Blocks.leaves, 4);
		world.setBlockMetadataWithNotify(i + 3, j + 16, k + 2, 4, 2);
		setBlock(world, i + 3, j + 16, k + 3, Blocks.leaves, 4);
		world.setBlockMetadataWithNotify(i + 3, j + 16, k + 3, 4, 2);
		setBlock(world, i + 3, j + 16, k + 4, Blocks.leaves, 4);
		world.setBlockMetadataWithNotify(i + 3, j + 16, k + 4, 4, 2);
		setBlock(world, i + 3, j + 17, k + 1, Blocks.leaves, 4);
		world.setBlockMetadataWithNotify(i + 3, j + 17, k + 1, 4, 2);
		setBlock(world, i + 3, j + 17, k + 2, Blocks.leaves, 4);
		world.setBlockMetadataWithNotify(i + 3, j + 17, k + 2, 4, 2);
		setBlock(world, i + 3, j + 17, k + 3, Blocks.leaves, 4);
		world.setBlockMetadataWithNotify(i + 3, j + 17, k + 3, 4, 2);
		setBlock(world, i + 3, j + 18, k + 2, Blocks.leaves, 4);
		world.setBlockMetadataWithNotify(i + 3, j + 18, k + 2, 4, 2);
		setBlock(world, i + 3, j + 18, k + 4, Blocks.leaves, 4);
		world.setBlockMetadataWithNotify(i + 3, j + 18, k + 4, 4, 2);
		setBlock(world, i + 3, j + 18, k + 5, Blocks.leaves, 4);
		world.setBlockMetadataWithNotify(i + 3, j + 18, k + 5, 4, 2);
		setBlock(world, i + 3, j + 18, k + 6, Blocks.leaves, 4);
		world.setBlockMetadataWithNotify(i + 3, j + 18, k + 6, 4, 2);
		setBlock(world, i + 3, j + 18, k + 7, Blocks.leaves, 4);
		world.setBlockMetadataWithNotify(i + 3, j + 18, k + 7, 4, 2);
		setBlock(world, i + 3, j + 18, k + 8, Blocks.leaves, 4);
		world.setBlockMetadataWithNotify(i + 3, j + 18, k + 8, 4, 2);
		setBlock(world, i + 3, j + 19, k + 4, Blocks.leaves, 4);
		world.setBlockMetadataWithNotify(i + 3, j + 19, k + 4, 4, 2);
		setBlock(world, i + 3, j + 19, k + 5, Blocks.leaves, 4);
		world.setBlockMetadataWithNotify(i + 3, j + 19, k + 5, 4, 2);
		setBlock(world, i + 3, j + 19, k + 7, Blocks.leaves, 4);
		world.setBlockMetadataWithNotify(i + 3, j + 19, k + 7, 4, 2);
		setBlock(world, i + 3, j + 19, k + 8, Blocks.leaves, 4);
		world.setBlockMetadataWithNotify(i + 3, j + 19, k + 8, 4, 2);
		setBlock(world, i + 3, j + 20, k + 4, Blocks.leaves, 4);
		world.setBlockMetadataWithNotify(i + 3, j + 20, k + 4, 4, 2);
		setBlock(world, i + 3, j + 20, k + 5, Blocks.leaves, 4);
		world.setBlockMetadataWithNotify(i + 3, j + 20, k + 5, 4, 2);
		setBlock(world, i + 3, j + 20, k + 6, Blocks.leaves, 4);
		world.setBlockMetadataWithNotify(i + 3, j + 20, k + 6, 4, 2);
		setBlock(world, i + 3, j + 20, k + 7, Blocks.leaves, 4);
		world.setBlockMetadataWithNotify(i + 3, j + 20, k + 7, 4, 2);
		setBlock(world, i + 3, j + 20, k + 8, Blocks.leaves, 4);
		world.setBlockMetadataWithNotify(i + 3, j + 20, k + 8, 4, 2);
		setBlock(world, i + 3, j + 21, k + 0, Blocks.leaves, 4);
		world.setBlockMetadataWithNotify(i + 3, j + 21, k + 0, 4, 2);
		setBlock(world, i + 3, j + 21, k + 1, Blocks.leaves, 4);
		world.setBlockMetadataWithNotify(i + 3, j + 21, k + 1, 4, 2);
		setBlock(world, i + 3, j + 21, k + 2, Blocks.leaves, 4);
		world.setBlockMetadataWithNotify(i + 3, j + 21, k + 2, 4, 2);
		setBlock(world, i + 3, j + 21, k + 6, Blocks.leaves, 4);
		world.setBlockMetadataWithNotify(i + 3, j + 21, k + 6, 4, 2);
		setBlock(world, i + 3, j + 21, k + 7, Blocks.leaves, 4);
		world.setBlockMetadataWithNotify(i + 3, j + 21, k + 7, 4, 2);
		setBlock(world, i + 3, j + 22, k + 1, Blocks.leaves, 4);
		world.setBlockMetadataWithNotify(i + 3, j + 22, k + 1, 4, 2);
		setBlock(world, i + 3, j + 22, k + 2, Blocks.leaves, 4);
		world.setBlockMetadataWithNotify(i + 3, j + 22, k + 2, 4, 2);
		setBlock(world, i + 3, j + 22, k + 3, Blocks.leaves, 4);
		world.setBlockMetadataWithNotify(i + 3, j + 22, k + 3, 4, 2);
		setBlock(world, i + 3, j + 22, k + 4, Blocks.leaves, 4);
		world.setBlockMetadataWithNotify(i + 3, j + 22, k + 4, 4, 2);
		setBlock(world, i + 3, j + 22, k + 6, Blocks.leaves, 4);
		world.setBlockMetadataWithNotify(i + 3, j + 22, k + 6, 4, 2);
		setBlock(world, i + 3, j + 23, k + 3, Blocks.leaves, 4);
		world.setBlockMetadataWithNotify(i + 3, j + 23, k + 3, 4, 2);
		setBlock(world, i + 3, j + 31, k + 6, Blocks.leaves, 4);
		world.setBlockMetadataWithNotify(i + 3, j + 31, k + 6, 4, 2);
		setBlock(world, i + 3, j + 31, k + 7, Blocks.leaves, 4);
		world.setBlockMetadataWithNotify(i + 3, j + 31, k + 7, 4, 2);
		setBlock(world, i + 3, j + 31, k + 8, Blocks.leaves, 4);
		world.setBlockMetadataWithNotify(i + 3, j + 31, k + 8, 4, 2);
		setBlock(world, i + 3, j + 31, k + 9, Blocks.leaves, 4);
		world.setBlockMetadataWithNotify(i + 3, j + 31, k + 9, 4, 2);
		setBlock(world, i + 3, j + 31, k + 10, Blocks.leaves, 4);
		world.setBlockMetadataWithNotify(i + 3, j + 31, k + 10, 4, 2);
		setBlock(world, i + 3, j + 32, k + 7, Blocks.leaves, 4);
		world.setBlockMetadataWithNotify(i + 3, j + 32, k + 7, 4, 2);
		setBlock(world, i + 3, j + 32, k + 8, Blocks.leaves, 4);
		world.setBlockMetadataWithNotify(i + 3, j + 32, k + 8, 4, 2);
		setBlock(world, i + 3, j + 32, k + 9, Blocks.leaves, 4);
		world.setBlockMetadataWithNotify(i + 3, j + 32, k + 9, 4, 2);
		setBlock(world, i + 3, j + 33, k + 8, Blocks.leaves, 4);
		world.setBlockMetadataWithNotify(i + 3, j + 33, k + 8, 4, 2);
		setBlock(world, i + 3, j + 35, k + 10, Blocks.leaves, 4);
		world.setBlockMetadataWithNotify(i + 3, j + 35, k + 10, 4, 2);
		setBlock(world, i + 3, j + 35, k + 11, Blocks.leaves, 4);
		world.setBlockMetadataWithNotify(i + 3, j + 35, k + 11, 4, 2);
		setBlock(world, i + 3, j + 35, k + 12, Blocks.leaves, 4);
		world.setBlockMetadataWithNotify(i + 3, j + 35, k + 12, 4, 2);
		setBlock(world, i + 3, j + 36, k + 6, Blocks.leaves, 4);
		world.setBlockMetadataWithNotify(i + 3, j + 36, k + 6, 4, 2);
		setBlock(world, i + 3, j + 36, k + 7, Blocks.leaves, 4);
		world.setBlockMetadataWithNotify(i + 3, j + 36, k + 7, 4, 2);
		setBlock(world, i + 3, j + 36, k + 8, Blocks.leaves, 4);
		world.setBlockMetadataWithNotify(i + 3, j + 36, k + 8, 4, 2);
		setBlock(world, i + 3, j + 36, k + 11, Blocks.leaves, 4);
		world.setBlockMetadataWithNotify(i + 3, j + 36, k + 11, 4, 2);
		setBlock(world, i + 3, j + 37, k + 7, Blocks.leaves, 4);
		world.setBlockMetadataWithNotify(i + 3, j + 37, k + 7, 4, 2);
		setBlock(world, i + 3, j + 39, k + 6, Blocks.leaves, 4);
		world.setBlockMetadataWithNotify(i + 3, j + 39, k + 6, 4, 2);
		setBlock(world, i + 3, j + 39, k + 7, Blocks.leaves, 4);
		world.setBlockMetadataWithNotify(i + 3, j + 39, k + 7, 4, 2);
		setBlock(world, i + 3, j + 39, k + 8, Blocks.leaves, 4);
		world.setBlockMetadataWithNotify(i + 3, j + 39, k + 8, 4, 2);
		setBlock(world, i + 3, j + 39, k + 9, Blocks.leaves, 4);
		world.setBlockMetadataWithNotify(i + 3, j + 39, k + 9, 4, 2);
		setBlock(world, i + 3, j + 39, k + 10, Blocks.leaves, 4);
		world.setBlockMetadataWithNotify(i + 3, j + 39, k + 10, 4, 2);
		setBlock(world, i + 3, j + 40, k + 6, Blocks.leaves, 4);
		world.setBlockMetadataWithNotify(i + 3, j + 40, k + 6, 4, 2);
		setBlock(world, i + 3, j + 40, k + 7, Blocks.leaves, 4);
		world.setBlockMetadataWithNotify(i + 3, j + 40, k + 7, 4, 2);
		setBlock(world, i + 3, j + 40, k + 8, Blocks.leaves, 4);
		world.setBlockMetadataWithNotify(i + 3, j + 40, k + 8, 4, 2);
		setBlock(world, i + 3, j + 40, k + 9, Blocks.leaves, 4);
		world.setBlockMetadataWithNotify(i + 3, j + 40, k + 9, 4, 2);
		setBlock(world, i + 3, j + 41, k + 7, Blocks.leaves, 4);
		world.setBlockMetadataWithNotify(i + 3, j + 41, k + 7, 4, 2);
		setBlock(world, i + 3, j + 41, k + 8, Blocks.leaves, 4);
		world.setBlockMetadataWithNotify(i + 3, j + 41, k + 8, 4, 2);
		setBlock(world, i + 4, j + 16, k + 1, Blocks.leaves, 4);
		world.setBlockMetadataWithNotify(i + 4, j + 16, k + 1, 4, 2);
		setBlock(world, i + 4, j + 16, k + 2, Blocks.leaves, 4);
		world.setBlockMetadataWithNotify(i + 4, j + 16, k + 2, 4, 2);
		setBlock(world, i + 4, j + 16, k + 3, Blocks.leaves, 4);
		world.setBlockMetadataWithNotify(i + 4, j + 16, k + 3, 4, 2);
		setBlock(world, i + 4, j + 17, k + 2, Blocks.leaves, 4);
		world.setBlockMetadataWithNotify(i + 4, j + 17, k + 2, 4, 2);
		setBlock(world, i + 4, j + 18, k + 4, Blocks.leaves, 4);
		world.setBlockMetadataWithNotify(i + 4, j + 18, k + 4, 4, 2);
		setBlock(world, i + 4, j + 18, k + 5, Blocks.leaves, 4);
		world.setBlockMetadataWithNotify(i + 4, j + 18, k + 5, 4, 2);
		setBlock(world, i + 4, j + 18, k + 8, Blocks.leaves, 4);
		world.setBlockMetadataWithNotify(i + 4, j + 18, k + 8, 4, 2);
		setBlock(world, i + 4, j + 19, k + 3, Blocks.leaves, 4);
		world.setBlockMetadataWithNotify(i + 4, j + 19, k + 3, 4, 2);
		setBlock(world, i + 4, j + 19, k + 4, Blocks.leaves, 4);
		world.setBlockMetadataWithNotify(i + 4, j + 19, k + 4, 4, 2);
		setBlock(world, i + 4, j + 19, k + 5, Blocks.leaves, 4);
		world.setBlockMetadataWithNotify(i + 4, j + 19, k + 5, 4, 2);
		setBlock(world, i + 4, j + 19, k + 6, Blocks.leaves, 4);
		world.setBlockMetadataWithNotify(i + 4, j + 19, k + 6, 4, 2);
		setBlock(world, i + 4, j + 19, k + 7, Blocks.leaves, 4);
		world.setBlockMetadataWithNotify(i + 4, j + 19, k + 7, 4, 2);
		setBlock(world, i + 4, j + 19, k + 8, Blocks.leaves, 4);
		world.setBlockMetadataWithNotify(i + 4, j + 19, k + 8, 4, 2);
		setBlock(world, i + 4, j + 20, k + 4, Blocks.leaves, 4);
		world.setBlockMetadataWithNotify(i + 4, j + 20, k + 4, 4, 2);
		setBlock(world, i + 4, j + 20, k + 5, Blocks.leaves, 4);
		world.setBlockMetadataWithNotify(i + 4, j + 20, k + 5, 4, 2);
		setBlock(world, i + 4, j + 20, k + 6, Blocks.leaves, 4);
		world.setBlockMetadataWithNotify(i + 4, j + 20, k + 6, 4, 2);
		setBlock(world, i + 4, j + 20, k + 7, Blocks.leaves, 4);
		world.setBlockMetadataWithNotify(i + 4, j + 20, k + 7, 4, 2);
		setBlock(world, i + 4, j + 21, k + 0, Blocks.leaves, 4);
		world.setBlockMetadataWithNotify(i + 4, j + 21, k + 0, 4, 2);
		setBlock(world, i + 4, j + 21, k + 1, Blocks.leaves, 4);
		world.setBlockMetadataWithNotify(i + 4, j + 21, k + 1, 4, 2);
		setBlock(world, i + 4, j + 21, k + 2, Blocks.leaves, 4);
		world.setBlockMetadataWithNotify(i + 4, j + 21, k + 2, 4, 2);
		setBlock(world, i + 4, j + 21, k + 3, Blocks.leaves, 4);
		world.setBlockMetadataWithNotify(i + 4, j + 21, k + 3, 4, 2);
		setBlock(world, i + 4, j + 21, k + 6, Blocks.leaves, 4);
		world.setBlockMetadataWithNotify(i + 4, j + 21, k + 6, 4, 2);
		setBlock(world, i + 4, j + 22, k + 0, Blocks.leaves, 4);
		world.setBlockMetadataWithNotify(i + 4, j + 22, k + 0, 4, 2);
		setBlock(world, i + 4, j + 22, k + 1, Blocks.leaves, 4);
		world.setBlockMetadataWithNotify(i + 4, j + 22, k + 1, 4, 2);
		setBlock(world, i + 4, j + 22, k + 2, Blocks.leaves, 4);
		world.setBlockMetadataWithNotify(i + 4, j + 22, k + 2, 4, 2);
		setBlock(world, i + 4, j + 23, k + 1, Blocks.leaves, 4);
		world.setBlockMetadataWithNotify(i + 4, j + 23, k + 1, 4, 2);
		setBlock(world, i + 4, j + 31, k + 7, Blocks.leaves, 4);
		world.setBlockMetadataWithNotify(i + 4, j + 31, k + 7, 4, 2);
		setBlock(world, i + 4, j + 31, k + 8, Blocks.leaves, 4);
		world.setBlockMetadataWithNotify(i + 4, j + 31, k + 8, 4, 2);
		setBlock(world, i + 4, j + 31, k + 9, Blocks.leaves, 4);
		world.setBlockMetadataWithNotify(i + 4, j + 31, k + 9, 4, 2);
		setBlock(world, i + 4, j + 32, k + 8, Blocks.leaves, 4);
		world.setBlockMetadataWithNotify(i + 4, j + 32, k + 8, 4, 2);
		setBlock(world, i + 4, j + 33, k + 11, Blocks.leaves, 4);
		world.setBlockMetadataWithNotify(i + 4, j + 33, k + 11, 4, 2);
		setBlock(world, i + 4, j + 33, k + 12, Blocks.leaves, 4);
		world.setBlockMetadataWithNotify(i + 4, j + 33, k + 12, 4, 2);
		setBlock(world, i + 4, j + 33, k + 13, Blocks.leaves, 4);
		world.setBlockMetadataWithNotify(i + 4, j + 33, k + 13, 4, 2);
		setBlock(world, i + 4, j + 34, k + 1, Blocks.leaves, 4);
		world.setBlockMetadataWithNotify(i + 4, j + 34, k + 1, 4, 2);
		setBlock(world, i + 4, j + 34, k + 2, Blocks.leaves, 4);
		world.setBlockMetadataWithNotify(i + 4, j + 34, k + 2, 4, 2);
		setBlock(world, i + 4, j + 34, k + 3, Blocks.leaves, 4);
		world.setBlockMetadataWithNotify(i + 4, j + 34, k + 3, 4, 2);
		setBlock(world, i + 4, j + 34, k + 5, Blocks.leaves, 4);
		world.setBlockMetadataWithNotify(i + 4, j + 34, k + 5, 4, 2);
		setBlock(world, i + 4, j + 34, k + 6, Blocks.leaves, 4);
		world.setBlockMetadataWithNotify(i + 4, j + 34, k + 6, 4, 2);
		setBlock(world, i + 4, j + 34, k + 7, Blocks.leaves, 4);
		world.setBlockMetadataWithNotify(i + 4, j + 34, k + 7, 4, 2);
		setBlock(world, i + 4, j + 34, k + 12, Blocks.leaves, 4);
		world.setBlockMetadataWithNotify(i + 4, j + 34, k + 12, 4, 2);
		setBlock(world, i + 4, j + 35, k + 2, Blocks.leaves, 4);
		world.setBlockMetadataWithNotify(i + 4, j + 35, k + 2, 4, 2);
		setBlock(world, i + 4, j + 35, k + 6, Blocks.leaves, 4);
		world.setBlockMetadataWithNotify(i + 4, j + 35, k + 6, 4, 2);
		setBlock(world, i + 4, j + 35, k + 9, Blocks.leaves, 4);
		world.setBlockMetadataWithNotify(i + 4, j + 35, k + 9, 4, 2);
		setBlock(world, i + 4, j + 35, k + 10, Blocks.leaves, 4);
		world.setBlockMetadataWithNotify(i + 4, j + 35, k + 10, 4, 2);
		setBlock(world, i + 4, j + 35, k + 11, Blocks.leaves, 4);
		world.setBlockMetadataWithNotify(i + 4, j + 35, k + 11, 4, 2);
		setBlock(world, i + 4, j + 35, k + 12, Blocks.leaves, 4);
		world.setBlockMetadataWithNotify(i + 4, j + 35, k + 12, 4, 2);
		setBlock(world, i + 4, j + 35, k + 13, Blocks.leaves, 4);
		world.setBlockMetadataWithNotify(i + 4, j + 35, k + 13, 4, 2);
		setBlock(world, i + 4, j + 36, k + 5, Blocks.leaves, 4);
		world.setBlockMetadataWithNotify(i + 4, j + 36, k + 5, 4, 2);
		setBlock(world, i + 4, j + 36, k + 6, Blocks.leaves, 4);
		world.setBlockMetadataWithNotify(i + 4, j + 36, k + 6, 4, 2);
		setBlock(world, i + 4, j + 36, k + 7, Blocks.leaves, 4);
		world.setBlockMetadataWithNotify(i + 4, j + 36, k + 7, 4, 2);
		setBlock(world, i + 4, j + 36, k + 8, Blocks.leaves, 4);
		world.setBlockMetadataWithNotify(i + 4, j + 36, k + 8, 4, 2);
		setBlock(world, i + 4, j + 36, k + 9, Blocks.leaves, 4);
		world.setBlockMetadataWithNotify(i + 4, j + 36, k + 9, 4, 2);
		setBlock(world, i + 4, j + 36, k + 10, Blocks.leaves, 4);
		world.setBlockMetadataWithNotify(i + 4, j + 36, k + 10, 4, 2);
		setBlock(world, i + 4, j + 36, k + 11, Blocks.leaves, 4);
		world.setBlockMetadataWithNotify(i + 4, j + 36, k + 11, 4, 2);
		setBlock(world, i + 4, j + 36, k + 12, Blocks.leaves, 4);
		world.setBlockMetadataWithNotify(i + 4, j + 36, k + 12, 4, 2);
		setBlock(world, i + 4, j + 37, k + 6, Blocks.leaves, 4);
		world.setBlockMetadataWithNotify(i + 4, j + 37, k + 6, 4, 2);
		setBlock(world, i + 4, j + 37, k + 7, Blocks.leaves, 4);
		world.setBlockMetadataWithNotify(i + 4, j + 37, k + 7, 4, 2);
		setBlock(world, i + 4, j + 37, k + 8, Blocks.leaves, 4);
		world.setBlockMetadataWithNotify(i + 4, j + 37, k + 8, 4, 2);
		setBlock(world, i + 4, j + 37, k + 11, Blocks.leaves, 4);
		world.setBlockMetadataWithNotify(i + 4, j + 37, k + 11, 4, 2);
		setBlock(world, i + 4, j + 38, k + 7, Blocks.leaves, 4);
		world.setBlockMetadataWithNotify(i + 4, j + 38, k + 7, 4, 2);
		setBlock(world, i + 4, j + 39, k + 6, Blocks.leaves, 4);
		world.setBlockMetadataWithNotify(i + 4, j + 39, k + 6, 4, 2);
		setBlock(world, i + 4, j + 39, k + 7, Blocks.leaves, 4);
		world.setBlockMetadataWithNotify(i + 4, j + 39, k + 7, 4, 2);
		setBlock(world, i + 4, j + 39, k + 9, Blocks.leaves, 4);
		world.setBlockMetadataWithNotify(i + 4, j + 39, k + 9, 4, 2);
		setBlock(world, i + 4, j + 39, k + 10, Blocks.leaves, 4);
		world.setBlockMetadataWithNotify(i + 4, j + 39, k + 10, 4, 2);
		setBlock(world, i + 4, j + 40, k + 5, Blocks.leaves, 4);
		world.setBlockMetadataWithNotify(i + 4, j + 40, k + 5, 4, 2);
		setBlock(world, i + 4, j + 40, k + 6, Blocks.leaves, 4);
		world.setBlockMetadataWithNotify(i + 4, j + 40, k + 6, 4, 2);
		setBlock(world, i + 4, j + 40, k + 7, Blocks.leaves, 4);
		world.setBlockMetadataWithNotify(i + 4, j + 40, k + 7, 4, 2);
		setBlock(world, i + 4, j + 40, k + 8, Blocks.leaves, 4);
		world.setBlockMetadataWithNotify(i + 4, j + 40, k + 8, 4, 2);
		setBlock(world, i + 4, j + 40, k + 9, Blocks.leaves, 4);
		world.setBlockMetadataWithNotify(i + 4, j + 40, k + 9, 4, 2);
		setBlock(world, i + 4, j + 40, k + 10, Blocks.leaves, 4);
		world.setBlockMetadataWithNotify(i + 4, j + 40, k + 10, 4, 2);
		setBlock(world, i + 4, j + 40, k + 11, Blocks.leaves, 4);
		world.setBlockMetadataWithNotify(i + 4, j + 40, k + 11, 4, 2);
		setBlock(world, i + 4, j + 41, k + 6, Blocks.leaves, 4);
		world.setBlockMetadataWithNotify(i + 4, j + 41, k + 6, 4, 2);
		setBlock(world, i + 4, j + 41, k + 7, Blocks.leaves, 4);
		world.setBlockMetadataWithNotify(i + 4, j + 41, k + 7, 4, 2);
		setBlock(world, i + 4, j + 41, k + 8, Blocks.leaves, 4);
		world.setBlockMetadataWithNotify(i + 4, j + 41, k + 8, 4, 2);
		setBlock(world, i + 4, j + 41, k + 9, Blocks.leaves, 4);
		world.setBlockMetadataWithNotify(i + 4, j + 41, k + 9, 4, 2);
		setBlock(world, i + 4, j + 41, k + 10, Blocks.leaves, 4);
		world.setBlockMetadataWithNotify(i + 4, j + 41, k + 10, 4, 2);
		setBlock(world, i + 4, j + 42, k + 7, Blocks.leaves, 4);
		world.setBlockMetadataWithNotify(i + 4, j + 42, k + 7, 4, 2);
		setBlock(world, i + 4, j + 42, k + 8, Blocks.leaves, 4);
		world.setBlockMetadataWithNotify(i + 4, j + 42, k + 8, 4, 2);
		setBlock(world, i + 5, j + 15, k + 2, Blocks.leaves, 4);
		world.setBlockMetadataWithNotify(i + 5, j + 15, k + 2, 4, 2);
		setBlock(world, i + 5, j + 15, k + 3, Blocks.leaves, 4);
		world.setBlockMetadataWithNotify(i + 5, j + 15, k + 3, 4, 2);
		setBlock(world, i + 5, j + 15, k + 4, Blocks.leaves, 4);
		world.setBlockMetadataWithNotify(i + 5, j + 15, k + 4, 4, 2);
		setBlock(world, i + 5, j + 16, k + 3, Blocks.leaves, 4);
		world.setBlockMetadataWithNotify(i + 5, j + 16, k + 3, 4, 2);
		setBlock(world, i + 5, j + 18, k + 4, Blocks.leaves, 4);
		world.setBlockMetadataWithNotify(i + 5, j + 18, k + 4, 4, 2);
		setBlock(world, i + 5, j + 18, k + 5, Blocks.leaves, 4);
		world.setBlockMetadataWithNotify(i + 5, j + 18, k + 5, 4, 2);
		setBlock(world, i + 5, j + 18, k + 8, Blocks.leaves, 4);
		world.setBlockMetadataWithNotify(i + 5, j + 18, k + 8, 4, 2);
		setBlock(world, i + 5, j + 19, k + 3, Blocks.leaves, 4);
		world.setBlockMetadataWithNotify(i + 5, j + 19, k + 3, 4, 2);
		setBlock(world, i + 5, j + 19, k + 4, Blocks.leaves, 4);
		world.setBlockMetadataWithNotify(i + 5, j + 19, k + 4, 4, 2);
		setBlock(world, i + 5, j + 19, k + 6, Blocks.leaves, 4);
		world.setBlockMetadataWithNotify(i + 5, j + 19, k + 6, 4, 2);
		setBlock(world, i + 5, j + 19, k + 7, Blocks.leaves, 4);
		world.setBlockMetadataWithNotify(i + 5, j + 19, k + 7, 4, 2);
		setBlock(world, i + 5, j + 20, k + 4, Blocks.leaves, 4);
		world.setBlockMetadataWithNotify(i + 5, j + 20, k + 4, 4, 2);
		setBlock(world, i + 5, j + 20, k + 5, Blocks.leaves, 4);
		world.setBlockMetadataWithNotify(i + 5, j + 20, k + 5, 4, 2);
		setBlock(world, i + 5, j + 20, k + 6, Blocks.leaves, 4);
		world.setBlockMetadataWithNotify(i + 5, j + 20, k + 6, 4, 2);
		setBlock(world, i + 5, j + 20, k + 7, Blocks.leaves, 4);
		world.setBlockMetadataWithNotify(i + 5, j + 20, k + 7, 4, 2);
		setBlock(world, i + 5, j + 21, k + 0, Blocks.leaves, 4);
		world.setBlockMetadataWithNotify(i + 5, j + 21, k + 0, 4, 2);
		setBlock(world, i + 5, j + 21, k + 2, Blocks.leaves, 4);
		world.setBlockMetadataWithNotify(i + 5, j + 21, k + 2, 4, 2);
		setBlock(world, i + 5, j + 21, k + 3, Blocks.leaves, 4);
		world.setBlockMetadataWithNotify(i + 5, j + 21, k + 3, 4, 2);
		setBlock(world, i + 5, j + 21, k + 4, Blocks.leaves, 4);
		world.setBlockMetadataWithNotify(i + 5, j + 21, k + 4, 4, 2);
		setBlock(world, i + 5, j + 21, k + 5, Blocks.leaves, 4);
		world.setBlockMetadataWithNotify(i + 5, j + 21, k + 5, 4, 2);
		setBlock(world, i + 5, j + 22, k + 0, Blocks.leaves, 4);
		world.setBlockMetadataWithNotify(i + 5, j + 22, k + 0, 4, 2);
		setBlock(world, i + 5, j + 22, k + 1, Blocks.leaves, 4);
		world.setBlockMetadataWithNotify(i + 5, j + 22, k + 1, 4, 2);
		setBlock(world, i + 5, j + 22, k + 2, Blocks.leaves, 4);
		world.setBlockMetadataWithNotify(i + 5, j + 22, k + 2, 4, 2);
		setBlock(world, i + 5, j + 22, k + 3, Blocks.leaves, 4);
		world.setBlockMetadataWithNotify(i + 5, j + 22, k + 3, 4, 2);
		setBlock(world, i + 5, j + 22, k + 5, Blocks.leaves, 4);
		world.setBlockMetadataWithNotify(i + 5, j + 22, k + 5, 4, 2);
		setBlock(world, i + 5, j + 23, k + 0, Blocks.leaves, 4);
		world.setBlockMetadataWithNotify(i + 5, j + 23, k + 0, 4, 2);
		setBlock(world, i + 5, j + 23, k + 1, Blocks.leaves, 4);
		world.setBlockMetadataWithNotify(i + 5, j + 23, k + 1, 4, 2);
		setBlock(world, i + 5, j + 23, k + 2, Blocks.leaves, 4);
		world.setBlockMetadataWithNotify(i + 5, j + 23, k + 2, 4, 2);
		setBlock(world, i + 5, j + 24, k + 1, Blocks.leaves, 4);
		world.setBlockMetadataWithNotify(i + 5, j + 24, k + 1, 4, 2);
		setBlock(world, i + 5, j + 33, k + 10, Blocks.leaves, 4);
		world.setBlockMetadataWithNotify(i + 5, j + 33, k + 10, 4, 2);
		setBlock(world, i + 5, j + 33, k + 11, Blocks.leaves, 4);
		world.setBlockMetadataWithNotify(i + 5, j + 33, k + 11, 4, 2);
		setBlock(world, i + 5, j + 33, k + 12, Blocks.leaves, 4);
		world.setBlockMetadataWithNotify(i + 5, j + 33, k + 12, 4, 2);
		setBlock(world, i + 5, j + 33, k + 13, Blocks.leaves, 4);
		world.setBlockMetadataWithNotify(i + 5, j + 33, k + 13, 4, 2);
		setBlock(world, i + 5, j + 33, k + 14, Blocks.leaves, 4);
		world.setBlockMetadataWithNotify(i + 5, j + 33, k + 14, 4, 2);
		setBlock(world, i + 5, j + 34, k + 0, Blocks.leaves, 4);
		world.setBlockMetadataWithNotify(i + 5, j + 34, k + 0, 4, 2);
		setBlock(world, i + 5, j + 34, k + 1, Blocks.leaves, 4);
		world.setBlockMetadataWithNotify(i + 5, j + 34, k + 1, 4, 2);
		setBlock(world, i + 5, j + 34, k + 2, Blocks.leaves, 4);
		world.setBlockMetadataWithNotify(i + 5, j + 34, k + 2, 4, 2);
		setBlock(world, i + 5, j + 34, k + 3, Blocks.leaves, 4);
		world.setBlockMetadataWithNotify(i + 5, j + 34, k + 3, 4, 2);
		setBlock(world, i + 5, j + 34, k + 4, Blocks.leaves, 4);
		world.setBlockMetadataWithNotify(i + 5, j + 34, k + 4, 4, 2);
		setBlock(world, i + 5, j + 34, k + 5, Blocks.leaves, 4);
		world.setBlockMetadataWithNotify(i + 5, j + 34, k + 5, 4, 2);
		setBlock(world, i + 5, j + 34, k + 6, Blocks.leaves, 4);
		world.setBlockMetadataWithNotify(i + 5, j + 34, k + 6, 4, 2);
		setBlock(world, i + 5, j + 34, k + 7, Blocks.leaves, 4);
		world.setBlockMetadataWithNotify(i + 5, j + 34, k + 7, 4, 2);
		setBlock(world, i + 5, j + 34, k + 8, Blocks.leaves, 4);
		world.setBlockMetadataWithNotify(i + 5, j + 34, k + 8, 4, 2);
		setBlock(world, i + 5, j + 34, k + 11, Blocks.leaves, 4);
		world.setBlockMetadataWithNotify(i + 5, j + 34, k + 11, 4, 2);
		setBlock(world, i + 5, j + 34, k + 12, Blocks.leaves, 4);
		world.setBlockMetadataWithNotify(i + 5, j + 34, k + 12, 4, 2);
		setBlock(world, i + 5, j + 34, k + 13, Blocks.leaves, 4);
		world.setBlockMetadataWithNotify(i + 5, j + 34, k + 13, 4, 2);
		setBlock(world, i + 5, j + 35, k + 1, Blocks.leaves, 4);
		world.setBlockMetadataWithNotify(i + 5, j + 35, k + 1, 4, 2);
		setBlock(world, i + 5, j + 35, k + 2, Blocks.leaves, 4);
		world.setBlockMetadataWithNotify(i + 5, j + 35, k + 2, 4, 2);
		setBlock(world, i + 5, j + 35, k + 3, Blocks.leaves, 4);
		world.setBlockMetadataWithNotify(i + 5, j + 35, k + 3, 4, 2);
		setBlock(world, i + 5, j + 35, k + 5, Blocks.leaves, 4);
		world.setBlockMetadataWithNotify(i + 5, j + 35, k + 5, 4, 2);
		setBlock(world, i + 5, j + 35, k + 6, Blocks.leaves, 4);
		world.setBlockMetadataWithNotify(i + 5, j + 35, k + 6, 4, 2);
		setBlock(world, i + 5, j + 35, k + 7, Blocks.leaves, 4);
		world.setBlockMetadataWithNotify(i + 5, j + 35, k + 7, 4, 2);
		setBlock(world, i + 5, j + 35, k + 9, Blocks.leaves, 4);
		world.setBlockMetadataWithNotify(i + 5, j + 35, k + 9, 4, 2);
		setBlock(world, i + 5, j + 35, k + 10, Blocks.leaves, 4);
		world.setBlockMetadataWithNotify(i + 5, j + 35, k + 10, 4, 2);
		setBlock(world, i + 5, j + 35, k + 12, Blocks.leaves, 4);
		world.setBlockMetadataWithNotify(i + 5, j + 35, k + 12, 4, 2);
		setBlock(world, i + 5, j + 35, k + 13, Blocks.leaves, 4);
		world.setBlockMetadataWithNotify(i + 5, j + 35, k + 13, 4, 2);
		setBlock(world, i + 5, j + 36, k + 2, Blocks.leaves, 4);
		world.setBlockMetadataWithNotify(i + 5, j + 36, k + 2, 4, 2);
		setBlock(world, i + 5, j + 36, k + 5, Blocks.leaves, 4);
		world.setBlockMetadataWithNotify(i + 5, j + 36, k + 5, 4, 2);
		setBlock(world, i + 5, j + 36, k + 6, Blocks.leaves, 4);
		world.setBlockMetadataWithNotify(i + 5, j + 36, k + 6, 4, 2);
		setBlock(world, i + 5, j + 36, k + 8, Blocks.leaves, 4);
		world.setBlockMetadataWithNotify(i + 5, j + 36, k + 8, 4, 2);
		setBlock(world, i + 5, j + 36, k + 9, Blocks.leaves, 4);
		world.setBlockMetadataWithNotify(i + 5, j + 36, k + 9, 4, 2);
		setBlock(world, i + 5, j + 36, k + 10, Blocks.leaves, 4);
		world.setBlockMetadataWithNotify(i + 5, j + 36, k + 10, 4, 2);
		setBlock(world, i + 5, j + 36, k + 11, Blocks.leaves, 4);
		world.setBlockMetadataWithNotify(i + 5, j + 36, k + 11, 4, 2);
		setBlock(world, i + 5, j + 36, k + 12, Blocks.leaves, 4);
		world.setBlockMetadataWithNotify(i + 5, j + 36, k + 12, 4, 2);
		setBlock(world, i + 5, j + 36, k + 13, Blocks.leaves, 4);
		world.setBlockMetadataWithNotify(i + 5, j + 36, k + 13, 4, 2);
		setBlock(world, i + 5, j + 37, k + 4, Blocks.leaves, 4);
		world.setBlockMetadataWithNotify(i + 5, j + 37, k + 4, 4, 2);
		setBlock(world, i + 5, j + 37, k + 5, Blocks.leaves, 4);
		world.setBlockMetadataWithNotify(i + 5, j + 37, k + 5, 4, 2);
		setBlock(world, i + 5, j + 37, k + 6, Blocks.leaves, 4);
		world.setBlockMetadataWithNotify(i + 5, j + 37, k + 6, 4, 2);
		setBlock(world, i + 5, j + 37, k + 7, Blocks.leaves, 4);
		world.setBlockMetadataWithNotify(i + 5, j + 37, k + 7, 4, 2);
		setBlock(world, i + 5, j + 37, k + 8, Blocks.leaves, 4);
		world.setBlockMetadataWithNotify(i + 5, j + 37, k + 8, 4, 2);
		setBlock(world, i + 5, j + 37, k + 9, Blocks.leaves, 4);
		world.setBlockMetadataWithNotify(i + 5, j + 37, k + 9, 4, 2);
		setBlock(world, i + 5, j + 37, k + 10, Blocks.leaves, 4);
		world.setBlockMetadataWithNotify(i + 5, j + 37, k + 10, 4, 2);
		setBlock(world, i + 5, j + 37, k + 11, Blocks.leaves, 4);
		world.setBlockMetadataWithNotify(i + 5, j + 37, k + 11, 4, 2);
		setBlock(world, i + 5, j + 37, k + 12, Blocks.leaves, 4);
		world.setBlockMetadataWithNotify(i + 5, j + 37, k + 12, 4, 2);
		setBlock(world, i + 5, j + 38, k + 5, Blocks.leaves, 4);
		world.setBlockMetadataWithNotify(i + 5, j + 38, k + 5, 4, 2);
		setBlock(world, i + 5, j + 38, k + 6, Blocks.leaves, 4);
		world.setBlockMetadataWithNotify(i + 5, j + 38, k + 6, 4, 2);
		setBlock(world, i + 5, j + 38, k + 7, Blocks.leaves, 4);
		world.setBlockMetadataWithNotify(i + 5, j + 38, k + 7, 4, 2);
		setBlock(world, i + 5, j + 38, k + 8, Blocks.leaves, 4);
		world.setBlockMetadataWithNotify(i + 5, j + 38, k + 8, 4, 2);
		setBlock(world, i + 5, j + 38, k + 9, Blocks.leaves, 4);
		world.setBlockMetadataWithNotify(i + 5, j + 38, k + 9, 4, 2);
		setBlock(world, i + 5, j + 38, k + 10, Blocks.leaves, 4);
		world.setBlockMetadataWithNotify(i + 5, j + 38, k + 10, 4, 2);
		setBlock(world, i + 5, j + 38, k + 11, Blocks.leaves, 4);
		world.setBlockMetadataWithNotify(i + 5, j + 38, k + 11, 4, 2);
		setBlock(world, i + 5, j + 39, k + 5, Blocks.leaves, 4);
		world.setBlockMetadataWithNotify(i + 5, j + 39, k + 5, 4, 2);
		setBlock(world, i + 5, j + 39, k + 6, Blocks.leaves, 4);
		world.setBlockMetadataWithNotify(i + 5, j + 39, k + 6, 4, 2);
		setBlock(world, i + 5, j + 39, k + 7, Blocks.leaves, 4);
		world.setBlockMetadataWithNotify(i + 5, j + 39, k + 7, 4, 2);
		setBlock(world, i + 5, j + 39, k + 8, Blocks.leaves, 4);
		world.setBlockMetadataWithNotify(i + 5, j + 39, k + 8, 4, 2);
		setBlock(world, i + 5, j + 39, k + 9, Blocks.leaves, 4);
		world.setBlockMetadataWithNotify(i + 5, j + 39, k + 9, 4, 2);
		setBlock(world, i + 5, j + 39, k + 10, Blocks.leaves, 4);
		world.setBlockMetadataWithNotify(i + 5, j + 39, k + 10, 4, 2);
		setBlock(world, i + 5, j + 40, k + 5, Blocks.leaves, 4);
		world.setBlockMetadataWithNotify(i + 5, j + 40, k + 5, 4, 2);
		setBlock(world, i + 5, j + 40, k + 6, Blocks.leaves, 4);
		world.setBlockMetadataWithNotify(i + 5, j + 40, k + 6, 4, 2);
		setBlock(world, i + 5, j + 40, k + 8, Blocks.leaves, 4);
		world.setBlockMetadataWithNotify(i + 5, j + 40, k + 8, 4, 2);
		setBlock(world, i + 5, j + 40, k + 9, Blocks.leaves, 4);
		world.setBlockMetadataWithNotify(i + 5, j + 40, k + 9, 4, 2);
		setBlock(world, i + 5, j + 40, k + 10, Blocks.leaves, 4);
		world.setBlockMetadataWithNotify(i + 5, j + 40, k + 10, 4, 2);
		setBlock(world, i + 5, j + 40, k + 11, Blocks.leaves, 4);
		world.setBlockMetadataWithNotify(i + 5, j + 40, k + 11, 4, 2);
		setBlock(world, i + 5, j + 40, k + 12, Blocks.leaves, 4);
		world.setBlockMetadataWithNotify(i + 5, j + 40, k + 12, 4, 2);
		setBlock(world, i + 5, j + 41, k + 5, Blocks.leaves, 4);
		world.setBlockMetadataWithNotify(i + 5, j + 41, k + 5, 4, 2);
		setBlock(world, i + 5, j + 41, k + 6, Blocks.leaves, 4);
		world.setBlockMetadataWithNotify(i + 5, j + 41, k + 6, 4, 2);
		setBlock(world, i + 5, j + 41, k + 7, Blocks.leaves, 4);
		world.setBlockMetadataWithNotify(i + 5, j + 41, k + 7, 4, 2);
		setBlock(world, i + 5, j + 41, k + 8, Blocks.leaves, 4);
		world.setBlockMetadataWithNotify(i + 5, j + 41, k + 8, 4, 2);
		setBlock(world, i + 5, j + 41, k + 9, Blocks.leaves, 4);
		world.setBlockMetadataWithNotify(i + 5, j + 41, k + 9, 4, 2);
		setBlock(world, i + 5, j + 41, k + 10, Blocks.leaves, 4);
		world.setBlockMetadataWithNotify(i + 5, j + 41, k + 10, 4, 2);
		setBlock(world, i + 5, j + 41, k + 11, Blocks.leaves, 4);
		world.setBlockMetadataWithNotify(i + 5, j + 41, k + 11, 4, 2);
		setBlock(world, i + 5, j + 42, k + 6, Blocks.leaves, 4);
		world.setBlockMetadataWithNotify(i + 5, j + 42, k + 6, 4, 2);
		setBlock(world, i + 5, j + 42, k + 7, Blocks.leaves, 4);
		world.setBlockMetadataWithNotify(i + 5, j + 42, k + 7, 4, 2);
		setBlock(world, i + 5, j + 42, k + 8, Blocks.leaves, 4);
		world.setBlockMetadataWithNotify(i + 5, j + 42, k + 8, 4, 2);
		setBlock(world, i + 5, j + 42, k + 9, Blocks.leaves, 4);
		world.setBlockMetadataWithNotify(i + 5, j + 42, k + 9, 4, 2);
		setBlock(world, i + 5, j + 42, k + 10, Blocks.leaves, 4);
		world.setBlockMetadataWithNotify(i + 5, j + 42, k + 10, 4, 2);
		setBlock(world, i + 5, j + 43, k + 7, Blocks.leaves, 4);
		world.setBlockMetadataWithNotify(i + 5, j + 43, k + 7, 4, 2);
		setBlock(world, i + 5, j + 43, k + 8, Blocks.leaves, 4);
		world.setBlockMetadataWithNotify(i + 5, j + 43, k + 8, 4, 2);
		setBlock(world, i + 5, j + 44, k + 7, Blocks.leaves, 4);
		world.setBlockMetadataWithNotify(i + 5, j + 44, k + 7, 4, 2);
		setBlock(world, i + 5, j + 44, k + 8, Blocks.leaves, 4);
		world.setBlockMetadataWithNotify(i + 5, j + 44, k + 8, 4, 2);
		setBlock(world, i + 5, j + 44, k + 9, Blocks.leaves, 4);
		world.setBlockMetadataWithNotify(i + 5, j + 44, k + 9, 4, 2);
		setBlock(world, i + 5, j + 45, k + 7, Blocks.leaves, 4);
		world.setBlockMetadataWithNotify(i + 5, j + 45, k + 7, 4, 2);
		setBlock(world, i + 5, j + 45, k + 8, Blocks.leaves, 4);
		world.setBlockMetadataWithNotify(i + 5, j + 45, k + 8, 4, 2);
		setBlock(world, i + 5, j + 45, k + 9, Blocks.leaves, 4);
		world.setBlockMetadataWithNotify(i + 5, j + 45, k + 9, 4, 2);
		setBlock(world, i + 5, j + 46, k + 8, Blocks.leaves, 4);
		world.setBlockMetadataWithNotify(i + 5, j + 46, k + 8, 4, 2);
		setBlock(world, i + 6, j + 15, k + 1, Blocks.leaves, 4);
		world.setBlockMetadataWithNotify(i + 6, j + 15, k + 1, 4, 2);
		setBlock(world, i + 6, j + 15, k + 2, Blocks.leaves, 4);
		world.setBlockMetadataWithNotify(i + 6, j + 15, k + 2, 4, 2);
		setBlock(world, i + 6, j + 15, k + 3, Blocks.leaves, 4);
		world.setBlockMetadataWithNotify(i + 6, j + 15, k + 3, 4, 2);
		setBlock(world, i + 6, j + 15, k + 4, Blocks.leaves, 4);
		world.setBlockMetadataWithNotify(i + 6, j + 15, k + 4, 4, 2);
		setBlock(world, i + 6, j + 15, k + 5, Blocks.leaves, 4);
		world.setBlockMetadataWithNotify(i + 6, j + 15, k + 5, 4, 2);
		setBlock(world, i + 6, j + 16, k + 2, Blocks.leaves, 4);
		world.setBlockMetadataWithNotify(i + 6, j + 16, k + 2, 4, 2);
		setBlock(world, i + 6, j + 16, k + 3, Blocks.leaves, 4);
		world.setBlockMetadataWithNotify(i + 6, j + 16, k + 3, 4, 2);
		setBlock(world, i + 6, j + 16, k + 4, Blocks.leaves, 4);
		world.setBlockMetadataWithNotify(i + 6, j + 16, k + 4, 4, 2);
		setBlock(world, i + 6, j + 17, k + 3, Blocks.leaves, 4);
		world.setBlockMetadataWithNotify(i + 6, j + 17, k + 3, 4, 2);
		setBlock(world, i + 6, j + 18, k + 5, Blocks.leaves, 4);
		world.setBlockMetadataWithNotify(i + 6, j + 18, k + 5, 4, 2);
		setBlock(world, i + 6, j + 18, k + 6, Blocks.leaves, 4);
		world.setBlockMetadataWithNotify(i + 6, j + 18, k + 6, 4, 2);
		setBlock(world, i + 6, j + 19, k + 3, Blocks.leaves, 4);
		world.setBlockMetadataWithNotify(i + 6, j + 19, k + 3, 4, 2);
		setBlock(world, i + 6, j + 19, k + 4, Blocks.leaves, 4);
		world.setBlockMetadataWithNotify(i + 6, j + 19, k + 4, 4, 2);
		setBlock(world, i + 6, j + 19, k + 5, Blocks.leaves, 4);
		world.setBlockMetadataWithNotify(i + 6, j + 19, k + 5, 4, 2);
		setBlock(world, i + 6, j + 19, k + 6, Blocks.leaves, 4);
		world.setBlockMetadataWithNotify(i + 6, j + 19, k + 6, 4, 2);
		setBlock(world, i + 6, j + 19, k + 7, Blocks.leaves, 4);
		world.setBlockMetadataWithNotify(i + 6, j + 19, k + 7, 4, 2);
		setBlock(world, i + 6, j + 21, k + 0, Blocks.leaves, 4);
		world.setBlockMetadataWithNotify(i + 6, j + 21, k + 0, 4, 2);
		setBlock(world, i + 6, j + 21, k + 1, Blocks.leaves, 4);
		world.setBlockMetadataWithNotify(i + 6, j + 21, k + 1, 4, 2);
		setBlock(world, i + 6, j + 21, k + 2, Blocks.leaves, 4);
		world.setBlockMetadataWithNotify(i + 6, j + 21, k + 2, 4, 2);
		setBlock(world, i + 6, j + 21, k + 3, Blocks.leaves, 4);
		world.setBlockMetadataWithNotify(i + 6, j + 21, k + 3, 4, 2);
		setBlock(world, i + 6, j + 21, k + 5, Blocks.leaves, 4);
		world.setBlockMetadataWithNotify(i + 6, j + 21, k + 5, 4, 2);
		setBlock(world, i + 6, j + 22, k + 0, Blocks.leaves, 4);
		world.setBlockMetadataWithNotify(i + 6, j + 22, k + 0, 4, 2);
		setBlock(world, i + 6, j + 22, k + 1, Blocks.leaves, 4);
		world.setBlockMetadataWithNotify(i + 6, j + 22, k + 1, 4, 2);
		setBlock(world, i + 6, j + 22, k + 2, Blocks.leaves, 4);
		world.setBlockMetadataWithNotify(i + 6, j + 22, k + 2, 4, 2);
		setBlock(world, i + 6, j + 23, k + 1, Blocks.leaves, 4);
		world.setBlockMetadataWithNotify(i + 6, j + 23, k + 1, 4, 2);
		setBlock(world, i + 6, j + 23, k + 5, Blocks.leaves, 4);
		world.setBlockMetadataWithNotify(i + 6, j + 23, k + 5, 4, 2);
		setBlock(world, i + 6, j + 23, k + 6, Blocks.leaves, 4);
		world.setBlockMetadataWithNotify(i + 6, j + 23, k + 6, 4, 2);
		setBlock(world, i + 6, j + 23, k + 7, Blocks.leaves, 4);
		world.setBlockMetadataWithNotify(i + 6, j + 23, k + 7, 4, 2);
		setBlock(world, i + 6, j + 24, k + 6, Blocks.leaves, 4);
		world.setBlockMetadataWithNotify(i + 6, j + 24, k + 6, 4, 2);
		setBlock(world, i + 6, j + 31, k + 10, Blocks.leaves, 4);
		world.setBlockMetadataWithNotify(i + 6, j + 31, k + 10, 4, 2);
		setBlock(world, i + 6, j + 31, k + 11, Blocks.leaves, 4);
		world.setBlockMetadataWithNotify(i + 6, j + 31, k + 11, 4, 2);
		setBlock(world, i + 6, j + 31, k + 12, Blocks.leaves, 4);
		world.setBlockMetadataWithNotify(i + 6, j + 31, k + 12, 4, 2);
		setBlock(world, i + 6, j + 32, k + 10, Blocks.leaves, 4);
		world.setBlockMetadataWithNotify(i + 6, j + 32, k + 10, 4, 2);
		setBlock(world, i + 6, j + 32, k + 11, Blocks.leaves, 4);
		world.setBlockMetadataWithNotify(i + 6, j + 32, k + 11, 4, 2);
		setBlock(world, i + 6, j + 32, k + 12, Blocks.leaves, 4);
		world.setBlockMetadataWithNotify(i + 6, j + 32, k + 12, 4, 2);
		setBlock(world, i + 6, j + 33, k + 10, Blocks.leaves, 4);
		world.setBlockMetadataWithNotify(i + 6, j + 33, k + 10, 4, 2);
		setBlock(world, i + 6, j + 33, k + 11, Blocks.leaves, 4);
		world.setBlockMetadataWithNotify(i + 6, j + 33, k + 11, 4, 2);
		setBlock(world, i + 6, j + 33, k + 13, Blocks.leaves, 4);
		world.setBlockMetadataWithNotify(i + 6, j + 33, k + 13, 4, 2);
		setBlock(world, i + 6, j + 33, k + 14, Blocks.leaves, 4);
		world.setBlockMetadataWithNotify(i + 6, j + 33, k + 14, 4, 2);
		setBlock(world, i + 6, j + 34, k + 0, Blocks.leaves, 4);
		world.setBlockMetadataWithNotify(i + 6, j + 34, k + 0, 4, 2);
		setBlock(world, i + 6, j + 34, k + 1, Blocks.leaves, 4);
		world.setBlockMetadataWithNotify(i + 6, j + 34, k + 1, 4, 2);
		setBlock(world, i + 6, j + 34, k + 3, Blocks.leaves, 4);
		world.setBlockMetadataWithNotify(i + 6, j + 34, k + 3, 4, 2);
		setBlock(world, i + 6, j + 34, k + 4, Blocks.leaves, 4);
		world.setBlockMetadataWithNotify(i + 6, j + 34, k + 4, 4, 2);
		setBlock(world, i + 6, j + 34, k + 5, Blocks.leaves, 4);
		world.setBlockMetadataWithNotify(i + 6, j + 34, k + 5, 4, 2);
		setBlock(world, i + 6, j + 34, k + 7, Blocks.leaves, 4);
		world.setBlockMetadataWithNotify(i + 6, j + 34, k + 7, 4, 2);
		setBlock(world, i + 6, j + 34, k + 8, Blocks.leaves, 4);
		world.setBlockMetadataWithNotify(i + 6, j + 34, k + 8, 4, 2);
		setBlock(world, i + 6, j + 34, k + 11, Blocks.leaves, 4);
		world.setBlockMetadataWithNotify(i + 6, j + 34, k + 11, 4, 2);
		setBlock(world, i + 6, j + 34, k + 12, Blocks.leaves, 4);
		world.setBlockMetadataWithNotify(i + 6, j + 34, k + 12, 4, 2);
		setBlock(world, i + 6, j + 34, k + 13, Blocks.leaves, 4);
		world.setBlockMetadataWithNotify(i + 6, j + 34, k + 13, 4, 2);
		setBlock(world, i + 6, j + 34, k + 14, Blocks.leaves, 4);
		world.setBlockMetadataWithNotify(i + 6, j + 34, k + 14, 4, 2);
		setBlock(world, i + 6, j + 35, k + 0, Blocks.leaves, 4);
		world.setBlockMetadataWithNotify(i + 6, j + 35, k + 0, 4, 2);
		setBlock(world, i + 6, j + 35, k + 1, Blocks.leaves, 4);
		world.setBlockMetadataWithNotify(i + 6, j + 35, k + 1, 4, 2);
		setBlock(world, i + 6, j + 35, k + 2, Blocks.leaves, 4);
		world.setBlockMetadataWithNotify(i + 6, j + 35, k + 2, 4, 2);
		setBlock(world, i + 6, j + 35, k + 3, Blocks.leaves, 4);
		world.setBlockMetadataWithNotify(i + 6, j + 35, k + 3, 4, 2);
		setBlock(world, i + 6, j + 35, k + 4, Blocks.leaves, 4);
		world.setBlockMetadataWithNotify(i + 6, j + 35, k + 4, 4, 2);
		setBlock(world, i + 6, j + 35, k + 5, Blocks.leaves, 4);
		world.setBlockMetadataWithNotify(i + 6, j + 35, k + 5, 4, 2);
		setBlock(world, i + 6, j + 35, k + 6, Blocks.leaves, 4);
		world.setBlockMetadataWithNotify(i + 6, j + 35, k + 6, 4, 2);
		setBlock(world, i + 6, j + 35, k + 7, Blocks.leaves, 4);
		world.setBlockMetadataWithNotify(i + 6, j + 35, k + 7, 4, 2);
		setBlock(world, i + 6, j + 35, k + 8, Blocks.leaves, 4);
		world.setBlockMetadataWithNotify(i + 6, j + 35, k + 8, 4, 2);
		setBlock(world, i + 6, j + 35, k + 9, Blocks.leaves, 4);
		world.setBlockMetadataWithNotify(i + 6, j + 35, k + 9, 4, 2);
		setBlock(world, i + 6, j + 35, k + 10, Blocks.leaves, 4);
		world.setBlockMetadataWithNotify(i + 6, j + 35, k + 10, 4, 2);
		setBlock(world, i + 6, j + 35, k + 11, Blocks.leaves, 4);
		world.setBlockMetadataWithNotify(i + 6, j + 35, k + 11, 4, 2);
		setBlock(world, i + 6, j + 35, k + 12, Blocks.leaves, 4);
		world.setBlockMetadataWithNotify(i + 6, j + 35, k + 12, 4, 2);
		setBlock(world, i + 6, j + 35, k + 13, Blocks.leaves, 4);
		world.setBlockMetadataWithNotify(i + 6, j + 35, k + 13, 4, 2);
		setBlock(world, i + 6, j + 36, k + 1, Blocks.leaves, 4);
		world.setBlockMetadataWithNotify(i + 6, j + 36, k + 1, 4, 2);
		setBlock(world, i + 6, j + 36, k + 2, Blocks.leaves, 4);
		world.setBlockMetadataWithNotify(i + 6, j + 36, k + 2, 4, 2);
		setBlock(world, i + 6, j + 36, k + 3, Blocks.leaves, 4);
		world.setBlockMetadataWithNotify(i + 6, j + 36, k + 3, 4, 2);
		setBlock(world, i + 6, j + 36, k + 5, Blocks.leaves, 4);
		world.setBlockMetadataWithNotify(i + 6, j + 36, k + 5, 4, 2);
		setBlock(world, i + 6, j + 36, k + 6, Blocks.leaves, 4);
		world.setBlockMetadataWithNotify(i + 6, j + 36, k + 6, 4, 2);
		setBlock(world, i + 6, j + 36, k + 7, Blocks.leaves, 4);
		world.setBlockMetadataWithNotify(i + 6, j + 36, k + 7, 4, 2);
		setBlock(world, i + 6, j + 36, k + 8, Blocks.leaves, 4);
		world.setBlockMetadataWithNotify(i + 6, j + 36, k + 8, 4, 2);
		setBlock(world, i + 6, j + 36, k + 9, Blocks.leaves, 4);
		world.setBlockMetadataWithNotify(i + 6, j + 36, k + 9, 4, 2);
		setBlock(world, i + 6, j + 36, k + 10, Blocks.leaves, 4);
		world.setBlockMetadataWithNotify(i + 6, j + 36, k + 10, 4, 2);
		setBlock(world, i + 6, j + 36, k + 11, Blocks.leaves, 4);
		world.setBlockMetadataWithNotify(i + 6, j + 36, k + 11, 4, 2);
		setBlock(world, i + 6, j + 36, k + 12, Blocks.leaves, 4);
		world.setBlockMetadataWithNotify(i + 6, j + 36, k + 12, 4, 2);
		setBlock(world, i + 6, j + 37, k + 2, Blocks.leaves, 4);
		world.setBlockMetadataWithNotify(i + 6, j + 37, k + 2, 4, 2);
		setBlock(world, i + 6, j + 37, k + 3, Blocks.leaves, 4);
		world.setBlockMetadataWithNotify(i + 6, j + 37, k + 3, 4, 2);
		setBlock(world, i + 6, j + 37, k + 4, Blocks.leaves, 4);
		world.setBlockMetadataWithNotify(i + 6, j + 37, k + 4, 4, 2);
		setBlock(world, i + 6, j + 37, k + 5, Blocks.leaves, 4);
		world.setBlockMetadataWithNotify(i + 6, j + 37, k + 5, 4, 2);
		setBlock(world, i + 6, j + 37, k + 6, Blocks.leaves, 4);
		world.setBlockMetadataWithNotify(i + 6, j + 37, k + 6, 4, 2);
		setBlock(world, i + 6, j + 37, k + 7, Blocks.leaves, 4);
		world.setBlockMetadataWithNotify(i + 6, j + 37, k + 7, 4, 2);
		setBlock(world, i + 6, j + 37, k + 8, Blocks.leaves, 4);
		world.setBlockMetadataWithNotify(i + 6, j + 37, k + 8, 4, 2);
		setBlock(world, i + 6, j + 37, k + 11, Blocks.leaves, 4);
		world.setBlockMetadataWithNotify(i + 6, j + 37, k + 11, 4, 2);
		setBlock(world, i + 6, j + 38, k + 3, Blocks.leaves, 4);
		world.setBlockMetadataWithNotify(i + 6, j + 38, k + 3, 4, 2);
		setBlock(world, i + 6, j + 38, k + 4, Blocks.leaves, 4);
		world.setBlockMetadataWithNotify(i + 6, j + 38, k + 4, 4, 2);
		setBlock(world, i + 6, j + 38, k + 5, Blocks.leaves, 4);
		world.setBlockMetadataWithNotify(i + 6, j + 38, k + 5, 4, 2);
		setBlock(world, i + 6, j + 38, k + 6, Blocks.leaves, 4);
		world.setBlockMetadataWithNotify(i + 6, j + 38, k + 6, 4, 2);
		setBlock(world, i + 6, j + 38, k + 7, Blocks.leaves, 4);
		world.setBlockMetadataWithNotify(i + 6, j + 38, k + 7, 4, 2);
		setBlock(world, i + 6, j + 38, k + 8, Blocks.leaves, 4);
		world.setBlockMetadataWithNotify(i + 6, j + 38, k + 8, 4, 2);
		setBlock(world, i + 6, j + 38, k + 9, Blocks.leaves, 4);
		world.setBlockMetadataWithNotify(i + 6, j + 38, k + 9, 4, 2);
		setBlock(world, i + 6, j + 38, k + 10, Blocks.leaves, 4);
		world.setBlockMetadataWithNotify(i + 6, j + 38, k + 10, 4, 2);
		setBlock(world, i + 6, j + 38, k + 11, Blocks.leaves, 4);
		world.setBlockMetadataWithNotify(i + 6, j + 38, k + 11, 4, 2);
		setBlock(world, i + 6, j + 38, k + 12, Blocks.leaves, 4);
		world.setBlockMetadataWithNotify(i + 6, j + 38, k + 12, 4, 2);
		setBlock(world, i + 6, j + 39, k + 3, Blocks.leaves, 4);
		world.setBlockMetadataWithNotify(i + 6, j + 39, k + 3, 4, 2);
		setBlock(world, i + 6, j + 39, k + 4, Blocks.leaves, 4);
		world.setBlockMetadataWithNotify(i + 6, j + 39, k + 4, 4, 2);
		setBlock(world, i + 6, j + 39, k + 5, Blocks.leaves, 4);
		world.setBlockMetadataWithNotify(i + 6, j + 39, k + 5, 4, 2);
		setBlock(world, i + 6, j + 39, k + 6, Blocks.leaves, 4);
		world.setBlockMetadataWithNotify(i + 6, j + 39, k + 6, 4, 2);
		setBlock(world, i + 6, j + 39, k + 9, Blocks.leaves, 4);
		world.setBlockMetadataWithNotify(i + 6, j + 39, k + 9, 4, 2);
		setBlock(world, i + 6, j + 39, k + 10, Blocks.leaves, 4);
		world.setBlockMetadataWithNotify(i + 6, j + 39, k + 10, 4, 2);
		setBlock(world, i + 6, j + 39, k + 11, Blocks.leaves, 4);
		world.setBlockMetadataWithNotify(i + 6, j + 39, k + 11, 4, 2);
		setBlock(world, i + 6, j + 40, k + 4, Blocks.leaves, 4);
		world.setBlockMetadataWithNotify(i + 6, j + 40, k + 4, 4, 2);
		setBlock(world, i + 6, j + 40, k + 5, Blocks.leaves, 4);
		world.setBlockMetadataWithNotify(i + 6, j + 40, k + 5, 4, 2);
		setBlock(world, i + 6, j + 40, k + 6, Blocks.leaves, 4);
		world.setBlockMetadataWithNotify(i + 6, j + 40, k + 6, 4, 2);
		setBlock(world, i + 6, j + 40, k + 7, Blocks.leaves, 4);
		world.setBlockMetadataWithNotify(i + 6, j + 40, k + 7, 4, 2);
		setBlock(world, i + 6, j + 40, k + 8, Blocks.leaves, 4);
		world.setBlockMetadataWithNotify(i + 6, j + 40, k + 8, 4, 2);
		setBlock(world, i + 6, j + 40, k + 9, Blocks.leaves, 4);
		world.setBlockMetadataWithNotify(i + 6, j + 40, k + 9, 4, 2);
		setBlock(world, i + 6, j + 40, k + 11, Blocks.leaves, 4);
		world.setBlockMetadataWithNotify(i + 6, j + 40, k + 11, 4, 2);
		setBlock(world, i + 6, j + 40, k + 12, Blocks.leaves, 4);
		world.setBlockMetadataWithNotify(i + 6, j + 40, k + 12, 4, 2);
		setBlock(world, i + 6, j + 41, k + 5, Blocks.leaves, 4);
		world.setBlockMetadataWithNotify(i + 6, j + 41, k + 5, 4, 2);
		setBlock(world, i + 6, j + 41, k + 6, Blocks.leaves, 4);
		world.setBlockMetadataWithNotify(i + 6, j + 41, k + 6, 4, 2);
		setBlock(world, i + 6, j + 41, k + 7, Blocks.leaves, 4);
		world.setBlockMetadataWithNotify(i + 6, j + 41, k + 7, 4, 2);
		setBlock(world, i + 6, j + 41, k + 8, Blocks.leaves, 4);
		world.setBlockMetadataWithNotify(i + 6, j + 41, k + 8, 4, 2);
		setBlock(world, i + 6, j + 41, k + 9, Blocks.leaves, 4);
		world.setBlockMetadataWithNotify(i + 6, j + 41, k + 9, 4, 2);
		setBlock(world, i + 6, j + 41, k + 10, Blocks.leaves, 4);
		world.setBlockMetadataWithNotify(i + 6, j + 41, k + 10, 4, 2);
		setBlock(world, i + 6, j + 41, k + 11, Blocks.leaves, 4);
		world.setBlockMetadataWithNotify(i + 6, j + 41, k + 11, 4, 2);
		setBlock(world, i + 6, j + 41, k + 12, Blocks.leaves, 4);
		world.setBlockMetadataWithNotify(i + 6, j + 41, k + 12, 4, 2);
		setBlock(world, i + 6, j + 42, k + 6, Blocks.leaves, 4);
		world.setBlockMetadataWithNotify(i + 6, j + 42, k + 6, 4, 2);
		setBlock(world, i + 6, j + 42, k + 7, Blocks.leaves, 4);
		world.setBlockMetadataWithNotify(i + 6, j + 42, k + 7, 4, 2);
		setBlock(world, i + 6, j + 42, k + 8, Blocks.leaves, 4);
		world.setBlockMetadataWithNotify(i + 6, j + 42, k + 8, 4, 2);
		setBlock(world, i + 6, j + 42, k + 9, Blocks.leaves, 4);
		world.setBlockMetadataWithNotify(i + 6, j + 42, k + 9, 4, 2);
		setBlock(world, i + 6, j + 42, k + 10, Blocks.leaves, 4);
		world.setBlockMetadataWithNotify(i + 6, j + 42, k + 10, 4, 2);
		setBlock(world, i + 6, j + 42, k + 11, Blocks.leaves, 4);
		world.setBlockMetadataWithNotify(i + 6, j + 42, k + 11, 4, 2);
		setBlock(world, i + 6, j + 43, k + 6, Blocks.leaves, 4);
		world.setBlockMetadataWithNotify(i + 6, j + 43, k + 6, 4, 2);
		setBlock(world, i + 6, j + 43, k + 7, Blocks.leaves, 4);
		world.setBlockMetadataWithNotify(i + 6, j + 43, k + 7, 4, 2);
		setBlock(world, i + 6, j + 43, k + 8, Blocks.leaves, 4);
		world.setBlockMetadataWithNotify(i + 6, j + 43, k + 8, 4, 2);
		setBlock(world, i + 6, j + 43, k + 9, Blocks.leaves, 4);
		world.setBlockMetadataWithNotify(i + 6, j + 43, k + 9, 4, 2);
		setBlock(world, i + 6, j + 43, k + 10, Blocks.leaves, 4);
		world.setBlockMetadataWithNotify(i + 6, j + 43, k + 10, 4, 2);
		setBlock(world, i + 6, j + 44, k + 6, Blocks.leaves, 4);
		world.setBlockMetadataWithNotify(i + 6, j + 44, k + 6, 4, 2);
		setBlock(world, i + 6, j + 44, k + 7, Blocks.leaves, 4);
		world.setBlockMetadataWithNotify(i + 6, j + 44, k + 7, 4, 2);
		setBlock(world, i + 6, j + 44, k + 8, Blocks.leaves, 4);
		world.setBlockMetadataWithNotify(i + 6, j + 44, k + 8, 4, 2);
		setBlock(world, i + 6, j + 44, k + 9, Blocks.leaves, 4);
		world.setBlockMetadataWithNotify(i + 6, j + 44, k + 9, 4, 2);
		setBlock(world, i + 6, j + 44, k + 10, Blocks.leaves, 4);
		world.setBlockMetadataWithNotify(i + 6, j + 44, k + 10, 4, 2);
		setBlock(world, i + 6, j + 45, k + 6, Blocks.leaves, 4);
		world.setBlockMetadataWithNotify(i + 6, j + 45, k + 6, 4, 2);
		setBlock(world, i + 6, j + 45, k + 7, Blocks.leaves, 4);
		world.setBlockMetadataWithNotify(i + 6, j + 45, k + 7, 4, 2);
		setBlock(world, i + 6, j + 45, k + 8, Blocks.leaves, 4);
		world.setBlockMetadataWithNotify(i + 6, j + 45, k + 8, 4, 2);
		setBlock(world, i + 6, j + 45, k + 9, Blocks.leaves, 4);
		world.setBlockMetadataWithNotify(i + 6, j + 45, k + 9, 4, 2);
		setBlock(world, i + 6, j + 45, k + 10, Blocks.leaves, 4);
		world.setBlockMetadataWithNotify(i + 6, j + 45, k + 10, 4, 2);
		setBlock(world, i + 6, j + 46, k + 7, Blocks.leaves, 4);
		world.setBlockMetadataWithNotify(i + 6, j + 46, k + 7, 4, 2);
		setBlock(world, i + 6, j + 46, k + 8, Blocks.leaves, 4);
		world.setBlockMetadataWithNotify(i + 6, j + 46, k + 8, 4, 2);
		setBlock(world, i + 6, j + 46, k + 9, Blocks.leaves, 4);
		world.setBlockMetadataWithNotify(i + 6, j + 46, k + 9, 4, 2);
		setBlock(world, i + 6, j + 47, k + 8, Blocks.leaves, 4);
		world.setBlockMetadataWithNotify(i + 6, j + 47, k + 8, 4, 2);
		setBlock(world, i + 7, j + 15, k + 1, Blocks.leaves, 4);
		world.setBlockMetadataWithNotify(i + 7, j + 15, k + 1, 4, 2);
		setBlock(world, i + 7, j + 15, k + 2, Blocks.leaves, 4);
		world.setBlockMetadataWithNotify(i + 7, j + 15, k + 2, 4, 2);
		setBlock(world, i + 7, j + 15, k + 4, Blocks.leaves, 4);
		world.setBlockMetadataWithNotify(i + 7, j + 15, k + 4, 4, 2);
		setBlock(world, i + 7, j + 15, k + 5, Blocks.leaves, 4);
		world.setBlockMetadataWithNotify(i + 7, j + 15, k + 5, 4, 2);
		setBlock(world, i + 7, j + 16, k + 1, Blocks.leaves, 4);
		world.setBlockMetadataWithNotify(i + 7, j + 16, k + 1, 4, 2);
		setBlock(world, i + 7, j + 16, k + 2, Blocks.leaves, 4);
		world.setBlockMetadataWithNotify(i + 7, j + 16, k + 2, 4, 2);
		setBlock(world, i + 7, j + 16, k + 3, Blocks.leaves, 4);
		world.setBlockMetadataWithNotify(i + 7, j + 16, k + 3, 4, 2);
		setBlock(world, i + 7, j + 16, k + 4, Blocks.leaves, 4);
		world.setBlockMetadataWithNotify(i + 7, j + 16, k + 4, 4, 2);
		setBlock(world, i + 7, j + 16, k + 5, Blocks.leaves, 4);
		world.setBlockMetadataWithNotify(i + 7, j + 16, k + 5, 4, 2);
		setBlock(world, i + 7, j + 17, k + 2, Blocks.leaves, 4);
		world.setBlockMetadataWithNotify(i + 7, j + 17, k + 2, 4, 2);
		setBlock(world, i + 7, j + 17, k + 3, Blocks.leaves, 4);
		world.setBlockMetadataWithNotify(i + 7, j + 17, k + 3, 4, 2);
		setBlock(world, i + 7, j + 17, k + 4, Blocks.leaves, 4);
		world.setBlockMetadataWithNotify(i + 7, j + 17, k + 4, 4, 2);
		setBlock(world, i + 7, j + 18, k + 3, Blocks.leaves, 4);
		world.setBlockMetadataWithNotify(i + 7, j + 18, k + 3, 4, 2);
		setBlock(world, i + 7, j + 19, k + 4, Blocks.leaves, 4);
		world.setBlockMetadataWithNotify(i + 7, j + 19, k + 4, 4, 2);
		setBlock(world, i + 7, j + 19, k + 5, Blocks.leaves, 4);
		world.setBlockMetadataWithNotify(i + 7, j + 19, k + 5, 4, 2);
		setBlock(world, i + 7, j + 19, k + 6, Blocks.leaves, 4);
		world.setBlockMetadataWithNotify(i + 7, j + 19, k + 6, 4, 2);
		setBlock(world, i + 7, j + 20, k + 5, Blocks.leaves, 4);
		world.setBlockMetadataWithNotify(i + 7, j + 20, k + 5, 4, 2);
		setBlock(world, i + 7, j + 21, k + 0, Blocks.leaves, 4);
		world.setBlockMetadataWithNotify(i + 7, j + 21, k + 0, 4, 2);
		setBlock(world, i + 7, j + 21, k + 1, Blocks.leaves, 4);
		world.setBlockMetadataWithNotify(i + 7, j + 21, k + 1, 4, 2);
		setBlock(world, i + 7, j + 21, k + 2, Blocks.leaves, 4);
		world.setBlockMetadataWithNotify(i + 7, j + 21, k + 2, 4, 2);
		setBlock(world, i + 7, j + 22, k + 1, Blocks.leaves, 4);
		world.setBlockMetadataWithNotify(i + 7, j + 22, k + 1, 4, 2);
		setBlock(world, i + 7, j + 23, k + 4, Blocks.leaves, 4);
		world.setBlockMetadataWithNotify(i + 7, j + 23, k + 4, 4, 2);
		setBlock(world, i + 7, j + 23, k + 5, Blocks.leaves, 4);
		world.setBlockMetadataWithNotify(i + 7, j + 23, k + 5, 4, 2);
		setBlock(world, i + 7, j + 23, k + 6, Blocks.leaves, 4);
		world.setBlockMetadataWithNotify(i + 7, j + 23, k + 6, 4, 2);
		setBlock(world, i + 7, j + 23, k + 7, Blocks.leaves, 4);
		world.setBlockMetadataWithNotify(i + 7, j + 23, k + 7, 4, 2);
		setBlock(world, i + 7, j + 23, k + 8, Blocks.leaves, 4);
		world.setBlockMetadataWithNotify(i + 7, j + 23, k + 8, 4, 2);
		setBlock(world, i + 7, j + 24, k + 5, Blocks.leaves, 4);
		world.setBlockMetadataWithNotify(i + 7, j + 24, k + 5, 4, 2);
		setBlock(world, i + 7, j + 24, k + 6, Blocks.leaves, 4);
		world.setBlockMetadataWithNotify(i + 7, j + 24, k + 6, 4, 2);
		setBlock(world, i + 7, j + 24, k + 7, Blocks.leaves, 4);
		world.setBlockMetadataWithNotify(i + 7, j + 24, k + 7, 4, 2);
		setBlock(world, i + 7, j + 25, k + 6, Blocks.leaves, 4);
		world.setBlockMetadataWithNotify(i + 7, j + 25, k + 6, 4, 2);
		setBlock(world, i + 7, j + 31, k + 9, Blocks.leaves, 4);
		world.setBlockMetadataWithNotify(i + 7, j + 31, k + 9, 4, 2);
		setBlock(world, i + 7, j + 31, k + 10, Blocks.leaves, 4);
		world.setBlockMetadataWithNotify(i + 7, j + 31, k + 10, 4, 2);
		setBlock(world, i + 7, j + 31, k + 11, Blocks.leaves, 4);
		world.setBlockMetadataWithNotify(i + 7, j + 31, k + 11, 4, 2);
		setBlock(world, i + 7, j + 31, k + 12, Blocks.leaves, 4);
		world.setBlockMetadataWithNotify(i + 7, j + 31, k + 12, 4, 2);
		setBlock(world, i + 7, j + 31, k + 13, Blocks.leaves, 4);
		world.setBlockMetadataWithNotify(i + 7, j + 31, k + 13, 4, 2);
		setBlock(world, i + 7, j + 32, k + 9, Blocks.leaves, 4);
		world.setBlockMetadataWithNotify(i + 7, j + 32, k + 9, 4, 2);
		setBlock(world, i + 7, j + 32, k + 10, Blocks.leaves, 4);
		world.setBlockMetadataWithNotify(i + 7, j + 32, k + 10, 4, 2);

		generate2(world, rand, i, j, k);
		return true;
	}

	public boolean generate2(World world, Random rand, int i, int j, int k)
	{
		setBlock(world, i + 7, j + 32, k + 11, Blocks.leaves, 4);
		world.setBlockMetadataWithNotify(i + 7, j + 32, k + 11, 4, 2);
		setBlock(world, i + 7, j + 32, k + 12, Blocks.leaves, 4);
		world.setBlockMetadataWithNotify(i + 7, j + 32, k + 12, 4, 2);
		setBlock(world, i + 7, j + 32, k + 13, Blocks.leaves, 4);
		world.setBlockMetadataWithNotify(i + 7, j + 32, k + 13, 4, 2);
		setBlock(world, i + 7, j + 33, k + 1, Blocks.leaves, 4);
		world.setBlockMetadataWithNotify(i + 7, j + 33, k + 1, 4, 2);
		setBlock(world, i + 7, j + 33, k + 2, Blocks.leaves, 4);
		world.setBlockMetadataWithNotify(i + 7, j + 33, k + 2, 4, 2);
		setBlock(world, i + 7, j + 33, k + 3, Blocks.leaves, 4);
		world.setBlockMetadataWithNotify(i + 7, j + 33, k + 3, 4, 2);
		setBlock(world, i + 7, j + 33, k + 10, Blocks.leaves, 4);
		world.setBlockMetadataWithNotify(i + 7, j + 33, k + 10, 4, 2);
		setBlock(world, i + 7, j + 33, k + 11, Blocks.leaves, 4);
		world.setBlockMetadataWithNotify(i + 7, j + 33, k + 11, 4, 2);
		setBlock(world, i + 7, j + 33, k + 12, Blocks.leaves, 4);
		world.setBlockMetadataWithNotify(i + 7, j + 33, k + 12, 4, 2);
		setBlock(world, i + 7, j + 33, k + 13, Blocks.leaves, 4);
		world.setBlockMetadataWithNotify(i + 7, j + 33, k + 13, 4, 2);
		setBlock(world, i + 7, j + 33, k + 14, Blocks.leaves, 4);
		world.setBlockMetadataWithNotify(i + 7, j + 33, k + 14, 4, 2);
		setBlock(world, i + 7, j + 34, k + 0, Blocks.leaves, 4);
		world.setBlockMetadataWithNotify(i + 7, j + 34, k + 0, 4, 2);
		setBlock(world, i + 7, j + 34, k + 1, Blocks.leaves, 4);
		world.setBlockMetadataWithNotify(i + 7, j + 34, k + 1, 4, 2);
		setBlock(world, i + 7, j + 34, k + 2, Blocks.leaves, 4);
		world.setBlockMetadataWithNotify(i + 7, j + 34, k + 2, 4, 2);
		setBlock(world, i + 7, j + 34, k + 3, Blocks.leaves, 4);
		world.setBlockMetadataWithNotify(i + 7, j + 34, k + 3, 4, 2);
		setBlock(world, i + 7, j + 34, k + 4, Blocks.leaves, 4);
		world.setBlockMetadataWithNotify(i + 7, j + 34, k + 4, 4, 2);
		setBlock(world, i + 7, j + 34, k + 5, Blocks.leaves, 4);
		world.setBlockMetadataWithNotify(i + 7, j + 34, k + 5, 4, 2);
		setBlock(world, i + 7, j + 34, k + 6, Blocks.leaves, 4);
		world.setBlockMetadataWithNotify(i + 7, j + 34, k + 6, 4, 2);
		setBlock(world, i + 7, j + 34, k + 7, Blocks.leaves, 4);
		world.setBlockMetadataWithNotify(i + 7, j + 34, k + 7, 4, 2);
		setBlock(world, i + 7, j + 34, k + 8, Blocks.leaves, 4);
		world.setBlockMetadataWithNotify(i + 7, j + 34, k + 8, 4, 2);
		setBlock(world, i + 7, j + 34, k + 11, Blocks.leaves, 4);
		world.setBlockMetadataWithNotify(i + 7, j + 34, k + 11, 4, 2);
		setBlock(world, i + 7, j + 34, k + 12, Blocks.leaves, 4);
		world.setBlockMetadataWithNotify(i + 7, j + 34, k + 12, 4, 2);
		setBlock(world, i + 7, j + 34, k + 13, Blocks.leaves, 4);
		world.setBlockMetadataWithNotify(i + 7, j + 34, k + 13, 4, 2);
		setBlock(world, i + 7, j + 35, k + 1, Blocks.leaves, 4);
		world.setBlockMetadataWithNotify(i + 7, j + 35, k + 1, 4, 2);
		setBlock(world, i + 7, j + 35, k + 2, Blocks.leaves, 4);
		world.setBlockMetadataWithNotify(i + 7, j + 35, k + 2, 4, 2);
		setBlock(world, i + 7, j + 35, k + 3, Blocks.leaves, 4);
		world.setBlockMetadataWithNotify(i + 7, j + 35, k + 3, 4, 2);
		setBlock(world, i + 7, j + 35, k + 5, Blocks.leaves, 4);
		world.setBlockMetadataWithNotify(i + 7, j + 35, k + 5, 4, 2);
		setBlock(world, i + 7, j + 35, k + 6, Blocks.leaves, 4);
		world.setBlockMetadataWithNotify(i + 7, j + 35, k + 6, 4, 2);
		setBlock(world, i + 7, j + 35, k + 7, Blocks.leaves, 4);
		world.setBlockMetadataWithNotify(i + 7, j + 35, k + 7, 4, 2);
		setBlock(world, i + 7, j + 35, k + 10, Blocks.leaves, 4);
		world.setBlockMetadataWithNotify(i + 7, j + 35, k + 10, 4, 2);
		setBlock(world, i + 7, j + 35, k + 11, Blocks.leaves, 4);
		world.setBlockMetadataWithNotify(i + 7, j + 35, k + 11, 4, 2);
		setBlock(world, i + 7, j + 35, k + 12, Blocks.leaves, 4);
		world.setBlockMetadataWithNotify(i + 7, j + 35, k + 12, 4, 2);
		setBlock(world, i + 7, j + 36, k + 2, Blocks.leaves, 4);
		world.setBlockMetadataWithNotify(i + 7, j + 36, k + 2, 4, 2);
		setBlock(world, i + 7, j + 36, k + 8, Blocks.leaves, 4);
		world.setBlockMetadataWithNotify(i + 7, j + 36, k + 8, 4, 2);
		setBlock(world, i + 7, j + 36, k + 11, Blocks.leaves, 4);
		world.setBlockMetadataWithNotify(i + 7, j + 36, k + 11, 4, 2);
		setBlock(world, i + 7, j + 36, k + 12, Blocks.leaves, 4);
		world.setBlockMetadataWithNotify(i + 7, j + 36, k + 12, 4, 2);
		setBlock(world, i + 7, j + 36, k + 13, Blocks.leaves, 4);
		world.setBlockMetadataWithNotify(i + 7, j + 36, k + 13, 4, 2);
		setBlock(world, i + 7, j + 37, k + 1, Blocks.leaves, 4);
		world.setBlockMetadataWithNotify(i + 7, j + 37, k + 1, 4, 2);
		setBlock(world, i + 7, j + 37, k + 2, Blocks.leaves, 4);
		world.setBlockMetadataWithNotify(i + 7, j + 37, k + 2, 4, 2);
		setBlock(world, i + 7, j + 37, k + 3, Blocks.leaves, 4);
		world.setBlockMetadataWithNotify(i + 7, j + 37, k + 3, 4, 2);
		setBlock(world, i + 7, j + 37, k + 4, Blocks.leaves, 4);
		world.setBlockMetadataWithNotify(i + 7, j + 37, k + 4, 4, 2);
		setBlock(world, i + 7, j + 37, k + 6, Blocks.leaves, 4);
		world.setBlockMetadataWithNotify(i + 7, j + 37, k + 6, 4, 2);
		setBlock(world, i + 7, j + 37, k + 7, Blocks.leaves, 4);
		world.setBlockMetadataWithNotify(i + 7, j + 37, k + 7, 4, 2);
		setBlock(world, i + 7, j + 37, k + 12, Blocks.leaves, 4);
		world.setBlockMetadataWithNotify(i + 7, j + 37, k + 12, 4, 2);
		setBlock(world, i + 7, j + 38, k + 2, Blocks.leaves, 4);
		world.setBlockMetadataWithNotify(i + 7, j + 38, k + 2, 4, 2);
		setBlock(world, i + 7, j + 38, k + 3, Blocks.leaves, 4);
		world.setBlockMetadataWithNotify(i + 7, j + 38, k + 3, 4, 2);
		setBlock(world, i + 7, j + 38, k + 4, Blocks.leaves, 4);
		world.setBlockMetadataWithNotify(i + 7, j + 38, k + 4, 4, 2);
		setBlock(world, i + 7, j + 38, k + 5, Blocks.leaves, 4);
		world.setBlockMetadataWithNotify(i + 7, j + 38, k + 5, 4, 2);
		setBlock(world, i + 7, j + 38, k + 6, Blocks.leaves, 4);
		world.setBlockMetadataWithNotify(i + 7, j + 38, k + 6, 4, 2);
		setBlock(world, i + 7, j + 38, k + 7, Blocks.leaves, 4);
		world.setBlockMetadataWithNotify(i + 7, j + 38, k + 7, 4, 2);
		setBlock(world, i + 7, j + 38, k + 9, Blocks.leaves, 4);
		world.setBlockMetadataWithNotify(i + 7, j + 38, k + 9, 4, 2);
		setBlock(world, i + 7, j + 38, k + 11, Blocks.leaves, 4);
		world.setBlockMetadataWithNotify(i + 7, j + 38, k + 11, 4, 2);
		setBlock(world, i + 7, j + 38, k + 12, Blocks.leaves, 4);
		world.setBlockMetadataWithNotify(i + 7, j + 38, k + 12, 4, 2);
		setBlock(world, i + 7, j + 39, k + 2, Blocks.leaves, 4);
		world.setBlockMetadataWithNotify(i + 7, j + 39, k + 2, 4, 2);
		setBlock(world, i + 7, j + 39, k + 3, Blocks.leaves, 4);
		world.setBlockMetadataWithNotify(i + 7, j + 39, k + 3, 4, 2);
		setBlock(world, i + 7, j + 39, k + 4, Blocks.leaves, 4);
		world.setBlockMetadataWithNotify(i + 7, j + 39, k + 4, 4, 2);
		setBlock(world, i + 7, j + 39, k + 5, Blocks.leaves, 4);
		world.setBlockMetadataWithNotify(i + 7, j + 39, k + 5, 4, 2);
		setBlock(world, i + 7, j + 39, k + 6, Blocks.leaves, 4);
		world.setBlockMetadataWithNotify(i + 7, j + 39, k + 6, 4, 2);
		setBlock(world, i + 7, j + 39, k + 7, Blocks.leaves, 4);
		world.setBlockMetadataWithNotify(i + 7, j + 39, k + 7, 4, 2);
		setBlock(world, i + 7, j + 39, k + 8, Blocks.leaves, 4);
		world.setBlockMetadataWithNotify(i + 7, j + 39, k + 8, 4, 2);
		setBlock(world, i + 7, j + 39, k + 10, Blocks.leaves, 4);
		world.setBlockMetadataWithNotify(i + 7, j + 39, k + 10, 4, 2);
		setBlock(world, i + 7, j + 39, k + 11, Blocks.leaves, 4);
		world.setBlockMetadataWithNotify(i + 7, j + 39, k + 11, 4, 2);
		setBlock(world, i + 7, j + 39, k + 12, Blocks.leaves, 4);
		world.setBlockMetadataWithNotify(i + 7, j + 39, k + 12, 4, 2);
		setBlock(world, i + 7, j + 40, k + 3, Blocks.leaves, 4);
		world.setBlockMetadataWithNotify(i + 7, j + 40, k + 3, 4, 2);
		setBlock(world, i + 7, j + 40, k + 4, Blocks.leaves, 4);
		world.setBlockMetadataWithNotify(i + 7, j + 40, k + 4, 4, 2);
		setBlock(world, i + 7, j + 40, k + 5, Blocks.leaves, 4);
		world.setBlockMetadataWithNotify(i + 7, j + 40, k + 5, 4, 2);
		setBlock(world, i + 7, j + 40, k + 6, Blocks.leaves, 4);
		world.setBlockMetadataWithNotify(i + 7, j + 40, k + 6, 4, 2);
		setBlock(world, i + 7, j + 40, k + 7, Blocks.leaves, 4);
		world.setBlockMetadataWithNotify(i + 7, j + 40, k + 7, 4, 2);
		setBlock(world, i + 7, j + 40, k + 8, Blocks.leaves, 4);
		world.setBlockMetadataWithNotify(i + 7, j + 40, k + 8, 4, 2);
		setBlock(world, i + 7, j + 40, k + 9, Blocks.leaves, 4);
		world.setBlockMetadataWithNotify(i + 7, j + 40, k + 9, 4, 2);
		setBlock(world, i + 7, j + 40, k + 11, Blocks.leaves, 4);
		world.setBlockMetadataWithNotify(i + 7, j + 40, k + 11, 4, 2);
		setBlock(world, i + 7, j + 40, k + 12, Blocks.leaves, 4);
