package com.parzi.starwarsmod.world.gen;

import java.util.Random;

import net.minecraft.block.Block;
import net.minecraft.init.Blocks;
import net.minecraft.tileentity.TileEntityChest;
import net.minecraft.world.World;
import net.minecraft.world.chunk.IChunkProvider;
import net.minecraft.world.gen.feature.WorldGenerator;

import com.parzi.starwarsmod.StarWarsMod;
import com.parzi.starwarsmod.utils.LootGenUtils;

import cpw.mods.fml.common.IWorldGenerator;

public class WorldGenTatooineHomestead extends WorldGenerator implements IWorldGenerator
{
	public WorldGenTatooineHomestead()
	{
	}

	@Override
	public void generate(Random random, int chunkX, int chunkZ, World world, IChunkProvider chunkGenerator, IChunkProvider chunkProvider)
	{
	}

	@Override
	public boolean generate(World world, Random rand, int i, int j, int k)
	{
		// check that each corner is one of the valid spawn blocks
		if (!locationIsValidSpawn(world, i, j, k) || !locationIsValidSpawn(world, i + 23, j, k) || !locationIsValidSpawn(world, i + 23, j, k + 25) || !locationIsValidSpawn(world, i, j, k + 25)) { return false; }

		k = k - 10;
		i = i - 10;

		setBlock(world, i + 0, j + 0, k + 11, Blocks.sandstone, 0);
		setBlock(world, i + 0, j + 0, k + 12, Blocks.sandstone, 0);
		setBlock(world, i + 0, j + 0, k + 13, Blocks.sandstone, 0);
		setBlock(world, i + 0, j + 0, k + 14, Blocks.sandstone, 0);
		setBlock(world, i + 0, j + 0, k + 15, Blocks.sandstone, 0);
		setBlock(world, i + 0, j + 1, k + 11, Blocks.sandstone, 0);
		setBlock(world, i + 0, j + 1, k + 12, Blocks.sandstone, 0);
		setBlock(world, i + 0, j + 1, k + 13, Blocks.sandstone, 0);
		setBlock(world, i + 0, j + 1, k + 14, Blocks.sandstone, 0);
		setBlock(world, i + 0, j + 1, k + 15, Blocks.sandstone, 0);
		setBlock(world, i + 0, j + 2, k + 11, Blocks.sandstone, 0);
		setBlock(world, i + 0, j + 2, k + 12, Blocks.sandstone, 0);
		setBlock(world, i + 0, j + 2, k + 13, Blocks.sandstone, 0);
		setBlock(world, i + 0, j + 2, k + 14, Blocks.sandstone, 0);
		setBlock(world, i + 0, j + 2, k + 15, Blocks.sandstone, 0);
		setBlock(world, i + 1, j + 0, k + 11, Blocks.sandstone, 0);
		setBlock(world, i + 1, j + 0, k + 12, Blocks.sandstone, 0);
		setBlock(world, i + 1, j + 0, k + 13, Blocks.sandstone, 0);
		setBlock(world, i + 1, j + 0, k + 14, Blocks.sandstone, 0);
		setBlock(world, i + 1, j + 0, k + 15, Blocks.sandstone, 0);
		setBlock(world, i + 1, j + 1, k + 11, Blocks.sandstone, 0);
		setBlock(world, i + 1, j + 1, k + 12, Blocks.sandstone, 0);
		setBlock(world, i + 1, j + 1, k + 13, Blocks.sandstone, 0);
		setBlock(world, i + 1, j + 1, k + 14, Blocks.sandstone, 0);
		setBlock(world, i + 1, j + 1, k + 15, Blocks.sandstone, 0);
		setBlock(world, i + 1, j + 2, k + 11, Blocks.sandstone, 0);
		setBlock(world, i + 1, j + 2, k + 12, Blocks.sandstone, 0);
		setBlock(world, i + 1, j + 2, k + 13, Blocks.sandstone, 0);
		setBlock(world, i + 1, j + 2, k + 14, Blocks.sandstone, 0);
		setBlock(world, i + 1, j + 2, k + 15, Blocks.sandstone, 0);
		setBlock(world, i + 2, j + 0, k + 11, Blocks.sandstone, 0);
		setBlock(world, i + 2, j + 0, k + 12, Blocks.sandstone, 0);
		setBlock(world, i + 2, j + 0, k + 13, Blocks.sandstone, 0);
		setBlock(world, i + 2, j + 0, k + 14, Blocks.sandstone, 0);
		setBlock(world, i + 2, j + 0, k + 15, Blocks.sandstone, 0);
		setBlock(world, i + 2, j + 1, k + 11, Blocks.sandstone, 0);
		setBlock(world, i + 2, j + 1, k + 12, Blocks.sandstone, 0);
		setBlock(world, i + 2, j + 1, k + 13, Blocks.sandstone, 0);
		setBlock(world, i + 2, j + 1, k + 14, Blocks.sandstone, 0);
		setBlock(world, i + 2, j + 1, k + 15, Blocks.sandstone, 0);
		setBlock(world, i + 2, j + 2, k + 11, Blocks.sandstone, 0);
		setBlock(world, i + 2, j + 2, k + 15, Blocks.sandstone, 0);
		setBlock(world, i + 2, j + 3, k + 11, Blocks.sandstone_stairs, 0);
		setBlock(world, i + 2, j + 3, k + 15, Blocks.sandstone_stairs, 0);
		setBlock(world, i + 3, j + 0, k + 11, Blocks.sandstone, 0);
		setBlock(world, i + 3, j + 0, k + 12, Blocks.sandstone, 0);
		setBlock(world, i + 3, j + 0, k + 13, Blocks.sandstone, 0);
		setBlock(world, i + 3, j + 0, k + 14, Blocks.sandstone, 0);
		setBlock(world, i + 3, j + 0, k + 15, Blocks.sandstone, 0);
		setBlock(world, i + 3, j + 1, k + 11, Blocks.sandstone, 0);
		setBlock(world, i + 3, j + 1, k + 12, Blocks.sandstone, 0);
		setBlock(world, i + 3, j + 1, k + 13, Blocks.sandstone, 0);
		setBlock(world, i + 3, j + 1, k + 14, Blocks.sandstone, 0);
		setBlock(world, i + 3, j + 1, k + 15, Blocks.sandstone, 0);
		setBlock(world, i + 3, j + 2, k + 11, Blocks.sandstone, 0);
		setBlock(world, i + 3, j + 2, k + 15, Blocks.sandstone, 0);
		setBlock(world, i + 3, j + 3, k + 11, Blocks.sandstone, 0);
		setBlock(world, i + 3, j + 3, k + 15, Blocks.sandstone, 0);
		setBlock(world, i + 4, j + 0, k + 11, Blocks.sandstone, 0);
		setBlock(world, i + 4, j + 0, k + 12, Blocks.sandstone, 0);
		setBlock(world, i + 4, j + 0, k + 13, Blocks.sandstone, 0);
		setBlock(world, i + 4, j + 0, k + 14, Blocks.sandstone, 0);
		setBlock(world, i + 4, j + 0, k + 15, Blocks.sandstone, 0);
		setBlock(world, i + 4, j + 1, k + 11, Blocks.sandstone, 0);
		setBlock(world, i + 4, j + 1, k + 15, Blocks.sandstone, 0);
		setBlock(world, i + 4, j + 2, k + 11, Blocks.sandstone, 0);
		setBlock(world, i + 4, j + 2, k + 15, Blocks.sandstone, 0);
		setBlock(world, i + 4, j + 3, k + 11, Blocks.sandstone, 0);
		setBlock(world, i + 4, j + 3, k + 15, Blocks.sandstone, 0);
		setBlock(world, i + 4, j + 4, k + 11, Blocks.sandstone, 0);
		setBlock(world, i + 4, j + 4, k + 15, Blocks.sandstone, 0);
		setBlock(world, i + 4, j + 5, k + 11, Blocks.sandstone, 0);
		setBlock(world, i + 4, j + 5, k + 15, Blocks.sandstone, 0);
		setBlock(world, i + 4, j + 6, k + 12, Blocks.sandstone, 0);
		setBlock(world, i + 4, j + 6, k + 13, Blocks.sandstone, 0);
		setBlock(world, i + 4, j + 6, k + 14, Blocks.sandstone, 0);
		setBlock(world, i + 5, j + 0, k + 11, Blocks.sandstone, 0);
		setBlock(world, i + 5, j + 0, k + 12, Blocks.sandstone, 0);
		setBlock(world, i + 5, j + 0, k + 13, Blocks.sandstone, 0);
		setBlock(world, i + 5, j + 0, k + 14, Blocks.sandstone, 0);
		setBlock(world, i + 5, j + 0, k + 15, Blocks.sandstone, 0);
		setBlock(world, i + 5, j + 1, k + 11, Blocks.sandstone, 0);
		setBlock(world, i + 5, j + 1, k + 15, Blocks.sandstone, 0);
		setBlock(world, i + 5, j + 2, k + 11, Blocks.sandstone, 0);
		setBlock(world, i + 5, j + 2, k + 15, Blocks.sandstone, 0);
		setBlock(world, i + 5, j + 3, k + 11, Blocks.sandstone, 0);
		setBlock(world, i + 5, j + 3, k + 15, Blocks.sandstone, 0);
		setBlock(world, i + 5, j + 4, k + 11, Blocks.sandstone, 0);
		setBlock(world, i + 5, j + 4, k + 15, Blocks.sandstone, 0);
		setBlock(world, i + 5, j + 5, k + 11, Blocks.sandstone, 0);
		setBlock(world, i + 5, j + 5, k + 15, Blocks.sandstone, 0);
		setBlock(world, i + 5, j + 6, k + 12, Blocks.sandstone, 0);
		setBlock(world, i + 5, j + 6, k + 13, Blocks.sandstone, 0);
		setBlock(world, i + 5, j + 6, k + 14, Blocks.sandstone, 0);
		setBlock(world, i + 6, j + 0, k + 9, Blocks.sandstone, 0);
		setBlock(world, i + 6, j + 0, k + 10, Blocks.sandstone, 0);
		setBlock(world, i + 6, j + 0, k + 11, Blocks.sandstone, 0);
		setBlock(world, i + 6, j + 0, k + 12, Blocks.sandstone, 0);
		setBlock(world, i + 6, j + 0, k + 13, Blocks.sandstone, 0);
		setBlock(world, i + 6, j + 0, k + 14, Blocks.sandstone, 0);
		setBlock(world, i + 6, j + 0, k + 15, Blocks.sandstone, 0);
		setBlock(world, i + 6, j + 0, k + 16, Blocks.sandstone, 0);
		setBlock(world, i + 6, j + 0, k + 17, Blocks.sandstone, 0);
		setBlock(world, i + 6, j + 1, k + 9, Blocks.sandstone, 0);
		setBlock(world, i + 6, j + 1, k + 10, Blocks.sandstone, 0);
		setBlock(world, i + 6, j + 1, k + 16, Blocks.sandstone, 0);
		setBlock(world, i + 6, j + 1, k + 17, Blocks.sandstone, 0);
		setBlock(world, i + 6, j + 2, k + 9, Blocks.sandstone, 0);
		setBlock(world, i + 6, j + 2, k + 10, Blocks.sandstone, 0);
		setBlock(world, i + 6, j + 2, k + 16, Blocks.sandstone, 0);
		setBlock(world, i + 6, j + 2, k + 17, Blocks.sandstone, 0);
		setBlock(world, i + 6, j + 3, k + 9, Blocks.sandstone, 0);
		setBlock(world, i + 6, j + 3, k + 10, Blocks.sandstone, 0);
		setBlock(world, i + 6, j + 3, k + 16, Blocks.sandstone, 0);
		setBlock(world, i + 6, j + 3, k + 17, Blocks.sandstone, 0);
		setBlock(world, i + 6, j + 4, k + 9, Blocks.sandstone, 0);
		setBlock(world, i + 6, j + 4, k + 10, Blocks.sandstone, 0);
		setBlock(world, i + 6, j + 4, k + 16, Blocks.sandstone, 0);
		setBlock(world, i + 6, j + 4, k + 17, Blocks.sandstone, 0);
		setBlock(world, i + 6, j + 5, k + 9, Blocks.sandstone, 0);
		setBlock(world, i + 6, j + 5, k + 10, Blocks.sandstone, 0);
		setBlock(world, i + 6, j + 5, k + 16, Blocks.sandstone, 0);
		setBlock(world, i + 6, j + 5, k + 17, Blocks.sandstone, 0);
		setBlock(world, i + 6, j + 6, k + 10, Blocks.sandstone, 0);
		setBlock(world, i + 6, j + 6, k + 11, Blocks.sandstone, 0);
		setBlock(world, i + 6, j + 6, k + 12, Blocks.sandstone, 0);
		setBlock(world, i + 6, j + 6, k + 13, Blocks.sandstone, 0);
		setBlock(world, i + 6, j + 6, k + 14, Blocks.sandstone, 0);
		setBlock(world, i + 6, j + 6, k + 15, Blocks.sandstone, 0);
		setBlock(world, i + 6, j + 6, k + 16, Blocks.sandstone, 0);
		setBlock(world, i + 6, j + 7, k + 11, Blocks.sandstone, 0);
		setBlock(world, i + 6, j + 7, k + 12, Blocks.sandstone, 0);
		setBlock(world, i + 6, j + 7, k + 13, Blocks.sandstone, 0);
		setBlock(world, i + 6, j + 7, k + 14, Blocks.sandstone, 0);
		setBlock(world, i + 6, j + 7, k + 15, Blocks.sandstone, 0);
		setBlock(world, i + 7, j + 0, k + 7, Blocks.sandstone, 0);
		setBlock(world, i + 7, j + 0, k + 8, Blocks.sandstone, 0);
		setBlock(world, i + 7, j + 0, k + 9, Blocks.sandstone, 0);
		setBlock(world, i + 7, j + 0, k + 10, Blocks.sandstone, 0);
		setBlock(world, i + 7, j + 0, k + 11, Blocks.sandstone, 0);
		setBlock(world, i + 7, j + 0, k + 12, Blocks.sandstone, 0);
		setBlock(world, i + 7, j + 0, k + 13, Blocks.glowstone, 0);
		setBlock(world, i + 7, j + 0, k + 14, Blocks.sandstone, 0);
		setBlock(world, i + 7, j + 0, k + 15, Blocks.sandstone, 0);
		setBlock(world, i + 7, j + 0, k + 16, Blocks.sandstone, 0);
		setBlock(world, i + 7, j + 0, k + 17, Blocks.sandstone, 0);
		setBlock(world, i + 7, j + 0, k + 18, Blocks.sandstone, 0);
		setBlock(world, i + 7, j + 0, k + 19, Blocks.sandstone, 0);
		setBlock(world, i + 7, j + 1, k + 7, Blocks.sandstone, 0);
		setBlock(world, i + 7, j + 1, k + 8, Blocks.sandstone, 0);
		setBlock(world, i + 7, j + 1, k + 18, Blocks.sandstone, 0);
		setBlock(world, i + 7, j + 1, k + 19, Blocks.sandstone, 0);
		setBlock(world, i + 7, j + 2, k + 7, Blocks.sandstone, 0);
		setBlock(world, i + 7, j + 2, k + 8, Blocks.sandstone, 0);
		setBlock(world, i + 7, j + 2, k + 18, Blocks.sandstone, 0);
		setBlock(world, i + 7, j + 2, k + 19, Blocks.sandstone, 0);
		setBlock(world, i + 7, j + 3, k + 7, Blocks.sandstone, 0);
		setBlock(world, i + 7, j + 3, k + 8, Blocks.sandstone, 0);
		setBlock(world, i + 7, j + 3, k + 18, Blocks.sandstone, 0);
		setBlock(world, i + 7, j + 3, k + 19, Blocks.sandstone, 0);
		setBlock(world, i + 7, j + 4, k + 8, Blocks.sandstone, 0);
		setBlock(world, i + 7, j + 4, k + 18, Blocks.sandstone, 0);
		setBlock(world, i + 7, j + 5, k + 8, Blocks.sandstone, 0);
		setBlock(world, i + 7, j + 5, k + 18, Blocks.sandstone, 0);
		setBlock(world, i + 7, j + 6, k + 8, Blocks.sandstone, 0);
		setBlock(world, i + 7, j + 6, k + 9, Blocks.sandstone, 0);
		setBlock(world, i + 7, j + 6, k + 17, Blocks.sandstone, 0);
		setBlock(world, i + 7, j + 6, k + 18, Blocks.sandstone, 0);
		setBlock(world, i + 7, j + 7, k + 9, Blocks.sandstone, 0);
		setBlock(world, i + 7, j + 7, k + 10, Blocks.sandstone, 0);
		setBlock(world, i + 7, j + 7, k + 16, Blocks.sandstone, 0);
		setBlock(world, i + 7, j + 7, k + 17, Blocks.sandstone, 0);
		setBlock(world, i + 7, j + 8, k + 10, Blocks.sandstone, 0);
		setBlock(world, i + 7, j + 8, k + 11, Blocks.sandstone, 0);
		setBlock(world, i + 7, j + 8, k + 12, Blocks.sandstone, 0);
		setBlock(world, i + 7, j + 8, k + 13, Blocks.sandstone, 0);
		setBlock(world, i + 7, j + 8, k + 14, Blocks.sandstone, 0);
		setBlock(world, i + 7, j + 8, k + 15, Blocks.sandstone, 0);
		setBlock(world, i + 7, j + 8, k + 16, Blocks.sandstone, 0);
		setBlock(world, i + 7, j + 9, k + 13, Blocks.sandstone, 0);
		setBlock(world, i + 8, j + 0, k + 7, Blocks.sandstone, 0);
		setBlock(world, i + 8, j + 0, k + 8, Blocks.sand, 0);
		setBlock(world, i + 8, j + 0, k + 9, Blocks.sandstone, 0);
		setBlock(world, i + 8, j + 0, k + 10, Blocks.sandstone, 0);
		setBlock(world, i + 8, j + 0, k + 11, Blocks.sandstone, 0);
		setBlock(world, i + 8, j + 0, k + 12, Blocks.sandstone, 0);
		setBlock(world, i + 8, j + 0, k + 13, Blocks.sandstone, 0);
		setBlock(world, i + 8, j + 0, k + 14, Blocks.sandstone, 0);
		setBlock(world, i + 8, j + 0, k + 15, Blocks.sandstone, 0);
		setBlock(world, i + 8, j + 0, k + 16, Blocks.sandstone, 0);
		setBlock(world, i + 8, j + 0, k + 17, Blocks.sandstone, 0);
		setBlock(world, i + 8, j + 0, k + 18, Blocks.sand, 0);
		setBlock(world, i + 8, j + 0, k + 19, Blocks.sandstone, 0);
		setBlock(world, i + 8, j + 1, k + 7, Blocks.sandstone, 0);
		setBlock(world, i + 8, j + 1, k + 19, Blocks.sandstone, 0);
		setBlock(world, i + 8, j + 2, k + 7, Blocks.sandstone, 0);
		setBlock(world, i + 8, j + 2, k + 19, Blocks.sandstone, 0);
		setBlock(world, i + 8, j + 3, k + 7, Blocks.sandstone, 0);
		setBlock(world, i + 8, j + 3, k + 19, Blocks.sandstone, 0);
		setBlock(world, i + 8, j + 4, k + 7, Blocks.sandstone, 0);
		setBlock(world, i + 8, j + 4, k + 19, Blocks.sandstone, 0);
		setBlock(world, i + 8, j + 5, k + 7, Blocks.sandstone, 0);
		setBlock(world, i + 8, j + 5, k + 19, Blocks.sandstone, 0);
		setBlock(world, i + 8, j + 6, k + 7, Blocks.sandstone, 0);
		setBlock(world, i + 8, j + 6, k + 19, Blocks.sandstone, 0);
		setBlock(world, i + 8, j + 7, k + 8, Blocks.sandstone, 0);
		setBlock(world, i + 8, j + 7, k + 18, Blocks.sandstone, 0);
		setBlock(world, i + 8, j + 8, k + 9, Blocks.sandstone, 0);
		setBlock(world, i + 8, j + 8, k + 17, Blocks.sandstone, 0);
		setBlock(world, i + 8, j + 9, k + 10, Blocks.sandstone, 0);
		setBlock(world, i + 8, j + 9, k + 11, Blocks.sandstone, 0);
		setBlock(world, i + 8, j + 9, k + 12, Blocks.sandstone, 0);
		setBlock(world, i + 8, j + 9, k + 13, Blocks.sandstone, 0);
		setBlock(world, i + 8, j + 9, k + 14, Blocks.sandstone, 0);
		setBlock(world, i + 8, j + 9, k + 15, Blocks.sandstone, 0);
		setBlock(world, i + 8, j + 9, k + 16, Blocks.sandstone, 0);
		setBlock(world, i + 9, j + 0, k + 6, Blocks.sandstone, 0);
		setBlock(world, i + 9, j + 0, k + 7, Blocks.sandstone, 0);
		setBlock(world, i + 9, j + 0, k + 8, Blocks.sandstone, 0);
		setBlock(world, i + 9, j + 0, k + 9, Blocks.sand, 0);
		setBlock(world, i + 9, j + 0, k + 10, Blocks.sandstone, 0);
		setBlock(world, i + 9, j + 0, k + 11, Blocks.sandstone, 0);
		setBlock(world, i + 9, j + 0, k + 12, Blocks.sandstone, 0);
		setBlock(world, i + 9, j + 0, k + 13, Blocks.sand, 0);
		setBlock(world, i + 9, j + 0, k + 14, Blocks.sandstone, 0);
		setBlock(world, i + 9, j + 0, k + 15, Blocks.sandstone, 0);
		setBlock(world, i + 9, j + 0, k + 16, Blocks.sandstone, 0);
		setBlock(world, i + 9, j + 0, k + 17, Blocks.sand, 0);
		setBlock(world, i + 9, j + 0, k + 18, Blocks.sandstone, 0);
		setBlock(world, i + 9, j + 0, k + 19, Blocks.sandstone, 0);
		setBlock(world, i + 9, j + 0, k + 20, Blocks.sandstone, 0);
		setBlock(world, i + 9, j + 1, k + 6, Blocks.sandstone, 0);
		setBlock(world, i + 9, j + 1, k + 20, Blocks.sandstone, 0);
		setBlock(world, i + 9, j + 2, k + 6, Blocks.sandstone, 0);
		setBlock(world, i + 9, j + 2, k + 20, Blocks.sandstone, 0);
		setBlock(world, i + 9, j + 3, k + 6, Blocks.sandstone, 0);
		setBlock(world, i + 9, j + 3, k + 20, Blocks.sandstone, 0);
		setBlock(world, i + 9, j + 4, k + 6, Blocks.sandstone, 0);
		setBlock(world, i + 9, j + 4, k + 20, Blocks.sandstone, 0);
		setBlock(world, i + 9, j + 5, k + 6, Blocks.sandstone, 0);
		setBlock(world, i + 9, j + 5, k + 20, Blocks.sandstone, 0);
		setBlock(world, i + 9, j + 6, k + 7, Blocks.sandstone, 0);
		setBlock(world, i + 9, j + 6, k + 19, Blocks.sandstone, 0);
		setBlock(world, i + 9, j + 7, k + 7, Blocks.sandstone, 0);
		setBlock(world, i + 9, j + 7, k + 19, Blocks.sandstone, 0);
		setBlock(world, i + 9, j + 8, k + 8, Blocks.sandstone, 0);
		setBlock(world, i + 9, j + 8, k + 18, Blocks.sandstone, 0);
		setBlock(world, i + 9, j + 9, k + 9, Blocks.sandstone, 0);
		setBlock(world, i + 9, j + 9, k + 10, Blocks.sandstone, 0);
		setBlock(world, i + 9, j + 9, k + 16, Blocks.sandstone, 0);
		setBlock(world, i + 9, j + 9, k + 17, Blocks.sandstone, 0);
		setBlock(world, i + 9, j + 10, k + 11, Blocks.sandstone, 0);
		setBlock(world, i + 9, j + 10, k + 12, Blocks.sandstone, 0);
		setBlock(world, i + 9, j + 10, k + 13, Blocks.sandstone, 0);
		setBlock(world, i + 9, j + 10, k + 14, Blocks.sandstone, 0);
		setBlock(world, i + 9, j + 10, k + 15, Blocks.sandstone, 0);
		setBlock(world, i + 10, j + 0, k + 6, Blocks.sandstone, 0);
		setBlock(world, i + 10, j + 0, k + 7, Blocks.sandstone, 0);
		setBlock(world, i + 10, j + 0, k + 8, Blocks.sandstone, 0);
		setBlock(world, i + 10, j + 0, k + 9, Blocks.sandstone, 0);
		setBlock(world, i + 10, j + 0, k + 10, Blocks.sand, 0);
		setBlock(world, i + 10, j + 0, k + 11, Blocks.sandstone, 0);
		setBlock(world, i + 10, j + 0, k + 12, Blocks.sandstone, 0);
		setBlock(world, i + 10, j + 0, k + 13, Blocks.sandstone, 0);
		setBlock(world, i + 10, j + 0, k + 14, Blocks.sandstone, 0);
		setBlock(world, i + 10, j + 0, k + 15, Blocks.sandstone, 0);
		setBlock(world, i + 10, j + 0, k + 16, Blocks.sand, 0);
		setBlock(world, i + 10, j + 0, k + 17, Blocks.sandstone, 0);
		setBlock(world, i + 10, j + 0, k + 18, Blocks.sandstone, 0);
		setBlock(world, i + 10, j + 0, k + 19, Blocks.sandstone, 0);
		setBlock(world, i + 10, j + 0, k + 20, Blocks.sandstone, 0);
		setBlock(world, i + 10, j + 1, k + 6, Blocks.sandstone, 0);
		setBlock(world, i + 10, j + 1, k + 20, Blocks.sandstone, 0);
		setBlock(world, i + 10, j + 2, k + 6, Blocks.sandstone, 0);
		setBlock(world, i + 10, j + 2, k + 20, Blocks.sandstone, 0);
		setBlock(world, i + 10, j + 3, k + 6, Blocks.sandstone, 0);
		setBlock(world, i + 10, j + 3, k + 20, Blocks.sandstone, 0);
		setBlock(world, i + 10, j + 4, k + 6, Blocks.sandstone, 0);
		setBlock(world, i + 10, j + 4, k + 20, Blocks.sandstone, 0);
		setBlock(world, i + 10, j + 5, k + 6, Blocks.sandstone, 0);
		setBlock(world, i + 10, j + 5, k + 20, Blocks.sandstone, 0);
		setBlock(world, i + 10, j + 6, k + 6, Blocks.sandstone, 0);
		setBlock(world, i + 10, j + 6, k + 20, Blocks.sandstone, 0);
		setBlock(world, i + 10, j + 7, k + 7, Blocks.sandstone, 0);
		setBlock(world, i + 10, j + 7, k + 19, Blocks.sandstone, 0);
		setBlock(world, i + 10, j + 8, k + 7, Blocks.sandstone, 0);
		setBlock(world, i + 10, j + 8, k + 19, Blocks.sandstone, 0);
		setBlock(world, i + 10, j + 9, k + 8, Blocks.sandstone, 0);
		setBlock(world, i + 10, j + 9, k + 9, Blocks.sandstone, 0);
		setBlock(world, i + 10, j + 9, k + 17, Blocks.sandstone, 0);
		setBlock(world, i + 10, j + 9, k + 18, Blocks.sandstone, 0);
		setBlock(world, i + 10, j + 10, k + 10, Blocks.sandstone, 0);
		setBlock(world, i + 10, j + 10, k + 11, Blocks.sandstone, 0);
		setBlock(world, i + 10, j + 10, k + 12, Blocks.sandstone, 0);
		setBlock(world, i + 10, j + 10, k + 13, Blocks.sandstone, 0);
		setBlock(world, i + 10, j + 10, k + 14, Blocks.sandstone, 0);
		setBlock(world, i + 10, j + 10, k + 15, Blocks.sandstone, 0);
		setBlock(world, i + 10, j + 10, k + 16, Blocks.sandstone, 0);
		setBlock(world, i + 11, j + 0, k + 3, Blocks.sandstone, 0);
		setBlock(world, i + 11, j + 0, k + 4, Blocks.sandstone, 0);
		setBlock(world, i + 11, j + 0, k + 5, Blocks.sandstone, 0);
		setBlock(world, i + 11, j + 0, k + 6, Blocks.sandstone, 0);
		setBlock(world, i + 11, j + 0, k + 7, Blocks.sandstone, 0);
		setBlock(world, i + 11, j + 0, k + 8, Blocks.sandstone, 0);
		setBlock(world, i + 11, j + 0, k + 9, Blocks.sandstone, 0);
		setBlock(world, i + 11, j + 0, k + 10, Blocks.sandstone, 0);
		setBlock(world, i + 11, j + 0, k + 11, Blocks.sand, 0);
		setBlock(world, i + 11, j + 0, k + 12, Blocks.sandstone, 0);
		setBlock(world, i + 11, j + 0, k + 13, Blocks.sand, 0);
		setBlock(world, i + 11, j + 0, k + 14, Blocks.sandstone, 0);
		setBlock(world, i + 11, j + 0, k + 15, Blocks.sand, 0);
		setBlock(world, i + 11, j + 0, k + 16, Blocks.sandstone, 0);
		setBlock(world, i + 11, j + 0, k + 17, Blocks.sandstone, 0);
		setBlock(world, i + 11, j + 0, k + 18, Blocks.sandstone, 0);
		setBlock(world, i + 11, j + 0, k + 19, Blocks.sandstone, 0);
		setBlock(world, i + 11, j + 0, k + 20, Blocks.sandstone, 0);
		setBlock(world, i + 11, j + 0, k + 21, Blocks.sandstone, 0);
		setBlock(world, i + 11, j + 0, k + 22, Blocks.sandstone, 0);
		setBlock(world, i + 11, j + 0, k + 23, Blocks.sandstone, 0);
		setBlock(world, i + 11, j + 1, k + 3, Blocks.sandstone, 0);
		setBlock(world, i + 11, j + 1, k + 4, Blocks.sandstone, 0);
		setBlock(world, i + 11, j + 1, k + 5, Blocks.sandstone, 0);
		setBlock(world, i + 11, j + 1, k + 21, Blocks.sandstone, 0);
		setBlock(world, i + 11, j + 1, k + 22, Blocks.sandstone, 0);
		setBlock(world, i + 11, j + 1, k + 23, Blocks.sandstone, 0);
		setBlock(world, i + 11, j + 2, k + 3, Blocks.sandstone, 0);
		setBlock(world, i + 11, j + 2, k + 4, Blocks.sandstone, 0);
		setBlock(world, i + 11, j + 2, k + 5, Blocks.sandstone, 0);
		setBlock(world, i + 11, j + 2, k + 21, Blocks.sandstone, 0);
		setBlock(world, i + 11, j + 2, k + 22, Blocks.sandstone, 0);
		setBlock(world, i + 11, j + 2, k + 23, Blocks.sandstone, 0);
		setBlock(world, i + 11, j + 3, k + 4, Blocks.sandstone, 0);
		setBlock(world, i + 11, j + 3, k + 5, Blocks.sandstone, 0);
		setBlock(world, i + 11, j + 3, k + 21, Blocks.sandstone, 0);
		setBlock(world, i + 11, j + 3, k + 22, Blocks.sandstone, 0);
		setBlock(world, i + 11, j + 4, k + 4, Blocks.sandstone, 0);
		setBlock(world, i + 11, j + 4, k + 5, Blocks.sandstone, 0);
		setBlock(world, i + 11, j + 4, k + 21, Blocks.sandstone, 0);
		setBlock(world, i + 11, j + 4, k + 22, Blocks.sandstone, 0);
		setBlock(world, i + 11, j + 5, k + 4, Blocks.sandstone, 0);
		setBlock(world, i + 11, j + 5, k + 5, Blocks.sandstone, 0);
		setBlock(world, i + 11, j + 5, k + 21, Blocks.sandstone, 0);
		setBlock(world, i + 11, j + 5, k + 22, Blocks.sandstone, 0);
		setBlock(world, i + 11, j + 6, k + 3, Blocks.sandstone_stairs, 0);
		setBlock(world, i + 11, j + 6, k + 4, Blocks.sandstone_stairs, 0);
		setBlock(world, i + 11, j + 6, k + 5, Blocks.sandstone_stairs, 0);
		setBlock(world, i + 11, j + 6, k + 6, Blocks.sandstone, 0);
		setBlock(world, i + 11, j + 6, k + 20, Blocks.sandstone, 0);
		setBlock(world, i + 11, j + 6, k + 21, Blocks.sandstone_stairs, 0);
		setBlock(world, i + 11, j + 6, k + 22, Blocks.sandstone_stairs, 0);
		setBlock(world, i + 11, j + 6, k + 23, Blocks.sandstone_stairs, 0);
		setBlock(world, i + 11, j + 7, k + 6, Blocks.sandstone, 0);
		setBlock(world, i + 11, j + 7, k + 20, Blocks.sandstone, 0);
		setBlock(world, i + 11, j + 8, k + 7, Blocks.sandstone, 0);
		setBlock(world, i + 11, j + 8, k + 19, Blocks.sandstone, 0);
		setBlock(world, i + 11, j + 9, k + 8, Blocks.sandstone, 0);
		setBlock(world, i + 11, j + 9, k + 18, Blocks.sandstone, 0);
		setBlock(world, i + 11, j + 10, k + 9, Blocks.sandstone, 0);
		setBlock(world, i + 11, j + 10, k + 10, Blocks.sandstone, 0);
		setBlock(world, i + 11, j + 10, k + 16, Blocks.sandstone, 0);
		setBlock(world, i + 11, j + 10, k + 17, Blocks.sandstone, 0);
		setBlock(world, i + 11, j + 11, k + 11, Blocks.sandstone, 0);
		setBlock(world, i + 11, j + 11, k + 12, Blocks.sandstone, 0);
		setBlock(world, i + 11, j + 11, k + 13, Blocks.sandstone, 0);
		setBlock(world, i + 11, j + 11, k + 14, Blocks.sandstone, 0);
		setBlock(world, i + 11, j + 11, k + 15, Blocks.sandstone, 0);
		setBlock(world, i + 12, j + 0, k + 3, Blocks.sandstone, 0);
		setBlock(world, i + 12, j + 0, k + 4, Blocks.sandstone, 0);
		setBlock(world, i + 12, j + 0, k + 5, Blocks.sandstone, 0);
		setBlock(world, i + 12, j + 0, k + 6, Blocks.sandstone, 0);
		setBlock(world, i + 12, j + 0, k + 7, Blocks.sandstone, 0);
		setBlock(world, i + 12, j + 0, k + 8, Blocks.sandstone, 0);
		setBlock(world, i + 12, j + 0, k + 9, Blocks.sandstone, 0);
		setBlock(world, i + 12, j + 0, k + 10, Blocks.sandstone, 0);
		setBlock(world, i + 12, j + 0, k + 11, Blocks.sandstone, 0);
		setBlock(world, i + 12, j + 0, k + 12, Blocks.sand, 0);
		setBlock(world, i + 12, j + 0, k + 13, Blocks.sandstone, 0);
		setBlock(world, i + 12, j + 0, k + 14, Blocks.sand, 0);
		setBlock(world, i + 12, j + 0, k + 15, Blocks.sandstone, 0);
		setBlock(world, i + 12, j + 0, k + 16, Blocks.sandstone, 0);
		setBlock(world, i + 12, j + 0, k + 17, Blocks.sandstone, 0);
		setBlock(world, i + 12, j + 0, k + 18, Blocks.sandstone, 0);
		setBlock(world, i + 12, j + 0, k + 19, Blocks.sandstone, 0);
		setBlock(world, i + 12, j + 0, k + 20, Blocks.sandstone, 0);
		setBlock(world, i + 12, j + 0, k + 21, Blocks.sandstone, 0);
		setBlock(world, i + 12, j + 0, k + 22, Blocks.sandstone, 0);
		setBlock(world, i + 12, j + 0, k + 23, Blocks.sandstone, 0);
		setBlock(world, i + 12, j + 1, k + 3, Blocks.sandstone, 0);
		setBlock(world, i + 12, j + 1, k + 23, Blocks.sandstone, 0);
		setBlock(world, i + 12, j + 2, k + 3, Blocks.sandstone, 0);
		setBlock(world, i + 12, j + 2, k + 23, Blocks.sandstone, 0);
		setBlock(world, i + 12, j + 3, k + 3, Blocks.sandstone, 0);
		setBlock(world, i + 12, j + 3, k + 23, Blocks.sandstone, 0);
		setBlock(world, i + 12, j + 4, k + 3, Blocks.sandstone, 0);
		setBlock(world, i + 12, j + 4, k + 23, Blocks.sandstone, 0);
		setBlock(world, i + 12, j + 5, k + 3, Blocks.sandstone, 0);
		setBlock(world, i + 12, j + 5, k + 23, Blocks.sandstone, 0);
		setBlock(world, i + 12, j + 6, k + 4, Blocks.sandstone, 0);
		setBlock(world, i + 12, j + 6, k + 5, Blocks.sandstone, 0);
		setBlock(world, i + 12, j + 6, k + 6, Blocks.sandstone, 0);
		setBlock(world, i + 12, j + 6, k + 20, Blocks.sandstone, 0);
		setBlock(world, i + 12, j + 6, k + 21, Blocks.sandstone, 0);
		setBlock(world, i + 12, j + 6, k + 22, Blocks.sandstone, 0);
		setBlock(world, i + 12, j + 7, k + 6, Blocks.sandstone, 0);
		setBlock(world, i + 12, j + 7, k + 20, Blocks.sandstone, 0);
		setBlock(world, i + 12, j + 8, k + 7, Blocks.sandstone, 0);
		setBlock(world, i + 12, j + 8, k + 19, Blocks.sandstone, 0);
		setBlock(world, i + 12, j + 9, k + 8, Blocks.sandstone, 0);
		setBlock(world, i + 12, j + 9, k + 18, Blocks.sandstone, 0);
		setBlock(world, i + 12, j + 10, k + 9, Blocks.sandstone, 0);
		setBlock(world, i + 12, j + 10, k + 10, Blocks.sandstone, 0);
		setBlock(world, i + 12, j + 10, k + 16, Blocks.sandstone, 0);
		setBlock(world, i + 12, j + 10, k + 17, Blocks.sandstone, 0);
		setBlock(world, i + 12, j + 11, k + 11, Blocks.sandstone, 0);
		setBlock(world, i + 12, j + 11, k + 12, Blocks.sandstone, 0);
		setBlock(world, i + 12, j + 11, k + 13, Blocks.sandstone, 0);
		setBlock(world, i + 12, j + 11, k + 14, Blocks.sandstone, 0);
		setBlock(world, i + 12, j + 11, k + 15, Blocks.sandstone, 0);
		setBlock(world, i + 13, j + 0, k + 3, Blocks.sandstone, 0);
		setBlock(world, i + 13, j + 0, k + 4, Blocks.sandstone, 0);
		setBlock(world, i + 13, j + 0, k + 5, Blocks.glowstone, 0);
		setBlock(world, i + 13, j + 0, k + 6, Blocks.sandstone, 0);
		setBlock(world, i + 13, j + 0, k + 7, Blocks.sand, 0);
		setBlock(world, i + 13, j + 0, k + 8, Blocks.sandstone, 0);
		setBlock(world, i + 13, j + 0, k + 9, Blocks.sand, 0);
		setBlock(world, i + 13, j + 0, k + 10, Blocks.sandstone, 0);
		setBlock(world, i + 13, j + 0, k + 11, Blocks.sand, 0);
		setBlock(world, i + 13, j + 0, k + 12, Blocks.sandstone, 0);
		setBlock(world, i + 13, j + 0, k + 13, Blocks.glowstone, 0);
		setBlock(world, i + 13, j + 0, k + 14, Blocks.sandstone, 0);
		setBlock(world, i + 13, j + 0, k + 15, Blocks.sand, 0);
		setBlock(world, i + 13, j + 0, k + 16, Blocks.sandstone, 0);
		setBlock(world, i + 13, j + 0, k + 17, Blocks.sand, 0);
		setBlock(world, i + 13, j + 0, k + 18, Blocks.sandstone, 0);
		setBlock(world, i + 13, j + 0, k + 19, Blocks.sand, 0);
		setBlock(world, i + 13, j + 0, k + 20, Blocks.sandstone, 0);
		setBlock(world, i + 13, j + 0, k + 21, Blocks.glowstone, 0);
		setBlock(world, i + 13, j + 0, k + 22, Blocks.sandstone, 0);
		setBlock(world, i + 13, j + 0, k + 23, Blocks.sandstone, 0);
		setBlock(world, i + 13, j + 1, k + 3, Blocks.sandstone, 0);
		setBlock(world, i + 13, j + 1, k + 23, Blocks.sandstone, 0);
		setBlock(world, i + 13, j + 5, k + 3, Blocks.sandstone, 0);
		setBlock(world, i + 13, j + 5, k + 23, Blocks.sandstone, 0);
		setBlock(world, i + 13, j + 6, k + 4, Blocks.sandstone, 0);
		setBlock(world, i + 13, j + 6, k + 5, Blocks.sandstone, 0);
		setBlock(world, i + 13, j + 6, k + 6, Blocks.sandstone, 0);
		setBlock(world, i + 13, j + 6, k + 20, Blocks.sandstone, 0);
		setBlock(world, i + 13, j + 6, k + 21, Blocks.sandstone, 0);
		setBlock(world, i + 13, j + 6, k + 22, Blocks.sandstone, 0);
		setBlock(world, i + 13, j + 7, k + 6, Blocks.sandstone, 0);
		setBlock(world, i + 13, j + 7, k + 20, Blocks.sandstone, 0);
		setBlock(world, i + 13, j + 8, k + 7, Blocks.sandstone, 0);
		setBlock(world, i + 13, j + 8, k + 19, Blocks.sandstone, 0);
		setBlock(world, i + 13, j + 9, k + 7, Blocks.sandstone, 0);
		setBlock(world, i + 13, j + 9, k + 8, Blocks.sandstone, 0);
		setBlock(world, i + 13, j + 9, k + 18, Blocks.sandstone, 0);
		setBlock(world, i + 13, j + 9, k + 19, Blocks.sandstone, 0);
		setBlock(world, i + 13, j + 10, k + 9, Blocks.sandstone, 0);
		setBlock(world, i + 13, j + 10, k + 10, Blocks.sandstone, 0);
		setBlock(world, i + 13, j + 10, k + 16, Blocks.sandstone, 0);
		setBlock(world, i + 13, j + 10, k + 17, Blocks.sandstone, 0);
		setBlock(world, i + 13, j + 11, k + 11, Blocks.sandstone, 0);
		setBlock(world, i + 13, j + 11, k + 12, Blocks.sandstone, 0);
		setBlock(world, i + 13, j + 11, k + 13, Blocks.sandstone, 0);
		setBlock(world, i + 13, j + 11, k + 14, Blocks.sandstone, 0);
		setBlock(world, i + 13, j + 11, k + 15, Blocks.sandstone, 0);
		setBlock(world, i + 14, j + 0, k + 3, Blocks.sandstone, 0);
		setBlock(world, i + 14, j + 0, k + 4, Blocks.sandstone, 0);
		setBlock(world, i + 14, j + 0, k + 5, Blocks.sandstone, 0);
		setBlock(world, i + 14, j + 0, k + 6, Blocks.sandstone, 0);
		setBlock(world, i + 14, j + 0, k + 7, Blocks.sandstone, 0);
		setBlock(world, i + 14, j + 0, k + 8, Blocks.sandstone, 0);
		setBlock(world, i + 14, j + 0, k + 9, Blocks.sandstone, 0);
		setBlock(world, i + 14, j + 0, k + 10, Blocks.sandstone, 0);
		setBlock(world, i + 14, j + 0, k + 11, Blocks.sandstone, 0);
		setBlock(world, i + 14, j + 0, k + 12, Blocks.sand, 0);
		setBlock(world, i + 14, j + 0, k + 13, Blocks.sandstone, 0);
		setBlock(world, i + 14, j + 0, k + 14, Blocks.sand, 0);
		setBlock(world, i + 14, j + 0, k + 15, Blocks.sandstone, 0);
		setBlock(world, i + 14, j + 0, k + 16, Blocks.sandstone, 0);
		setBlock(world, i + 14, j + 0, k + 17, Blocks.sandstone, 0);
		setBlock(world, i + 14, j + 0, k + 18, Blocks.sandstone, 0);
		setBlock(world, i + 14, j + 0, k + 19, Blocks.sandstone, 0);
		setBlock(world, i + 14, j + 0, k + 20, Blocks.sandstone, 0);
		setBlock(world, i + 14, j + 0, k + 21, Blocks.sandstone, 0);
		setBlock(world, i + 14, j + 0, k + 22, Blocks.sandstone, 0);
		setBlock(world, i + 14, j + 0, k + 23, Blocks.sandstone, 0);
		setBlock(world, i + 14, j + 1, k + 3, Blocks.sandstone, 0);
		setBlock(world, i + 14, j + 1, k + 23, Blocks.sandstone, 0);
		setBlock(world, i + 14, j + 2, k + 3, Blocks.sandstone, 0);
		setBlock(world, i + 14, j + 2, k + 23, Blocks.sandstone, 0);
		setBlock(world, i + 14, j + 3, k + 3, Blocks.sandstone, 0);
		setBlock(world, i + 14, j + 3, k + 23, Blocks.sandstone, 0);
		setBlock(world, i + 14, j + 4, k + 3, Blocks.sandstone, 0);
		setBlock(world, i + 14, j + 4, k + 23, Blocks.sandstone, 0);
		setBlock(world, i + 14, j + 5, k + 3, Blocks.sandstone, 0);
		setBlock(world, i + 14, j + 5, k + 23, Blocks.sandstone, 0);
		setBlock(world, i + 14, j + 6, k + 4, Blocks.sandstone, 0);
		setBlock(world, i + 14, j + 6, k + 5, Blocks.sandstone, 0);
		setBlock(world, i + 14, j + 6, k + 6, Blocks.sandstone, 0);
		setBlock(world, i + 14, j + 6, k + 20, Blocks.sandstone, 0);
		setBlock(world, i + 14, j + 6, k + 21, Blocks.sandstone, 0);
		setBlock(world, i + 14, j + 6, k + 22, Blocks.sandstone, 0);
		setBlock(world, i + 14, j + 7, k + 6, Blocks.sandstone, 0);
		setBlock(world, i + 14, j + 7, k + 20, Blocks.sandstone, 0);
		setBlock(world, i + 14, j + 8, k + 7, Blocks.sandstone, 0);
		setBlock(world, i + 14, j + 8, k + 19, Blocks.sandstone, 0);
		setBlock(world, i + 14, j + 9, k + 8, Blocks.sandstone, 0);
		setBlock(world, i + 14, j + 9, k + 18, Blocks.sandstone, 0);
		setBlock(world, i + 14, j + 10, k + 9, Blocks.sandstone, 0);
		setBlock(world, i + 14, j + 10, k + 10, Blocks.sandstone, 0);
		setBlock(world, i + 14, j + 10, k + 16, Blocks.sandstone, 0);
		setBlock(world, i + 14, j + 10, k + 17, Blocks.sandstone, 0);
		setBlock(world, i + 14, j + 11, k + 11, Blocks.sandstone, 0);
		setBlock(world, i + 14, j + 11, k + 12, Blocks.sandstone, 0);
		setBlock(world, i + 14, j + 11, k + 13, Blocks.sandstone, 0);
		setBlock(world, i + 14, j + 11, k + 14, Blocks.sandstone, 0);
		setBlock(world, i + 14, j + 11, k + 15, Blocks.sandstone, 0);
		setBlock(world, i + 15, j + 0, k + 3, Blocks.sandstone, 0);
		setBlock(world, i + 15, j + 0, k + 4, Blocks.sandstone, 0);
		setBlock(world, i + 15, j + 0, k + 5, Blocks.sandstone, 0);
		setBlock(world, i + 15, j + 0, k + 6, Blocks.sandstone, 0);
		setBlock(world, i + 15, j + 0, k + 7, Blocks.sandstone, 0);
		setBlock(world, i + 15, j + 0, k + 8, Blocks.sandstone, 0);
		setBlock(world, i + 15, j + 0, k + 9, Blocks.sandstone, 0);
		setBlock(world, i + 15, j + 0, k + 10, Blocks.sandstone, 0);
		setBlock(world, i + 15, j + 0, k + 11, Blocks.sand, 0);
		setBlock(world, i + 15, j + 0, k + 12, Blocks.sandstone, 0);
		setBlock(world, i + 15, j + 0, k + 13, Blocks.sand, 0);
		setBlock(world, i + 15, j + 0, k + 14, Blocks.sandstone, 0);
		setBlock(world, i + 15, j + 0, k + 15, Blocks.sand, 0);
		setBlock(world, i + 15, j + 0, k + 16, Blocks.sandstone, 0);
		setBlock(world, i + 15, j + 0, k + 17, Blocks.sandstone, 0);
		setBlock(world, i + 15, j + 0, k + 18, Blocks.sandstone, 0);
		setBlock(world, i + 15, j + 0, k + 19, Blocks.sandstone, 0);
		setBlock(world, i + 15, j + 0, k + 20, Blocks.sandstone, 0);
		setBlock(world, i + 15, j + 0, k + 21, Blocks.sandstone, 0);
		setBlock(world, i + 15, j + 0, k + 22, Blocks.sandstone, 0);
		setBlock(world, i + 15, j + 0, k + 23, Blocks.sandstone, 0);
		setBlock(world, i + 15, j + 1, k + 3, Blocks.sandstone, 0);
		setBlock(world, i + 15, j + 1, k + 4, Blocks.sandstone, 0);
		setBlock(world, i + 15, j + 1, k + 5, Blocks.sandstone, 0);
		setBlock(world, i + 15, j + 1, k + 21, Blocks.sandstone, 0);
		setBlock(world, i + 15, j + 1, k + 22, Blocks.sandstone, 0);
		setBlock(world, i + 15, j + 1, k + 23, Blocks.sandstone, 0);
		setBlock(world, i + 15, j + 2, k + 3, Blocks.sandstone, 0);
		setBlock(world, i + 15, j + 2, k + 4, Blocks.sandstone, 0);
		setBlock(world, i + 15, j + 2, k + 5, Blocks.sandstone, 0);
		setBlock(world, i + 15, j + 2, k + 21, Blocks.sandstone, 0);
		setBlock(world, i + 15, j + 2, k + 22, Blocks.sandstone, 0);
		setBlock(world, i + 15, j + 2, k + 23, Blocks.sandstone, 0);
		setBlock(world, i + 15, j + 3, k + 4, Blocks.sandstone, 0);
		setBlock(world, i + 15, j + 3, k + 5, Blocks.sandstone, 0);
		setBlock(world, i + 15, j + 3, k + 21, Blocks.sandstone, 0);
		setBlock(world, i + 15, j + 3, k + 22, Blocks.sandstone, 0);
		setBlock(world, i + 15, j + 4, k + 4, Blocks.sandstone, 0);
		setBlock(world, i + 15, j + 4, k + 5, Blocks.sandstone, 0);
		setBlock(world, i + 15, j + 4, k + 21, Blocks.sandstone, 0);
		setBlock(world, i + 15, j + 4, k + 22, Blocks.sandstone, 0);
		setBlock(world, i + 15, j + 5, k + 4, Blocks.sandstone, 0);
		setBlock(world, i + 15, j + 5, k + 5, Blocks.sandstone, 0);
		setBlock(world, i + 15, j + 5, k + 21, Blocks.sandstone, 0);
		setBlock(world, i + 15, j + 5, k + 22, Blocks.sandstone, 0);
		setBlock(world, i + 15, j + 6, k + 6, Blocks.sandstone, 0);
		setBlock(world, i + 15, j + 6, k + 20, Blocks.sandstone, 0);
		setBlock(world, i + 15, j + 7, k + 6, Blocks.sandstone, 0);
		setBlock(world, i + 15, j + 7, k + 20, Blocks.sandstone, 0);
		setBlock(world, i + 15, j + 8, k + 7, Blocks.sandstone, 0);
		setBlock(world, i + 15, j + 8, k + 19, Blocks.sandstone, 0);
		setBlock(world, i + 15, j + 9, k + 8, Blocks.sandstone, 0);
		setBlock(world, i + 15, j + 9, k + 18, Blocks.sandstone, 0);
		setBlock(world, i + 15, j + 10, k + 9, Blocks.sandstone, 0);
		setBlock(world, i + 15, j + 10, k + 10, Blocks.sandstone, 0);
		setBlock(world, i + 15, j + 10, k + 16, Blocks.sandstone, 0);
		setBlock(world, i + 15, j + 10, k + 17, Blocks.sandstone, 0);
		setBlock(world, i + 15, j + 11, k + 11, Blocks.sandstone, 0);
		setBlock(world, i + 15, j + 11, k + 12, Blocks.sandstone, 0);
		setBlock(world, i + 15, j + 11, k + 13, Blocks.sandstone, 0);
		setBlock(world, i + 15, j + 11, k + 14, Blocks.sandstone, 0);
		setBlock(world, i + 15, j + 11, k + 15, Blocks.sandstone, 0);
		setBlock(world, i + 16, j + 0, k + 6, Blocks.sandstone, 0);
		setBlock(world, i + 16, j + 0, k + 7, Blocks.sandstone, 0);
		setBlock(world, i + 16, j + 0, k + 8, Blocks.sandstone, 0);
		setBlock(world, i + 16, j + 0, k + 9, Blocks.sandstone, 0);
		setBlock(world, i + 16, j + 0, k + 10, Blocks.sand, 0);
		setBlock(world, i + 16, j + 0, k + 11, Blocks.sandstone, 0);
		setBlock(world, i + 16, j + 0, k + 12, Blocks.sandstone, 0);
		setBlock(world, i + 16, j + 0, k + 13, Blocks.sandstone, 0);
		setBlock(world, i + 16, j + 0, k + 14, Blocks.sandstone, 0);
		setBlock(world, i + 16, j + 0, k + 15, Blocks.sandstone, 0);
		setBlock(world, i + 16, j + 0, k + 16, Blocks.sand, 0);
		setBlock(world, i + 16, j + 0, k + 17, Blocks.sandstone, 0);
		setBlock(world, i + 16, j + 0, k + 18, Blocks.sandstone, 0);
		setBlock(world, i + 16, j + 0, k + 19, Blocks.sandstone, 0);
		setBlock(world, i + 16, j + 0, k + 20, Blocks.sandstone, 0);
		setBlock(world, i + 16, j + 1, k + 6, Blocks.sandstone, 0);
		setBlock(world, i + 16, j + 1, k + 20, Blocks.sandstone, 0);
		setBlock(world, i + 16, j + 2, k + 6, Blocks.sandstone, 0);
		setBlock(world, i + 16, j + 2, k + 20, Blocks.sandstone, 0);
		setBlock(world, i + 16, j + 3, k + 6, Blocks.sandstone, 0);
		setBlock(world, i + 16, j + 3, k + 20, Blocks.sandstone, 0);
		setBlock(world, i + 16, j + 4, k + 6, Blocks.sandstone, 0);
		setBlock(world, i + 16, j + 4, k + 20, Blocks.sandstone, 0);
		setBlock(world, i + 16, j + 5, k + 6, Blocks.sandstone, 0);
		setBlock(world, i + 16, j + 5, k + 20, Blocks.sandstone, 0);
		setBlock(world, i + 16, j + 6, k + 6, Blocks.sandstone, 0);
		setBlock(world, i + 16, j + 6, k + 20, Blocks.sandstone, 0);
		setBlock(world, i + 16, j + 7, k + 7, Blocks.sandstone, 0);
		setBlock(world, i + 16, j + 7, k + 19, Blocks.sandstone, 0);
		setBlock(world, i + 16, j + 8, k + 7, Blocks.sandstone, 0);
		setBlock(world, i + 16, j + 8, k + 19, Blocks.sandstone, 0);
		setBlock(world, i + 16, j + 9, k + 8, Blocks.sandstone, 0);
		setBlock(world, i + 16, j + 9, k + 9, Blocks.sandstone, 0);
		setBlock(world, i + 16, j + 9, k + 17, Blocks.sandstone, 0);
		setBlock(world, i + 16, j + 9, k + 18, Blocks.sandstone, 0);
		setBlock(world, i + 16, j + 10, k + 10, Blocks.sandstone, 0);
		setBlock(world, i + 16, j + 10, k + 11, Blocks.sandstone, 0);
		setBlock(world, i + 16, j + 10, k + 12, Blocks.sandstone, 0);
		setBlock(world, i + 16, j + 10, k + 13, Blocks.sandstone, 0);
		setBlock(world, i + 16, j + 10, k + 14, Blocks.sandstone, 0);
		setBlock(world, i + 16, j + 10, k + 15, Blocks.sandstone, 0);
		setBlock(world, i + 16, j + 10, k + 16, Blocks.sandstone, 0);
		setBlock(world, i + 17, j + 0, k + 6, Blocks.sandstone, 0);
		setBlock(world, i + 17, j + 0, k + 7, Blocks.sandstone, 0);
		setBlock(world, i + 17, j + 0, k + 8, Blocks.sandstone, 0);
		setBlock(world, i + 17, j + 0, k + 9, Blocks.sand, 0);
		setBlock(world, i + 17, j + 0, k + 10, Blocks.sandstone, 0);
		setBlock(world, i + 17, j + 0, k + 11, Blocks.sandstone, 0);
		setBlock(world, i + 17, j + 0, k + 12, Blocks.sandstone, 0);
		setBlock(world, i + 17, j + 0, k + 13, Blocks.sand, 0);
		setBlock(world, i + 17, j + 0, k + 14, Blocks.sandstone, 0);
		setBlock(world, i + 17, j + 0, k + 15, Blocks.sandstone, 0);
		setBlock(world, i + 17, j + 0, k + 16, Blocks.sandstone, 0);
		setBlock(world, i + 17, j + 0, k + 17, Blocks.sand, 0);
		setBlock(world, i + 17, j + 0, k + 18, Blocks.sandstone, 0);
		setBlock(world, i + 17, j + 0, k + 19, Blocks.sandstone, 0);
		setBlock(world, i + 17, j + 0, k + 20, Blocks.sandstone, 0);
		setBlock(world, i + 17, j + 1, k + 6, Blocks.sandstone, 0);
		setBlock(world, i + 17, j + 1, k + 20, Blocks.sandstone, 0);
		setBlock(world, i + 17, j + 2, k + 6, Blocks.sandstone, 0);
		setBlock(world, i + 17, j + 2, k + 20, Blocks.sandstone, 0);
		setBlock(world, i + 17, j + 3, k + 6, Blocks.sandstone, 0);
		setBlock(world, i + 17, j + 3, k + 20, Blocks.sandstone, 0);
		setBlock(world, i + 17, j + 4, k + 6, Blocks.sandstone, 0);
		setBlock(world, i + 17, j + 4, k + 20, Blocks.sandstone, 0);
		setBlock(world, i + 17, j + 5, k + 6, Blocks.sandstone, 0);
		setBlock(world, i + 17, j + 5, k + 20, Blocks.sandstone, 0);
		setBlock(world, i + 17, j + 6, k + 7, Blocks.sandstone, 0);
		setBlock(world, i + 17, j + 6, k + 19, Blocks.sandstone, 0);
		setBlock(world, i + 17, j + 7, k + 7, Blocks.sandstone, 0);
		setBlock(world, i + 17, j + 7, k + 19, Blocks.sandstone, 0);
		setBlock(world, i + 17, j + 8, k + 8, Blocks.sandstone, 0);
		setBlock(world, i + 17, j + 8, k + 18, Blocks.sandstone, 0);
		setBlock(world, i + 17, j + 9, k + 9, Blocks.sandstone, 0);
		setBlock(world, i + 17, j + 9, k + 10, Blocks.sandstone, 0);
		setBlock(world, i + 17, j + 9, k + 16, Blocks.sandstone, 0);
		setBlock(world, i + 17, j + 9, k + 17, Blocks.sandstone, 0);
		setBlock(world, i + 17, j + 10, k + 11, Blocks.sandstone, 0);
		setBlock(world, i + 17, j + 10, k + 12, Blocks.sandstone, 0);
		setBlock(world, i + 17, j + 10, k + 13, Blocks.sandstone, 0);
		setBlock(world, i + 17, j + 10, k + 14, Blocks.sandstone, 0);
		setBlock(world, i + 17, j + 10, k + 15, Blocks.sandstone, 0);
		setBlock(world, i + 18, j + 0, k + 7, Blocks.sandstone, 0);
		setBlock(world, i + 18, j + 0, k + 8, Blocks.sand, 0);
		setBlock(world, i + 18, j + 0, k + 9, Blocks.sandstone, 0);
		setBlock(world, i + 18, j + 0, k + 10, Blocks.sandstone, 0);
		setBlock(world, i + 18, j + 0, k + 11, Blocks.sandstone, 0);
		setBlock(world, i + 18, j + 0, k + 12, Blocks.sandstone, 0);
		setBlock(world, i + 18, j + 0, k + 13, Blocks.sandstone, 0);
		setBlock(world, i + 18, j + 0, k + 14, Blocks.sandstone, 0);
		setBlock(world, i + 18, j + 0, k + 15, Blocks.sandstone, 0);
		setBlock(world, i + 18, j + 0, k + 16, Blocks.sandstone, 0);
		setBlock(world, i + 18, j + 0, k + 17, Blocks.sandstone, 0);
		setBlock(world, i + 18, j + 0, k + 18, Blocks.sand, 0);
		setBlock(world, i + 18, j + 0, k + 19, Blocks.sandstone, 0);
		setBlock(world, i + 18, j + 1, k + 7, Blocks.sandstone, 0);
		setBlock(world, i + 18, j + 1, k + 19, Blocks.sandstone, 0);
		setBlock(world, i + 18, j + 2, k + 7, Blocks.sandstone, 0);
		setBlock(world, i + 18, j + 2, k + 19, Blocks.sandstone, 0);
		setBlock(world, i + 18, j + 3, k + 7, Blocks.sandstone, 0);
		setBlock(world, i + 18, j + 3, k + 19, Blocks.sandstone, 0);
		setBlock(world, i + 18, j + 4, k + 7, Blocks.sandstone, 0);
		setBlock(world, i + 18, j + 4, k + 19, Blocks.sandstone, 0);
		setBlock(world, i + 18, j + 5, k + 7, Blocks.sandstone, 0);
		setBlock(world, i + 18, j + 5, k + 19, Blocks.sandstone, 0);
		setBlock(world, i + 18, j + 6, k + 7, Blocks.sandstone, 0);
		setBlock(world, i + 18, j + 6, k + 19, Blocks.sandstone, 0);
		setBlock(world, i + 18, j + 7, k + 8, Blocks.sandstone, 0);
		setBlock(world, i + 18, j + 7, k + 18, Blocks.sandstone, 0);
		setBlock(world, i + 18, j + 8, k + 9, Blocks.sandstone, 0);
		setBlock(world, i + 18, j + 8, k + 17, Blocks.sandstone, 0);
		setBlock(world, i + 18, j + 9, k + 10, Blocks.sandstone, 0);
		setBlock(world, i + 18, j + 9, k + 11, Blocks.sandstone, 0);
		setBlock(world, i + 18, j + 9, k + 12, Blocks.sandstone, 0);
		setBlock(world, i + 18, j + 9, k + 13, Blocks.sandstone, 0);
		setBlock(world, i + 18, j + 9, k + 14, Blocks.sandstone, 0);
		setBlock(world, i + 18, j + 9, k + 15, Blocks.sandstone, 0);
		setBlock(world, i + 18, j + 9, k + 16, Blocks.sandstone, 0);
		setBlock(world, i + 19, j + 0, k + 7, Blocks.sandstone, 0);
		setBlock(world, i + 19, j + 0, k + 8, Blocks.sandstone, 0);
		setBlock(world, i + 19, j + 0, k + 9, Blocks.sandstone, 0);
		setBlock(world, i + 19, j + 0, k + 10, Blocks.sandstone, 0);
		setBlock(world, i + 19, j + 0, k + 11, Blocks.sandstone, 0);
		setBlock(world, i + 19, j + 0, k + 12, Blocks.sandstone, 0);
		setBlock(world, i + 19, j + 0, k + 13, Blocks.glowstone, 0);
		setBlock(world, i + 19, j + 0, k + 14, Blocks.sandstone, 0);
		setBlock(world, i + 19, j + 0, k + 15, Blocks.sandstone, 0);
		setBlock(world, i + 19, j + 0, k + 16, Blocks.sandstone, 0);
		setBlock(world, i + 19, j + 0, k + 17, Blocks.sandstone, 0);
		setBlock(world, i + 19, j + 0, k + 18, Blocks.sandstone, 0);
		setBlock(world, i + 19, j + 0, k + 19, Blocks.sandstone, 0);
		setBlock(world, i + 19, j + 1, k + 7, Blocks.sandstone, 0);
		setBlock(world, i + 19, j + 1, k + 8, Blocks.sandstone, 0);
		setBlock(world, i + 19, j + 1, k + 18, Blocks.sandstone, 0);
		setBlock(world, i + 19, j + 1, k + 19, Blocks.sandstone, 0);
		setBlock(world, i + 19, j + 2, k + 7, Blocks.sandstone, 0);
		setBlock(world, i + 19, j + 2, k + 8, Blocks.sandstone, 0);
		setBlock(world, i + 19, j + 2, k + 18, Blocks.sandstone, 0);
		setBlock(world, i + 19, j + 2, k + 19, Blocks.sandstone, 0);
		setBlock(world, i + 19, j + 3, k + 7, Blocks.sandstone, 0);
		setBlock(world, i + 19, j + 3, k + 8, Blocks.sandstone, 0);
		setBlock(world, i + 19, j + 3, k + 18, Blocks.sandstone, 0);
		setBlock(world, i + 19, j + 3, k + 19, Blocks.sandstone, 0);
		setBlock(world, i + 19, j + 4, k + 8, Blocks.sandstone, 0);
		setBlock(world, i + 19, j + 4, k + 18, Blocks.sandstone, 0);
		setBlock(world, i + 19, j + 5, k + 8, Blocks.sandstone, 0);
		setBlock(world, i + 19, j + 5, k + 18, Blocks.sandstone, 0);
		setBlock(world, i + 19, j + 6, k + 8, Blocks.sandstone, 0);
		setBlock(world, i + 19, j + 6, k + 9, Blocks.sandstone, 0);
		setBlock(world, i + 19, j + 6, k + 17, Blocks.sandstone, 0);
		setBlock(world, i + 19, j + 6, k + 18, Blocks.sandstone, 0);
		setBlock(world, i + 19, j + 7, k + 9, Blocks.sandstone, 0);
		setBlock(world, i + 19, j + 7, k + 10, Blocks.sandstone, 0);
		setBlock(world, i + 19, j + 7, k + 16, Blocks.sandstone, 0);
		setBlock(world, i + 19, j + 7, k + 17, Blocks.sandstone, 0);
		setBlock(world, i + 19, j + 8, k + 10, Blocks.sandstone, 0);
		setBlock(world, i + 19, j + 8, k + 11, Blocks.sandstone, 0);
		setBlock(world, i + 19, j + 8, k + 12, Blocks.sandstone, 0);
		setBlock(world, i + 19, j + 8, k + 13, Blocks.sandstone, 0);
		setBlock(world, i + 19, j + 8, k + 14, Blocks.sandstone, 0);
		setBlock(world, i + 19, j + 8, k + 15, Blocks.sandstone, 0);
		setBlock(world, i + 19, j + 8, k + 16, Blocks.sandstone, 0);
		setBlock(world, i + 19, j + 9, k + 13, Blocks.sandstone, 0);
		setBlock(world, i + 20, j + 0, k + 9, Blocks.sandstone, 0);
		setBlock(world, i + 20, j + 0, k + 10, Blocks.sandstone, 0);
		setBlock(world, i + 20, j + 0, k + 11, Blocks.sandstone, 0);
		setBlock(world, i + 20, j + 0, k + 12, Blocks.sandstone, 0);
		setBlock(world, i + 20, j + 0, k + 13, Blocks.sandstone, 0);
		setBlock(world, i + 20, j + 0, k + 14, Blocks.sandstone, 0);
		setBlock(world, i + 20, j + 0, k + 15, Blocks.sandstone, 0);
		setBlock(world, i + 20, j + 0, k + 16, Blocks.sandstone, 0);
		setBlock(world, i + 20, j + 0, k + 17, Blocks.sandstone, 0);
		setBlock(world, i + 20, j + 1, k + 9, Blocks.sandstone, 0);
		setBlock(world, i + 20, j + 1, k + 10, Blocks.sandstone, 0);
		setBlock(world, i + 20, j + 1, k + 16, Blocks.sandstone, 0);
		setBlock(world, i + 20, j + 1, k + 17, Blocks.sandstone, 0);
		setBlock(world, i + 20, j + 2, k + 9, Blocks.sandstone, 0);
		setBlock(world, i + 20, j + 2, k + 10, Blocks.sandstone, 0);
		setBlock(world, i + 20, j + 2, k + 16, Blocks.sandstone, 0);
		setBlock(world, i + 20, j + 2, k + 17, Blocks.sandstone, 0);
		setBlock(world, i + 20, j + 3, k + 9, Blocks.sandstone, 0);
		setBlock(world, i + 20, j + 3, k + 10, Blocks.sandstone, 0);
		setBlock(world, i + 20, j + 3, k + 16, Blocks.sandstone, 0);
		setBlock(world, i + 20, j + 3, k + 17, Blocks.sandstone, 0);
		setBlock(world, i + 20, j + 4, k + 9, Blocks.sandstone, 0);
		setBlock(world, i + 20, j + 4, k + 10, Blocks.sandstone, 0);
		setBlock(world, i + 20, j + 4, k + 16, Blocks.sandstone, 0);
		setBlock(world, i + 20, j + 4, k + 17, Blocks.sandstone, 0);
		setBlock(world, i + 20, j + 5, k + 9, Blocks.sandstone, 0);
		setBlock(world, i + 20, j + 5, k + 10, Blocks.sandstone, 0);
		setBlock(world, i + 20, j + 5, k + 16, Blocks.sandstone, 0);
		setBlock(world, i + 20, j + 5, k + 17, Blocks.sandstone, 0);
		setBlock(world, i + 20, j + 6, k + 10, Blocks.sandstone, 0);
		setBlock(world, i + 20, j + 6, k + 11, Blocks.sandstone, 0);
		setBlock(world, i + 20, j + 6, k + 12, Blocks.sandstone, 0);
		setBlock(world, i + 20, j + 6, k + 13, Blocks.sandstone, 0);
		setBlock(world, i + 20, j + 6, k + 14, Blocks.sandstone, 0);
		setBlock(world, i + 20, j + 6, k + 15, Blocks.sandstone, 0);
		setBlock(world, i + 20, j + 6, k + 16, Blocks.sandstone, 0);
		setBlock(world, i + 20, j + 7, k + 11, Blocks.sandstone, 0);
		setBlock(world, i + 20, j + 7, k + 12, Blocks.sandstone, 0);
		setBlock(world, i + 20, j + 7, k + 13, Blocks.sandstone, 0);
		setBlock(world, i + 20, j + 7, k + 14, Blocks.sandstone, 0);
		setBlock(world, i + 20, j + 7, k + 15, Blocks.sandstone, 0);
		setBlock(world, i + 21, j + 0, k + 11, Blocks.sandstone, 0);
		setBlock(world, i + 21, j + 0, k + 12, Blocks.sandstone, 0);
		setBlock(world, i + 21, j + 0, k + 13, Blocks.sandstone, 0);
		setBlock(world, i + 21, j + 0, k + 14, Blocks.sandstone, 0);
		setBlock(world, i + 21, j + 0, k + 15, Blocks.sandstone, 0);
		setBlock(world, i + 21, j + 1, k + 11, Blocks.sandstone, 0);
		setBlock(world, i + 21, j + 1, k + 12, Blocks.sandstone, 0);
		setBlock(world, i + 21, j + 1, k + 13, Blocks.sandstone, 0);
		setBlock(world, i + 21, j + 1, k + 14, Blocks.sandstone, 0);
		setBlock(world, i + 21, j + 1, k + 15, Blocks.sandstone, 0);
		setBlock(world, i + 21, j + 2, k + 11, Blocks.sandstone, 0);
		setBlock(world, i + 21, j + 2, k + 15, Blocks.sandstone, 0);
		setBlock(world, i + 21, j + 3, k + 11, Blocks.sandstone, 0);
		setBlock(world, i + 21, j + 3, k + 15, Blocks.sandstone, 0);
		setBlock(world, i + 21, j + 4, k + 11, Blocks.sandstone, 0);
		setBlock(world, i + 21, j + 4, k + 15, Blocks.sandstone, 0);
		setBlock(world, i + 21, j + 5, k + 11, Blocks.sandstone, 0);
		setBlock(world, i + 21, j + 5, k + 12, Blocks.sandstone, 0);
		setBlock(world, i + 21, j + 5, k + 13, Blocks.sandstone, 0);
		setBlock(world, i + 21, j + 5, k + 14, Blocks.sandstone, 0);
		setBlock(world, i + 21, j + 5, k + 15, Blocks.sandstone, 0);
		setBlock(world, i + 0, j + 3, k + 11, Blocks.stone_slab, 1);
		world.setBlockMetadataWithNotify(i + 0, j + 3, k + 11, 1, 2);
		setBlock(world, i + 0, j + 3, k + 15, Blocks.stone_slab, 1);
		world.setBlockMetadataWithNotify(i + 0, j + 3, k + 15, 1, 2);
		setBlock(world, i + 1, j + 3, k + 11, Blocks.stone_slab, 1);
		world.setBlockMetadataWithNotify(i + 1, j + 3, k + 11, 1, 2);
		setBlock(world, i + 1, j + 3, k + 15, Blocks.stone_slab, 1);
		world.setBlockMetadataWithNotify(i + 1, j + 3, k + 15, 1, 2);
		setBlock(world, i + 2, j + 2, k + 12, Blocks.sandstone_stairs, 1);
		world.setBlockMetadataWithNotify(i + 2, j + 2, k + 12, 1, 2);
		setBlock(world, i + 2, j + 2, k + 13, Blocks.sandstone_stairs, 1);
		world.setBlockMetadataWithNotify(i + 2, j + 2, k + 13, 1, 2);
		setBlock(world, i + 2, j + 2, k + 14, Blocks.sandstone_stairs, 1);
		world.setBlockMetadataWithNotify(i + 2, j + 2, k + 14, 1, 2);
		setBlock(world, i + 3, j + 4, k + 11, Blocks.sandstone, 1);
		world.setBlockMetadataWithNotify(i + 3, j + 4, k + 11, 1, 2);
		setBlock(world, i + 3, j + 4, k + 12, Blocks.torch, 3);
		world.setBlockMetadataWithNotify(i + 3, j + 4, k + 12, 3, 2);
		setBlock(world, i + 3, j + 4, k + 14, Blocks.torch, 4);
		world.setBlockMetadataWithNotify(i + 3, j + 4, k + 14, 4, 2);
		setBlock(world, i + 3, j + 4, k + 15, Blocks.sandstone, 1);
		world.setBlockMetadataWithNotify(i + 3, j + 4, k + 15, 1, 2);
		setBlock(world, i + 3, j + 5, k + 11, Blocks.sandstone, 1);
		world.setBlockMetadataWithNotify(i + 3, j + 5, k + 11, 1, 2);
		setBlock(world, i + 3, j + 5, k + 15, Blocks.sandstone, 1);
		world.setBlockMetadataWithNotify(i + 3, j + 5, k + 15, 1, 2);
		setBlock(world, i + 3, j + 6, k + 11, Blocks.sandstone_stairs, 2);
		world.setBlockMetadataWithNotify(i + 3, j + 6, k + 11, 2, 2);
		setBlock(world, i + 3, j + 6, k + 12, Blocks.sandstone, 1);
		world.setBlockMetadataWithNotify(i + 3, j + 6, k + 12, 1, 2);
		setBlock(world, i + 3, j + 6, k + 13, Blocks.sandstone, 1);
		world.setBlockMetadataWithNotify(i + 3, j + 6, k + 13, 1, 2);
		setBlock(world, i + 3, j + 6, k + 14, Blocks.sandstone, 1);
		world.setBlockMetadataWithNotify(i + 3, j + 6, k + 14, 1, 2);
		setBlock(world, i + 3, j + 6, k + 15, Blocks.sandstone_stairs, 3);
		world.setBlockMetadataWithNotify(i + 3, j + 6, k + 15, 3, 2);
		setBlock(world, i + 4, j + 1, k + 12, Blocks.sandstone_stairs, 1);
		world.setBlockMetadataWithNotify(i + 4, j + 1, k + 12, 1, 2);
		setBlock(world, i + 4, j + 1, k + 13, Blocks.sandstone_stairs, 1);
		world.setBlockMetadataWithNotify(i + 4, j + 1, k + 13, 1, 2);
		setBlock(world, i + 4, j + 1, k + 14, Blocks.sandstone_stairs, 1);
		world.setBlockMetadataWithNotify(i + 4, j + 1, k + 14, 1, 2);
		setBlock(world, i + 4, j + 6, k + 11, Blocks.sandstone_stairs, 2);
		world.setBlockMetadataWithNotify(i + 4, j + 6, k + 11, 2, 2);
		setBlock(world, i + 4, j + 6, k + 15, Blocks.sandstone_stairs, 3);
		world.setBlockMetadataWithNotify(i + 4, j + 6, k + 15, 3, 2);
		setBlock(world, i + 5, j + 6, k + 11, Blocks.sandstone_stairs, 2);
		world.setBlockMetadataWithNotify(i + 5, j + 6, k + 11, 2, 2);
		setBlock(world, i + 5, j + 6, k + 15, Blocks.sandstone_stairs, 3);
		world.setBlockMetadataWithNotify(i + 5, j + 6, k + 15, 3, 2);
		setBlock(world, i + 6, j + 4, k + 11, Blocks.torch, 3);
		world.setBlockMetadataWithNotify(i + 6, j + 4, k + 11, 3, 2);
		setBlock(world, i + 6, j + 4, k + 15, Blocks.torch, 4);
		world.setBlockMetadataWithNotify(i + 6, j + 4, k + 15, 4, 2);
		setBlock(world, i + 7, j + 1, k + 13, Blocks.carpet, 1);
		world.setBlockMetadataWithNotify(i + 7, j + 1, k + 13, 1, 2);
		setBlock(world, i + 8, j + 7, k + 9, Blocks.torch, 3);
		world.setBlockMetadataWithNotify(i + 8, j + 7, k + 9, 3, 2);
		setBlock(world, i + 8, j + 7, k + 17, Blocks.torch, 4);
		world.setBlockMetadataWithNotify(i + 8, j + 7, k + 17, 4, 2);
		setBlock(world, i + 9, j + 7, k + 8, Blocks.torch, 1);
		world.setBlockMetadataWithNotify(i + 9, j + 7, k + 8, 1, 2);
		setBlock(world, i + 9, j + 7, k + 18, Blocks.torch, 1);
		world.setBlockMetadataWithNotify(i + 9, j + 7, k + 18, 1, 2);
		setBlock(world, i + 9, j + 9, k + 11, Blocks.torch, 3);
		world.setBlockMetadataWithNotify(i + 9, j + 9, k + 11, 3, 2);
		setBlock(world, i + 9, j + 9, k + 15, Blocks.torch, 4);
		world.setBlockMetadataWithNotify(i + 9, j + 9, k + 15, 4, 2);
		setBlock(world, i + 11, j + 3, k + 3, Blocks.sandstone, 1);
		world.setBlockMetadataWithNotify(i + 11, j + 3, k + 3, 1, 2);
		setBlock(world, i + 11, j + 3, k + 23, Blocks.sandstone, 1);
		world.setBlockMetadataWithNotify(i + 11, j + 3, k + 23, 1, 2);
		setBlock(world, i + 11, j + 4, k + 3, Blocks.sandstone, 1);
		world.setBlockMetadataWithNotify(i + 11, j + 4, k + 3, 1, 2);
		setBlock(world, i + 11, j + 4, k + 23, Blocks.sandstone, 1);
		world.setBlockMetadataWithNotify(i + 11, j + 4, k + 23, 1, 2);
		setBlock(world, i + 11, j + 5, k + 3, Blocks.sandstone, 1);
		world.setBlockMetadataWithNotify(i + 11, j + 5, k + 3, 1, 2);
		setBlock(world, i + 11, j + 5, k + 23, Blocks.sandstone, 1);
		world.setBlockMetadataWithNotify(i + 11, j + 5, k + 23, 1, 2);
		setBlock(world, i + 11, j + 9, k + 9, Blocks.torch, 1);
		world.setBlockMetadataWithNotify(i + 11, j + 9, k + 9, 1, 2);
		setBlock(world, i + 11, j + 9, k + 17, Blocks.torch, 1);
		world.setBlockMetadataWithNotify(i + 11, j + 9, k + 17, 1, 2);
		setBlock(world, i + 11, j + 10, k + 13, Blocks.torch, 1);
		world.setBlockMetadataWithNotify(i + 11, j + 10, k + 13, 1, 2);
		setBlock(world, i + 12, j + 4, k + 22, Blocks.torch, 1);
		world.setBlockMetadataWithNotify(i + 12, j + 4, k + 22, 1, 2);
		setBlock(world, i + 12, j + 5, k + 4, Blocks.torch, 1);
		world.setBlockMetadataWithNotify(i + 12, j + 5, k + 4, 1, 2);
		setBlock(world, i + 12, j + 6, k + 3, Blocks.sandstone, 1);
		world.setBlockMetadataWithNotify(i + 12, j + 6, k + 3, 1, 2);
		setBlock(world, i + 12, j + 6, k + 23, Blocks.sandstone, 1);
		world.setBlockMetadataWithNotify(i + 12, j + 6, k + 23, 1, 2);
		setBlock(world, i + 13, j + 1, k + 4, Blocks.chest, 3);
		world.setBlockMetadataWithNotify(i + 13, j + 1, k + 4, 3, 2);
		LootGenUtils.fillLootChest(world.provider.dimensionId, world.rand, (TileEntityChest)world.getTileEntity(i + 13, j + 1, k + 4));
		setBlock(world, i + 13, j + 1, k + 5, Blocks.carpet, 1);
		world.setBlockMetadataWithNotify(i + 13, j + 1, k + 5, 1, 2);
		setBlock(world, i + 13, j + 1, k + 13, Blocks.carpet, 1);
		world.setBlockMetadataWithNotify(i + 13, j + 1, k + 13, 1, 2);
		setBlock(world, i + 13, j + 1, k + 21, Blocks.carpet, 1);
		world.setBlockMetadataWithNotify(i + 13, j + 1, k + 21, 1, 2);
		setBlock(world, i + 13, j + 1, k + 22, Blocks.chest, 2);
		world.setBlockMetadataWithNotify(i + 13, j + 1, k + 22, 2, 2);
		LootGenUtils.fillLootChest(world.provider.dimensionId, world.rand, (TileEntityChest)world.getTileEntity(i + 13, j + 1, k + 22));
		setBlock(world, i + 13, j + 2, k + 3, Blocks.sandstone, 1);
		world.setBlockMetadataWithNotify(i + 13, j + 2, k + 3, 1, 2);
		setBlock(world, i + 13, j + 2, k + 23, Blocks.sandstone, 1);
		world.setBlockMetadataWithNotify(i + 13, j + 2, k + 23, 1, 2);
		setBlock(world, i + 13, j + 3, k + 3, Blocks.sandstone, 1);
		world.setBlockMetadataWithNotify(i + 13, j + 3, k + 3, 1, 2);
		setBlock(world, i + 13, j + 3, k + 23, Blocks.sandstone, 1);
		world.setBlockMetadataWithNotify(i + 13, j + 3, k + 23, 1, 2);
		setBlock(world, i + 13, j + 4, k + 3, Blocks.sandstone, 1);
		world.setBlockMetadataWithNotify(i + 13, j + 4, k + 3, 1, 2);
		setBlock(world, i + 13, j + 4, k + 23, Blocks.sandstone, 1);
		world.setBlockMetadataWithNotify(i + 13, j + 4, k + 23, 1, 2);
		setBlock(world, i + 13, j + 6, k + 3, Blocks.sandstone, 1);
		world.setBlockMetadataWithNotify(i + 13, j + 6, k + 3, 1, 2);
		setBlock(world, i + 13, j + 6, k + 23, Blocks.sandstone, 1);
		world.setBlockMetadataWithNotify(i + 13, j + 6, k + 23, 1, 2);
		setBlock(world, i + 13, j + 10, k + 11, Blocks.torch, 3);
		world.setBlockMetadataWithNotify(i + 13, j + 10, k + 11, 3, 2);
		setBlock(world, i + 13, j + 10, k + 15, Blocks.torch, 4);
		world.setBlockMetadataWithNotify(i + 13, j + 10, k + 15, 4, 2);
		setBlock(world, i + 14, j + 4, k + 22, Blocks.torch, 2);
		world.setBlockMetadataWithNotify(i + 14, j + 4, k + 22, 2, 2);
		setBlock(world, i + 14, j + 5, k + 4, Blocks.torch, 2);
		world.setBlockMetadataWithNotify(i + 14, j + 5, k + 4, 2, 2);
		setBlock(world, i + 14, j + 6, k + 3, Blocks.sandstone, 1);
		world.setBlockMetadataWithNotify(i + 14, j + 6, k + 3, 1, 2);
		setBlock(world, i + 14, j + 6, k + 23, Blocks.sandstone, 1);
		world.setBlockMetadataWithNotify(i + 14, j + 6, k + 23, 1, 2);
		setBlock(world, i + 15, j + 3, k + 3, Blocks.sandstone, 1);
		world.setBlockMetadataWithNotify(i + 15, j + 3, k + 3, 1, 2);
		setBlock(world, i + 15, j + 3, k + 23, Blocks.sandstone, 1);
		world.setBlockMetadataWithNotify(i + 15, j + 3, k + 23, 1, 2);
		setBlock(world, i + 15, j + 4, k + 3, Blocks.sandstone, 1);
		world.setBlockMetadataWithNotify(i + 15, j + 4, k + 3, 1, 2);
		setBlock(world, i + 15, j + 4, k + 23, Blocks.sandstone, 1);
		world.setBlockMetadataWithNotify(i + 15, j + 4, k + 23, 1, 2);
		setBlock(world, i + 15, j + 5, k + 3, Blocks.sandstone, 1);
		world.setBlockMetadataWithNotify(i + 15, j + 5, k + 3, 1, 2);
		setBlock(world, i + 15, j + 5, k + 23, Blocks.sandstone, 1);
		world.setBlockMetadataWithNotify(i + 15, j + 5, k + 23, 1, 2);
		setBlock(world, i + 15, j + 6, k + 3, Blocks.sandstone_stairs, 1);
		world.setBlockMetadataWithNotify(i + 15, j + 6, k + 3, 1, 2);
		setBlock(world, i + 15, j + 6, k + 4, Blocks.sandstone_stairs, 1);
		world.setBlockMetadataWithNotify(i + 15, j + 6, k + 4, 1, 2);
		setBlock(world, i + 15, j + 6, k + 5, Blocks.sandstone_stairs, 1);
		world.setBlockMetadataWithNotify(i + 15, j + 6, k + 5, 1, 2);
		setBlock(world, i + 15, j + 6, k + 21, Blocks.sandstone_stairs, 1);
		world.setBlockMetadataWithNotify(i + 15, j + 6, k + 21, 1, 2);
		setBlock(world, i + 15, j + 6, k + 22, Blocks.sandstone_stairs, 1);
		world.setBlockMetadataWithNotify(i + 15, j + 6, k + 22, 1, 2);
		setBlock(world, i + 15, j + 6, k + 23, Blocks.sandstone_stairs, 1);
		world.setBlockMetadataWithNotify(i + 15, j + 6, k + 23, 1, 2);
		setBlock(world, i + 15, j + 9, k + 9, Blocks.torch, 2);
		world.setBlockMetadataWithNotify(i + 15, j + 9, k + 9, 2, 2);
		setBlock(world, i + 15, j + 9, k + 17, Blocks.torch, 2);
		world.setBlockMetadataWithNotify(i + 15, j + 9, k + 17, 2, 2);
		setBlock(world, i + 15, j + 10, k + 13, Blocks.torch, 2);
		world.setBlockMetadataWithNotify(i + 15, j + 10, k + 13, 2, 2);
		setBlock(world, i + 17, j + 7, k + 8, Blocks.torch, 2);
		world.setBlockMetadataWithNotify(i + 17, j + 7, k + 8, 2, 2);
		setBlock(world, i + 17, j + 7, k + 18, Blocks.torch, 2);
		world.setBlockMetadataWithNotify(i + 17, j + 7, k + 18, 2, 2);
		setBlock(world, i + 17, j + 9, k + 11, Blocks.torch, 3);
		world.setBlockMetadataWithNotify(i + 17, j + 9, k + 11, 3, 2);
		setBlock(world, i + 17, j + 9, k + 15, Blocks.torch, 4);
		world.setBlockMetadataWithNotify(i + 17, j + 9, k + 15, 4, 2);
		setBlock(world, i + 18, j + 7, k + 9, Blocks.torch, 3);
		world.setBlockMetadataWithNotify(i + 18, j + 7, k + 9, 3, 2);
		setBlock(world, i + 18, j + 7, k + 17, Blocks.torch, 4);
		world.setBlockMetadataWithNotify(i + 18, j + 7, k + 17, 4, 2);
		setBlock(world, i + 19, j + 1, k + 13, Blocks.carpet, 1);
		world.setBlockMetadataWithNotify(i + 19, j + 1, k + 13, 1, 2);
		setBlock(world, i + 20, j + 4, k + 11, Blocks.torch, 3);
		world.setBlockMetadataWithNotify(i + 20, j + 4, k + 11, 3, 2);
		setBlock(world, i + 20, j + 4, k + 15, Blocks.torch, 4);
		world.setBlockMetadataWithNotify(i + 20, j + 4, k + 15, 4, 2);
		setBlock(world, i + 21, j + 2, k + 12, Blocks.sandstone, 1);
		world.setBlockMetadataWithNotify(i + 21, j + 2, k + 12, 1, 2);
		setBlock(world, i + 21, j + 2, k + 13, Blocks.sandstone, 1);
		world.setBlockMetadataWithNotify(i + 21, j + 2, k + 13, 1, 2);
		setBlock(world, i + 21, j + 2, k + 14, Blocks.sandstone, 1);
		world.setBlockMetadataWithNotify(i + 21, j + 2, k + 14, 1, 2);
		setBlock(world, i + 21, j + 3, k + 12, Blocks.sandstone, 1);
		world.setBlockMetadataWithNotify(i + 21, j + 3, k + 12, 1, 2);
		setBlock(world, i + 21, j + 3, k + 13, Blocks.sandstone, 1);
		world.setBlockMetadataWithNotify(i + 21, j + 3, k + 13, 1, 2);
		setBlock(world, i + 21, j + 3, k + 14, Blocks.sandstone, 1);
		world.setBlockMetadataWithNotify(i + 21, j + 3, k + 14, 1, 2);
		setBlock(world, i + 21, j + 4, k + 12, Blocks.sandstone, 1);
		world.setBlockMetadataWithNotify(i + 21, j + 4, k + 12, 1, 2);
		setBlock(world, i + 21, j + 4, k + 13, Blocks.sandstone, 1);
		world.setBlockMetadataWithNotify(i + 21, j + 4, k + 13, 1, 2);
		setBlock(world, i + 21, j + 4, k + 14, Blocks.sandstone, 1);
		world.setBlockMetadataWithNotify(i + 21, j + 4, k + 14, 1, 2);

		return true;
	}

	protected Block[] getValidSpawnBlocks()
	{
		return new Block[] { StarWarsMod.tatooineSand };
	}

	public boolean locationIsValidSpawn(World world, int i, int j, int k)
	{
		int distanceToAir = 0;
		Block check = world.getBlock(i, j, k);

		while (check != Blocks.air)
		{
			if (distanceToAir > 3) { return false; }

			distanceToAir++;
			check = world.getBlock(i, j + distanceToAir, k);
		}

		j += distanceToAir - 1;

		Block block = world.getBlock(i, j, k);
		Block blockAbove = world.getBlock(i, j + 1, k);
		Block blockBelow = world.getBlock(i, j - 1, k);

		for (Block x : getValidSpawnBlocks())
		{
			if (blockAbove != Blocks.air) { return false; }
			if (block == x)
			{
				return true;
			}
			else if (block == Blocks.snow && blockBelow == x) { return true; }
		}

		return false;
	}

	public void setBlock(World world, int x, int y, int z, Block block, int metadata)
	{
		world.setBlock(x, y, z, block, metadata, 2);
	}
}