package com.parzi.starwarsmod.world.gen;

import java.util.Random;

import net.minecraft.block.Block;
import net.minecraft.init.Blocks;
import net.minecraft.tileentity.TileEntityChest;
import net.minecraft.world.World;
import net.minecraft.world.chunk.IChunkProvider;
import net.minecraft.world.gen.feature.WorldGenerator;

import com.parzi.starwarsmod.utils.LootGenUtils;

import cpw.mods.fml.common.IWorldGenerator;

public class WorldGenYavinTempleRuins extends WorldGenerator implements IWorldGenerator
{
	public WorldGenYavinTempleRuins()
	{
	}

	@Override
	public void generate(Random random, int chunkX, int chunkZ, World world, IChunkProvider chunkGenerator, IChunkProvider chunkProvider)
	{
	}

	@Override
	public boolean generate(World world, Random rand, int i, int j, int k)
	{
		// check that each corner is one of the valid spawn blocks
		if (!locationIsValidSpawn(world, i, j, k) || !locationIsValidSpawn(world, i + 47, j, k) || !locationIsValidSpawn(world, i + 47, j, k + 47) || !locationIsValidSpawn(world, i, j, k + 47)) { return false; }

		k = k - 10;
		i = i - 10;

		setBlock(world, i + 0, j + 0, k + 20, Blocks.stonebrick, 0);
		setBlock(world, i + 0, j + 0, k + 21, Blocks.stonebrick, 0);
		setBlock(world, i + 0, j + 0, k + 26, Blocks.stonebrick, 0);
		setBlock(world, i + 0, j + 0, k + 27, Blocks.stonebrick, 0);
		setBlock(world, i + 1, j + 0, k + 20, Blocks.stonebrick, 0);
		setBlock(world, i + 1, j + 0, k + 21, Blocks.stonebrick, 0);
		setBlock(world, i + 1, j + 0, k + 22, Blocks.stone_brick_stairs, 0);
		setBlock(world, i + 1, j + 0, k + 23, Blocks.stone_brick_stairs, 0);
		setBlock(world, i + 1, j + 0, k + 24, Blocks.stone_brick_stairs, 0);
		setBlock(world, i + 1, j + 0, k + 25, Blocks.stone_brick_stairs, 0);
		setBlock(world, i + 1, j + 0, k + 26, Blocks.stonebrick, 0);
		setBlock(world, i + 1, j + 0, k + 27, Blocks.stonebrick, 0);
		setBlock(world, i + 1, j + 1, k + 20, Blocks.stonebrick, 0);
		setBlock(world, i + 1, j + 1, k + 21, Blocks.stonebrick, 0);
		setBlock(world, i + 1, j + 1, k + 26, Blocks.stonebrick, 0);
		setBlock(world, i + 1, j + 1, k + 27, Blocks.stonebrick, 0);
		setBlock(world, i + 2, j + 0, k + 20, Blocks.stonebrick, 0);
		setBlock(world, i + 2, j + 0, k + 21, Blocks.stonebrick, 0);
		setBlock(world, i + 2, j + 0, k + 26, Blocks.stonebrick, 0);
		setBlock(world, i + 2, j + 0, k + 27, Blocks.stonebrick, 0);
		setBlock(world, i + 2, j + 1, k + 20, Blocks.stonebrick, 0);
		setBlock(world, i + 2, j + 1, k + 21, Blocks.stonebrick, 0);
		setBlock(world, i + 2, j + 1, k + 22, Blocks.stone_brick_stairs, 0);
		setBlock(world, i + 2, j + 1, k + 23, Blocks.stone_brick_stairs, 0);
		setBlock(world, i + 2, j + 1, k + 24, Blocks.stone_brick_stairs, 0);
		setBlock(world, i + 2, j + 1, k + 25, Blocks.stone_brick_stairs, 0);
		setBlock(world, i + 2, j + 1, k + 26, Blocks.stonebrick, 0);
		setBlock(world, i + 2, j + 1, k + 27, Blocks.stonebrick, 0);
		setBlock(world, i + 2, j + 2, k + 20, Blocks.stonebrick, 0);
		setBlock(world, i + 2, j + 2, k + 21, Blocks.stonebrick, 0);
		setBlock(world, i + 2, j + 2, k + 26, Blocks.stonebrick, 0);
		setBlock(world, i + 2, j + 2, k + 27, Blocks.stonebrick, 0);
		setBlock(world, i + 3, j + 0, k + 20, Blocks.stonebrick, 0);
		setBlock(world, i + 3, j + 0, k + 21, Blocks.stonebrick, 0);
		setBlock(world, i + 3, j + 0, k + 26, Blocks.stonebrick, 0);
		setBlock(world, i + 3, j + 0, k + 27, Blocks.stonebrick, 0);
		setBlock(world, i + 3, j + 1, k + 20, Blocks.stonebrick, 0);
		setBlock(world, i + 3, j + 1, k + 21, Blocks.stonebrick, 0);
		setBlock(world, i + 3, j + 1, k + 22, Blocks.stonebrick, 0);
		setBlock(world, i + 3, j + 1, k + 23, Blocks.stonebrick, 0);
		setBlock(world, i + 3, j + 1, k + 24, Blocks.stonebrick, 0);
		setBlock(world, i + 3, j + 1, k + 25, Blocks.stonebrick, 0);
		setBlock(world, i + 3, j + 1, k + 26, Blocks.stonebrick, 0);
		setBlock(world, i + 3, j + 1, k + 27, Blocks.stonebrick, 0);
		setBlock(world, i + 3, j + 2, k + 20, Blocks.stonebrick, 0);
		setBlock(world, i + 3, j + 2, k + 21, Blocks.stonebrick, 0);
		setBlock(world, i + 3, j + 2, k + 22, Blocks.stone_brick_stairs, 0);
		setBlock(world, i + 3, j + 2, k + 23, Blocks.stone_brick_stairs, 0);
		setBlock(world, i + 3, j + 2, k + 24, Blocks.stone_brick_stairs, 0);
		setBlock(world, i + 3, j + 2, k + 25, Blocks.stone_brick_stairs, 0);
		setBlock(world, i + 3, j + 2, k + 26, Blocks.stonebrick, 0);
		setBlock(world, i + 3, j + 2, k + 27, Blocks.stonebrick, 0);
		setBlock(world, i + 3, j + 3, k + 20, Blocks.stonebrick, 0);
		setBlock(world, i + 3, j + 3, k + 21, Blocks.stonebrick, 0);
		setBlock(world, i + 3, j + 3, k + 26, Blocks.stonebrick, 0);
		setBlock(world, i + 3, j + 3, k + 27, Blocks.stonebrick, 0);
		setBlock(world, i + 4, j + 0, k + 20, Blocks.stonebrick, 0);
		setBlock(world, i + 4, j + 0, k + 21, Blocks.stonebrick, 0);
		setBlock(world, i + 4, j + 0, k + 26, Blocks.stonebrick, 0);
		setBlock(world, i + 4, j + 0, k + 27, Blocks.stonebrick, 0);
		setBlock(world, i + 4, j + 1, k + 20, Blocks.stonebrick, 0);
		setBlock(world, i + 4, j + 1, k + 21, Blocks.stonebrick, 0);
		setBlock(world, i + 4, j + 1, k + 26, Blocks.stonebrick, 0);
		setBlock(world, i + 4, j + 1, k + 27, Blocks.stonebrick, 0);
		setBlock(world, i + 4, j + 2, k + 20, Blocks.stonebrick, 0);
		setBlock(world, i + 4, j + 2, k + 21, Blocks.stonebrick, 0);
		setBlock(world, i + 4, j + 2, k + 22, Blocks.stonebrick, 0);
		setBlock(world, i + 4, j + 2, k + 23, Blocks.stonebrick, 0);
		setBlock(world, i + 4, j + 2, k + 24, Blocks.stonebrick, 0);
		setBlock(world, i + 4, j + 2, k + 25, Blocks.stonebrick, 0);
		setBlock(world, i + 4, j + 2, k + 26, Blocks.stonebrick, 0);
		setBlock(world, i + 4, j + 2, k + 27, Blocks.stonebrick, 0);
		setBlock(world, i + 4, j + 3, k + 20, Blocks.stonebrick, 0);
		setBlock(world, i + 4, j + 3, k + 21, Blocks.stonebrick, 0);
		setBlock(world, i + 4, j + 3, k + 22, Blocks.stone_brick_stairs, 0);
		setBlock(world, i + 4, j + 3, k + 23, Blocks.stone_brick_stairs, 0);
		setBlock(world, i + 4, j + 3, k + 24, Blocks.stone_brick_stairs, 0);
		setBlock(world, i + 4, j + 3, k + 25, Blocks.stone_brick_stairs, 0);
		setBlock(world, i + 4, j + 3, k + 26, Blocks.stonebrick, 0);
		setBlock(world, i + 4, j + 3, k + 27, Blocks.stonebrick, 0);
		setBlock(world, i + 4, j + 4, k + 20, Blocks.stonebrick, 0);
		setBlock(world, i + 4, j + 4, k + 21, Blocks.stonebrick, 0);
		setBlock(world, i + 4, j + 4, k + 26, Blocks.stonebrick, 0);
		setBlock(world, i + 4, j + 4, k + 27, Blocks.stonebrick, 0);
		setBlock(world, i + 5, j + 0, k + 20, Blocks.stonebrick, 0);
		setBlock(world, i + 5, j + 0, k + 21, Blocks.stonebrick, 0);
		setBlock(world, i + 5, j + 0, k + 26, Blocks.stonebrick, 0);
		setBlock(world, i + 5, j + 0, k + 27, Blocks.stonebrick, 0);
		setBlock(world, i + 5, j + 1, k + 20, Blocks.stonebrick, 0);
		setBlock(world, i + 5, j + 1, k + 21, Blocks.stonebrick, 0);
		setBlock(world, i + 5, j + 1, k + 26, Blocks.stonebrick, 0);
		setBlock(world, i + 5, j + 1, k + 27, Blocks.stonebrick, 0);
		setBlock(world, i + 5, j + 2, k + 20, Blocks.stonebrick, 0);
		setBlock(world, i + 5, j + 2, k + 21, Blocks.stonebrick, 0);
		setBlock(world, i + 5, j + 2, k + 26, Blocks.stonebrick, 0);
		setBlock(world, i + 5, j + 2, k + 27, Blocks.stonebrick, 0);
		setBlock(world, i + 5, j + 3, k + 20, Blocks.stonebrick, 0);
		setBlock(world, i + 5, j + 3, k + 21, Blocks.stonebrick, 0);
		setBlock(world, i + 5, j + 3, k + 22, Blocks.stonebrick, 0);
		setBlock(world, i + 5, j + 3, k + 23, Blocks.stonebrick, 0);
		setBlock(world, i + 5, j + 3, k + 24, Blocks.stonebrick, 0);
		setBlock(world, i + 5, j + 3, k + 25, Blocks.stonebrick, 0);
		setBlock(world, i + 5, j + 3, k + 26, Blocks.stonebrick, 0);
		setBlock(world, i + 5, j + 3, k + 27, Blocks.stonebrick, 0);
		setBlock(world, i + 5, j + 4, k + 20, Blocks.stonebrick, 0);
		setBlock(world, i + 5, j + 4, k + 21, Blocks.stonebrick, 0);
		setBlock(world, i + 5, j + 4, k + 22, Blocks.stone_brick_stairs, 0);
		setBlock(world, i + 5, j + 4, k + 23, Blocks.stone_brick_stairs, 0);
		setBlock(world, i + 5, j + 4, k + 24, Blocks.stone_brick_stairs, 0);
		setBlock(world, i + 5, j + 4, k + 25, Blocks.stone_brick_stairs, 0);
		setBlock(world, i + 5, j + 4, k + 26, Blocks.stonebrick, 0);
		setBlock(world, i + 5, j + 4, k + 27, Blocks.stonebrick, 0);
		setBlock(world, i + 5, j + 5, k + 20, Blocks.stonebrick, 0);
		setBlock(world, i + 5, j + 5, k + 21, Blocks.stonebrick, 0);
		setBlock(world, i + 5, j + 5, k + 26, Blocks.stonebrick, 0);
		setBlock(world, i + 5, j + 5, k + 27, Blocks.stonebrick, 0);
		setBlock(world, i + 6, j + 0, k + 20, Blocks.stonebrick, 0);
		setBlock(world, i + 6, j + 0, k + 21, Blocks.stonebrick, 0);
		setBlock(world, i + 6, j + 0, k + 26, Blocks.stonebrick, 0);
		setBlock(world, i + 6, j + 0, k + 27, Blocks.stonebrick, 0);
		setBlock(world, i + 6, j + 1, k + 20, Blocks.stonebrick, 0);
		setBlock(world, i + 6, j + 1, k + 21, Blocks.stonebrick, 0);
		setBlock(world, i + 6, j + 1, k + 26, Blocks.stonebrick, 0);
		setBlock(world, i + 6, j + 1, k + 27, Blocks.stonebrick, 0);
		setBlock(world, i + 6, j + 2, k + 20, Blocks.stonebrick, 0);
		setBlock(world, i + 6, j + 2, k + 21, Blocks.stonebrick, 0);
		setBlock(world, i + 6, j + 2, k + 26, Blocks.stonebrick, 0);
		setBlock(world, i + 6, j + 2, k + 27, Blocks.stonebrick, 0);
		setBlock(world, i + 6, j + 3, k + 20, Blocks.stonebrick, 0);
		setBlock(world, i + 6, j + 3, k + 21, Blocks.stonebrick, 0);
		setBlock(world, i + 6, j + 3, k + 26, Blocks.stonebrick, 0);
		setBlock(world, i + 6, j + 3, k + 27, Blocks.stonebrick, 0);
		setBlock(world, i + 6, j + 4, k + 20, Blocks.stonebrick, 0);
		setBlock(world, i + 6, j + 4, k + 21, Blocks.stonebrick, 0);
		setBlock(world, i + 6, j + 4, k + 22, Blocks.stonebrick, 0);
		setBlock(world, i + 6, j + 4, k + 23, Blocks.stonebrick, 0);
		setBlock(world, i + 6, j + 4, k + 24, Blocks.stonebrick, 0);
		setBlock(world, i + 6, j + 4, k + 25, Blocks.stonebrick, 0);
		setBlock(world, i + 6, j + 4, k + 26, Blocks.stonebrick, 0);
		setBlock(world, i + 6, j + 4, k + 27, Blocks.stonebrick, 0);
		setBlock(world, i + 6, j + 5, k + 20, Blocks.stonebrick, 0);
		setBlock(world, i + 6, j + 5, k + 21, Blocks.stonebrick, 0);
		setBlock(world, i + 6, j + 5, k + 22, Blocks.stone_brick_stairs, 0);
		setBlock(world, i + 6, j + 5, k + 23, Blocks.stone_brick_stairs, 0);
		setBlock(world, i + 6, j + 5, k + 24, Blocks.stone_brick_stairs, 0);
		setBlock(world, i + 6, j + 5, k + 25, Blocks.stone_brick_stairs, 0);
		setBlock(world, i + 6, j + 5, k + 26, Blocks.stonebrick, 0);
		setBlock(world, i + 6, j + 5, k + 27, Blocks.stonebrick, 0);
		setBlock(world, i + 6, j + 6, k + 20, Blocks.stonebrick, 0);
		setBlock(world, i + 6, j + 6, k + 21, Blocks.stonebrick, 0);
		setBlock(world, i + 6, j + 6, k + 26, Blocks.stonebrick, 0);
		setBlock(world, i + 6, j + 6, k + 27, Blocks.stonebrick, 0);
		setBlock(world, i + 7, j + 0, k + 20, Blocks.stonebrick, 0);
		setBlock(world, i + 7, j + 0, k + 21, Blocks.stonebrick, 0);
		setBlock(world, i + 7, j + 0, k + 26, Blocks.stonebrick, 0);
		setBlock(world, i + 7, j + 0, k + 27, Blocks.stonebrick, 0);
		setBlock(world, i + 7, j + 1, k + 20, Blocks.stonebrick, 0);
		setBlock(world, i + 7, j + 1, k + 21, Blocks.stonebrick, 0);
		setBlock(world, i + 7, j + 1, k + 26, Blocks.stonebrick, 0);
		setBlock(world, i + 7, j + 1, k + 27, Blocks.stonebrick, 0);
		setBlock(world, i + 7, j + 2, k + 20, Blocks.stonebrick, 0);
		setBlock(world, i + 7, j + 2, k + 21, Blocks.stonebrick, 0);
		setBlock(world, i + 7, j + 2, k + 26, Blocks.stonebrick, 0);
		setBlock(world, i + 7, j + 2, k + 27, Blocks.stonebrick, 0);
		setBlock(world, i + 7, j + 3, k + 20, Blocks.stonebrick, 0);
		setBlock(world, i + 7, j + 3, k + 21, Blocks.stonebrick, 0);
		setBlock(world, i + 7, j + 3, k + 26, Blocks.stonebrick, 0);
		setBlock(world, i + 7, j + 3, k + 27, Blocks.stonebrick, 0);
		setBlock(world, i + 7, j + 4, k + 20, Blocks.stonebrick, 0);
		setBlock(world, i + 7, j + 4, k + 21, Blocks.stonebrick, 0);
		setBlock(world, i + 7, j + 4, k + 26, Blocks.stonebrick, 0);
		setBlock(world, i + 7, j + 4, k + 27, Blocks.stonebrick, 0);
		setBlock(world, i + 7, j + 5, k + 20, Blocks.stonebrick, 0);
		setBlock(world, i + 7, j + 5, k + 21, Blocks.stonebrick, 0);
		setBlock(world, i + 7, j + 5, k + 22, Blocks.stonebrick, 0);
		setBlock(world, i + 7, j + 5, k + 23, Blocks.stonebrick, 0);
		setBlock(world, i + 7, j + 5, k + 24, Blocks.stonebrick, 0);
		setBlock(world, i + 7, j + 5, k + 25, Blocks.stonebrick, 0);
		setBlock(world, i + 7, j + 5, k + 26, Blocks.stonebrick, 0);
		setBlock(world, i + 7, j + 5, k + 27, Blocks.stonebrick, 0);
		setBlock(world, i + 7, j + 6, k + 20, Blocks.stonebrick, 0);
		setBlock(world, i + 7, j + 6, k + 21, Blocks.stonebrick, 0);
		setBlock(world, i + 7, j + 6, k + 22, Blocks.stone_brick_stairs, 0);
		setBlock(world, i + 7, j + 6, k + 23, Blocks.stone_brick_stairs, 0);
		setBlock(world, i + 7, j + 6, k + 24, Blocks.stone_brick_stairs, 0);
		setBlock(world, i + 7, j + 6, k + 25, Blocks.stone_brick_stairs, 0);
		setBlock(world, i + 7, j + 6, k + 26, Blocks.stonebrick, 0);
		setBlock(world, i + 7, j + 6, k + 27, Blocks.stonebrick, 0);
		setBlock(world, i + 7, j + 7, k + 20, Blocks.stonebrick, 0);
		setBlock(world, i + 7, j + 7, k + 21, Blocks.stonebrick, 0);
		setBlock(world, i + 7, j + 7, k + 26, Blocks.stonebrick, 0);
		setBlock(world, i + 7, j + 7, k + 27, Blocks.stonebrick, 0);
		setBlock(world, i + 8, j + 0, k + 8, Blocks.stone_brick_stairs, 0);
		setBlock(world, i + 8, j + 0, k + 9, Blocks.stone_brick_stairs, 0);
		setBlock(world, i + 8, j + 0, k + 10, Blocks.stone_brick_stairs, 0);
		setBlock(world, i + 8, j + 0, k + 11, Blocks.stone_brick_stairs, 0);
		setBlock(world, i + 8, j + 0, k + 12, Blocks.stone_brick_stairs, 0);
		setBlock(world, i + 8, j + 0, k + 13, Blocks.stone_brick_stairs, 0);
		setBlock(world, i + 8, j + 0, k + 14, Blocks.stone_brick_stairs, 0);
		setBlock(world, i + 8, j + 0, k + 15, Blocks.stone_brick_stairs, 0);
		setBlock(world, i + 8, j + 0, k + 16, Blocks.stone_brick_stairs, 0);
		setBlock(world, i + 8, j + 0, k + 17, Blocks.stone_brick_stairs, 0);
		setBlock(world, i + 8, j + 0, k + 18, Blocks.stone_brick_stairs, 0);
		setBlock(world, i + 8, j + 0, k + 19, Blocks.stone_brick_stairs, 0);
		setBlock(world, i + 8, j + 0, k + 20, Blocks.stonebrick, 0);
		setBlock(world, i + 8, j + 0, k + 21, Blocks.stonebrick, 0);
		setBlock(world, i + 8, j + 0, k + 26, Blocks.stonebrick, 0);
		setBlock(world, i + 8, j + 0, k + 27, Blocks.stonebrick, 0);
		setBlock(world, i + 8, j + 0, k + 28, Blocks.stone_brick_stairs, 0);
		setBlock(world, i + 8, j + 0, k + 29, Blocks.stone_brick_stairs, 0);
		setBlock(world, i + 8, j + 0, k + 30, Blocks.stone_brick_stairs, 0);
		setBlock(world, i + 8, j + 0, k + 31, Blocks.stone_brick_stairs, 0);
		setBlock(world, i + 8, j + 0, k + 32, Blocks.stone_brick_stairs, 0);
		setBlock(world, i + 8, j + 0, k + 33, Blocks.stone_brick_stairs, 0);
		setBlock(world, i + 8, j + 0, k + 34, Blocks.stone_brick_stairs, 0);
		setBlock(world, i + 8, j + 0, k + 35, Blocks.stone_brick_stairs, 0);
		setBlock(world, i + 8, j + 0, k + 36, Blocks.stone_brick_stairs, 0);
		setBlock(world, i + 8, j + 0, k + 37, Blocks.stone_brick_stairs, 0);
		setBlock(world, i + 8, j + 0, k + 38, Blocks.stone_brick_stairs, 0);
		setBlock(world, i + 8, j + 1, k + 20, Blocks.stonebrick, 0);
		setBlock(world, i + 8, j + 1, k + 21, Blocks.stonebrick, 0);
		setBlock(world, i + 8, j + 1, k + 26, Blocks.stonebrick, 0);
		setBlock(world, i + 8, j + 1, k + 27, Blocks.stonebrick, 0);
		setBlock(world, i + 8, j + 2, k + 20, Blocks.stonebrick, 0);
		setBlock(world, i + 8, j + 2, k + 21, Blocks.stonebrick, 0);
		setBlock(world, i + 8, j + 2, k + 26, Blocks.stonebrick, 0);
		setBlock(world, i + 8, j + 2, k + 27, Blocks.stonebrick, 0);
		setBlock(world, i + 8, j + 3, k + 20, Blocks.stonebrick, 0);
		setBlock(world, i + 8, j + 3, k + 21, Blocks.stonebrick, 0);
		setBlock(world, i + 8, j + 3, k + 26, Blocks.stonebrick, 0);
		setBlock(world, i + 8, j + 3, k + 27, Blocks.stonebrick, 0);
		setBlock(world, i + 8, j + 4, k + 20, Blocks.stonebrick, 0);
		setBlock(world, i + 8, j + 4, k + 21, Blocks.stonebrick, 0);
		setBlock(world, i + 8, j + 4, k + 26, Blocks.stonebrick, 0);
		setBlock(world, i + 8, j + 4, k + 27, Blocks.stonebrick, 0);
		setBlock(world, i + 8, j + 5, k + 20, Blocks.stonebrick, 0);
		setBlock(world, i + 8, j + 5, k + 21, Blocks.stonebrick, 0);
		setBlock(world, i + 8, j + 5, k + 26, Blocks.stonebrick, 0);
		setBlock(world, i + 8, j + 5, k + 27, Blocks.stonebrick, 0);
		setBlock(world, i + 8, j + 6, k + 20, Blocks.stonebrick, 0);
		setBlock(world, i + 8, j + 6, k + 21, Blocks.stonebrick, 0);
		setBlock(world, i + 8, j + 6, k + 22, Blocks.stonebrick, 0);
		setBlock(world, i + 8, j + 6, k + 23, Blocks.stonebrick, 0);
		setBlock(world, i + 8, j + 6, k + 24, Blocks.stonebrick, 0);
		setBlock(world, i + 8, j + 6, k + 25, Blocks.stonebrick, 0);
		setBlock(world, i + 8, j + 6, k + 26, Blocks.stonebrick, 0);
		setBlock(world, i + 8, j + 6, k + 27, Blocks.stonebrick, 0);
		setBlock(world, i + 8, j + 7, k + 20, Blocks.stonebrick, 0);
		setBlock(world, i + 8, j + 7, k + 21, Blocks.stonebrick, 0);
		setBlock(world, i + 8, j + 7, k + 22, Blocks.stone_brick_stairs, 0);
		setBlock(world, i + 8, j + 7, k + 23, Blocks.stone_brick_stairs, 0);
		setBlock(world, i + 8, j + 7, k + 24, Blocks.stone_brick_stairs, 0);
		setBlock(world, i + 8, j + 7, k + 25, Blocks.stone_brick_stairs, 0);
		setBlock(world, i + 8, j + 7, k + 26, Blocks.stonebrick, 0);
		setBlock(world, i + 8, j + 7, k + 27, Blocks.stonebrick, 0);
		setBlock(world, i + 8, j + 8, k + 20, Blocks.stonebrick, 0);
		setBlock(world, i + 8, j + 8, k + 21, Blocks.stonebrick, 0);
		setBlock(world, i + 8, j + 8, k + 26, Blocks.stonebrick, 0);
		setBlock(world, i + 8, j + 8, k + 27, Blocks.stonebrick, 0);
		setBlock(world, i + 9, j + 0, k + 26, Blocks.stonebrick, 0);
		setBlock(world, i + 9, j + 1, k + 26, Blocks.stonebrick, 0);
		setBlock(world, i + 9, j + 1, k + 28, Blocks.stonebrick, 0);
		setBlock(world, i + 9, j + 1, k + 30, Blocks.stonebrick, 0);
		setBlock(world, i + 9, j + 2, k + 10, Blocks.stone_brick_stairs, 0);
		setBlock(world, i + 9, j + 2, k + 11, Blocks.stone_brick_stairs, 0);
		setBlock(world, i + 9, j + 2, k + 12, Blocks.stone_brick_stairs, 0);
		setBlock(world, i + 9, j + 2, k + 13, Blocks.stone_brick_stairs, 0);
		setBlock(world, i + 9, j + 2, k + 14, Blocks.stone_brick_stairs, 0);
		setBlock(world, i + 9, j + 2, k + 15, Blocks.stone_brick_stairs, 0);
		setBlock(world, i + 9, j + 2, k + 16, Blocks.stone_brick_stairs, 0);
		setBlock(world, i + 9, j + 2, k + 17, Blocks.stone_brick_stairs, 0);
		setBlock(world, i + 9, j + 2, k + 18, Blocks.stone_brick_stairs, 0);
		setBlock(world, i + 9, j + 2, k + 19, Blocks.stone_brick_stairs, 0);
		setBlock(world, i + 9, j + 2, k + 20, Blocks.stonebrick, 0);
		setBlock(world, i + 9, j + 2, k + 21, Blocks.stonebrick, 0);
		setBlock(world, i + 9, j + 2, k + 26, Blocks.stonebrick, 0);
		setBlock(world, i + 9, j + 2, k + 27, Blocks.stonebrick, 0);
		setBlock(world, i + 9, j + 2, k + 28, Blocks.stone_brick_stairs, 0);
		setBlock(world, i + 9, j + 2, k + 29, Blocks.stone_brick_stairs, 0);
		setBlock(world, i + 9, j + 2, k + 30, Blocks.stone_brick_stairs, 0);
		setBlock(world, i + 9, j + 2, k + 31, Blocks.stone_brick_stairs, 0);
		setBlock(world, i + 9, j + 2, k + 32, Blocks.stone_brick_stairs, 0);
		setBlock(world, i + 9, j + 2, k + 33, Blocks.stone_brick_stairs, 0);
		setBlock(world, i + 9, j + 2, k + 34, Blocks.stone_brick_stairs, 0);
		setBlock(world, i + 9, j + 2, k + 35, Blocks.stone_brick_stairs, 0);
		setBlock(world, i + 9, j + 2, k + 36, Blocks.stone_brick_stairs, 0);
		setBlock(world, i + 9, j + 2, k + 37, Blocks.stone_brick_stairs, 0);
		setBlock(world, i + 9, j + 3, k + 20, Blocks.stonebrick, 0);
		setBlock(world, i + 9, j + 3, k + 21, Blocks.stonebrick, 0);
		setBlock(world, i + 9, j + 3, k + 26, Blocks.stonebrick, 0);
		setBlock(world, i + 9, j + 3, k + 27, Blocks.stonebrick, 0);
		setBlock(world, i + 9, j + 4, k + 20, Blocks.stonebrick, 0);
		setBlock(world, i + 9, j + 4, k + 21, Blocks.stonebrick, 0);
		setBlock(world, i + 9, j + 4, k + 26, Blocks.stonebrick, 0);
		setBlock(world, i + 9, j + 4, k + 27, Blocks.stonebrick, 0);
		setBlock(world, i + 9, j + 5, k + 20, Blocks.stonebrick, 0);
		setBlock(world, i + 9, j + 5, k + 21, Blocks.stonebrick, 0);
		setBlock(world, i + 9, j + 5, k + 26, Blocks.stonebrick, 0);
		setBlock(world, i + 9, j + 5, k + 27, Blocks.stonebrick, 0);
		setBlock(world, i + 9, j + 6, k + 20, Blocks.stonebrick, 0);
		setBlock(world, i + 9, j + 6, k + 21, Blocks.stonebrick, 0);
		setBlock(world, i + 9, j + 6, k + 26, Blocks.stonebrick, 0);
		setBlock(world, i + 9, j + 6, k + 27, Blocks.stonebrick, 0);
		setBlock(world, i + 9, j + 7, k + 20, Blocks.stonebrick, 0);
		setBlock(world, i + 9, j + 7, k + 21, Blocks.stonebrick, 0);
		setBlock(world, i + 9, j + 7, k + 22, Blocks.stonebrick, 0);
		setBlock(world, i + 9, j + 7, k + 23, Blocks.stonebrick, 0);
		setBlock(world, i + 9, j + 7, k + 24, Blocks.stonebrick, 0);
		setBlock(world, i + 9, j + 7, k + 25, Blocks.stonebrick, 0);
		setBlock(world, i + 9, j + 7, k + 26, Blocks.stonebrick, 0);
		setBlock(world, i + 9, j + 7, k + 27, Blocks.stonebrick, 0);
		setBlock(world, i + 9, j + 8, k + 20, Blocks.stonebrick, 0);
		setBlock(world, i + 9, j + 8, k + 21, Blocks.stonebrick, 0);
		setBlock(world, i + 9, j + 8, k + 22, Blocks.stone_brick_stairs, 0);
		setBlock(world, i + 9, j + 8, k + 23, Blocks.stone_brick_stairs, 0);
		setBlock(world, i + 9, j + 8, k + 24, Blocks.stone_brick_stairs, 0);
		setBlock(world, i + 9, j + 8, k + 25, Blocks.stone_brick_stairs, 0);
		setBlock(world, i + 9, j + 8, k + 26, Blocks.stonebrick, 0);
		setBlock(world, i + 9, j + 8, k + 27, Blocks.stonebrick, 0);
		setBlock(world, i + 9, j + 9, k + 20, Blocks.stonebrick, 0);
		setBlock(world, i + 9, j + 9, k + 21, Blocks.stonebrick, 0);
		setBlock(world, i + 9, j + 9, k + 26, Blocks.stonebrick, 0);
		setBlock(world, i + 9, j + 9, k + 27, Blocks.stonebrick, 0);
		setBlock(world, i + 10, j + 0, k + 31, Blocks.stonebrick, 0);
		setBlock(world, i + 10, j + 0, k + 33, Blocks.stonebrick, 0);
		setBlock(world, i + 10, j + 1, k + 17, Blocks.stonebrick, 0);
		setBlock(world, i + 10, j + 1, k + 18, Blocks.stonebrick, 0);
		setBlock(world, i + 10, j + 1, k + 21, Blocks.stonebrick, 0);
		setBlock(world, i + 10, j + 1, k + 23, Blocks.stonebrick, 0);
		setBlock(world, i + 10, j + 1, k + 25, Blocks.stonebrick, 0);
		setBlock(world, i + 10, j + 1, k + 27, Blocks.stonebrick, 0);
		setBlock(world, i + 10, j + 1, k + 33, Blocks.stonebrick, 0);
		setBlock(world, i + 10, j + 1, k + 36, Blocks.stonebrick, 0);
		setBlock(world, i + 10, j + 2, k + 14, Blocks.stonebrick, 0);
		setBlock(world, i + 10, j + 2, k + 19, Blocks.stonebrick, 0);
		setBlock(world, i + 10, j + 2, k + 21, Blocks.stonebrick, 0);
		setBlock(world, i + 10, j + 2, k + 26, Blocks.stonebrick, 0);
		setBlock(world, i + 10, j + 2, k + 27, Blocks.stonebrick, 0);
		setBlock(world, i + 10, j + 3, k + 12, Blocks.stonebrick, 0);
		setBlock(world, i + 10, j + 3, k + 14, Blocks.stonebrick, 0);
		setBlock(world, i + 10, j + 3, k + 17, Blocks.stonebrick, 0);
		setBlock(world, i + 10, j + 3, k + 19, Blocks.stonebrick, 0);
		setBlock(world, i + 10, j + 3, k + 25, Blocks.stonebrick, 0);
		setBlock(world, i + 10, j + 3, k + 26, Blocks.stonebrick, 0);
		setBlock(world, i + 10, j + 3, k + 27, Blocks.stonebrick, 0);
		setBlock(world, i + 10, j + 3, k + 29, Blocks.stonebrick, 0);
		setBlock(world, i + 10, j + 3, k + 31, Blocks.stonebrick, 0);
		setBlock(world, i + 10, j + 4, k + 11, Blocks.stone_brick_stairs, 0);
		setBlock(world, i + 10, j + 4, k + 12, Blocks.stone_brick_stairs, 0);
		setBlock(world, i + 10, j + 4, k + 13, Blocks.stone_brick_stairs, 0);
		setBlock(world, i + 10, j + 4, k + 14, Blocks.stone_brick_stairs, 0);
		setBlock(world, i + 10, j + 4, k + 15, Blocks.stone_brick_stairs, 0);
		setBlock(world, i + 10, j + 4, k + 16, Blocks.stone_brick_stairs, 0);
		setBlock(world, i + 10, j + 4, k + 17, Blocks.stone_brick_stairs, 0);
		setBlock(world, i + 10, j + 4, k + 18, Blocks.stone_brick_stairs, 0);
		setBlock(world, i + 10, j + 4, k + 19, Blocks.stone_brick_stairs, 0);
		setBlock(world, i + 10, j + 4, k + 20, Blocks.stonebrick, 0);
		setBlock(world, i + 10, j + 4, k + 21, Blocks.stonebrick, 0);
		setBlock(world, i + 10, j + 4, k + 26, Blocks.stonebrick, 0);
		setBlock(world, i + 10, j + 4, k + 27, Blocks.stonebrick, 0);
		setBlock(world, i + 10, j + 4, k + 28, Blocks.stone_brick_stairs, 0);
		setBlock(world, i + 10, j + 4, k + 29, Blocks.stone_brick_stairs, 0);
		setBlock(world, i + 10, j + 4, k + 30, Blocks.stone_brick_stairs, 0);
		setBlock(world, i + 10, j + 4, k + 31, Blocks.stone_brick_stairs, 0);
		setBlock(world, i + 10, j + 4, k + 32, Blocks.stone_brick_stairs, 0);
		setBlock(world, i + 10, j + 4, k + 33, Blocks.stone_brick_stairs, 0);
		setBlock(world, i + 10, j + 4, k + 34, Blocks.stone_brick_stairs, 0);
		setBlock(world, i + 10, j + 4, k + 35, Blocks.stone_brick_stairs, 0);
		setBlock(world, i + 10, j + 4, k + 36, Blocks.stone_brick_stairs, 0);
		setBlock(world, i + 10, j + 5, k + 20, Blocks.stonebrick, 0);
		setBlock(world, i + 10, j + 5, k + 21, Blocks.stonebrick, 0);
		setBlock(world, i + 10, j + 5, k + 26, Blocks.stonebrick, 0);
		setBlock(world, i + 10, j + 5, k + 27, Blocks.stonebrick, 0);
		setBlock(world, i + 10, j + 6, k + 20, Blocks.stonebrick, 0);
		setBlock(world, i + 10, j + 6, k + 21, Blocks.stonebrick, 0);
		setBlock(world, i + 10, j + 6, k + 26, Blocks.stonebrick, 0);
		setBlock(world, i + 10, j + 6, k + 27, Blocks.stonebrick, 0);
		setBlock(world, i + 10, j + 7, k + 20, Blocks.stonebrick, 0);
		setBlock(world, i + 10, j + 7, k + 21, Blocks.stonebrick, 0);
		setBlock(world, i + 10, j + 7, k + 26, Blocks.stonebrick, 0);
		setBlock(world, i + 10, j + 7, k + 27, Blocks.stonebrick, 0);
		setBlock(world, i + 10, j + 8, k + 20, Blocks.stonebrick, 0);
		setBlock(world, i + 10, j + 8, k + 21, Blocks.stonebrick, 0);
		setBlock(world, i + 10, j + 8, k + 22, Blocks.stonebrick, 0);
		setBlock(world, i + 10, j + 8, k + 23, Blocks.stonebrick, 0);
		setBlock(world, i + 10, j + 8, k + 24, Blocks.stonebrick, 0);
		setBlock(world, i + 10, j + 8, k + 25, Blocks.stonebrick, 0);
		setBlock(world, i + 10, j + 8, k + 26, Blocks.stonebrick, 0);
		setBlock(world, i + 10, j + 8, k + 27, Blocks.stonebrick, 0);
		setBlock(world, i + 10, j + 9, k + 20, Blocks.stonebrick, 0);
		setBlock(world, i + 10, j + 9, k + 21, Blocks.stonebrick, 0);
		setBlock(world, i + 10, j + 9, k + 22, Blocks.stone_brick_stairs, 0);
		setBlock(world, i + 10, j + 9, k + 23, Blocks.stone_brick_stairs, 0);
		setBlock(world, i + 10, j + 9, k + 24, Blocks.stone_brick_stairs, 0);
		setBlock(world, i + 10, j + 9, k + 25, Blocks.stone_brick_stairs, 0);
		setBlock(world, i + 10, j + 9, k + 26, Blocks.stonebrick, 0);
		setBlock(world, i + 10, j + 9, k + 27, Blocks.stonebrick, 0);
		setBlock(world, i + 10, j + 10, k + 20, Blocks.stonebrick, 0);
		setBlock(world, i + 10, j + 10, k + 21, Blocks.stonebrick, 0);
		setBlock(world, i + 10, j + 10, k + 26, Blocks.stonebrick, 0);
		setBlock(world, i + 10, j + 10, k + 27, Blocks.stonebrick, 0);
		setBlock(world, i + 11, j + 1, k + 10, Blocks.stonebrick, 0);
		setBlock(world, i + 11, j + 2, k + 11, Blocks.stonebrick, 0);
		setBlock(world, i + 11, j + 2, k + 13, Blocks.stonebrick, 0);
		setBlock(world, i + 11, j + 2, k + 14, Blocks.stonebrick, 0);
		setBlock(world, i + 11, j + 2, k + 20, Blocks.stonebrick, 0);
		setBlock(world, i + 11, j + 2, k + 22, Blocks.stonebrick, 0);
		setBlock(world, i + 11, j + 2, k + 25, Blocks.stonebrick, 0);
		setBlock(world, i + 11, j + 2, k + 28, Blocks.stonebrick, 0);
		setBlock(world, i + 11, j + 2, k + 30, Blocks.stonebrick, 0);
		setBlock(world, i + 11, j + 2, k + 36, Blocks.stonebrick, 0);
		setBlock(world, i + 11, j + 3, k + 13, Blocks.stonebrick, 0);
		setBlock(world, i + 11, j + 3, k + 14, Blocks.stonebrick, 0);
		setBlock(world, i + 11, j + 3, k + 16, Blocks.stonebrick, 0);
		setBlock(world, i + 11, j + 3, k + 17, Blocks.stonebrick, 0);
		setBlock(world, i + 11, j + 3, k + 18, Blocks.stonebrick, 0);
		setBlock(world, i + 11, j + 3, k + 21, Blocks.stonebrick, 0);
		setBlock(world, i + 11, j + 3, k + 23, Blocks.stonebrick, 0);
		setBlock(world, i + 11, j + 3, k + 24, Blocks.stonebrick, 0);
		setBlock(world, i + 11, j + 3, k + 27, Blocks.stonebrick, 0);
		setBlock(world, i + 11, j + 3, k + 28, Blocks.stonebrick, 0);
		setBlock(world, i + 11, j + 3, k + 29, Blocks.stonebrick, 0);
		setBlock(world, i + 11, j + 3, k + 30, Blocks.stonebrick, 0);
		setBlock(world, i + 11, j + 3, k + 35, Blocks.stonebrick, 0);
		setBlock(world, i + 11, j + 4, k + 12, Blocks.stonebrick, 0);
		setBlock(world, i + 11, j + 4, k + 13, Blocks.stonebrick, 0);
		setBlock(world, i + 11, j + 4, k + 14, Blocks.stonebrick, 0);
		setBlock(world, i + 11, j + 4, k + 15, Blocks.stonebrick, 0);
		setBlock(world, i + 11, j + 4, k + 20, Blocks.stonebrick, 0);
		setBlock(world, i + 11, j + 4, k + 24, Blocks.stonebrick, 0);
		setBlock(world, i + 11, j + 4, k + 26, Blocks.stonebrick, 0);
		setBlock(world, i + 11, j + 4, k + 29, Blocks.stonebrick, 0);
		setBlock(world, i + 11, j + 4, k + 30, Blocks.stonebrick, 0);
		setBlock(world, i + 11, j + 5, k + 14, Blocks.stonebrick, 0);
		setBlock(world, i + 11, j + 5, k + 15, Blocks.stonebrick, 0);
		setBlock(world, i + 11, j + 5, k + 16, Blocks.stonebrick, 0);
		setBlock(world, i + 11, j + 5, k + 17, Blocks.stonebrick, 0);
		setBlock(world, i + 11, j + 5, k + 20, Blocks.stonebrick, 0);
		setBlock(world, i + 11, j + 5, k + 21, Blocks.stonebrick, 0);
		setBlock(world, i + 11, j + 5, k + 24, Blocks.stonebrick, 0);
		setBlock(world, i + 11, j + 5, k + 25, Blocks.stonebrick, 0);
		setBlock(world, i + 11, j + 6, k + 12, Blocks.stone_brick_stairs, 0);
		setBlock(world, i + 11, j + 6, k + 13, Blocks.stone_brick_stairs, 0);
		setBlock(world, i + 11, j + 6, k + 14, Blocks.stone_brick_stairs, 0);
		setBlock(world, i + 11, j + 6, k + 15, Blocks.stone_brick_stairs, 0);
		setBlock(world, i + 11, j + 6, k + 16, Blocks.stone_brick_stairs, 0);
		setBlock(world, i + 11, j + 6, k + 17, Blocks.stone_brick_stairs, 0);
		setBlock(world, i + 11, j + 6, k + 18, Blocks.stone_brick_stairs, 0);
		setBlock(world, i + 11, j + 6, k + 19, Blocks.stone_brick_stairs, 0);
		setBlock(world, i + 11, j + 6, k + 20, Blocks.stonebrick, 0);
		setBlock(world, i + 11, j + 6, k + 21, Blocks.stonebrick, 0);
		setBlock(world, i + 11, j + 6, k + 26, Blocks.stonebrick, 0);
		setBlock(world, i + 11, j + 6, k + 27, Blocks.stonebrick, 0);
		setBlock(world, i + 11, j + 6, k + 28, Blocks.stone_brick_stairs, 0);
		setBlock(world, i + 11, j + 6, k + 29, Blocks.stone_brick_stairs, 0);
		setBlock(world, i + 11, j + 6, k + 30, Blocks.stone_brick_stairs, 0);
		setBlock(world, i + 11, j + 6, k + 31, Blocks.stone_brick_stairs, 0);
		setBlock(world, i + 11, j + 6, k + 32, Blocks.stone_brick_stairs, 0);
		setBlock(world, i + 11, j + 6, k + 33, Blocks.stone_brick_stairs, 0);
		setBlock(world, i + 11, j + 6, k + 34, Blocks.stone_brick_stairs, 0);
		setBlock(world, i + 11, j + 6, k + 35, Blocks.stone_brick_stairs, 0);
		setBlock(world, i + 11, j + 7, k + 20, Blocks.stonebrick, 0);
		setBlock(world, i + 11, j + 7, k + 21, Blocks.stonebrick, 0);
		setBlock(world, i + 11, j + 7, k + 26, Blocks.stonebrick, 0);
		setBlock(world, i + 11, j + 7, k + 27, Blocks.stonebrick, 0);
		setBlock(world, i + 11, j + 8, k + 20, Blocks.stonebrick, 0);
		setBlock(world, i + 11, j + 8, k + 21, Blocks.stonebrick, 0);
		setBlock(world, i + 11, j + 8, k + 26, Blocks.stonebrick, 0);
		setBlock(world, i + 11, j + 8, k + 27, Blocks.stonebrick, 0);
		setBlock(world, i + 11, j + 9, k + 20, Blocks.stonebrick, 0);
		setBlock(world, i + 11, j + 9, k + 21, Blocks.stonebrick, 0);
		setBlock(world, i + 11, j + 9, k + 22, Blocks.stonebrick, 0);
		setBlock(world, i + 11, j + 9, k + 23, Blocks.stonebrick, 0);
		setBlock(world, i + 11, j + 9, k + 24, Blocks.stonebrick, 0);
		setBlock(world, i + 11, j + 9, k + 25, Blocks.stonebrick, 0);
		setBlock(world, i + 11, j + 9, k + 26, Blocks.stonebrick, 0);
		setBlock(world, i + 11, j + 9, k + 27, Blocks.stonebrick, 0);
		setBlock(world, i + 11, j + 10, k + 20, Blocks.stonebrick, 0);
		setBlock(world, i + 11, j + 10, k + 21, Blocks.stonebrick, 0);
		setBlock(world, i + 11, j + 10, k + 22, Blocks.stone_brick_stairs, 0);
		setBlock(world, i + 11, j + 10, k + 23, Blocks.stone_brick_stairs, 0);
		setBlock(world, i + 11, j + 10, k + 24, Blocks.stone_brick_stairs, 0);
		setBlock(world, i + 11, j + 10, k + 25, Blocks.stone_brick_stairs, 0);
		setBlock(world, i + 11, j + 10, k + 26, Blocks.stonebrick, 0);
		setBlock(world, i + 11, j + 10, k + 27, Blocks.stonebrick, 0);
		setBlock(world, i + 11, j + 11, k + 20, Blocks.stonebrick, 0);
		setBlock(world, i + 11, j + 11, k + 21, Blocks.stonebrick, 0);
		setBlock(world, i + 11, j + 11, k + 26, Blocks.stonebrick, 0);
		setBlock(world, i + 11, j + 11, k + 27, Blocks.stonebrick, 0);
		setBlock(world, i + 12, j + 3, k + 11, Blocks.stonebrick, 0);
		setBlock(world, i + 12, j + 3, k + 14, Blocks.stonebrick, 0);
		setBlock(world, i + 12, j + 3, k + 16, Blocks.stonebrick, 0);
		setBlock(world, i + 12, j + 3, k + 17, Blocks.stonebrick, 0);
		setBlock(world, i + 12, j + 3, k + 19, Blocks.stonebrick, 0);
		setBlock(world, i + 12, j + 3, k + 21, Blocks.stonebrick, 0);
		setBlock(world, i + 12, j + 3, k + 37, Blocks.stonebrick, 0);
		setBlock(world, i + 12, j + 4, k + 15, Blocks.stonebrick, 0);
		setBlock(world, i + 12, j + 4, k + 18, Blocks.stonebrick, 0);
		setBlock(world, i + 12, j + 4, k + 22, Blocks.stonebrick, 0);
		setBlock(world, i + 12, j + 4, k + 23, Blocks.stonebrick, 0);
		setBlock(world, i + 12, j + 4, k + 26, Blocks.stonebrick, 0);
		setBlock(world, i + 12, j + 4, k + 36, Blocks.stonebrick, 0);
		setBlock(world, i + 12, j + 5, k + 21, Blocks.stonebrick, 0);
		setBlock(world, i + 12, j + 5, k + 22, Blocks.stonebrick, 0);
		setBlock(world, i + 12, j + 5, k + 23, Blocks.stonebrick, 0);
		setBlock(world, i + 12, j + 5, k + 26, Blocks.stonebrick, 0);
		setBlock(world, i + 12, j + 5, k + 29, Blocks.stonebrick, 0);
		setBlock(world, i + 12, j + 5, k + 30, Blocks.stonebrick, 0);
		setBlock(world, i + 12, j + 5, k + 32, Blocks.stonebrick, 0);
		setBlock(world, i + 12, j + 6, k + 16, Blocks.stonebrick, 0);
		setBlock(world, i + 12, j + 6, k + 17, Blocks.stonebrick, 0);
		setBlock(world, i + 12, j + 6, k + 21, Blocks.stonebrick, 0);
		setBlock(world, i + 12, j + 6, k + 27, Blocks.stonebrick, 0);
		setBlock(world, i + 12, j + 6, k + 28, Blocks.stonebrick, 0);
		setBlock(world, i + 12, j + 6, k + 32, Blocks.stonebrick, 0);
		setBlock(world, i + 12, j + 7, k + 15, Blocks.stonebrick, 0);
		setBlock(world, i + 12, j + 7, k + 16, Blocks.stonebrick, 0);
		setBlock(world, i + 12, j + 7, k + 21, Blocks.stonebrick, 0);
		setBlock(world, i + 12, j + 7, k + 24, Blocks.stonebrick, 0);
		setBlock(world, i + 12, j + 7, k + 25, Blocks.stonebrick, 0);
		setBlock(world, i + 12, j + 7, k + 26, Blocks.stonebrick, 0);
		setBlock(world, i + 12, j + 7, k + 29, Blocks.stonebrick, 0);
		setBlock(world, i + 12, j + 7, k + 32, Blocks.stonebrick, 0);
		setBlock(world, i + 12, j + 7, k + 33, Blocks.stonebrick, 0);
		setBlock(world, i + 12, j + 7, k + 34, Blocks.stonebrick, 0);
		setBlock(world, i + 12, j + 8, k + 13, Blocks.stone_brick_stairs, 0);
		setBlock(world, i + 12, j + 8, k + 14, Blocks.stone_brick_stairs, 0);
		setBlock(world, i + 12, j + 8, k + 15, Blocks.stone_brick_stairs, 0);
		setBlock(world, i + 12, j + 8, k + 16, Blocks.stone_brick_stairs, 0);
		setBlock(world, i + 12, j + 8, k + 17, Blocks.stone_brick_stairs, 0);
		setBlock(world, i + 12, j + 8, k + 18, Blocks.stone_brick_stairs, 0);
		setBlock(world, i + 12, j + 8, k + 19, Blocks.stone_brick_stairs, 0);
		setBlock(world, i + 12, j + 8, k + 20, Blocks.stonebrick, 0);
		setBlock(world, i + 12, j + 8, k + 21, Blocks.stonebrick, 0);
		setBlock(world, i + 12, j + 8, k + 26, Blocks.stonebrick, 0);
		setBlock(world, i + 12, j + 8, k + 27, Blocks.stonebrick, 0);
		setBlock(world, i + 12, j + 8, k + 28, Blocks.stone_brick_stairs, 0);
		setBlock(world, i + 12, j + 8, k + 29, Blocks.stone_brick_stairs, 0);
		setBlock(world, i + 12, j + 8, k + 30, Blocks.stone_brick_stairs, 0);
		setBlock(world, i + 12, j + 8, k + 31, Blocks.stone_brick_stairs, 0);
		setBlock(world, i + 12, j + 8, k + 32, Blocks.stone_brick_stairs, 0);
		setBlock(world, i + 12, j + 8, k + 33, Blocks.stone_brick_stairs, 0);
		setBlock(world, i + 12, j + 8, k + 34, Blocks.stone_brick_stairs, 0);
		setBlock(world, i + 12, j + 9, k + 20, Blocks.stonebrick, 0);
		setBlock(world, i + 12, j + 9, k + 21, Blocks.stonebrick, 0);
		setBlock(world, i + 12, j + 9, k + 26, Blocks.stonebrick, 0);
		setBlock(world, i + 12, j + 9, k + 27, Blocks.stonebrick, 0);
		setBlock(world, i + 12, j + 10, k + 20, Blocks.stonebrick, 0);
		setBlock(world, i + 12, j + 10, k + 21, Blocks.stonebrick, 0);
		setBlock(world, i + 12, j + 10, k + 22, Blocks.stonebrick, 0);
		setBlock(world, i + 12, j + 10, k + 23, Blocks.stonebrick, 0);
		setBlock(world, i + 12, j + 10, k + 24, Blocks.stonebrick, 0);
		setBlock(world, i + 12, j + 10, k + 25, Blocks.stonebrick, 0);
		setBlock(world, i + 12, j + 10, k + 26, Blocks.stonebrick, 0);
		setBlock(world, i + 12, j + 10, k + 27, Blocks.stonebrick, 0);
		setBlock(world, i + 12, j + 11, k + 20, Blocks.stonebrick, 0);
		setBlock(world, i + 12, j + 11, k + 21, Blocks.stonebrick, 0);
		setBlock(world, i + 12, j + 11, k + 22, Blocks.stone_brick_stairs, 0);
		setBlock(world, i + 12, j + 11, k + 23, Blocks.stone_brick_stairs, 0);
		setBlock(world, i + 12, j + 11, k + 24, Blocks.stone_brick_stairs, 0);
		setBlock(world, i + 12, j + 11, k + 25, Blocks.stone_brick_stairs, 0);
		setBlock(world, i + 12, j + 11, k + 26, Blocks.stonebrick, 0);
		setBlock(world, i + 12, j + 11, k + 27, Blocks.stonebrick, 0);
		setBlock(world, i + 12, j + 12, k + 20, Blocks.stonebrick, 0);
		setBlock(world, i + 12, j + 12, k + 21, Blocks.stonebrick, 0);
		setBlock(world, i + 12, j + 12, k + 26, Blocks.stonebrick, 0);
		setBlock(world, i + 12, j + 12, k + 27, Blocks.stonebrick, 0);
		setBlock(world, i + 13, j + 2, k + 36, Blocks.stonebrick, 0);
		setBlock(world, i + 13, j + 3, k + 36, Blocks.stonebrick, 0);
		setBlock(world, i + 13, j + 4, k + 36, Blocks.stonebrick, 0);
		setBlock(world, i + 13, j + 5, k + 27, Blocks.stonebrick, 0);
		setBlock(world, i + 13, j + 5, k + 28, Blocks.stonebrick, 0);
		setBlock(world, i + 13, j + 6, k + 16, Blocks.stonebrick, 0);
		setBlock(world, i + 13, j + 6, k + 17, Blocks.stonebrick, 0);
		setBlock(world, i + 13, j + 6, k + 18, Blocks.stonebrick, 0);
		setBlock(world, i + 13, j + 6, k + 22, Blocks.stonebrick, 0);
		setBlock(world, i + 13, j + 6, k + 23, Blocks.stonebrick, 0);
		setBlock(world, i + 13, j + 6, k + 24, Blocks.stonebrick, 0);
		setBlock(world, i + 13, j + 6, k + 25, Blocks.stonebrick, 0);
		setBlock(world, i + 13, j + 6, k + 30, Blocks.stonebrick, 0);
		setBlock(world, i + 13, j + 6, k + 31, Blocks.stonebrick, 0);
		setBlock(world, i + 13, j + 7, k + 12, Blocks.stonebrick, 0);
		setBlock(world, i + 13, j + 7, k + 16, Blocks.stonebrick, 0);
		setBlock(world, i + 13, j + 7, k + 17, Blocks.stonebrick, 0);
		setBlock(world, i + 13, j + 7, k + 19, Blocks.stonebrick, 0);
		setBlock(world, i + 13, j + 7, k + 20, Blocks.stonebrick, 0);
		setBlock(world, i + 13, j + 7, k + 21, Blocks.stonebrick, 0);
		setBlock(world, i + 13, j + 7, k + 29, Blocks.stonebrick, 0);
		setBlock(world, i + 13, j + 7, k + 30, Blocks.stonebrick, 0);
		setBlock(world, i + 13, j + 7, k + 33, Blocks.stonebrick, 0);
		setBlock(world, i + 13, j + 8, k + 15, Blocks.stonebrick, 0);
		setBlock(world, i + 13, j + 8, k + 18, Blocks.stonebrick, 0);
		setBlock(world, i + 13, j + 8, k + 26, Blocks.stonebrick, 0);
		setBlock(world, i + 13, j + 8, k + 29, Blocks.stonebrick, 0);
		setBlock(world, i + 13, j + 9, k + 17, Blocks.stonebrick, 0);
		setBlock(world, i + 13, j + 9, k + 23, Blocks.stonebrick, 0);
		setBlock(world, i + 13, j + 9, k + 25, Blocks.stonebrick, 0);
		setBlock(world, i + 13, j + 9, k + 29, Blocks.stonebrick, 0);
		setBlock(world, i + 13, j + 9, k + 30, Blocks.stonebrick, 0);
		setBlock(world, i + 13, j + 9, k + 31, Blocks.stonebrick, 0);
		setBlock(world, i + 13, j + 9, k + 32, Blocks.stonebrick, 0);
		setBlock(world, i + 13, j + 10, k + 14, Blocks.stone_brick_stairs, 0);
		setBlock(world, i + 13, j + 10, k + 15, Blocks.stone_brick_stairs, 0);
		setBlock(world, i + 13, j + 10, k + 16, Blocks.stone_brick_stairs, 0);
		setBlock(world, i + 13, j + 10, k + 17, Blocks.stone_brick_stairs, 0);
		setBlock(world, i + 13, j + 10, k + 18, Blocks.stone_brick_stairs, 0);
		setBlock(world, i + 13, j + 10, k + 19, Blocks.stone_brick_stairs, 0);
		setBlock(world, i + 13, j + 10, k + 20, Blocks.stonebrick, 0);
		setBlock(world, i + 13, j + 10, k + 21, Blocks.stonebrick, 0);
		setBlock(world, i + 13, j + 10, k + 26, Blocks.stonebrick, 0);
		setBlock(world, i + 13, j + 10, k + 27, Blocks.stonebrick, 0);
		setBlock(world, i + 13, j + 10, k + 28, Blocks.stone_brick_stairs, 0);
		setBlock(world, i + 13, j + 10, k + 29, Blocks.stone_brick_stairs, 0);
		setBlock(world, i + 13, j + 10, k + 30, Blocks.stone_brick_stairs, 0);
		setBlock(world, i + 13, j + 10, k + 31, Blocks.stone_brick_stairs, 0);
		setBlock(world, i + 13, j + 10, k + 32, Blocks.stone_brick_stairs, 0);
		setBlock(world, i + 13, j + 10, k + 33, Blocks.stone_brick_stairs, 0);
		setBlock(world, i + 13, j + 11, k + 20, Blocks.stonebrick, 0);
		setBlock(world, i + 13, j + 11, k + 21, Blocks.stonebrick, 0);
		setBlock(world, i + 13, j + 11, k + 22, Blocks.stonebrick, 0);
		setBlock(world, i + 13, j + 11, k + 23, Blocks.stonebrick, 0);
		setBlock(world, i + 13, j + 11, k + 24, Blocks.stonebrick, 0);
		setBlock(world, i + 13, j + 11, k + 25, Blocks.stonebrick, 0);
		setBlock(world, i + 13, j + 11, k + 26, Blocks.stonebrick, 0);
		setBlock(world, i + 13, j + 11, k + 27, Blocks.stonebrick, 0);
		setBlock(world, i + 13, j + 12, k + 20, Blocks.stonebrick, 0);
		setBlock(world, i + 13, j + 12, k + 21, Blocks.stonebrick, 0);
		setBlock(world, i + 13, j + 12, k + 22, Blocks.stone_brick_stairs, 0);
		setBlock(world, i + 13, j + 12, k + 23, Blocks.stone_brick_stairs, 0);
		setBlock(world, i + 13, j + 12, k + 24, Blocks.stone_brick_stairs, 0);
		setBlock(world, i + 13, j + 12, k + 25, Blocks.stone_brick_stairs, 0);
		setBlock(world, i + 13, j + 12, k + 26, Blocks.stonebrick, 0);
		setBlock(world, i + 13, j + 12, k + 27, Blocks.stonebrick, 0);
		setBlock(world, i + 13, j + 13, k + 20, Blocks.stonebrick, 0);
		setBlock(world, i + 13, j + 13, k + 21, Blocks.stonebrick, 0);
		setBlock(world, i + 13, j + 13, k + 26, Blocks.stonebrick, 0);
		setBlock(world, i + 13, j + 13, k + 27, Blocks.stonebrick, 0);
		setBlock(world, i + 14, j + 0, k + 10, Blocks.stonebrick, 0);
		setBlock(world, i + 14, j + 1, k + 10, Blocks.stonebrick, 0);
		setBlock(world, i + 14, j + 2, k + 36, Blocks.stonebrick, 0);
		setBlock(world, i + 14, j + 2, k + 37, Blocks.stonebrick, 0);
		setBlock(world, i + 14, j + 3, k + 35, Blocks.stonebrick, 0);
		setBlock(world, i + 14, j + 3, k + 36, Blocks.stonebrick, 0);
		setBlock(world, i + 14, j + 3, k + 37, Blocks.stonebrick, 0);
		setBlock(world, i + 14, j + 4, k + 36, Blocks.stonebrick, 0);
		setBlock(world, i + 14, j + 5, k + 36, Blocks.stonebrick, 0);
		setBlock(world, i + 14, j + 7, k + 12, Blocks.stonebrick, 0);
		setBlock(world, i + 14, j + 7, k + 13, Blocks.stonebrick, 0);
		setBlock(world, i + 14, j + 7, k + 16, Blocks.stonebrick, 0);
		setBlock(world, i + 14, j + 7, k + 24, Blocks.stonebrick, 0);
		setBlock(world, i + 14, j + 7, k + 27, Blocks.stonebrick, 0);
		setBlock(world, i + 14, j + 7, k + 30, Blocks.stonebrick, 0);
		setBlock(world, i + 14, j + 7, k + 32, Blocks.stonebrick, 0);
		setBlock(world, i + 14, j + 8, k + 15, Blocks.stonebrick, 0);
		setBlock(world, i + 14, j + 8, k + 22, Blocks.stonebrick, 0);
		setBlock(world, i + 14, j + 8, k + 25, Blocks.stonebrick, 0);
		setBlock(world, i + 14, j + 8, k + 28, Blocks.stonebrick, 0);
		setBlock(world, i + 14, j + 8, k + 29, Blocks.stonebrick, 0);
		setBlock(world, i + 14, j + 8, k + 31, Blocks.stonebrick, 0);
		setBlock(world, i + 14, j + 9, k + 14, Blocks.stonebrick, 0);
		setBlock(world, i + 14, j + 9, k + 21, Blocks.stonebrick, 0);
		setBlock(world, i + 14, j + 9, k + 24, Blocks.stonebrick, 0);
		setBlock(world, i + 14, j + 9, k + 25, Blocks.stonebrick, 0);
		setBlock(world, i + 14, j + 9, k + 26, Blocks.stonebrick, 0);
		setBlock(world, i + 14, j + 9, k + 29, Blocks.stonebrick, 0);
		setBlock(world, i + 14, j + 9, k + 30, Blocks.stonebrick, 0);
		setBlock(world, i + 14, j + 9, k + 31, Blocks.stonebrick, 0);
		setBlock(world, i + 14, j + 9, k + 33, Blocks.stonebrick, 0);
		setBlock(world, i + 14, j + 10, k + 23, Blocks.stonebrick, 0);
		setBlock(world, i + 14, j + 10, k + 27, Blocks.stonebrick, 0);
		setBlock(world, i + 14, j + 10, k + 29, Blocks.stonebrick, 0);
		setBlock(world, i + 14, j + 11, k + 21, Blocks.stonebrick, 0);
		setBlock(world, i + 14, j + 11, k + 26, Blocks.stonebrick, 0);
		setBlock(world, i + 14, j + 12, k + 15, Blocks.stone_brick_stairs, 0);
		setBlock(world, i + 14, j + 12, k + 16, Blocks.stone_brick_stairs, 0);
		setBlock(world, i + 14, j + 12, k + 17, Blocks.stone_brick_stairs, 0);
		setBlock(world, i + 14, j + 12, k + 18, Blocks.stone_brick_stairs, 0);
		setBlock(world, i + 14, j + 12, k + 19, Blocks.stone_brick_stairs, 0);
		setBlock(world, i + 14, j + 12, k + 20, Blocks.stonebrick, 0);
		setBlock(world, i + 14, j + 12, k + 21, Blocks.stonebrick, 0);
		setBlock(world, i + 14, j + 12, k + 22, Blocks.stonebrick, 0);
		setBlock(world, i + 14, j + 12, k + 23, Blocks.stonebrick, 0);
		setBlock(world, i + 14, j + 12, k + 24, Blocks.stonebrick, 0);
		setBlock(world, i + 14, j + 12, k + 25, Blocks.stonebrick, 0);
		setBlock(world, i + 14, j + 12, k + 26, Blocks.stonebrick, 0);
		setBlock(world, i + 14, j + 12, k + 27, Blocks.stonebrick, 0);
		setBlock(world, i + 14, j + 12, k + 28, Blocks.stone_brick_stairs, 0);
		setBlock(world, i + 14, j + 12, k + 29, Blocks.stone_brick_stairs, 0);
		setBlock(world, i + 14, j + 12, k + 30, Blocks.stone_brick_stairs, 0);
		setBlock(world, i + 14, j + 12, k + 31, Blocks.stone_brick_stairs, 0);
		setBlock(world, i + 14, j + 12, k + 32, Blocks.stone_brick_stairs, 0);
		setBlock(world, i + 14, j + 13, k + 20, Blocks.stonebrick, 0);
		setBlock(world, i + 14, j + 13, k + 21, Blocks.stonebrick, 0);
		setBlock(world, i + 14, j + 13, k + 22, Blocks.stone_brick_stairs, 0);
		setBlock(world, i + 14, j + 13, k + 23, Blocks.stone_brick_stairs, 0);
		setBlock(world, i + 14, j + 13, k + 24, Blocks.stone_brick_stairs, 0);
		setBlock(world, i + 14, j + 13, k + 25, Blocks.stone_brick_stairs, 0);
		setBlock(world, i + 14, j + 13, k + 26, Blocks.stonebrick, 0);
		setBlock(world, i + 14, j + 13, k + 27, Blocks.stonebrick, 0);
		setBlock(world, i + 14, j + 14, k + 20, Blocks.stonebrick, 0);
		setBlock(world, i + 14, j + 14, k + 21, Blocks.stonebrick, 0);
		setBlock(world, i + 14, j + 14, k + 26, Blocks.stonebrick, 0);
		setBlock(world, i + 14, j + 14, k + 27, Blocks.stonebrick, 0);
		setBlock(world, i + 15, j + 4, k + 35, Blocks.stonebrick, 0);
		setBlock(world, i + 15, j + 4, k + 36, Blocks.stonebrick, 0);
		setBlock(world, i + 15, j + 5, k + 12, Blocks.stonebrick, 0);
		setBlock(world, i + 15, j + 5, k + 36, Blocks.stonebrick, 0);
		setBlock(world, i + 15, j + 6, k + 12, Blocks.stonebrick, 0);
		setBlock(world, i + 15, j + 7, k + 12, Blocks.stonebrick, 0);
		setBlock(world, i + 15, j + 7, k + 14, Blocks.stonebrick, 0);
		setBlock(world, i + 15, j + 7, k + 35, Blocks.stonebrick, 0);
		setBlock(world, i + 15, j + 8, k + 33, Blocks.stonebrick, 0);
		setBlock(world, i + 15, j + 8, k + 34, Blocks.stonebrick, 0);
		setBlock(world, i + 15, j + 9, k + 13, Blocks.stonebrick, 0);
		setBlock(world, i + 15, j + 9, k + 15, Blocks.stonebrick, 0);
		setBlock(world, i + 15, j + 9, k + 27, Blocks.stonebrick, 0);
		setBlock(world, i + 15, j + 9, k + 32, Blocks.stonebrick, 0);
		setBlock(world, i + 15, j + 10, k + 22, Blocks.stonebrick, 0);
		setBlock(world, i + 15, j + 10, k + 26, Blocks.stonebrick, 0);
		setBlock(world, i + 15, j + 10, k + 27, Blocks.stonebrick, 0);
		setBlock(world, i + 15, j + 10, k + 28, Blocks.stonebrick, 0);
		setBlock(world, i + 15, j + 10, k + 29, Blocks.stonebrick, 0);
		setBlock(world, i + 15, j + 10, k + 30, Blocks.stonebrick, 0);
		setBlock(world, i + 15, j + 10, k + 31, Blocks.stonebrick, 0);
		setBlock(world, i + 15, j + 11, k + 20, Blocks.stonebrick, 0);
		setBlock(world, i + 15, j + 11, k + 21, Blocks.stonebrick, 0);
		setBlock(world, i + 15, j + 11, k + 22, Blocks.stonebrick, 0);
		setBlock(world, i + 15, j + 11, k + 23, Blocks.stonebrick, 0);
		setBlock(world, i + 15, j + 11, k + 24, Blocks.stonebrick, 0);
		setBlock(world, i + 15, j + 11, k + 25, Blocks.stonebrick, 0);
		setBlock(world, i + 15, j + 11, k + 30, Blocks.stonebrick, 0);
		setBlock(world, i + 15, j + 12, k + 21, Blocks.stonebrick, 0);
		setBlock(world, i + 15, j + 12, k + 24, Blocks.stonebrick, 0);
		setBlock(world, i + 15, j + 13, k + 19, Blocks.stonebrick, 0);
		setBlock(world, i + 15, j + 13, k + 20, Blocks.stonebrick, 0);
		setBlock(world, i + 15, j + 13, k + 21, Blocks.stonebrick, 0);
		setBlock(world, i + 15, j + 13, k + 22, Blocks.stonebrick, 0);
		setBlock(world, i + 15, j + 13, k + 23, Blocks.stonebrick, 0);
		setBlock(world, i + 15, j + 13, k + 25, Blocks.stonebrick, 0);
		setBlock(world, i + 15, j + 13, k + 26, Blocks.stonebrick, 0);
		setBlock(world, i + 15, j + 13, k + 30, Blocks.stonebrick, 0);
		setBlock(world, i + 15, j + 14, k + 19, Blocks.stonebrick, 0);
		setBlock(world, i + 15, j + 14, k + 20, Blocks.stonebrick, 0);
		setBlock(world, i + 15, j + 14, k + 21, Blocks.stonebrick, 0);
		setBlock(world, i + 15, j + 14, k + 22, Blocks.stone_brick_stairs, 0);
		setBlock(world, i + 15, j + 14, k + 23, Blocks.stone_brick_stairs, 0);
		setBlock(world, i + 15, j + 14, k + 24, Blocks.stone_brick_stairs, 0);
		setBlock(world, i + 15, j + 14, k + 25, Blocks.stone_brick_stairs, 0);
		setBlock(world, i + 15, j + 14, k + 26, Blocks.stonebrick, 0);
		setBlock(world, i + 15, j + 14, k + 27, Blocks.stonebrick, 0);
		setBlock(world, i + 15, j + 14, k + 28, Blocks.stonebrick, 0);
		setBlock(world, i + 15, j + 15, k + 19, Blocks.stone_brick_stairs, 0);
		setBlock(world, i + 15, j + 15, k + 20, Blocks.stonebrick, 0);
		setBlock(world, i + 15, j + 15, k + 21, Blocks.stonebrick, 0);
		setBlock(world, i + 15, j + 15, k + 26, Blocks.stonebrick, 0);
		setBlock(world, i + 15, j + 15, k + 27, Blocks.stonebrick, 0);
		setBlock(world, i + 15, j + 15, k + 28, Blocks.stone_brick_stairs, 0);
		setBlock(world, i + 16, j + 0, k + 10, Blocks.stonebrick, 0);
		setBlock(world, i + 16, j + 3, k + 10, Blocks.stonebrick, 0);
		setBlock(world, i + 16, j + 3, k + 35, Blocks.stonebrick, 0);
		setBlock(world, i + 16, j + 3, k + 36, Blocks.stonebrick, 0);
		setBlock(world, i + 16, j + 5, k + 36, Blocks.stonebrick, 0);
		setBlock(world, i + 16, j + 6, k + 13, Blocks.stonebrick, 0);
		setBlock(world, i + 16, j + 6, k + 34, Blocks.stonebrick, 0);
		setBlock(world, i + 16, j + 6, k + 35, Blocks.stonebrick, 0);
		setBlock(world, i + 16, j + 7, k + 33, Blocks.stonebrick, 0);
		setBlock(world, i + 16, j + 7, k + 34, Blocks.stonebrick, 0);
		setBlock(world, i + 16, j + 7, k + 35, Blocks.stonebrick, 0);
		setBlock(world, i + 16, j + 8, k + 14, Blocks.stonebrick, 0);
		setBlock(world, i + 16, j + 9, k + 13, Blocks.stonebrick, 0);
		setBlock(world, i + 16, j + 9, k + 14, Blocks.stonebrick, 0);
		setBlock(world, i + 16, j + 10, k + 15, Blocks.stonebrick, 0);
		setBlock(world, i + 16, j + 11, k + 21, Blocks.stonebrick, 0);
		setBlock(world, i + 16, j + 11, k + 22, Blocks.stonebrick, 0);
		setBlock(world, i + 16, j + 11, k + 23, Blocks.stonebrick, 0);
		setBlock(world, i + 16, j + 11, k + 29, Blocks.stonebrick, 0);
		setBlock(world, i + 16, j + 12, k + 23, Blocks.stonebrick, 0);
		setBlock(world, i + 16, j + 13, k + 19, Blocks.stonebrick, 0);
		setBlock(world, i + 16, j + 13, k + 20, Blocks.stonebrick, 0);
		setBlock(world, i + 16, j + 13, k + 22, Blocks.stonebrick, 0);
		setBlock(world, i + 16, j + 13, k + 23, Blocks.stonebrick, 0);
		setBlock(world, i + 16, j + 14, k + 18, Blocks.stonebrick, 0);
		setBlock(world, i + 16, j + 14, k + 19, Blocks.stonebrick, 0);
		setBlock(world, i + 16, j + 14, k + 20, Blocks.stonebrick, 0);
		setBlock(world, i + 16, j + 14, k + 21, Blocks.stonebrick, 0);
		setBlock(world, i + 16, j + 14, k + 22, Blocks.stonebrick, 0);
		setBlock(world, i + 16, j + 14, k + 23, Blocks.stonebrick, 0);
		setBlock(world, i + 16, j + 14, k + 24, Blocks.stonebrick, 0);
		setBlock(world, i + 16, j + 14, k + 25, Blocks.stonebrick, 0);
		setBlock(world, i + 16, j + 14, k + 26, Blocks.stonebrick, 0);
		setBlock(world, i + 16, j + 14, k + 27, Blocks.stonebrick, 0);
		setBlock(world, i + 16, j + 14, k + 28, Blocks.stonebrick, 0);
		setBlock(world, i + 16, j + 14, k + 29, Blocks.stonebrick, 0);
		setBlock(world, i + 16, j + 15, k + 18, Blocks.stone_brick_stairs, 0);
		setBlock(world, i + 16, j + 15, k + 19, Blocks.stonebrick, 0);
		setBlock(world, i + 16, j + 15, k + 20, Blocks.stonebrick, 0);
		setBlock(world, i + 16, j + 15, k + 21, Blocks.stonebrick, 0);
		setBlock(world, i + 16, j + 15, k + 26, Blocks.stonebrick, 0);
		setBlock(world, i + 16, j + 15, k + 27, Blocks.stonebrick, 0);
		setBlock(world, i + 16, j + 15, k + 28, Blocks.stonebrick, 0);
		setBlock(world, i + 16, j + 15, k + 29, Blocks.stone_brick_stairs, 0);
		setBlock(world, i + 16, j + 16, k + 19, Blocks.stone_brick_stairs, 0);
		setBlock(world, i + 16, j + 16, k + 20, Blocks.stonebrick, 0);
		setBlock(world, i + 16, j + 16, k + 21, Blocks.stonebrick, 0);
		setBlock(world, i + 16, j + 16, k + 26, Blocks.stonebrick, 0);
		setBlock(world, i + 16, j + 16, k + 27, Blocks.stonebrick, 0);
		setBlock(world, i + 16, j + 16, k + 28, Blocks.stone_brick_stairs, 0);
		setBlock(world, i + 17, j + 1, k + 9, Blocks.stonebrick, 0);
		setBlock(world, i + 17, j + 1, k + 37, Blocks.stonebrick, 0);
		setBlock(world, i + 17, j + 2, k + 11, Blocks.stonebrick, 0);
		setBlock(world, i + 17, j + 3, k + 11, Blocks.stonebrick, 0);
		setBlock(world, i + 17, j + 3, k + 35, Blocks.stonebrick, 0);
		setBlock(world, i + 17, j + 3, k + 36, Blocks.stonebrick, 0);
		setBlock(world, i + 17, j + 3, k + 37, Blocks.stonebrick, 0);
		setBlock(world, i + 17, j + 4, k + 11, Blocks.stonebrick, 0);
		setBlock(world, i + 17, j + 5, k + 12, Blocks.stonebrick, 0);
		setBlock(world, i + 17, j + 5, k + 36, Blocks.stonebrick, 0);
		setBlock(world, i + 17, j + 6, k + 13, Blocks.stonebrick, 0);
		setBlock(world, i + 17, j + 6, k + 34, Blocks.stonebrick, 0);
		setBlock(world, i + 17, j + 6, k + 35, Blocks.stonebrick, 0);
		setBlock(world, i + 17, j + 7, k + 13, Blocks.stonebrick, 0);
		setBlock(world, i + 17, j + 7, k + 14, Blocks.stonebrick, 0);
		setBlock(world, i + 17, j + 7, k + 34, Blocks.stonebrick, 0);
		setBlock(world, i + 17, j + 9, k + 13, Blocks.stonebrick, 0);
		setBlock(world, i + 17, j + 9, k + 14, Blocks.stonebrick, 0);
		setBlock(world, i + 17, j + 9, k + 34, Blocks.stonebrick, 0);
		setBlock(world, i + 17, j + 10, k + 15, Blocks.stonebrick, 0);
		setBlock(world, i + 17, j + 11, k + 15, Blocks.stonebrick, 0);
		setBlock(world, i + 17, j + 11, k + 22, Blocks.stonebrick, 0);
		setBlock(world, i + 17, j + 12, k + 17, Blocks.stonebrick, 0);
		setBlock(world, i + 17, j + 12, k + 18, Blocks.stonebrick, 0);
		setBlock(world, i + 17, j + 12, k + 23, Blocks.stonebrick, 0);
		setBlock(world, i + 17, j + 12, k + 29, Blocks.stonebrick, 0);
		setBlock(world, i + 17, j + 12, k + 30, Blocks.stonebrick, 0);
		setBlock(world, i + 17, j + 13, k + 15, Blocks.stonebrick, 0);
		setBlock(world, i + 17, j + 13, k + 17, Blocks.stonebrick, 0);
		setBlock(world, i + 17, j + 13, k + 22, Blocks.stonebrick, 0);
		setBlock(world, i + 17, j + 13, k + 24, Blocks.stonebrick, 0);
		setBlock(world, i + 17, j + 13, k + 26, Blocks.stonebrick, 0);
		setBlock(world, i + 17, j + 13, k + 29, Blocks.stonebrick, 0);
		setBlock(world, i + 17, j + 13, k + 30, Blocks.stonebrick, 0);
		setBlock(world, i + 17, j + 14, k + 16, Blocks.stone_brick_stairs, 0);
		setBlock(world, i + 17, j + 14, k + 17, Blocks.stonebrick, 0);
		setBlock(world, i + 17, j + 14, k + 18, Blocks.stonebrick, 0);
		setBlock(world, i + 17, j + 14, k + 19, Blocks.stonebrick, 0);
		setBlock(world, i + 17, j + 14, k + 20, Blocks.stonebrick, 0);
		setBlock(world, i + 17, j + 14, k + 21, Blocks.stonebrick, 0);
		setBlock(world, i + 17, j + 14, k + 22, Blocks.stonebrick, 0);
		setBlock(world, i + 17, j + 14, k + 23, Blocks.stonebrick, 0);
		setBlock(world, i + 17, j + 14, k + 24, Blocks.stonebrick, 0);
		setBlock(world, i + 17, j + 14, k + 25, Blocks.stonebrick, 0);
		setBlock(world, i + 17, j + 14, k + 26, Blocks.stonebrick, 0);
		setBlock(world, i + 17, j + 14, k + 27, Blocks.stonebrick, 0);
		setBlock(world, i + 17, j + 14, k + 28, Blocks.stonebrick, 0);
		setBlock(world, i + 17, j + 14, k + 29, Blocks.stonebrick, 0);
		setBlock(world, i + 17, j + 14, k + 30, Blocks.stonebrick, 0);
		setBlock(world, i + 17, j + 14, k + 31, Blocks.stone_brick_stairs, 0);
		setBlock(world, i + 17, j + 15, k + 17, Blocks.stonebrick, 0);
		setBlock(world, i + 17, j + 15, k + 18, Blocks.stonebrick, 0);
		setBlock(world, i + 17, j + 15, k + 19, Blocks.stonebrick, 0);
		setBlock(world, i + 17, j + 15, k + 20, Blocks.stonebrick, 0);
		setBlock(world, i + 17, j + 15, k + 21, Blocks.stonebrick, 0);
		setBlock(world, i + 17, j + 15, k + 26, Blocks.stonebrick, 0);
		setBlock(world, i + 17, j + 15, k + 27, Blocks.stonebrick, 0);
		setBlock(world, i + 17, j + 15, k + 28, Blocks.stonebrick, 0);
		setBlock(world, i + 17, j + 15, k + 29, Blocks.stonebrick, 0);
		setBlock(world, i + 17, j + 15, k + 30, Blocks.stonebrick, 0);
		setBlock(world, i + 17, j + 16, k + 18, Blocks.stone_brick_stairs, 0);
		setBlock(world, i + 17, j + 16, k + 19, Blocks.stonebrick, 0);
		setBlock(world, i + 17, j + 16, k + 20, Blocks.stonebrick, 0);
		setBlock(world, i + 17, j + 16, k + 21, Blocks.stonebrick, 0);
		setBlock(world, i + 17, j + 16, k + 26, Blocks.stonebrick, 0);
		setBlock(world, i + 17, j + 16, k + 27, Blocks.stonebrick, 0);
		setBlock(world, i + 17, j + 16, k + 28, Blocks.stonebrick, 0);
		setBlock(world, i + 17, j + 16, k + 29, Blocks.stone_brick_stairs, 0);
		setBlock(world, i + 17, j + 17, k + 19, Blocks.stone_brick_stairs, 0);
		setBlock(world, i + 17, j + 17, k + 20, Blocks.stonebrick, 0);
		setBlock(world, i + 17, j + 17, k + 21, Blocks.stonebrick, 0);
		setBlock(world, i + 17, j + 17, k + 26, Blocks.stonebrick, 0);
		setBlock(world, i + 17, j + 17, k + 27, Blocks.stonebrick, 0);
		setBlock(world, i + 17, j + 17, k + 28, Blocks.stone_brick_stairs, 0);
		setBlock(world, i + 18, j + 0, k + 20, Blocks.stonebrick, 0);
		setBlock(world, i + 18, j + 1, k + 20, Blocks.stonebrick, 0);
		setBlock(world, i + 18, j + 1, k + 37, Blocks.stonebrick, 0);
		setBlock(world, i + 18, j + 3, k + 10, Blocks.stonebrick, 0);
		setBlock(world, i + 18, j + 3, k + 11, Blocks.stonebrick, 0);
		setBlock(world, i + 18, j + 3, k + 36, Blocks.stonebrick, 0);
		setBlock(world, i + 18, j + 4, k + 11, Blocks.stonebrick, 0);
		setBlock(world, i + 18, j + 4, k + 35, Blocks.stonebrick, 0);
		setBlock(world, i + 18, j + 5, k + 12, Blocks.stonebrick, 0);
		setBlock(world, i + 18, j + 6, k + 34, Blocks.stonebrick, 0);
		setBlock(world, i + 18, j + 7, k + 12, Blocks.stonebrick, 0);
		setBlock(world, i + 18, j + 7, k + 13, Blocks.stonebrick, 0);
		setBlock(world, i + 18, j + 8, k + 13, Blocks.stonebrick, 0);
		setBlock(world, i + 18, j + 8, k + 14, Blocks.stonebrick, 0);
		setBlock(world, i + 18, j + 8, k + 34, Blocks.stonebrick, 0);
		setBlock(world, i + 18, j + 9, k + 13, Blocks.stonebrick, 0);
		setBlock(world, i + 18, j + 9, k + 14, Blocks.stonebrick, 0);
		setBlock(world, i + 18, j + 10, k + 14, Blocks.stonebrick, 0);
		setBlock(world, i + 18, j + 10, k + 15, Blocks.stonebrick, 0);
		setBlock(world, i + 18, j + 11, k + 16, Blocks.stonebrick, 0);
		setBlock(world, i + 18, j + 12, k + 17, Blocks.stonebrick, 0);
		setBlock(world, i + 18, j + 12, k + 18, Blocks.stonebrick, 0);
		setBlock(world, i + 18, j + 12, k + 22, Blocks.stonebrick, 0);
		setBlock(world, i + 18, j + 12, k + 29, Blocks.stonebrick, 0);
		setBlock(world, i + 18, j + 12, k + 30, Blocks.stonebrick, 0);
		setBlock(world, i + 18, j + 13, k + 17, Blocks.stonebrick, 0);
		setBlock(world, i + 18, j + 13, k + 23, Blocks.stonebrick, 0);
		setBlock(world, i + 18, j + 14, k + 15, Blocks.stone_brick_stairs, 0);
		setBlock(world, i + 18, j + 14, k + 16, Blocks.stonebrick, 0);
		setBlock(world, i + 18, j + 14, k + 17, Blocks.stonebrick, 0);
		setBlock(world, i + 18, j + 14, k + 18, Blocks.stonebrick, 0);
		setBlock(world, i + 18, j + 14, k + 19, Blocks.stonebrick, 0);
		setBlock(world, i + 18, j + 14, k + 20, Blocks.stonebrick, 0);
		setBlock(world, i + 18, j + 14, k + 21, Blocks.stonebrick, 0);
		setBlock(world, i + 18, j + 14, k + 26, Blocks.stonebrick, 0);
		setBlock(world, i + 18, j + 14, k + 27, Blocks.stonebrick, 0);
		setBlock(world, i + 18, j + 14, k + 28, Blocks.stonebrick, 0);
		setBlock(world, i + 18, j + 14, k + 29, Blocks.stonebrick, 0);
		setBlock(world, i + 18, j + 14, k + 30, Blocks.stonebrick, 0);
		setBlock(world, i + 18, j + 14, k + 31, Blocks.stonebrick, 0);
		setBlock(world, i + 18, j + 14, k + 32, Blocks.stone_brick_stairs, 0);
		setBlock(world, i + 18, j + 15, k + 17, Blocks.stonebrick, 0);
		setBlock(world, i + 18, j + 15, k + 18, Blocks.stonebrick, 0);
		setBlock(world, i + 18, j + 15, k + 19, Blocks.stonebrick, 0);
		setBlock(world, i + 18, j + 15, k + 20, Blocks.stonebrick, 0);
		setBlock(world, i + 18, j + 15, k + 21, Blocks.stonebrick, 0);
		setBlock(world, i + 18, j + 15, k + 26, Blocks.stonebrick, 0);
		setBlock(world, i + 18, j + 15, k + 27, Blocks.stonebrick, 0);
		setBlock(world, i + 18, j + 15, k + 28, Blocks.stonebrick, 0);
		setBlock(world, i + 18, j + 15, k + 29, Blocks.stonebrick, 0);
		setBlock(world, i + 18, j + 15, k + 30, Blocks.stonebrick, 0);
		setBlock(world, i + 18, j + 16, k + 18, Blocks.stonebrick, 0);
		setBlock(world, i + 18, j + 16, k + 19, Blocks.stonebrick, 0);
		setBlock(world, i + 18, j + 16, k + 20, Blocks.stonebrick, 0);
		setBlock(world, i + 18, j + 16, k + 21, Blocks.stonebrick, 0);
		setBlock(world, i + 18, j + 16, k + 26, Blocks.stonebrick, 0);
		setBlock(world, i + 18, j + 16, k + 27, Blocks.stonebrick, 0);
		setBlock(world, i + 18, j + 16, k + 28, Blocks.stonebrick, 0);
		setBlock(world, i + 18, j + 16, k + 29, Blocks.stonebrick, 0);
		setBlock(world, i + 18, j + 17, k + 18, Blocks.stonebrick, 0);
		setBlock(world, i + 18, j + 17, k + 19, Blocks.stonebrick, 0);
		setBlock(world, i + 18, j + 17, k + 20, Blocks.stonebrick, 0);
		setBlock(world, i + 18, j + 17, k + 21, Blocks.stonebrick, 0);
		setBlock(world, i + 18, j + 17, k + 26, Blocks.stonebrick, 0);
		setBlock(world, i + 18, j + 17, k + 27, Blocks.stonebrick, 0);
		setBlock(world, i + 18, j + 17, k + 28, Blocks.stonebrick, 0);
		setBlock(world, i + 18, j + 17, k + 29, Blocks.stonebrick, 0);
		setBlock(world, i + 18, j + 18, k + 19, Blocks.stone_brick_stairs, 0);
		setBlock(world, i + 18, j + 18, k + 20, Blocks.stonebrick, 0);
		setBlock(world, i + 18, j + 18, k + 21, Blocks.stonebrick, 0);
		setBlock(world, i + 18, j + 18, k + 26, Blocks.stonebrick, 0);
		setBlock(world, i + 18, j + 18, k + 27, Blocks.stonebrick, 0);
		setBlock(world, i + 18, j + 18, k + 28, Blocks.stone_brick_stairs, 0);
		setBlock(world, i + 19, j + 0, k + 20, Blocks.stonebrick, 0);
		setBlock(world, i + 19, j + 1, k + 9, Blocks.stonebrick, 0);
		setBlock(world, i + 19, j + 1, k + 20, Blocks.stonebrick, 0);
		setBlock(world, i + 19, j + 2, k + 11, Blocks.stonebrick, 0);
		setBlock(world, i + 19, j + 2, k + 37, Blocks.stonebrick, 0);
		setBlock(world, i + 19, j + 3, k + 11, Blocks.stonebrick, 0);
		setBlock(world, i + 19, j + 3, k + 35, Blocks.stonebrick, 0);
		setBlock(world, i + 19, j + 3, k + 37, Blocks.stonebrick, 0);
		setBlock(world, i + 19, j + 5, k + 13, Blocks.stonebrick, 0);
		setBlock(world, i + 19, j + 6, k + 12, Blocks.stonebrick, 0);
		setBlock(world, i + 19, j + 7, k + 34, Blocks.stonebrick, 0);
		setBlock(world, i + 19, j + 8, k + 14, Blocks.stonebrick, 0);
		setBlock(world, i + 19, j + 10, k + 15, Blocks.stonebrick, 0);
		setBlock(world, i + 19, j + 11, k + 24, Blocks.stonebrick, 0);
		setBlock(world, i + 19, j + 12, k + 25, Blocks.stonebrick, 0);
		setBlock(world, i + 19, j + 13, k + 20, Blocks.stonebrick, 0);
		setBlock(world, i + 19, j + 13, k + 27, Blocks.stonebrick, 0);
		setBlock(world, i + 19, j + 13, k + 31, Blocks.stonebrick, 0);
		setBlock(world, i + 19, j + 13, k + 32, Blocks.stonebrick, 0);
		setBlock(world, i + 19, j + 14, k + 15, Blocks.stonebrick, 0);
		setBlock(world, i + 19, j + 14, k + 16, Blocks.stonebrick, 0);
		setBlock(world, i + 19, j + 14, k + 17, Blocks.stonebrick, 0);
		setBlock(world, i + 19, j + 14, k + 18, Blocks.stonebrick, 0);
		setBlock(world, i + 19, j + 14, k + 21, Blocks.stonebrick, 0);
		setBlock(world, i + 19, j + 14, k + 27, Blocks.stonebrick, 0);
		setBlock(world, i + 19, j + 14, k + 29, Blocks.stonebrick, 0);
		setBlock(world, i + 19, j + 14, k + 30, Blocks.stonebrick, 0);
		setBlock(world, i + 19, j + 14, k + 31, Blocks.stonebrick, 0);
		setBlock(world, i + 19, j + 14, k + 32, Blocks.stonebrick, 0);
		setBlock(world, i + 19, j + 15, k + 16, Blocks.stonebrick, 0);
		setBlock(world, i + 19, j + 15, k + 17, Blocks.stonebrick, 0);
		setBlock(world, i + 19, j + 15, k + 18, Blocks.stonebrick, 0);
		setBlock(world, i + 19, j + 15, k + 19, Blocks.stonebrick, 0);
		setBlock(world, i + 19, j + 15, k + 21, Blocks.stonebrick, 0);
		setBlock(world, i + 19, j + 15, k + 28, Blocks.stonebrick, 0);
		setBlock(world, i + 19, j + 15, k + 29, Blocks.stonebrick, 0);
		setBlock(world, i + 19, j + 15, k + 30, Blocks.stonebrick, 0);
		setBlock(world, i + 19, j + 15, k + 31, Blocks.stonebrick, 0);
		setBlock(world, i + 19, j + 16, k + 17, Blocks.stonebrick, 0);
		setBlock(world, i + 19, j + 16, k + 18, Blocks.stonebrick, 0);
		setBlock(world, i + 19, j + 16, k + 20, Blocks.stonebrick, 0);
		setBlock(world, i + 19, j + 16, k + 21, Blocks.stonebrick, 0);
		setBlock(world, i + 19, j + 16, k + 29, Blocks.stonebrick, 0);
		setBlock(world, i + 19, j + 16, k + 30, Blocks.stonebrick, 0);
		setBlock(world, i + 19, j + 17, k + 18, Blocks.stonebrick, 0);
		setBlock(world, i + 19, j + 17, k + 20, Blocks.stonebrick, 0);
		setBlock(world, i + 19, j + 17, k + 29, Blocks.stonebrick, 0);
		setBlock(world, i + 19, j + 18, k + 20, Blocks.stonebrick, 0);
		setBlock(world, i + 19, j + 19, k + 21, Blocks.stonebrick, 0);
		setBlock(world, i + 19, j + 19, k + 22, Blocks.stonebrick, 0);
		setBlock(world, i + 19, j + 19, k + 26, Blocks.stonebrick, 0);
		setBlock(world, i + 19, j + 19, k + 27, Blocks.stonebrick, 0);
		setBlock(world, i + 20, j + 0, k + 0, Blocks.stonebrick, 0);
		setBlock(world, i + 20, j + 0, k + 1, Blocks.stonebrick, 0);
		setBlock(world, i + 20, j + 0, k + 2, Blocks.stonebrick, 0);
		setBlock(world, i + 20, j + 0, k + 3, Blocks.stonebrick, 0);
		setBlock(world, i + 20, j + 0, k + 4, Blocks.stonebrick, 0);
		setBlock(world, i + 20, j + 0, k + 5, Blocks.stonebrick, 0);
		setBlock(world, i + 20, j + 0, k + 6, Blocks.stonebrick, 0);
		setBlock(world, i + 20, j + 0, k + 7, Blocks.stonebrick, 0);
		setBlock(world, i + 20, j + 0, k + 8, Blocks.stonebrick, 0);
		setBlock(world, i + 20, j + 0, k + 18, Blocks.stonebrick, 0);
		setBlock(world, i + 20, j + 0, k + 19, Blocks.stonebrick, 0);
		setBlock(world, i + 20, j + 0, k + 39, Blocks.stonebrick, 0);
		setBlock(world, i + 20, j + 0, k + 40, Blocks.stonebrick, 0);
		setBlock(world, i + 20, j + 0, k + 41, Blocks.stonebrick, 0);
		setBlock(world, i + 20, j + 0, k + 42, Blocks.stonebrick, 0);
		setBlock(world, i + 20, j + 0, k + 43, Blocks.stonebrick, 0);
		setBlock(world, i + 20, j + 0, k + 44, Blocks.stonebrick, 0);
		setBlock(world, i + 20, j + 0, k + 45, Blocks.stonebrick, 0);
		setBlock(world, i + 20, j + 0, k + 46, Blocks.stonebrick, 0);
		setBlock(world, i + 20, j + 0, k + 47, Blocks.stonebrick, 0);
		setBlock(world, i + 20, j + 1, k + 1, Blocks.stonebrick, 0);
		setBlock(world, i + 20, j + 1, k + 2, Blocks.stonebrick, 0);
		setBlock(world, i + 20, j + 1, k + 3, Blocks.stonebrick, 0);
		setBlock(world, i + 20, j + 1, k + 4, Blocks.stonebrick, 0);
		setBlock(world, i + 20, j + 1, k + 5, Blocks.stonebrick, 0);
		setBlock(world, i + 20, j + 1, k + 6, Blocks.stonebrick, 0);
		setBlock(world, i + 20, j + 1, k + 7, Blocks.stonebrick, 0);
		setBlock(world, i + 20, j + 1, k + 8, Blocks.stonebrick, 0);
		setBlock(world, i + 20, j + 1, k + 10, Blocks.stonebrick, 0);
		setBlock(world, i + 20, j + 1, k + 18, Blocks.stonebrick, 0);
		setBlock(world, i + 20, j + 1, k + 19, Blocks.stonebrick, 0);
		setBlock(world, i + 20, j + 1, k + 39, Blocks.stonebrick, 0);
		setBlock(world, i + 20, j + 1, k + 40, Blocks.stonebrick, 0);
		setBlock(world, i + 20, j + 1, k + 41, Blocks.stonebrick, 0);
		setBlock(world, i + 20, j + 1, k + 42, Blocks.stonebrick, 0);
		setBlock(world, i + 20, j + 1, k + 43, Blocks.stonebrick, 0);
		setBlock(world, i + 20, j + 1, k + 44, Blocks.stonebrick, 0);
		setBlock(world, i + 20, j + 1, k + 45, Blocks.stonebrick, 0);
		setBlock(world, i + 20, j + 1, k + 46, Blocks.stonebrick, 0);
		setBlock(world, i + 20, j + 2, k + 2, Blocks.stonebrick, 0);
		setBlock(world, i + 20, j + 2, k + 3, Blocks.stonebrick, 0);
		setBlock(world, i + 20, j + 2, k + 4, Blocks.stonebrick, 0);
		setBlock(world, i + 20, j + 2, k + 5, Blocks.stonebrick, 0);
		setBlock(world, i + 20, j + 2, k + 6, Blocks.stonebrick, 0);
		setBlock(world, i + 20, j + 2, k + 7, Blocks.stonebrick, 0);
		setBlock(world, i + 20, j + 2, k + 8, Blocks.stonebrick, 0);
		setBlock(world, i + 20, j + 2, k + 9, Blocks.stonebrick, 0);
		setBlock(world, i + 20, j + 2, k + 10, Blocks.stonebrick, 0);
		setBlock(world, i + 20, j + 2, k + 36, Blocks.stonebrick, 0);
		setBlock(world, i + 20, j + 2, k + 38, Blocks.stonebrick, 0);
		setBlock(world, i + 20, j + 2, k + 39, Blocks.stonebrick, 0);
		setBlock(world, i + 20, j + 2, k + 40, Blocks.stonebrick, 0);
		setBlock(world, i + 20, j + 2, k + 41, Blocks.stonebrick, 0);
		setBlock(world, i + 20, j + 2, k + 42, Blocks.stonebrick, 0);
		setBlock(world, i + 20, j + 2, k + 43, Blocks.stonebrick, 0);
		setBlock(world, i + 20, j + 2, k + 44, Blocks.stonebrick, 0);
		setBlock(world, i + 20, j + 2, k + 45, Blocks.stonebrick, 0);
		setBlock(world, i + 20, j + 3, k + 3, Blocks.stonebrick, 0);
		setBlock(world, i + 20, j + 3, k + 4, Blocks.stonebrick, 0);
		setBlock(world, i + 20, j + 3, k + 5, Blocks.stonebrick, 0);
		setBlock(world, i + 20, j + 3, k + 6, Blocks.stonebrick, 0);
		setBlock(world, i + 20, j + 3, k + 7, Blocks.stonebrick, 0);
		setBlock(world, i + 20, j + 3, k + 8, Blocks.stonebrick, 0);
		setBlock(world, i + 20, j + 3, k + 9, Blocks.stonebrick, 0);
		setBlock(world, i + 20, j + 3, k + 10, Blocks.stonebrick, 0);
		setBlock(world, i + 20, j + 3, k + 11, Blocks.stonebrick, 0);
		setBlock(world, i + 20, j + 3, k + 38, Blocks.stonebrick, 0);
		setBlock(world, i + 20, j + 3, k + 39, Blocks.stonebrick, 0);
		setBlock(world, i + 20, j + 3, k + 40, Blocks.stonebrick, 0);
		setBlock(world, i + 20, j + 3, k + 41, Blocks.stonebrick, 0);
		setBlock(world, i + 20, j + 3, k + 42, Blocks.stonebrick, 0);
		setBlock(world, i + 20, j + 3, k + 43, Blocks.stonebrick, 0);
		setBlock(world, i + 20, j + 3, k + 44, Blocks.stonebrick, 0);
		setBlock(world, i + 20, j + 4, k + 4, Blocks.stonebrick, 0);
		setBlock(world, i + 20, j + 4, k + 5, Blocks.stonebrick, 0);
		setBlock(world, i + 20, j + 4, k + 6, Blocks.stonebrick, 0);
		setBlock(world, i + 20, j + 4, k + 7, Blocks.stonebrick, 0);
		setBlock(world, i + 20, j + 4, k + 8, Blocks.stonebrick, 0);
		setBlock(world, i + 20, j + 4, k + 9, Blocks.stonebrick, 0);
		setBlock(world, i + 20, j + 4, k + 10, Blocks.stonebrick, 0);
		setBlock(world, i + 20, j + 4, k + 36, Blocks.stonebrick, 0);
		setBlock(world, i + 20, j + 4, k + 37, Blocks.stonebrick, 0);
		setBlock(world, i + 20, j + 4, k + 38, Blocks.stonebrick, 0);
		setBlock(world, i + 20, j + 4, k + 39, Blocks.stonebrick, 0);
		setBlock(world, i + 20, j + 4, k + 40, Blocks.stonebrick, 0);
		setBlock(world, i + 20, j + 4, k + 41, Blocks.stonebrick, 0);
		setBlock(world, i + 20, j + 4, k + 42, Blocks.stonebrick, 0);
		setBlock(world, i + 20, j + 4, k + 43, Blocks.stonebrick, 0);
		setBlock(world, i + 20, j + 5, k + 5, Blocks.stonebrick, 0);
		setBlock(world, i + 20, j + 5, k + 6, Blocks.stonebrick, 0);
		setBlock(world, i + 20, j + 5, k + 7, Blocks.stonebrick, 0);
		setBlock(world, i + 20, j + 5, k + 8, Blocks.stonebrick, 0);
		setBlock(world, i + 20, j + 5, k + 9, Blocks.stonebrick, 0);
		setBlock(world, i + 20, j + 5, k + 10, Blocks.stonebrick, 0);
		setBlock(world, i + 20, j + 5, k + 13, Blocks.stonebrick, 0);
		setBlock(world, i + 20, j + 5, k + 36, Blocks.stonebrick, 0);
		setBlock(world, i + 20, j + 5, k + 37, Blocks.stonebrick, 0);
		setBlock(world, i + 20, j + 5, k + 38, Blocks.stonebrick, 0);
		setBlock(world, i + 20, j + 5, k + 39, Blocks.stonebrick, 0);
		setBlock(world, i + 20, j + 5, k + 40, Blocks.stonebrick, 0);
		setBlock(world, i + 20, j + 5, k + 41, Blocks.stonebrick, 0);
		setBlock(world, i + 20, j + 5, k + 42, Blocks.stonebrick, 0);
		setBlock(world, i + 20, j + 6, k + 6, Blocks.stonebrick, 0);
		setBlock(world, i + 20, j + 6, k + 7, Blocks.stonebrick, 0);
		setBlock(world, i + 20, j + 6, k + 8, Blocks.stonebrick, 0);
		setBlock(world, i + 20, j + 6, k + 9, Blocks.stonebrick, 0);
		setBlock(world, i + 20, j + 6, k + 10, Blocks.stonebrick, 0);
		setBlock(world, i + 20, j + 6, k + 11, Blocks.stonebrick, 0);
		setBlock(world, i + 20, j + 6, k + 12, Blocks.stonebrick, 0);
		setBlock(world, i + 20, j + 6, k + 36, Blocks.stonebrick, 0);
		setBlock(world, i + 20, j + 6, k + 37, Blocks.stonebrick, 0);
		setBlock(world, i + 20, j + 6, k + 38, Blocks.stonebrick, 0);
		setBlock(world, i + 20, j + 6, k + 39, Blocks.stonebrick, 0);
		setBlock(world, i + 20, j + 6, k + 40, Blocks.stonebrick, 0);
		setBlock(world, i + 20, j + 6, k + 41, Blocks.stonebrick, 0);
		setBlock(world, i + 20, j + 7, k + 7, Blocks.stonebrick, 0);
		setBlock(world, i + 20, j + 7, k + 8, Blocks.stonebrick, 0);
		setBlock(world, i + 20, j + 7, k + 9, Blocks.stonebrick, 0);
		setBlock(world, i + 20, j + 7, k + 10, Blocks.stonebrick, 0);
		setBlock(world, i + 20, j + 7, k + 11, Blocks.stonebrick, 0);
		setBlock(world, i + 20, j + 7, k + 14, Blocks.stonebrick, 0);
		setBlock(world, i + 20, j + 7, k + 34, Blocks.stonebrick, 0);
		setBlock(world, i + 20, j + 7, k + 36, Blocks.stonebrick, 0);
		setBlock(world, i + 20, j + 7, k + 37, Blocks.stonebrick, 0);
		setBlock(world, i + 20, j + 7, k + 38, Blocks.stonebrick, 0);
		setBlock(world, i + 20, j + 7, k + 39, Blocks.stonebrick, 0);
		setBlock(world, i + 20, j + 7, k + 40, Blocks.stonebrick, 0);
		setBlock(world, i + 20, j + 8, k + 8, Blocks.stonebrick, 0);
		setBlock(world, i + 20, j + 8, k + 9, Blocks.stonebrick, 0);
		setBlock(world, i + 20, j + 8, k + 10, Blocks.stonebrick, 0);
		setBlock(world, i + 20, j + 8, k + 11, Blocks.stonebrick, 0);
		setBlock(world, i + 20, j + 8, k + 12, Blocks.stonebrick, 0);
		setBlock(world, i + 20, j + 8, k + 35, Blocks.stonebrick, 0);
		setBlock(world, i + 20, j + 8, k + 36, Blocks.stonebrick, 0);
		setBlock(world, i + 20, j + 8, k + 37, Blocks.stonebrick, 0);
		setBlock(world, i + 20, j + 8, k + 38, Blocks.stonebrick, 0);
		setBlock(world, i + 20, j + 8, k + 39, Blocks.stonebrick, 0);
		setBlock(world, i + 20, j + 9, k + 9, Blocks.stonebrick, 0);
		setBlock(world, i + 20, j + 9, k + 10, Blocks.stonebrick, 0);
		setBlock(world, i + 20, j + 9, k + 11, Blocks.stonebrick, 0);
		setBlock(world, i + 20, j + 9, k + 12, Blocks.stonebrick, 0);
		setBlock(world, i + 20, j + 9, k + 15, Blocks.stonebrick, 0);
		setBlock(world, i + 20, j + 9, k + 35, Blocks.stonebrick, 0);
		setBlock(world, i + 20, j + 9, k + 36, Blocks.stonebrick, 0);
		setBlock(world, i + 20, j + 9, k + 37, Blocks.stonebrick, 0);
		setBlock(world, i + 20, j + 9, k + 38, Blocks.stonebrick, 0);
		setBlock(world, i + 20, j + 10, k + 10, Blocks.stonebrick, 0);
		setBlock(world, i + 20, j + 10, k + 11, Blocks.stonebrick, 0);
		setBlock(world, i + 20, j + 10, k + 12, Blocks.stonebrick, 0);
		setBlock(world, i + 20, j + 10, k + 13, Blocks.stonebrick, 0);
		setBlock(world, i + 20, j + 10, k + 14, Blocks.stonebrick, 0);
		setBlock(world, i + 20, j + 10, k + 15, Blocks.stonebrick, 0);
		setBlock(world, i + 20, j + 10, k + 34, Blocks.stonebrick, 0);
		setBlock(world, i + 20, j + 10, k + 35, Blocks.stonebrick, 0);
		setBlock(world, i + 20, j + 10, k + 36, Blocks.stonebrick, 0);
		setBlock(world, i + 20, j + 10, k + 37, Blocks.stonebrick, 0);
		setBlock(world, i + 20, j + 11, k + 11, Blocks.stonebrick, 0);
		setBlock(world, i + 20, j + 11, k + 12, Blocks.stonebrick, 0);
		setBlock(world, i + 20, j + 11, k + 13, Blocks.stonebrick, 0);
		setBlock(world, i + 20, j + 11, k + 32, Blocks.stonebrick, 0);
		setBlock(world, i + 20, j + 11, k + 34, Blocks.stonebrick, 0);
		setBlock(world, i + 20, j + 11, k + 35, Blocks.stonebrick, 0);
		setBlock(world, i + 20, j + 11, k + 36, Blocks.stonebrick, 0);
		setBlock(world, i + 20, j + 12, k + 12, Blocks.stonebrick, 0);
		setBlock(world, i + 20, j + 12, k + 13, Blocks.stonebrick, 0);
		setBlock(world, i + 20, j + 12, k + 14, Blocks.stonebrick, 0);
		setBlock(world, i + 20, j + 12, k + 19, Blocks.stonebrick, 0);
		setBlock(world, i + 20, j + 12, k + 33, Blocks.stonebrick, 0);
		setBlock(world, i + 20, j + 12, k + 34, Blocks.stonebrick, 0);
		setBlock(world, i + 20, j + 12, k + 35, Blocks.stonebrick, 0);
		setBlock(world, i + 20, j + 13, k + 13, Blocks.stonebrick, 0);
		setBlock(world, i + 20, j + 13, k + 14, Blocks.stonebrick, 0);
		setBlock(world, i + 20, j + 13, k + 31, Blocks.stonebrick, 0);
		setBlock(world, i + 20, j + 13, k + 32, Blocks.stonebrick, 0);
		setBlock(world, i + 20, j + 13, k + 33, Blocks.stonebrick, 0);
		setBlock(world, i + 20, j + 13, k + 34, Blocks.stonebrick, 0);
		setBlock(world, i + 20, j + 14, k + 14, Blocks.stonebrick, 0);
		setBlock(world, i + 20, j + 14, k + 15, Blocks.stonebrick, 0);
		setBlock(world, i + 20, j + 14, k + 16, Blocks.stonebrick, 0);
		setBlock(world, i + 20, j + 14, k + 17, Blocks.stonebrick, 0);
		setBlock(world, i + 20, j + 14, k + 18, Blocks.stonebrick, 0);
		setBlock(world, i + 20, j + 14, k + 29, Blocks.stonebrick, 0);
		setBlock(world, i + 20, j + 14, k + 30, Blocks.stonebrick, 0);
		setBlock(world, i + 20, j + 14, k + 31, Blocks.stonebrick, 0);
		setBlock(world, i + 20, j + 14, k + 32, Blocks.stonebrick, 0);
		setBlock(world, i + 20, j + 14, k + 33, Blocks.stonebrick, 0);
		setBlock(world, i + 20, j + 15, k + 15, Blocks.stonebrick, 0);
		setBlock(world, i + 20, j + 15, k + 16, Blocks.stonebrick, 0);
		setBlock(world, i + 20, j + 15, k + 17, Blocks.stonebrick, 0);
		setBlock(world, i + 20, j + 15, k + 18, Blocks.stonebrick, 0);
		setBlock(world, i + 20, j + 15, k + 19, Blocks.stonebrick, 0);
		setBlock(world, i + 20, j + 15, k + 28, Blocks.stonebrick, 0);
		setBlock(world, i + 20, j + 15, k + 29, Blocks.stonebrick, 0);
		setBlock(world, i + 20, j + 15, k + 30, Blocks.stonebrick, 0);
		setBlock(world, i + 20, j + 15, k + 31, Blocks.stonebrick, 0);
		setBlock(world, i + 20, j + 15, k + 32, Blocks.stonebrick, 0);
		setBlock(world, i + 20, j + 16, k + 16, Blocks.stonebrick, 0);
		setBlock(world, i + 20, j + 16, k + 17, Blocks.stonebrick, 0);
		setBlock(world, i + 20, j + 16, k + 18, Blocks.stonebrick, 0);
		setBlock(world, i + 20, j + 16, k + 19, Blocks.stonebrick, 0);
		setBlock(world, i + 20, j + 16, k + 28, Blocks.stonebrick, 0);
		setBlock(world, i + 20, j + 16, k + 29, Blocks.stonebrick, 0);
		setBlock(world, i + 20, j + 16, k + 30, Blocks.stonebrick, 0);
		setBlock(world, i + 20, j + 16, k + 31, Blocks.stonebrick, 0);
		setBlock(world, i + 20, j + 17, k + 17, Blocks.stonebrick, 0);
		setBlock(world, i + 20, j + 17, k + 18, Blocks.stonebrick, 0);
		setBlock(world, i + 20, j + 17, k + 29, Blocks.stonebrick, 0);
		setBlock(world, i + 20, j + 17, k + 30, Blocks.stonebrick, 0);
		setBlock(world, i + 20, j + 18, k + 18, Blocks.stonebrick, 0);
		setBlock(world, i + 20, j + 18, k + 29, Blocks.stonebrick, 0);
		setBlock(world, i + 20, j + 19, k + 20, Blocks.stonebrick, 0);
		setBlock(world, i + 20, j + 19, k + 26, Blocks.stonebrick, 0);
		setBlock(world, i + 21, j + 0, k + 0, Blocks.stonebrick, 0);
		setBlock(world, i + 21, j + 0, k + 1, Blocks.stonebrick, 0);
		setBlock(world, i + 21, j + 0, k + 2, Blocks.stonebrick, 0);
		setBlock(world, i + 21, j + 0, k + 3, Blocks.stonebrick, 0);
		setBlock(world, i + 21, j + 0, k + 4, Blocks.stonebrick, 0);
		setBlock(world, i + 21, j + 0, k + 5, Blocks.stonebrick, 0);
		setBlock(world, i + 21, j + 0, k + 6, Blocks.stonebrick, 0);
		setBlock(world, i + 21, j + 0, k + 7, Blocks.stonebrick, 0);
		setBlock(world, i + 21, j + 0, k + 8, Blocks.stonebrick, 0);
		setBlock(world, i + 21, j + 0, k + 9, Blocks.stonebrick, 0);
		setBlock(world, i + 21, j + 0, k + 39, Blocks.stonebrick, 0);
		setBlock(world, i + 21, j + 0, k + 40, Blocks.stonebrick, 0);
		setBlock(world, i + 21, j + 0, k + 41, Blocks.stonebrick, 0);
		setBlock(world, i + 21, j + 0, k + 42, Blocks.stonebrick, 0);
		setBlock(world, i + 21, j + 0, k + 43, Blocks.stonebrick, 0);
		setBlock(world, i + 21, j + 0, k + 44, Blocks.stonebrick, 0);
		setBlock(world, i + 21, j + 0, k + 45, Blocks.stonebrick, 0);
		setBlock(world, i + 21, j + 0, k + 46, Blocks.stonebrick, 0);
		setBlock(world, i + 21, j + 0, k + 47, Blocks.stonebrick, 0);
		setBlock(world, i + 21, j + 1, k + 1, Blocks.stonebrick, 0);
		setBlock(world, i + 21, j + 1, k + 2, Blocks.stonebrick, 0);
		setBlock(world, i + 21, j + 1, k + 3, Blocks.stonebrick, 0);
		setBlock(world, i + 21, j + 1, k + 4, Blocks.stonebrick, 0);
		setBlock(world, i + 21, j + 1, k + 5, Blocks.stonebrick, 0);
		setBlock(world, i + 21, j + 1, k + 6, Blocks.stonebrick, 0);
		setBlock(world, i + 21, j + 1, k + 7, Blocks.stonebrick, 0);
		setBlock(world, i + 21, j + 1, k + 8, Blocks.stonebrick, 0);
		setBlock(world, i + 21, j + 1, k + 9, Blocks.stonebrick, 0);
		setBlock(world, i + 21, j + 1, k + 37, Blocks.stonebrick, 0);
		setBlock(world, i + 21, j + 1, k + 39, Blocks.stonebrick, 0);
		setBlock(world, i + 21, j + 1, k + 40, Blocks.stonebrick, 0);
		setBlock(world, i + 21, j + 1, k + 41, Blocks.stonebrick, 0);
		setBlock(world, i + 21, j + 1, k + 42, Blocks.stonebrick, 0);
		setBlock(world, i + 21, j + 1, k + 43, Blocks.stonebrick, 0);
		setBlock(world, i + 21, j + 1, k + 44, Blocks.stonebrick, 0);
		setBlock(world, i + 21, j + 1, k + 45, Blocks.stonebrick, 0);
		setBlock(world, i + 21, j + 1, k + 46, Blocks.stonebrick, 0);
		setBlock(world, i + 21, j + 2, k + 2, Blocks.stonebrick, 0);
		setBlock(world, i + 21, j + 2, k + 3, Blocks.stonebrick, 0);
		setBlock(world, i + 21, j + 2, k + 4, Blocks.stonebrick, 0);
		setBlock(world, i + 21, j + 2, k + 5, Blocks.stonebrick, 0);
		setBlock(world, i + 21, j + 2, k + 6, Blocks.stonebrick, 0);
		setBlock(world, i + 21, j + 2, k + 7, Blocks.stonebrick, 0);
		setBlock(world, i + 21, j + 2, k + 8, Blocks.stonebrick, 0);
		setBlock(world, i + 21, j + 2, k + 9, Blocks.stonebrick, 0);
		setBlock(world, i + 21, j + 2, k + 10, Blocks.stonebrick, 0);
		setBlock(world, i + 21, j + 2, k + 37, Blocks.stonebrick, 0);
		setBlock(world, i + 21, j + 2, k + 38, Blocks.stonebrick, 0);
		setBlock(world, i + 21, j + 2, k + 39, Blocks.stonebrick, 0);
		setBlock(world, i + 21, j + 2, k + 40, Blocks.stonebrick, 0);
		setBlock(world, i + 21, j + 2, k + 41, Blocks.stonebrick, 0);
		setBlock(world, i + 21, j + 2, k + 42, Blocks.stonebrick, 0);
		setBlock(world, i + 21, j + 2, k + 43, Blocks.stonebrick, 0);
		setBlock(world, i + 21, j + 2, k + 44, Blocks.stonebrick, 0);
		setBlock(world, i + 21, j + 2, k + 45, Blocks.stonebrick, 0);
		setBlock(world, i + 21, j + 3, k + 3, Blocks.stonebrick, 0);
		setBlock(world, i + 21, j + 3, k + 4, Blocks.stonebrick, 0);
		setBlock(world, i + 21, j + 3, k + 5, Blocks.stonebrick, 0);
		setBlock(world, i + 21, j + 3, k + 6, Blocks.stonebrick, 0);
		setBlock(world, i + 21, j + 3, k + 7, Blocks.stonebrick, 0);
		setBlock(world, i + 21, j + 3, k + 8, Blocks.stonebrick, 0);
		setBlock(world, i + 21, j + 3, k + 9, Blocks.stonebrick, 0);
		setBlock(world, i + 21, j + 3, k + 10, Blocks.stonebrick, 0);
		setBlock(world, i + 21, j + 3, k + 38, Blocks.stonebrick, 0);
		setBlock(world, i + 21, j + 3, k + 39, Blocks.stonebrick, 0);
		setBlock(world, i + 21, j + 3, k + 40, Blocks.stonebrick, 0);
		setBlock(world, i + 21, j + 3, k + 41, Blocks.stonebrick, 0);
		setBlock(world, i + 21, j + 3, k + 42, Blocks.stonebrick, 0);
		setBlock(world, i + 21, j + 3, k + 43, Blocks.stonebrick, 0);
		setBlock(world, i + 21, j + 3, k + 44, Blocks.stonebrick, 0);
		setBlock(world, i + 21, j + 4, k + 4, Blocks.stonebrick, 0);
		setBlock(world, i + 21, j + 4, k + 5, Blocks.stonebrick, 0);
		setBlock(world, i + 21, j + 4, k + 6, Blocks.stonebrick, 0);
		setBlock(world, i + 21, j + 4, k + 7, Blocks.stonebrick, 0);
		setBlock(world, i + 21, j + 4, k + 8, Blocks.stonebrick, 0);
		setBlock(world, i + 21, j + 4, k + 9, Blocks.stonebrick, 0);
		setBlock(world, i + 21, j + 4, k + 10, Blocks.stonebrick, 0);
		setBlock(world, i + 21, j + 4, k + 11, Blocks.stonebrick, 0);
		setBlock(world, i + 21, j + 4, k + 12, Blocks.stonebrick, 0);
		setBlock(world, i + 21, j + 4, k + 37, Blocks.stonebrick, 0);
		setBlock(world, i + 21, j + 4, k + 38, Blocks.stonebrick, 0);
		setBlock(world, i + 21, j + 4, k + 39, Blocks.stonebrick, 0);
		setBlock(world, i + 21, j + 4, k + 40, Blocks.stonebrick, 0);
		setBlock(world, i + 21, j + 4, k + 41, Blocks.stonebrick, 0);
		setBlock(world, i + 21, j + 4, k + 42, Blocks.stonebrick, 0);
		setBlock(world, i + 21, j + 4, k + 43, Blocks.stonebrick, 0);
		setBlock(world, i + 21, j + 5, k + 5, Blocks.stonebrick, 0);
		setBlock(world, i + 21, j + 5, k + 6, Blocks.stonebrick, 0);
		setBlock(world, i + 21, j + 5, k + 7, Blocks.stonebrick, 0);
		setBlock(world, i + 21, j + 5, k + 8, Blocks.stonebrick, 0);
		setBlock(world, i + 21, j + 5, k + 9, Blocks.stonebrick, 0);
		setBlock(world, i + 21, j + 5, k + 10, Blocks.stonebrick, 0);
		setBlock(world, i + 21, j + 5, k + 12, Blocks.stonebrick, 0);
		setBlock(world, i + 21, j + 5, k + 35, Blocks.stonebrick, 0);
		setBlock(world, i + 21, j + 5, k + 36, Blocks.stonebrick, 0);
		setBlock(world, i + 21, j + 5, k + 37, Blocks.stonebrick, 0);
		setBlock(world, i + 21, j + 5, k + 38, Blocks.stonebrick, 0);
		setBlock(world, i + 21, j + 5, k + 39, Blocks.stonebrick, 0);
		setBlock(world, i + 21, j + 5, k + 40, Blocks.stonebrick, 0);
		setBlock(world, i + 21, j + 5, k + 41, Blocks.stonebrick, 0);
		setBlock(world, i + 21, j + 5, k + 42, Blocks.stonebrick, 0);
		setBlock(world, i + 21, j + 6, k + 6, Blocks.stonebrick, 0);
		setBlock(world, i + 21, j + 6, k + 7, Blocks.stonebrick, 0);
		setBlock(world, i + 21, j + 6, k + 8, Blocks.stonebrick, 0);
		setBlock(world, i + 21, j + 6, k + 9, Blocks.stonebrick, 0);
		setBlock(world, i + 21, j + 6, k + 10, Blocks.stonebrick, 0);
		setBlock(world, i + 21, j + 6, k + 11, Blocks.stonebrick, 0);
		setBlock(world, i + 21, j + 6, k + 35, Blocks.stonebrick, 0);
		setBlock(world, i + 21, j + 6, k + 36, Blocks.stonebrick, 0);
		setBlock(world, i + 21, j + 6, k + 37, Blocks.stonebrick, 0);
		setBlock(world, i + 21, j + 6, k + 38, Blocks.stonebrick, 0);
		setBlock(world, i + 21, j + 6, k + 39, Blocks.stonebrick, 0);
		setBlock(world, i + 21, j + 6, k + 40, Blocks.stonebrick, 0);
		setBlock(world, i + 21, j + 6, k + 41, Blocks.stonebrick, 0);
		setBlock(world, i + 21, j + 7, k + 7, Blocks.stonebrick, 0);
		setBlock(world, i + 21, j + 7, k + 8, Blocks.stonebrick, 0);
		setBlock(world, i + 21, j + 7, k + 9, Blocks.stonebrick, 0);
		setBlock(world, i + 21, j + 7, k + 10, Blocks.stonebrick, 0);
		setBlock(world, i + 21, j + 7, k + 11, Blocks.stonebrick, 0);
		setBlock(world, i + 21, j + 7, k + 12, Blocks.stonebrick, 0);
		setBlock(world, i + 21, j + 7, k + 34, Blocks.stonebrick, 0);
		setBlock(world, i + 21, j + 7, k + 35, Blocks.stonebrick, 0);
		setBlock(world, i + 21, j + 7, k + 36, Blocks.stonebrick, 0);
		setBlock(world, i + 21, j + 7, k + 37, Blocks.stonebrick, 0);
		setBlock(world, i + 21, j + 7, k + 38, Blocks.stonebrick, 0);
		setBlock(world, i + 21, j + 7, k + 39, Blocks.stonebrick, 0);
		setBlock(world, i + 21, j + 7, k + 40, Blocks.stonebrick, 0);
		setBlock(world, i + 21, j + 8, k + 8, Blocks.stonebrick, 0);
		setBlock(world, i + 21, j + 8, k + 9, Blocks.stonebrick, 0);
		setBlock(world, i + 21, j + 8, k + 10, Blocks.stonebrick, 0);
		setBlock(world, i + 21, j + 8, k + 11, Blocks.stonebrick, 0);
		setBlock(world, i + 21, j + 8, k + 12, Blocks.stonebrick, 0);
		setBlock(world, i + 21, j + 8, k + 13, Blocks.stonebrick, 0);
		setBlock(world, i + 21, j + 8, k + 35, Blocks.stonebrick, 0);
		setBlock(world, i + 21, j + 8, k + 36, Blocks.stonebrick, 0);
		setBlock(world, i + 21, j + 8, k + 37, Blocks.stonebrick, 0);
		setBlock(world, i + 21, j + 8, k + 38, Blocks.stonebrick, 0);
		setBlock(world, i + 21, j + 8, k + 39, Blocks.stonebrick, 0);
		setBlock(world, i + 21, j + 9, k + 9, Blocks.stonebrick, 0);
		setBlock(world, i + 21, j + 9, k + 10, Blocks.stonebrick, 0);
		setBlock(world, i + 21, j + 9, k + 11, Blocks.stonebrick, 0);
		setBlock(world, i + 21, j + 9, k + 12, Blocks.stonebrick, 0);
		setBlock(world, i + 21, j + 9, k + 14, Blocks.stonebrick, 0);
		setBlock(world, i + 21, j + 9, k + 33, Blocks.stonebrick, 0);
		setBlock(world, i + 21, j + 9, k + 35, Blocks.stonebrick, 0);
		setBlock(world, i + 21, j + 9, k + 36, Blocks.stonebrick, 0);
		setBlock(world, i + 21, j + 9, k + 37, Blocks.stonebrick, 0);
		setBlock(world, i + 21, j + 9, k + 38, Blocks.stonebrick, 0);
		setBlock(world, i + 21, j + 10, k + 10, Blocks.stonebrick, 0);
		setBlock(world, i + 21, j + 10, k + 11, Blocks.stonebrick, 0);
		setBlock(world, i + 21, j + 10, k + 12, Blocks.stonebrick, 0);
		setBlock(world, i + 21, j + 10, k + 13, Blocks.stonebrick, 0);
		setBlock(world, i + 21, j + 10, k + 15, Blocks.stonebrick, 0);
		setBlock(world, i + 21, j + 10, k + 34, Blocks.stonebrick, 0);
		setBlock(world, i + 21, j + 10, k + 35, Blocks.stonebrick, 0);
		setBlock(world, i + 21, j + 10, k + 36, Blocks.stonebrick, 0);
		setBlock(world, i + 21, j + 10, k + 37, Blocks.stonebrick, 0);
		setBlock(world, i + 21, j + 11, k + 11, Blocks.stonebrick, 0);
		setBlock(world, i + 21, j + 11, k + 12, Blocks.stonebrick, 0);
		setBlock(world, i + 21, j + 11, k + 13, Blocks.stonebrick, 0);
		setBlock(world, i + 21, j + 11, k + 14, Blocks.stonebrick, 0);
		setBlock(world, i + 21, j + 11, k + 31, Blocks.stonebrick, 0);
		setBlock(world, i + 21, j + 11, k + 32, Blocks.stonebrick, 0);
		setBlock(world, i + 21, j + 11, k + 33, Blocks.stonebrick, 0);
		setBlock(world, i + 21, j + 11, k + 34, Blocks.stonebrick, 0);
		setBlock(world, i + 21, j + 11, k + 35, Blocks.stonebrick, 0);
		setBlock(world, i + 21, j + 11, k + 36, Blocks.stonebrick, 0);
		setBlock(world, i + 21, j + 12, k + 12, Blocks.stonebrick, 0);
		setBlock(world, i + 21, j + 12, k + 13, Blocks.stonebrick, 0);
		setBlock(world, i + 21, j + 12, k + 14, Blocks.stonebrick, 0);
		setBlock(world, i + 21, j + 12, k + 32, Blocks.stonebrick, 0);
		setBlock(world, i + 21, j + 12, k + 33, Blocks.stonebrick, 0);
		setBlock(world, i + 21, j + 12, k + 34, Blocks.stonebrick, 0);
		setBlock(world, i + 21, j + 12, k + 35, Blocks.stonebrick, 0);
		setBlock(world, i + 21, j + 13, k + 13, Blocks.stonebrick, 0);
		setBlock(world, i + 21, j + 13, k + 14, Blocks.stonebrick, 0);
		setBlock(world, i + 21, j + 13, k + 15, Blocks.stonebrick, 0);
		setBlock(world, i + 21, j + 13, k + 17, Blocks.stonebrick, 0);
		setBlock(world, i + 21, j + 13, k + 19, Blocks.stonebrick, 0);
		setBlock(world, i + 21, j + 13, k + 32, Blocks.stonebrick, 0);
		setBlock(world, i + 21, j + 13, k + 33, Blocks.stonebrick, 0);
		setBlock(world, i + 21, j + 13, k + 34, Blocks.stonebrick, 0);
		setBlock(world, i + 21, j + 14, k + 14, Blocks.stonebrick, 0);
		setBlock(world, i + 21, j + 14, k + 15, Blocks.stonebrick, 0);
		setBlock(world, i + 21, j + 14, k + 16, Blocks.stonebrick, 0);
		setBlock(world, i + 21, j + 14, k + 17, Blocks.stonebrick, 0);
		setBlock(world, i + 21, j + 14, k + 18, Blocks.stonebrick, 0);
		setBlock(world, i + 21, j + 14, k + 29, Blocks.stonebrick, 0);
		setBlock(world, i + 21, j + 14, k + 30, Blocks.stonebrick, 0);
		setBlock(world, i + 21, j + 14, k + 31, Blocks.stonebrick, 0);
		setBlock(world, i + 21, j + 14, k + 32, Blocks.stonebrick, 0);
		setBlock(world, i + 21, j + 14, k + 33, Blocks.stonebrick, 0);
		setBlock(world, i + 21, j + 15, k + 15, Blocks.stonebrick, 0);
		setBlock(world, i + 21, j + 15, k + 16, Blocks.stonebrick, 0);
		setBlock(world, i + 21, j + 15, k + 17, Blocks.stonebrick, 0);
		setBlock(world, i + 21, j + 15, k + 18, Blocks.stonebrick, 0);
		setBlock(world, i + 21, j + 15, k + 29, Blocks.stonebrick, 0);
		setBlock(world, i + 21, j + 15, k + 30, Blocks.stonebrick, 0);
		setBlock(world, i + 21, j + 15, k + 31, Blocks.stonebrick, 0);
		setBlock(world, i + 21, j + 15, k + 32, Blocks.stonebrick, 0);
		setBlock(world, i + 21, j + 16, k + 16, Blocks.stonebrick, 0);
		setBlock(world, i + 21, j + 16, k + 17, Blocks.stonebrick, 0);
		setBlock(world, i + 21, j + 16, k + 18, Blocks.stonebrick, 0);
		setBlock(world, i + 21, j + 16, k + 29, Blocks.stonebrick, 0);
		setBlock(world, i + 21, j + 16, k + 30, Blocks.stonebrick, 0);
		setBlock(world, i + 21, j + 16, k + 31, Blocks.stonebrick, 0);
		setBlock(world, i + 21, j + 17, k + 17, Blocks.stonebrick, 0);
		setBlock(world, i + 21, j + 17, k + 18, Blocks.stonebrick, 0);
		setBlock(world, i + 21, j + 17, k + 19, Blocks.stonebrick, 0);
		setBlock(world, i + 21, j + 17, k + 29, Blocks.stonebrick, 0);
		setBlock(world, i + 21, j + 17, k + 30, Blocks.stonebrick, 0);
		setBlock(world, i + 21, j + 18, k + 18, Blocks.stonebrick, 0);
		setBlock(world, i + 21, j + 18, k + 29, Blocks.stonebrick, 0);
		setBlock(world, i + 21, j + 19, k + 19, Blocks.stonebrick, 0);
		setBlock(world, i + 22, j + 0, k + 37, Blocks.stonebrick, 0);
		setBlock(world, i + 22, j + 1, k + 3, Blocks.stonebrick, 0);
		setBlock(world, i + 22, j + 1, k + 10, Blocks.stonebrick, 0);
		setBlock(world, i + 22, j + 1, k + 37, Blocks.stonebrick, 0);
		setBlock(world, i + 22, j + 1, k + 44, Blocks.stonebrick, 0);
		setBlock(world, i + 22, j + 2, k + 4, Blocks.stonebrick, 0);
		setBlock(world, i + 22, j + 2, k + 11, Blocks.stonebrick, 0);
		setBlock(world, i + 22, j + 2, k + 37, Blocks.stonebrick, 0);
		setBlock(world, i + 22, j + 2, k + 43, Blocks.stonebrick, 0);
		setBlock(world, i + 22, j + 3, k + 5, Blocks.stonebrick, 0);
		setBlock(world, i + 22, j + 3, k + 10, Blocks.stonebrick, 0);
		setBlock(world, i + 22, j + 3, k + 42, Blocks.stonebrick, 0);
		setBlock(world, i + 22, j + 4, k + 6, Blocks.stonebrick, 0);
		setBlock(world, i + 22, j + 4, k + 41, Blocks.stonebrick, 0);
		setBlock(world, i + 22, j + 5, k + 7, Blocks.stonebrick, 0);
		setBlock(world, i + 22, j + 5, k + 11, Blocks.stonebrick, 0);
		setBlock(world, i + 22, j + 5, k + 35, Blocks.stonebrick, 0);
		setBlock(world, i + 22, j + 5, k + 40, Blocks.stonebrick, 0);
		setBlock(world, i + 22, j + 6, k + 8, Blocks.stonebrick, 0);
		setBlock(world, i + 22, j + 6, k + 13, Blocks.stonebrick, 0);
		setBlock(world, i + 22, j + 6, k + 34, Blocks.stonebrick, 0);
		setBlock(world, i + 22, j + 6, k + 39, Blocks.stonebrick, 0);
		setBlock(world, i + 22, j + 7, k + 9, Blocks.stonebrick, 0);
		setBlock(world, i + 22, j + 7, k + 12, Blocks.stonebrick, 0);
		setBlock(world, i + 22, j + 7, k + 38, Blocks.stonebrick, 0);
		setBlock(world, i + 22, j + 8, k + 10, Blocks.stonebrick, 0);
		setBlock(world, i + 22, j + 8, k + 14, Blocks.stonebrick, 0);
		setBlock(world, i + 22, j + 8, k + 33, Blocks.stonebrick, 0);
		setBlock(world, i + 22, j + 8, k + 37, Blocks.stonebrick, 0);
		setBlock(world, i + 22, j + 9, k + 11, Blocks.stonebrick, 0);
		setBlock(world, i + 22, j + 9, k + 13, Blocks.stonebrick, 0);
		setBlock(world, i + 22, j + 9, k + 14, Blocks.stonebrick, 0);
		setBlock(world, i + 22, j + 9, k + 36, Blocks.stonebrick, 0);
		setBlock(world, i + 22, j + 10, k + 12, Blocks.stonebrick, 0);
		setBlock(world, i + 22, j + 10, k + 32, Blocks.stonebrick, 0);
		setBlock(world, i + 22, j + 10, k + 35, Blocks.stonebrick, 0);
		setBlock(world, i + 22, j + 11, k + 13, Blocks.stonebrick, 0);
		setBlock(world, i + 22, j + 11, k + 15, Blocks.stonebrick, 0);
		setBlock(world, i + 22, j + 11, k + 30, Blocks.stonebrick, 0);
		setBlock(world, i + 22, j + 11, k + 31, Blocks.stonebrick, 0);
		setBlock(world, i + 22, j + 11, k + 32, Blocks.stonebrick, 0);
		setBlock(world, i + 22, j + 11, k + 34, Blocks.stonebrick, 0);
		setBlock(world, i + 22, j + 12, k + 14, Blocks.stonebrick, 0);
		setBlock(world, i + 22, j + 12, k + 29, Blocks.stonebrick, 0);
		setBlock(world, i + 22, j + 12, k + 33, Blocks.stonebrick, 0);
		setBlock(world, i + 22, j + 13, k + 15, Blocks.stonebrick, 0);
		setBlock(world, i + 22, j + 13, k + 30, Blocks.stonebrick, 0);
		setBlock(world, i + 22, j + 13, k + 31, Blocks.stonebrick, 0);
		setBlock(world, i + 22, j + 13, k + 32, Blocks.stonebrick, 0);
		setBlock(world, i + 22, j + 14, k + 16, Blocks.stonebrick, 0);
		setBlock(world, i + 22, j + 14, k + 17, Blocks.stonebrick, 0);
		setBlock(world, i + 22, j + 14, k + 30, Blocks.stonebrick, 0);
		setBlock(world, i + 22, j + 14, k + 31, Blocks.stonebrick, 0);
		setBlock(world, i + 22, j + 18, k + 19, Blocks.stonebrick, 0);
		setBlock(world, i + 22, j + 19, k + 21, Blocks.stonebrick, 0);
		setBlock(world, i + 22, j + 19, k + 24, Blocks.stonebrick, 0);
		setBlock(world, i + 22, j + 19, k + 25, Blocks.stonebrick, 0);
		setBlock(world, i + 22, j + 19, k + 27, Blocks.stonebrick, 0);
		setBlock(world, i + 22, j + 19, k + 28, Blocks.stonebrick, 0);
		setBlock(world, i + 23, j + 0, k + 37, Blocks.stonebrick, 0);
		setBlock(world, i + 23, j + 1, k + 3, Blocks.stonebrick, 0);
		setBlock(world, i + 23, j + 1, k + 44, Blocks.stonebrick, 0);
		setBlock(world, i + 23, j + 2, k + 4, Blocks.stonebrick, 0);
		setBlock(world, i + 23, j + 2, k + 43, Blocks.stonebrick, 0);
		setBlock(world, i + 23, j + 3, k + 5, Blocks.stonebrick, 0);
		setBlock(world, i + 23, j + 3, k + 11, Blocks.stonebrick, 0);
		setBlock(world, i + 23, j + 3, k + 42, Blocks.stonebrick, 0);
		setBlock(world, i + 23, j + 4, k + 6, Blocks.stonebrick, 0);

		generate2(world, rand, i, j, k);
		return true;
	}

	public boolean generate2(World world, Random rand, int i, int j, int k)
	{
		setBlock(world, i + 23, j + 4, k + 11, Blocks.stonebrick, 0);
		setBlock(world, i + 23, j + 4, k + 41, Blocks.stonebrick, 0);
		setBlock(world, i + 23, j + 5, k + 7, Blocks.stonebrick, 0);
		setBlock(world, i + 23, j + 5, k + 11, Blocks.stonebrick, 0);
		setBlock(world, i + 23, j + 5, k + 35, Blocks.stonebrick, 0);
		setBlock(world, i + 23, j + 5, k + 40, Blocks.stonebrick, 0);
		setBlock(world, i + 23, j + 6, k + 8, Blocks.stonebrick, 0);
		setBlock(world, i + 23, j + 6, k + 13, Blocks.stonebrick, 0);
		setBlock(world, i + 23, j + 6, k + 39, Blocks.stonebrick, 0);
		setBlock(world, i + 23, j + 7, k + 9, Blocks.stonebrick, 0);
		setBlock(world, i + 23, j + 7, k + 12, Blocks.stonebrick, 0);
		setBlock(world, i + 23, j + 7, k + 14, Blocks.stonebrick, 0);
		setBlock(world, i + 23, j + 7, k + 38, Blocks.stonebrick, 0);
		setBlock(world, i + 23, j + 8, k + 10, Blocks.stonebrick, 0);
		setBlock(world, i + 23, j + 8, k + 37, Blocks.stonebrick, 0);
		setBlock(world, i + 23, j + 9, k + 11, Blocks.stonebrick, 0);
		setBlock(world, i + 23, j + 9, k + 14, Blocks.stonebrick, 0);
		setBlock(world, i + 23, j + 9, k + 34, Blocks.stonebrick, 0);
		setBlock(world, i + 23, j + 9, k + 36, Blocks.stonebrick, 0);
