package com.parzi.starwarsmod.world.gen;

import java.util.Random;

import net.minecraft.block.Block;
import net.minecraft.init.Blocks;
import net.minecraft.world.World;
import net.minecraft.world.chunk.IChunkProvider;
import net.minecraft.world.gen.feature.WorldGenerator;
import cpw.mods.fml.common.IWorldGenerator;

public class WorldGenEndorTree4 extends WorldGenerator implements IWorldGenerator
{
	public WorldGenEndorTree4()
	{
	}

	@Override
	public void generate(Random random, int chunkX, int chunkZ, World world, IChunkProvider chunkGenerator, IChunkProvider chunkProvider)
	{
	}

	@Override
	public boolean generate(World world, Random rand, int i, int j, int k)
	{
		// check that each corner is one of the valid spawn blocks
		if (!locationIsValidSpawn(world, i, j, k) || !locationIsValidSpawn(world, i + 15, j, k) || !locationIsValidSpawn(world, i + 15, j, k + 15) || !locationIsValidSpawn(world, i, j, k + 15)) { return false; }

		k = k - 10;
		i = i - 10;

		setBlock(world, i + 0, j + 3, k + 13, Blocks.log, 0);
		setBlock(world, i + 0, j + 3, k + 14, Blocks.log, 0);
		setBlock(world, i + 0, j + 3, k + 15, Blocks.log, 0);
		setBlock(world, i + 0, j + 4, k + 12, Blocks.log, 0);
		setBlock(world, i + 0, j + 4, k + 13, Blocks.log, 0);
		setBlock(world, i + 0, j + 4, k + 14, Blocks.log, 0);
		setBlock(world, i + 0, j + 4, k + 15, Blocks.log, 0);
		setBlock(world, i + 0, j + 5, k + 12, Blocks.log, 0);
		setBlock(world, i + 0, j + 5, k + 13, Blocks.log, 0);
		setBlock(world, i + 0, j + 5, k + 14, Blocks.log, 0);
		setBlock(world, i + 0, j + 6, k + 12, Blocks.log, 0);
		setBlock(world, i + 1, j + 3, k + 14, Blocks.log, 0);
		setBlock(world, i + 1, j + 4, k + 13, Blocks.log, 0);
		setBlock(world, i + 1, j + 4, k + 14, Blocks.log, 0);
		setBlock(world, i + 1, j + 4, k + 15, Blocks.log, 0);
		setBlock(world, i + 1, j + 5, k + 11, Blocks.log, 0);
		setBlock(world, i + 1, j + 5, k + 12, Blocks.log, 0);
		setBlock(world, i + 1, j + 5, k + 13, Blocks.log, 0);
		setBlock(world, i + 1, j + 5, k + 14, Blocks.log, 0);
		setBlock(world, i + 1, j + 5, k + 15, Blocks.log, 0);
		setBlock(world, i + 1, j + 6, k + 11, Blocks.log, 0);
		setBlock(world, i + 1, j + 6, k + 12, Blocks.log, 0);
		setBlock(world, i + 1, j + 6, k + 13, Blocks.log, 0);
		setBlock(world, i + 1, j + 7, k + 12, Blocks.log, 0);
		setBlock(world, i + 1, j + 33, k + 2, Blocks.log, 0);
		setBlock(world, i + 1, j + 34, k + 2, Blocks.log, 0);
		setBlock(world, i + 1, j + 35, k + 2, Blocks.log, 0);
		setBlock(world, i + 1, j + 36, k + 2, Blocks.log, 0);
		setBlock(world, i + 1, j + 37, k + 2, Blocks.log, 0);
		setBlock(world, i + 1, j + 43, k + 0, Blocks.log, 0);
		setBlock(world, i + 1, j + 46, k + 8, Blocks.log, 0);
		setBlock(world, i + 1, j + 47, k + 6, Blocks.log, 0);
		setBlock(world, i + 1, j + 47, k + 7, Blocks.log, 0);
		setBlock(world, i + 1, j + 47, k + 8, Blocks.log, 0);
		setBlock(world, i + 2, j + 4, k + 14, Blocks.log, 0);
		setBlock(world, i + 2, j + 5, k + 12, Blocks.log, 0);
		setBlock(world, i + 2, j + 5, k + 13, Blocks.log, 0);
		setBlock(world, i + 2, j + 5, k + 14, Blocks.log, 0);
		setBlock(world, i + 2, j + 6, k + 10, Blocks.log, 0);
		setBlock(world, i + 2, j + 6, k + 11, Blocks.log, 0);
		setBlock(world, i + 2, j + 6, k + 12, Blocks.log, 0);
		setBlock(world, i + 2, j + 6, k + 13, Blocks.log, 0);
		setBlock(world, i + 2, j + 6, k + 14, Blocks.log, 0);
		setBlock(world, i + 2, j + 7, k + 11, Blocks.log, 0);
		setBlock(world, i + 2, j + 7, k + 12, Blocks.log, 0);
		setBlock(world, i + 2, j + 7, k + 13, Blocks.log, 0);
		setBlock(world, i + 2, j + 8, k + 11, Blocks.log, 0);
		setBlock(world, i + 2, j + 29, k + 1, Blocks.log, 0);
		setBlock(world, i + 2, j + 30, k + 0, Blocks.log, 0);
		setBlock(world, i + 2, j + 35, k + 3, Blocks.log, 0);
		setBlock(world, i + 2, j + 36, k + 3, Blocks.log, 0);
		setBlock(world, i + 2, j + 43, k + 4, Blocks.log, 0);
		setBlock(world, i + 2, j + 44, k + 8, Blocks.log, 0);
		setBlock(world, i + 2, j + 45, k + 1, Blocks.log, 0);
		setBlock(world, i + 2, j + 45, k + 8, Blocks.log, 0);
		setBlock(world, i + 2, j + 46, k + 3, Blocks.log, 0);
		setBlock(world, i + 3, j + 5, k + 13, Blocks.log, 0);
		setBlock(world, i + 3, j + 6, k + 11, Blocks.log, 0);
		setBlock(world, i + 3, j + 6, k + 12, Blocks.log, 0);
		setBlock(world, i + 3, j + 6, k + 13, Blocks.log, 0);
		setBlock(world, i + 3, j + 7, k + 10, Blocks.log, 0);
		setBlock(world, i + 3, j + 7, k + 11, Blocks.log, 0);
		setBlock(world, i + 3, j + 7, k + 12, Blocks.log, 0);
		setBlock(world, i + 3, j + 7, k + 13, Blocks.log, 0);
		setBlock(world, i + 3, j + 7, k + 14, Blocks.log, 0);
		setBlock(world, i + 3, j + 8, k + 10, Blocks.log, 0);
		setBlock(world, i + 3, j + 8, k + 11, Blocks.log, 0);
		setBlock(world, i + 3, j + 8, k + 12, Blocks.log, 0);
		setBlock(world, i + 3, j + 9, k + 10, Blocks.log, 0);
		setBlock(world, i + 3, j + 29, k + 2, Blocks.log, 0);
		setBlock(world, i + 3, j + 35, k + 4, Blocks.log, 0);
		setBlock(world, i + 3, j + 36, k + 4, Blocks.log, 0);
		setBlock(world, i + 3, j + 40, k + 12, Blocks.log, 0);
		setBlock(world, i + 3, j + 41, k + 12, Blocks.log, 0);
		setBlock(world, i + 3, j + 42, k + 8, Blocks.log, 0);
		setBlock(world, i + 3, j + 43, k + 8, Blocks.log, 0);
		setBlock(world, i + 3, j + 45, k + 13, Blocks.log, 0);
		setBlock(world, i + 4, j + 0, k + 7, Blocks.log, 0);
		setBlock(world, i + 4, j + 0, k + 8, Blocks.log, 0);
		setBlock(world, i + 4, j + 0, k + 9, Blocks.log, 0);
		setBlock(world, i + 4, j + 1, k + 8, Blocks.log, 0);
		setBlock(world, i + 4, j + 2, k + 8, Blocks.log, 0);
		setBlock(world, i + 4, j + 3, k + 8, Blocks.log, 0);
		setBlock(world, i + 4, j + 6, k + 12, Blocks.log, 0);
		setBlock(world, i + 4, j + 7, k + 11, Blocks.log, 0);
		setBlock(world, i + 4, j + 7, k + 12, Blocks.log, 0);
		setBlock(world, i + 4, j + 7, k + 13, Blocks.log, 0);
		setBlock(world, i + 4, j + 8, k + 9, Blocks.log, 0);
		setBlock(world, i + 4, j + 8, k + 10, Blocks.log, 0);
		setBlock(world, i + 4, j + 8, k + 11, Blocks.log, 0);
		setBlock(world, i + 4, j + 8, k + 12, Blocks.log, 0);
		setBlock(world, i + 4, j + 8, k + 13, Blocks.log, 0);
		setBlock(world, i + 4, j + 9, k + 9, Blocks.log, 0);
		setBlock(world, i + 4, j + 9, k + 10, Blocks.log, 0);
		setBlock(world, i + 4, j + 9, k + 11, Blocks.log, 0);
		setBlock(world, i + 4, j + 10, k + 10, Blocks.log, 0);
		setBlock(world, i + 4, j + 28, k + 3, Blocks.log, 0);
		setBlock(world, i + 4, j + 32, k + 5, Blocks.log, 0);
		setBlock(world, i + 4, j + 33, k + 5, Blocks.log, 0);
		setBlock(world, i + 4, j + 34, k + 5, Blocks.log, 0);
		setBlock(world, i + 4, j + 35, k + 5, Blocks.log, 0);
		setBlock(world, i + 4, j + 36, k + 5, Blocks.log, 0);
		setBlock(world, i + 4, j + 39, k + 11, Blocks.log, 0);
		setBlock(world, i + 4, j + 40, k + 8, Blocks.log, 0);
		setBlock(world, i + 4, j + 41, k + 8, Blocks.log, 0);
		setBlock(world, i + 4, j + 42, k + 8, Blocks.log, 0);
		setBlock(world, i + 5, j + 0, k + 6, Blocks.log, 0);
		setBlock(world, i + 5, j + 0, k + 7, Blocks.log, 0);
		setBlock(world, i + 5, j + 0, k + 8, Blocks.log, 0);
		setBlock(world, i + 5, j + 0, k + 9, Blocks.log, 0);
		setBlock(world, i + 5, j + 0, k + 10, Blocks.log, 0);
		setBlock(world, i + 5, j + 1, k + 6, Blocks.log, 0);
		setBlock(world, i + 5, j + 1, k + 7, Blocks.log, 0);
		setBlock(world, i + 5, j + 1, k + 8, Blocks.log, 0);
		setBlock(world, i + 5, j + 1, k + 9, Blocks.log, 0);
		setBlock(world, i + 5, j + 1, k + 10, Blocks.log, 0);
		setBlock(world, i + 5, j + 2, k + 6, Blocks.log, 0);
		setBlock(world, i + 5, j + 2, k + 7, Blocks.log, 0);
		setBlock(world, i + 5, j + 2, k + 8, Blocks.log, 0);
		setBlock(world, i + 5, j + 2, k + 9, Blocks.log, 0);
		setBlock(world, i + 5, j + 2, k + 10, Blocks.log, 0);
		setBlock(world, i + 5, j + 3, k + 6, Blocks.log, 0);
		setBlock(world, i + 5, j + 3, k + 7, Blocks.log, 0);
		setBlock(world, i + 5, j + 3, k + 8, Blocks.log, 0);
		setBlock(world, i + 5, j + 3, k + 9, Blocks.log, 0);
		setBlock(world, i + 5, j + 3, k + 10, Blocks.log, 0);
		setBlock(world, i + 5, j + 4, k + 6, Blocks.log, 0);
		setBlock(world, i + 5, j + 4, k + 7, Blocks.log, 0);
		setBlock(world, i + 5, j + 4, k + 8, Blocks.log, 0);
		setBlock(world, i + 5, j + 4, k + 9, Blocks.log, 0);
		setBlock(world, i + 5, j + 4, k + 10, Blocks.log, 0);
		setBlock(world, i + 5, j + 5, k + 6, Blocks.log, 0);
		setBlock(world, i + 5, j + 5, k + 7, Blocks.log, 0);
		setBlock(world, i + 5, j + 5, k + 8, Blocks.log, 0);
		setBlock(world, i + 5, j + 5, k + 9, Blocks.log, 0);
		setBlock(world, i + 5, j + 5, k + 10, Blocks.log, 0);
		setBlock(world, i + 5, j + 6, k + 6, Blocks.log, 0);
		setBlock(world, i + 5, j + 6, k + 7, Blocks.log, 0);
		setBlock(world, i + 5, j + 6, k + 8, Blocks.log, 0);
		setBlock(world, i + 5, j + 6, k + 9, Blocks.log, 0);
		setBlock(world, i + 5, j + 6, k + 10, Blocks.log, 0);
		setBlock(world, i + 5, j + 7, k + 7, Blocks.log, 0);
		setBlock(world, i + 5, j + 7, k + 8, Blocks.log, 0);
		setBlock(world, i + 5, j + 7, k + 9, Blocks.log, 0);
		setBlock(world, i + 5, j + 7, k + 12, Blocks.log, 0);
		setBlock(world, i + 5, j + 8, k + 7, Blocks.log, 0);
		setBlock(world, i + 5, j + 8, k + 8, Blocks.log, 0);
		setBlock(world, i + 5, j + 8, k + 9, Blocks.log, 0);
		setBlock(world, i + 5, j + 8, k + 10, Blocks.log, 0);
		setBlock(world, i + 5, j + 8, k + 11, Blocks.log, 0);
		setBlock(world, i + 5, j + 8, k + 12, Blocks.log, 0);
		setBlock(world, i + 5, j + 9, k + 7, Blocks.log, 0);
		setBlock(world, i + 5, j + 9, k + 8, Blocks.log, 0);
		setBlock(world, i + 5, j + 9, k + 9, Blocks.log, 0);
		setBlock(world, i + 5, j + 9, k + 10, Blocks.log, 0);
		setBlock(world, i + 5, j + 9, k + 11, Blocks.log, 0);
		setBlock(world, i + 5, j + 9, k + 12, Blocks.log, 0);
		setBlock(world, i + 5, j + 10, k + 7, Blocks.log, 0);
		setBlock(world, i + 5, j + 10, k + 8, Blocks.log, 0);
		setBlock(world, i + 5, j + 10, k + 9, Blocks.log, 0);
		setBlock(world, i + 5, j + 10, k + 10, Blocks.log, 0);
		setBlock(world, i + 5, j + 10, k + 11, Blocks.log, 0);
		setBlock(world, i + 5, j + 11, k + 7, Blocks.log, 0);
		setBlock(world, i + 5, j + 11, k + 8, Blocks.log, 0);
		setBlock(world, i + 5, j + 11, k + 9, Blocks.log, 0);
		setBlock(world, i + 5, j + 12, k + 7, Blocks.log, 0);
		setBlock(world, i + 5, j + 12, k + 8, Blocks.log, 0);
		setBlock(world, i + 5, j + 12, k + 9, Blocks.log, 0);
		setBlock(world, i + 5, j + 13, k + 8, Blocks.log, 0);
		setBlock(world, i + 5, j + 14, k + 8, Blocks.log, 0);
		setBlock(world, i + 5, j + 15, k + 8, Blocks.log, 0);
		setBlock(world, i + 5, j + 25, k + 10, Blocks.log, 0);
		setBlock(world, i + 5, j + 28, k + 4, Blocks.log, 0);
		setBlock(world, i + 5, j + 34, k + 6, Blocks.log, 0);
		setBlock(world, i + 5, j + 35, k + 6, Blocks.log, 0);
		setBlock(world, i + 5, j + 36, k + 6, Blocks.log, 0);
		setBlock(world, i + 5, j + 38, k + 8, Blocks.log, 0);
		setBlock(world, i + 5, j + 38, k + 11, Blocks.log, 0);
		setBlock(world, i + 5, j + 39, k + 8, Blocks.log, 0);
		setBlock(world, i + 5, j + 40, k + 8, Blocks.log, 0);
		setBlock(world, i + 5, j + 43, k + 6, Blocks.log, 0);
		setBlock(world, i + 5, j + 44, k + 6, Blocks.log, 0);
		setBlock(world, i + 5, j + 45, k + 6, Blocks.log, 0);
		setBlock(world, i + 5, j + 46, k + 6, Blocks.log, 0);
		setBlock(world, i + 5, j + 47, k + 5, Blocks.log, 0);
		setBlock(world, i + 6, j + 0, k + 5, Blocks.log, 0);
		setBlock(world, i + 6, j + 0, k + 6, Blocks.log, 0);
		setBlock(world, i + 6, j + 0, k + 7, Blocks.log, 0);
		setBlock(world, i + 6, j + 0, k + 8, Blocks.log, 0);
		setBlock(world, i + 6, j + 0, k + 9, Blocks.log, 0);
		setBlock(world, i + 6, j + 0, k + 10, Blocks.log, 0);
		setBlock(world, i + 6, j + 0, k + 11, Blocks.log, 0);
		setBlock(world, i + 6, j + 1, k + 5, Blocks.log, 0);
		setBlock(world, i + 6, j + 1, k + 6, Blocks.log, 0);
		setBlock(world, i + 6, j + 1, k + 7, Blocks.log, 0);
		setBlock(world, i + 6, j + 1, k + 8, Blocks.log, 0);
		setBlock(world, i + 6, j + 1, k + 9, Blocks.log, 0);
		setBlock(world, i + 6, j + 1, k + 10, Blocks.log, 0);
		setBlock(world, i + 6, j + 1, k + 11, Blocks.log, 0);
		setBlock(world, i + 6, j + 2, k + 5, Blocks.log, 0);
		setBlock(world, i + 6, j + 2, k + 6, Blocks.log, 0);
		setBlock(world, i + 6, j + 2, k + 7, Blocks.log, 0);
		setBlock(world, i + 6, j + 2, k + 8, Blocks.log, 0);
		setBlock(world, i + 6, j + 2, k + 9, Blocks.log, 0);
		setBlock(world, i + 6, j + 2, k + 10, Blocks.log, 0);
		setBlock(world, i + 6, j + 2, k + 11, Blocks.log, 0);
		setBlock(world, i + 6, j + 3, k + 5, Blocks.log, 0);
		setBlock(world, i + 6, j + 3, k + 6, Blocks.log, 0);
		setBlock(world, i + 6, j + 3, k + 7, Blocks.log, 0);
		setBlock(world, i + 6, j + 3, k + 8, Blocks.log, 0);
		setBlock(world, i + 6, j + 3, k + 9, Blocks.log, 0);
		setBlock(world, i + 6, j + 3, k + 10, Blocks.log, 0);
		setBlock(world, i + 6, j + 3, k + 11, Blocks.log, 0);
		setBlock(world, i + 6, j + 4, k + 5, Blocks.log, 0);
		setBlock(world, i + 6, j + 4, k + 6, Blocks.log, 0);
		setBlock(world, i + 6, j + 4, k + 7, Blocks.log, 0);
		setBlock(world, i + 6, j + 4, k + 8, Blocks.log, 0);
		setBlock(world, i + 6, j + 4, k + 9, Blocks.log, 0);
		setBlock(world, i + 6, j + 4, k + 10, Blocks.log, 0);
		setBlock(world, i + 6, j + 4, k + 11, Blocks.log, 0);
		setBlock(world, i + 6, j + 5, k + 5, Blocks.log, 0);
		setBlock(world, i + 6, j + 5, k + 6, Blocks.log, 0);
		setBlock(world, i + 6, j + 5, k + 7, Blocks.log, 0);
		setBlock(world, i + 6, j + 5, k + 8, Blocks.log, 0);
		setBlock(world, i + 6, j + 5, k + 9, Blocks.log, 0);
		setBlock(world, i + 6, j + 5, k + 10, Blocks.log, 0);
		setBlock(world, i + 6, j + 5, k + 11, Blocks.log, 0);
		setBlock(world, i + 6, j + 6, k + 5, Blocks.log, 0);
		setBlock(world, i + 6, j + 6, k + 6, Blocks.log, 0);
		setBlock(world, i + 6, j + 6, k + 7, Blocks.log, 0);
		setBlock(world, i + 6, j + 6, k + 8, Blocks.log, 0);
		setBlock(world, i + 6, j + 6, k + 9, Blocks.log, 0);
		setBlock(world, i + 6, j + 6, k + 10, Blocks.log, 0);
		setBlock(world, i + 6, j + 6, k + 11, Blocks.log, 0);
		setBlock(world, i + 6, j + 7, k + 6, Blocks.log, 0);
		setBlock(world, i + 6, j + 7, k + 7, Blocks.log, 0);
		setBlock(world, i + 6, j + 7, k + 8, Blocks.log, 0);
		setBlock(world, i + 6, j + 7, k + 9, Blocks.log, 0);
		setBlock(world, i + 6, j + 7, k + 10, Blocks.log, 0);
		setBlock(world, i + 6, j + 8, k + 6, Blocks.log, 0);
		setBlock(world, i + 6, j + 8, k + 7, Blocks.log, 0);
		setBlock(world, i + 6, j + 8, k + 8, Blocks.log, 0);
		setBlock(world, i + 6, j + 8, k + 9, Blocks.log, 0);
		setBlock(world, i + 6, j + 8, k + 10, Blocks.log, 0);
		setBlock(world, i + 6, j + 8, k + 11, Blocks.log, 0);
		setBlock(world, i + 6, j + 9, k + 6, Blocks.log, 0);
		setBlock(world, i + 6, j + 9, k + 7, Blocks.log, 0);
		setBlock(world, i + 6, j + 9, k + 8, Blocks.log, 0);
		setBlock(world, i + 6, j + 9, k + 9, Blocks.log, 0);
		setBlock(world, i + 6, j + 9, k + 10, Blocks.log, 0);
		setBlock(world, i + 6, j + 9, k + 11, Blocks.log, 0);
		setBlock(world, i + 6, j + 10, k + 6, Blocks.log, 0);
		setBlock(world, i + 6, j + 10, k + 7, Blocks.log, 0);
		setBlock(world, i + 6, j + 10, k + 8, Blocks.log, 0);
		setBlock(world, i + 6, j + 10, k + 9, Blocks.log, 0);
		setBlock(world, i + 6, j + 10, k + 10, Blocks.log, 0);
		setBlock(world, i + 6, j + 10, k + 11, Blocks.log, 0);
		setBlock(world, i + 6, j + 10, k + 12, Blocks.log, 0);
		setBlock(world, i + 6, j + 11, k + 6, Blocks.log, 0);
		setBlock(world, i + 6, j + 11, k + 7, Blocks.log, 0);
		setBlock(world, i + 6, j + 11, k + 8, Blocks.log, 0);
		setBlock(world, i + 6, j + 11, k + 9, Blocks.log, 0);
		setBlock(world, i + 6, j + 11, k + 10, Blocks.log, 0);
		setBlock(world, i + 6, j + 12, k + 6, Blocks.log, 0);
		setBlock(world, i + 6, j + 12, k + 7, Blocks.log, 0);
		setBlock(world, i + 6, j + 12, k + 8, Blocks.log, 0);
		setBlock(world, i + 6, j + 12, k + 9, Blocks.log, 0);
		setBlock(world, i + 6, j + 12, k + 10, Blocks.log, 0);
		setBlock(world, i + 6, j + 13, k + 6, Blocks.log, 0);
		setBlock(world, i + 6, j + 13, k + 7, Blocks.log, 0);
		setBlock(world, i + 6, j + 13, k + 8, Blocks.log, 0);
		setBlock(world, i + 6, j + 13, k + 9, Blocks.log, 0);
		setBlock(world, i + 6, j + 13, k + 10, Blocks.log, 0);
		setBlock(world, i + 6, j + 14, k + 6, Blocks.log, 0);
		setBlock(world, i + 6, j + 14, k + 7, Blocks.log, 0);
		setBlock(world, i + 6, j + 14, k + 8, Blocks.log, 0);
		setBlock(world, i + 6, j + 14, k + 9, Blocks.log, 0);
		setBlock(world, i + 6, j + 14, k + 10, Blocks.log, 0);
		setBlock(world, i + 6, j + 15, k + 6, Blocks.log, 0);
		setBlock(world, i + 6, j + 15, k + 7, Blocks.log, 0);
		setBlock(world, i + 6, j + 15, k + 8, Blocks.log, 0);
		setBlock(world, i + 6, j + 15, k + 9, Blocks.log, 0);
		setBlock(world, i + 6, j + 15, k + 10, Blocks.log, 0);
		setBlock(world, i + 6, j + 16, k + 7, Blocks.log, 0);
		setBlock(world, i + 6, j + 16, k + 8, Blocks.log, 0);
		setBlock(world, i + 6, j + 16, k + 9, Blocks.log, 0);
		setBlock(world, i + 6, j + 17, k + 7, Blocks.log, 0);
		setBlock(world, i + 6, j + 17, k + 8, Blocks.log, 0);
		setBlock(world, i + 6, j + 17, k + 9, Blocks.log, 0);
		setBlock(world, i + 6, j + 18, k + 7, Blocks.log, 0);
		setBlock(world, i + 6, j + 18, k + 8, Blocks.log, 0);
		setBlock(world, i + 6, j + 18, k + 9, Blocks.log, 0);
		setBlock(world, i + 6, j + 19, k + 7, Blocks.log, 0);
		setBlock(world, i + 6, j + 19, k + 8, Blocks.log, 0);
		setBlock(world, i + 6, j + 19, k + 9, Blocks.log, 0);
		setBlock(world, i + 6, j + 20, k + 7, Blocks.log, 0);
		setBlock(world, i + 6, j + 20, k + 8, Blocks.log, 0);
		setBlock(world, i + 6, j + 20, k + 9, Blocks.log, 0);
		setBlock(world, i + 6, j + 21, k + 7, Blocks.log, 0);
		setBlock(world, i + 6, j + 21, k + 8, Blocks.log, 0);
		setBlock(world, i + 6, j + 21, k + 9, Blocks.log, 0);
		setBlock(world, i + 6, j + 22, k + 7, Blocks.log, 0);
		setBlock(world, i + 6, j + 22, k + 8, Blocks.log, 0);
		setBlock(world, i + 6, j + 22, k + 9, Blocks.log, 0);
		setBlock(world, i + 6, j + 23, k + 8, Blocks.log, 0);
		setBlock(world, i + 6, j + 24, k + 8, Blocks.log, 0);
		setBlock(world, i + 6, j + 24, k + 10, Blocks.log, 0);
		setBlock(world, i + 6, j + 25, k + 8, Blocks.log, 0);
		setBlock(world, i + 6, j + 26, k + 8, Blocks.log, 0);
		setBlock(world, i + 6, j + 27, k + 5, Blocks.log, 0);
		setBlock(world, i + 6, j + 28, k + 5, Blocks.log, 0);
		setBlock(world, i + 6, j + 28, k + 6, Blocks.log, 0);
		setBlock(world, i + 6, j + 29, k + 4, Blocks.log, 0);
		setBlock(world, i + 6, j + 34, k + 7, Blocks.log, 0);
		setBlock(world, i + 6, j + 36, k + 8, Blocks.log, 0);
		setBlock(world, i + 6, j + 37, k + 8, Blocks.log, 0);
		setBlock(world, i + 6, j + 37, k + 10, Blocks.log, 0);
		setBlock(world, i + 6, j + 38, k + 8, Blocks.log, 0);
		setBlock(world, i + 6, j + 39, k + 7, Blocks.log, 0);
		setBlock(world, i + 6, j + 40, k + 2, Blocks.log, 0);
		setBlock(world, i + 6, j + 40, k + 7, Blocks.log, 0);
		setBlock(world, i + 6, j + 41, k + 7, Blocks.log, 0);
		setBlock(world, i + 6, j + 41, k + 12, Blocks.log, 0);
		setBlock(world, i + 6, j + 42, k + 7, Blocks.log, 0);
		setBlock(world, i + 6, j + 42, k + 12, Blocks.log, 0);
		setBlock(world, i + 6, j + 43, k + 12, Blocks.log, 0);
		setBlock(world, i + 6, j + 44, k + 13, Blocks.log, 0);
		setBlock(world, i + 6, j + 45, k + 13, Blocks.log, 0);
		setBlock(world, i + 6, j + 46, k + 13, Blocks.log, 0);
		setBlock(world, i + 6, j + 47, k + 3, Blocks.log, 0);
		setBlock(world, i + 6, j + 47, k + 11, Blocks.log, 0);
		setBlock(world, i + 6, j + 47, k + 13, Blocks.log, 0);
		setBlock(world, i + 7, j + 0, k + 4, Blocks.log, 0);
		setBlock(world, i + 7, j + 0, k + 5, Blocks.log, 0);
		setBlock(world, i + 7, j + 0, k + 6, Blocks.log, 0);
		setBlock(world, i + 7, j + 0, k + 7, Blocks.log, 0);
		setBlock(world, i + 7, j + 0, k + 8, Blocks.log, 0);
		setBlock(world, i + 7, j + 0, k + 9, Blocks.log, 0);
		setBlock(world, i + 7, j + 0, k + 10, Blocks.log, 0);
		setBlock(world, i + 7, j + 0, k + 11, Blocks.log, 0);
		setBlock(world, i + 7, j + 0, k + 12, Blocks.log, 0);
		setBlock(world, i + 7, j + 1, k + 5, Blocks.log, 0);
		setBlock(world, i + 7, j + 1, k + 6, Blocks.log, 0);
		setBlock(world, i + 7, j + 1, k + 7, Blocks.log, 0);
		setBlock(world, i + 7, j + 1, k + 8, Blocks.log, 0);
		setBlock(world, i + 7, j + 1, k + 9, Blocks.log, 0);
		setBlock(world, i + 7, j + 1, k + 10, Blocks.log, 0);
		setBlock(world, i + 7, j + 1, k + 11, Blocks.log, 0);
		setBlock(world, i + 7, j + 2, k + 5, Blocks.log, 0);
		setBlock(world, i + 7, j + 2, k + 6, Blocks.log, 0);
		setBlock(world, i + 7, j + 2, k + 7, Blocks.log, 0);
		setBlock(world, i + 7, j + 2, k + 8, Blocks.log, 0);
		setBlock(world, i + 7, j + 2, k + 9, Blocks.log, 0);
		setBlock(world, i + 7, j + 2, k + 10, Blocks.log, 0);
		setBlock(world, i + 7, j + 2, k + 11, Blocks.log, 0);
		setBlock(world, i + 7, j + 3, k + 5, Blocks.log, 0);
		setBlock(world, i + 7, j + 3, k + 6, Blocks.log, 0);
		setBlock(world, i + 7, j + 3, k + 7, Blocks.log, 0);
		setBlock(world, i + 7, j + 3, k + 8, Blocks.log, 0);
		setBlock(world, i + 7, j + 3, k + 9, Blocks.log, 0);
		setBlock(world, i + 7, j + 3, k + 10, Blocks.log, 0);
		setBlock(world, i + 7, j + 3, k + 11, Blocks.log, 0);
		setBlock(world, i + 7, j + 4, k + 5, Blocks.log, 0);
		setBlock(world, i + 7, j + 4, k + 6, Blocks.log, 0);
		setBlock(world, i + 7, j + 4, k + 7, Blocks.log, 0);
		setBlock(world, i + 7, j + 4, k + 8, Blocks.log, 0);
		setBlock(world, i + 7, j + 4, k + 9, Blocks.log, 0);
		setBlock(world, i + 7, j + 4, k + 10, Blocks.log, 0);
		setBlock(world, i + 7, j + 4, k + 11, Blocks.log, 0);
		setBlock(world, i + 7, j + 4, k + 12, Blocks.log, 0);
		setBlock(world, i + 7, j + 5, k + 5, Blocks.log, 0);
		setBlock(world, i + 7, j + 5, k + 6, Blocks.log, 0);
		setBlock(world, i + 7, j + 5, k + 7, Blocks.log, 0);
		setBlock(world, i + 7, j + 5, k + 8, Blocks.log, 0);
		setBlock(world, i + 7, j + 5, k + 9, Blocks.log, 0);
		setBlock(world, i + 7, j + 5, k + 10, Blocks.log, 0);
		setBlock(world, i + 7, j + 5, k + 11, Blocks.log, 0);
		setBlock(world, i + 7, j + 5, k + 13, Blocks.log, 0);
		setBlock(world, i + 7, j + 6, k + 5, Blocks.log, 0);
		setBlock(world, i + 7, j + 6, k + 6, Blocks.log, 0);
		setBlock(world, i + 7, j + 6, k + 7, Blocks.log, 0);
		setBlock(world, i + 7, j + 6, k + 8, Blocks.log, 0);
		setBlock(world, i + 7, j + 6, k + 9, Blocks.log, 0);
		setBlock(world, i + 7, j + 6, k + 10, Blocks.log, 0);
		setBlock(world, i + 7, j + 6, k + 11, Blocks.log, 0);
		setBlock(world, i + 7, j + 7, k + 5, Blocks.log, 0);
		setBlock(world, i + 7, j + 7, k + 6, Blocks.log, 0);
		setBlock(world, i + 7, j + 7, k + 7, Blocks.log, 0);
		setBlock(world, i + 7, j + 7, k + 8, Blocks.log, 0);
		setBlock(world, i + 7, j + 7, k + 9, Blocks.log, 0);
		setBlock(world, i + 7, j + 7, k + 10, Blocks.log, 0);
		setBlock(world, i + 7, j + 7, k + 11, Blocks.log, 0);
		setBlock(world, i + 7, j + 8, k + 5, Blocks.log, 0);
		setBlock(world, i + 7, j + 8, k + 6, Blocks.log, 0);
		setBlock(world, i + 7, j + 8, k + 7, Blocks.log, 0);
		setBlock(world, i + 7, j + 8, k + 8, Blocks.log, 0);
		setBlock(world, i + 7, j + 8, k + 9, Blocks.log, 0);
		setBlock(world, i + 7, j + 8, k + 10, Blocks.log, 0);
		setBlock(world, i + 7, j + 8, k + 11, Blocks.log, 0);
		setBlock(world, i + 7, j + 9, k + 5, Blocks.log, 0);
		setBlock(world, i + 7, j + 9, k + 6, Blocks.log, 0);
		setBlock(world, i + 7, j + 9, k + 7, Blocks.log, 0);
		setBlock(world, i + 7, j + 9, k + 8, Blocks.log, 0);
		setBlock(world, i + 7, j + 9, k + 9, Blocks.log, 0);
		setBlock(world, i + 7, j + 9, k + 10, Blocks.log, 0);
		setBlock(world, i + 7, j + 9, k + 11, Blocks.log, 0);
		setBlock(world, i + 7, j + 10, k + 5, Blocks.log, 0);
		setBlock(world, i + 7, j + 10, k + 6, Blocks.log, 0);
		setBlock(world, i + 7, j + 10, k + 7, Blocks.log, 0);
		setBlock(world, i + 7, j + 10, k + 8, Blocks.log, 0);
		setBlock(world, i + 7, j + 10, k + 9, Blocks.log, 0);
		setBlock(world, i + 7, j + 10, k + 10, Blocks.log, 0);
		setBlock(world, i + 7, j + 10, k + 11, Blocks.log, 0);
		setBlock(world, i + 7, j + 11, k + 5, Blocks.log, 0);
		setBlock(world, i + 7, j + 11, k + 6, Blocks.log, 0);
		setBlock(world, i + 7, j + 11, k + 7, Blocks.log, 0);
		setBlock(world, i + 7, j + 11, k + 8, Blocks.log, 0);
		setBlock(world, i + 7, j + 11, k + 9, Blocks.log, 0);
		setBlock(world, i + 7, j + 11, k + 10, Blocks.log, 0);
		setBlock(world, i + 7, j + 11, k + 11, Blocks.log, 0);
		setBlock(world, i + 7, j + 12, k + 5, Blocks.log, 0);
		setBlock(world, i + 7, j + 12, k + 6, Blocks.log, 0);
		setBlock(world, i + 7, j + 12, k + 7, Blocks.log, 0);
		setBlock(world, i + 7, j + 12, k + 8, Blocks.log, 0);
		setBlock(world, i + 7, j + 12, k + 9, Blocks.log, 0);
		setBlock(world, i + 7, j + 12, k + 10, Blocks.log, 0);
		setBlock(world, i + 7, j + 12, k + 11, Blocks.log, 0);
		setBlock(world, i + 7, j + 13, k + 6, Blocks.log, 0);
		setBlock(world, i + 7, j + 13, k + 7, Blocks.log, 0);
		setBlock(world, i + 7, j + 13, k + 8, Blocks.log, 0);
		setBlock(world, i + 7, j + 13, k + 9, Blocks.log, 0);
		setBlock(world, i + 7, j + 13, k + 10, Blocks.log, 0);
		setBlock(world, i + 7, j + 14, k + 6, Blocks.log, 0);
		setBlock(world, i + 7, j + 14, k + 7, Blocks.log, 0);
		setBlock(world, i + 7, j + 14, k + 8, Blocks.log, 0);
		setBlock(world, i + 7, j + 14, k + 9, Blocks.log, 0);
		setBlock(world, i + 7, j + 14, k + 10, Blocks.log, 0);
		setBlock(world, i + 7, j + 15, k + 6, Blocks.log, 0);
		setBlock(world, i + 7, j + 15, k + 7, Blocks.log, 0);
		setBlock(world, i + 7, j + 15, k + 8, Blocks.log, 0);
		setBlock(world, i + 7, j + 15, k + 9, Blocks.log, 0);
		setBlock(world, i + 7, j + 15, k + 10, Blocks.log, 0);
		setBlock(world, i + 7, j + 16, k + 6, Blocks.log, 0);
		setBlock(world, i + 7, j + 16, k + 7, Blocks.log, 0);
		setBlock(world, i + 7, j + 16, k + 8, Blocks.log, 0);
		setBlock(world, i + 7, j + 16, k + 9, Blocks.log, 0);
		setBlock(world, i + 7, j + 16, k + 10, Blocks.log, 0);
		setBlock(world, i + 7, j + 17, k + 6, Blocks.log, 0);
		setBlock(world, i + 7, j + 17, k + 7, Blocks.log, 0);
		setBlock(world, i + 7, j + 17, k + 8, Blocks.log, 0);
		setBlock(world, i + 7, j + 17, k + 9, Blocks.log, 0);
		setBlock(world, i + 7, j + 17, k + 10, Blocks.log, 0);
		setBlock(world, i + 7, j + 18, k + 6, Blocks.log, 0);
		setBlock(world, i + 7, j + 18, k + 7, Blocks.log, 0);
		setBlock(world, i + 7, j + 18, k + 8, Blocks.log, 0);
		setBlock(world, i + 7, j + 18, k + 9, Blocks.log, 0);
		setBlock(world, i + 7, j + 18, k + 10, Blocks.log, 0);
		setBlock(world, i + 7, j + 19, k + 6, Blocks.log, 0);
		setBlock(world, i + 7, j + 19, k + 7, Blocks.log, 0);
		setBlock(world, i + 7, j + 19, k + 8, Blocks.log, 0);
		setBlock(world, i + 7, j + 19, k + 9, Blocks.log, 0);
		setBlock(world, i + 7, j + 19, k + 10, Blocks.log, 0);
		setBlock(world, i + 7, j + 20, k + 6, Blocks.log, 0);
		setBlock(world, i + 7, j + 20, k + 7, Blocks.log, 0);
		setBlock(world, i + 7, j + 20, k + 8, Blocks.log, 0);
		setBlock(world, i + 7, j + 20, k + 9, Blocks.log, 0);
		setBlock(world, i + 7, j + 20, k + 10, Blocks.log, 0);
		setBlock(world, i + 7, j + 21, k + 6, Blocks.log, 0);
		setBlock(world, i + 7, j + 21, k + 7, Blocks.log, 0);
		setBlock(world, i + 7, j + 21, k + 8, Blocks.log, 0);
		setBlock(world, i + 7, j + 21, k + 9, Blocks.log, 0);
		setBlock(world, i + 7, j + 21, k + 10, Blocks.log, 0);
		setBlock(world, i + 7, j + 22, k + 6, Blocks.log, 0);
		setBlock(world, i + 7, j + 22, k + 7, Blocks.log, 0);
		setBlock(world, i + 7, j + 22, k + 8, Blocks.log, 0);
		setBlock(world, i + 7, j + 22, k + 9, Blocks.log, 0);
		setBlock(world, i + 7, j + 22, k + 10, Blocks.log, 0);
		setBlock(world, i + 7, j + 23, k + 7, Blocks.log, 0);
		setBlock(world, i + 7, j + 23, k + 8, Blocks.log, 0);
		setBlock(world, i + 7, j + 23, k + 9, Blocks.log, 0);
		setBlock(world, i + 7, j + 23, k + 10, Blocks.log, 0);
		setBlock(world, i + 7, j + 24, k + 7, Blocks.log, 0);
		setBlock(world, i + 7, j + 24, k + 8, Blocks.log, 0);
		setBlock(world, i + 7, j + 24, k + 9, Blocks.log, 0);
		setBlock(world, i + 7, j + 25, k + 7, Blocks.log, 0);
		setBlock(world, i + 7, j + 25, k + 8, Blocks.log, 0);
		setBlock(world, i + 7, j + 25, k + 9, Blocks.log, 0);
		setBlock(world, i + 7, j + 26, k + 7, Blocks.log, 0);
		setBlock(world, i + 7, j + 26, k + 8, Blocks.log, 0);
		setBlock(world, i + 7, j + 26, k + 9, Blocks.log, 0);
		setBlock(world, i + 7, j + 27, k + 6, Blocks.log, 0);
		setBlock(world, i + 7, j + 27, k + 7, Blocks.log, 0);
		setBlock(world, i + 7, j + 27, k + 8, Blocks.log, 0);
		setBlock(world, i + 7, j + 27, k + 9, Blocks.log, 0);
		setBlock(world, i + 7, j + 28, k + 7, Blocks.log, 0);
		setBlock(world, i + 7, j + 28, k + 8, Blocks.log, 0);
		setBlock(world, i + 7, j + 28, k + 9, Blocks.log, 0);
		setBlock(world, i + 7, j + 29, k + 7, Blocks.log, 0);
		setBlock(world, i + 7, j + 29, k + 8, Blocks.log, 0);
		setBlock(world, i + 7, j + 29, k + 9, Blocks.log, 0);
		setBlock(world, i + 7, j + 30, k + 7, Blocks.log, 0);
		setBlock(world, i + 7, j + 30, k + 8, Blocks.log, 0);
		setBlock(world, i + 7, j + 30, k + 9, Blocks.log, 0);
		setBlock(world, i + 7, j + 31, k + 8, Blocks.log, 0);
		setBlock(world, i + 7, j + 32, k + 8, Blocks.log, 0);
		setBlock(world, i + 7, j + 33, k + 8, Blocks.log, 0);
		setBlock(world, i + 7, j + 34, k + 8, Blocks.log, 0);
		setBlock(world, i + 7, j + 35, k + 8, Blocks.log, 0);
		setBlock(world, i + 7, j + 35, k + 9, Blocks.log, 0);
		setBlock(world, i + 7, j + 35, k + 10, Blocks.log, 0);
		setBlock(world, i + 7, j + 36, k + 8, Blocks.log, 0);
		setBlock(world, i + 7, j + 36, k + 9, Blocks.log, 0);
		setBlock(world, i + 7, j + 36, k + 10, Blocks.log, 0);
		setBlock(world, i + 7, j + 37, k + 8, Blocks.log, 0);
		setBlock(world, i + 7, j + 37, k + 9, Blocks.log, 0);
		setBlock(world, i + 7, j + 37, k + 10, Blocks.log, 0);
		setBlock(world, i + 7, j + 38, k + 8, Blocks.log, 0);
		setBlock(world, i + 7, j + 38, k + 9, Blocks.log, 0);
		setBlock(world, i + 7, j + 38, k + 11, Blocks.log, 0);
		setBlock(world, i + 7, j + 39, k + 8, Blocks.log, 0);
		setBlock(world, i + 7, j + 39, k + 11, Blocks.log, 0);
		setBlock(world, i + 7, j + 40, k + 8, Blocks.log, 0);
		setBlock(world, i + 7, j + 40, k + 11, Blocks.log, 0);
		setBlock(world, i + 7, j + 41, k + 8, Blocks.log, 0);
		setBlock(world, i + 7, j + 42, k + 8, Blocks.log, 0);
		setBlock(world, i + 7, j + 43, k + 7, Blocks.log, 0);
		setBlock(world, i + 7, j + 44, k + 7, Blocks.log, 0);
		setBlock(world, i + 7, j + 45, k + 7, Blocks.log, 0);
		setBlock(world, i + 7, j + 46, k + 7, Blocks.log, 0);
		setBlock(world, i + 7, j + 47, k + 6, Blocks.log, 0);
		setBlock(world, i + 8, j + 0, k + 4, Blocks.log, 0);
		setBlock(world, i + 8, j + 0, k + 5, Blocks.log, 0);
		setBlock(world, i + 8, j + 0, k + 6, Blocks.log, 0);
		setBlock(world, i + 8, j + 0, k + 7, Blocks.log, 0);
		setBlock(world, i + 8, j + 0, k + 8, Blocks.log, 0);
		setBlock(world, i + 8, j + 0, k + 9, Blocks.log, 0);
		setBlock(world, i + 8, j + 0, k + 10, Blocks.log, 0);
		setBlock(world, i + 8, j + 0, k + 11, Blocks.log, 0);
		setBlock(world, i + 8, j + 0, k + 12, Blocks.log, 0);
		setBlock(world, i + 8, j + 1, k + 4, Blocks.log, 0);
		setBlock(world, i + 8, j + 1, k + 5, Blocks.log, 0);
		setBlock(world, i + 8, j + 1, k + 6, Blocks.log, 0);
		setBlock(world, i + 8, j + 1, k + 7, Blocks.log, 0);
		setBlock(world, i + 8, j + 1, k + 8, Blocks.log, 0);
		setBlock(world, i + 8, j + 1, k + 9, Blocks.log, 0);
		setBlock(world, i + 8, j + 1, k + 10, Blocks.log, 0);
		setBlock(world, i + 8, j + 1, k + 11, Blocks.log, 0);
		setBlock(world, i + 8, j + 1, k + 12, Blocks.log, 0);
		setBlock(world, i + 8, j + 2, k + 4, Blocks.log, 0);
		setBlock(world, i + 8, j + 2, k + 5, Blocks.log, 0);
		setBlock(world, i + 8, j + 2, k + 6, Blocks.log, 0);
		setBlock(world, i + 8, j + 2, k + 7, Blocks.log, 0);
		setBlock(world, i + 8, j + 2, k + 8, Blocks.log, 0);
		setBlock(world, i + 8, j + 2, k + 9, Blocks.log, 0);
		setBlock(world, i + 8, j + 2, k + 10, Blocks.log, 0);
		setBlock(world, i + 8, j + 2, k + 11, Blocks.log, 0);
		setBlock(world, i + 8, j + 2, k + 12, Blocks.log, 0);
		setBlock(world, i + 8, j + 3, k + 4, Blocks.log, 0);
		setBlock(world, i + 8, j + 3, k + 5, Blocks.log, 0);
		setBlock(world, i + 8, j + 3, k + 6, Blocks.log, 0);
		setBlock(world, i + 8, j + 3, k + 7, Blocks.log, 0);
		setBlock(world, i + 8, j + 3, k + 8, Blocks.log, 0);
		setBlock(world, i + 8, j + 3, k + 9, Blocks.log, 0);
		setBlock(world, i + 8, j + 3, k + 10, Blocks.log, 0);
		setBlock(world, i + 8, j + 3, k + 11, Blocks.log, 0);
		setBlock(world, i + 8, j + 3, k + 12, Blocks.log, 0);
		setBlock(world, i + 8, j + 4, k + 5, Blocks.log, 0);
		setBlock(world, i + 8, j + 4, k + 6, Blocks.log, 0);
		setBlock(world, i + 8, j + 4, k + 7, Blocks.log, 0);
		setBlock(world, i + 8, j + 4, k + 8, Blocks.log, 0);
		setBlock(world, i + 8, j + 4, k + 9, Blocks.log, 0);
		setBlock(world, i + 8, j + 4, k + 10, Blocks.log, 0);
		setBlock(world, i + 8, j + 4, k + 11, Blocks.log, 0);
		setBlock(world, i + 8, j + 5, k + 5, Blocks.log, 0);
		setBlock(world, i + 8, j + 5, k + 6, Blocks.log, 0);
		setBlock(world, i + 8, j + 5, k + 7, Blocks.log, 0);
		setBlock(world, i + 8, j + 5, k + 8, Blocks.log, 0);
		setBlock(world, i + 8, j + 5, k + 9, Blocks.log, 0);
		setBlock(world, i + 8, j + 5, k + 10, Blocks.log, 0);
		setBlock(world, i + 8, j + 5, k + 11, Blocks.log, 0);
		setBlock(world, i + 8, j + 6, k + 5, Blocks.log, 0);
		setBlock(world, i + 8, j + 6, k + 6, Blocks.log, 0);
		setBlock(world, i + 8, j + 6, k + 7, Blocks.log, 0);
		setBlock(world, i + 8, j + 6, k + 8, Blocks.log, 0);
		setBlock(world, i + 8, j + 6, k + 9, Blocks.log, 0);
		setBlock(world, i + 8, j + 6, k + 10, Blocks.log, 0);
		setBlock(world, i + 8, j + 6, k + 11, Blocks.log, 0);
		setBlock(world, i + 8, j + 7, k + 5, Blocks.log, 0);
		setBlock(world, i + 8, j + 7, k + 6, Blocks.log, 0);
		setBlock(world, i + 8, j + 7, k + 7, Blocks.log, 0);
		setBlock(world, i + 8, j + 7, k + 8, Blocks.log, 0);
		setBlock(world, i + 8, j + 7, k + 9, Blocks.log, 0);
		setBlock(world, i + 8, j + 7, k + 10, Blocks.log, 0);
		setBlock(world, i + 8, j + 7, k + 11, Blocks.log, 0);
		setBlock(world, i + 8, j + 7, k + 12, Blocks.log, 0);
		setBlock(world, i + 8, j + 8, k + 5, Blocks.log, 0);
		setBlock(world, i + 8, j + 8, k + 6, Blocks.log, 0);
		setBlock(world, i + 8, j + 8, k + 7, Blocks.log, 0);
		setBlock(world, i + 8, j + 8, k + 8, Blocks.log, 0);
		setBlock(world, i + 8, j + 8, k + 9, Blocks.log, 0);
		setBlock(world, i + 8, j + 8, k + 10, Blocks.log, 0);
		setBlock(world, i + 8, j + 8, k + 11, Blocks.log, 0);
		setBlock(world, i + 8, j + 8, k + 12, Blocks.log, 0);
		setBlock(world, i + 8, j + 9, k + 5, Blocks.log, 0);
		setBlock(world, i + 8, j + 9, k + 6, Blocks.log, 0);
		setBlock(world, i + 8, j + 9, k + 7, Blocks.log, 0);
		setBlock(world, i + 8, j + 9, k + 8, Blocks.log, 0);
		setBlock(world, i + 8, j + 9, k + 9, Blocks.log, 0);
		setBlock(world, i + 8, j + 9, k + 10, Blocks.log, 0);
		setBlock(world, i + 8, j + 9, k + 11, Blocks.log, 0);
		setBlock(world, i + 8, j + 9, k + 12, Blocks.log, 0);
		setBlock(world, i + 8, j + 10, k + 5, Blocks.log, 0);
		setBlock(world, i + 8, j + 10, k + 6, Blocks.log, 0);
		setBlock(world, i + 8, j + 10, k + 7, Blocks.log, 0);
		setBlock(world, i + 8, j + 10, k + 8, Blocks.log, 0);
		setBlock(world, i + 8, j + 10, k + 9, Blocks.log, 0);
		setBlock(world, i + 8, j + 10, k + 10, Blocks.log, 0);
		setBlock(world, i + 8, j + 10, k + 11, Blocks.log, 0);
		setBlock(world, i + 8, j + 11, k + 5, Blocks.log, 0);
		setBlock(world, i + 8, j + 11, k + 6, Blocks.log, 0);
		setBlock(world, i + 8, j + 11, k + 7, Blocks.log, 0);
		setBlock(world, i + 8, j + 11, k + 8, Blocks.log, 0);
		setBlock(world, i + 8, j + 11, k + 9, Blocks.log, 0);
		setBlock(world, i + 8, j + 11, k + 10, Blocks.log, 0);
		setBlock(world, i + 8, j + 11, k + 11, Blocks.log, 0);
		setBlock(world, i + 8, j + 12, k + 5, Blocks.log, 0);
		setBlock(world, i + 8, j + 12, k + 6, Blocks.log, 0);
		setBlock(world, i + 8, j + 12, k + 7, Blocks.log, 0);
		setBlock(world, i + 8, j + 12, k + 8, Blocks.log, 0);
		setBlock(world, i + 8, j + 12, k + 9, Blocks.log, 0);
		setBlock(world, i + 8, j + 12, k + 10, Blocks.log, 0);
		setBlock(world, i + 8, j + 12, k + 11, Blocks.log, 0);
		setBlock(world, i + 8, j + 13, k + 5, Blocks.log, 0);
		setBlock(world, i + 8, j + 13, k + 6, Blocks.log, 0);
		setBlock(world, i + 8, j + 13, k + 7, Blocks.log, 0);
		setBlock(world, i + 8, j + 13, k + 8, Blocks.log, 0);
		setBlock(world, i + 8, j + 13, k + 9, Blocks.log, 0);
		setBlock(world, i + 8, j + 13, k + 10, Blocks.log, 0);
		setBlock(world, i + 8, j + 13, k + 11, Blocks.log, 0);
		setBlock(world, i + 8, j + 14, k + 5, Blocks.log, 0);
		setBlock(world, i + 8, j + 14, k + 6, Blocks.log, 0);
		setBlock(world, i + 8, j + 14, k + 7, Blocks.log, 0);
		setBlock(world, i + 8, j + 14, k + 8, Blocks.log, 0);
		setBlock(world, i + 8, j + 14, k + 9, Blocks.log, 0);
		setBlock(world, i + 8, j + 14, k + 10, Blocks.log, 0);
		setBlock(world, i + 8, j + 14, k + 11, Blocks.log, 0);
		setBlock(world, i + 8, j + 15, k + 5, Blocks.log, 0);
		setBlock(world, i + 8, j + 15, k + 6, Blocks.log, 0);
		setBlock(world, i + 8, j + 15, k + 7, Blocks.log, 0);
		setBlock(world, i + 8, j + 15, k + 8, Blocks.log, 0);
		setBlock(world, i + 8, j + 15, k + 9, Blocks.log, 0);
		setBlock(world, i + 8, j + 15, k + 10, Blocks.log, 0);
		setBlock(world, i + 8, j + 15, k + 11, Blocks.log, 0);
		setBlock(world, i + 8, j + 16, k + 5, Blocks.log, 0);
		setBlock(world, i + 8, j + 16, k + 6, Blocks.log, 0);
		setBlock(world, i + 8, j + 16, k + 7, Blocks.log, 0);
		setBlock(world, i + 8, j + 16, k + 8, Blocks.log, 0);
		setBlock(world, i + 8, j + 16, k + 9, Blocks.log, 0);
		setBlock(world, i + 8, j + 16, k + 10, Blocks.log, 0);
		setBlock(world, i + 8, j + 17, k + 3, Blocks.log, 0);
		setBlock(world, i + 8, j + 17, k + 4, Blocks.log, 0);
		setBlock(world, i + 8, j + 17, k + 6, Blocks.log, 0);
		setBlock(world, i + 8, j + 17, k + 7, Blocks.log, 0);
		setBlock(world, i + 8, j + 17, k + 8, Blocks.log, 0);
		setBlock(world, i + 8, j + 17, k + 9, Blocks.log, 0);
		setBlock(world, i + 8, j + 17, k + 10, Blocks.log, 0);
		setBlock(world, i + 8, j + 18, k + 2, Blocks.log, 0);
		setBlock(world, i + 8, j + 18, k + 6, Blocks.log, 0);
		setBlock(world, i + 8, j + 18, k + 7, Blocks.log, 0);
		setBlock(world, i + 8, j + 18, k + 8, Blocks.log, 0);
		setBlock(world, i + 8, j + 18, k + 9, Blocks.log, 0);
		setBlock(world, i + 8, j + 18, k + 10, Blocks.log, 0);
		setBlock(world, i + 8, j + 19, k + 6, Blocks.log, 0);
		setBlock(world, i + 8, j + 19, k + 7, Blocks.log, 0);
		setBlock(world, i + 8, j + 19, k + 8, Blocks.log, 0);
		setBlock(world, i + 8, j + 19, k + 9, Blocks.log, 0);
		setBlock(world, i + 8, j + 19, k + 10, Blocks.log, 0);
		setBlock(world, i + 8, j + 20, k + 6, Blocks.log, 0);
		setBlock(world, i + 8, j + 20, k + 7, Blocks.log, 0);
		setBlock(world, i + 8, j + 20, k + 8, Blocks.log, 0);
		setBlock(world, i + 8, j + 20, k + 9, Blocks.log, 0);
		setBlock(world, i + 8, j + 20, k + 10, Blocks.log, 0);
		setBlock(world, i + 8, j + 21, k + 6, Blocks.log, 0);
		setBlock(world, i + 8, j + 21, k + 7, Blocks.log, 0);
		setBlock(world, i + 8, j + 21, k + 8, Blocks.log, 0);
		setBlock(world, i + 8, j + 21, k + 9, Blocks.log, 0);
		setBlock(world, i + 8, j + 21, k + 10, Blocks.log, 0);
		setBlock(world, i + 8, j + 22, k + 6, Blocks.log, 0);
		setBlock(world, i + 8, j + 22, k + 7, Blocks.log, 0);
		setBlock(world, i + 8, j + 22, k + 8, Blocks.log, 0);
		setBlock(world, i + 8, j + 22, k + 9, Blocks.log, 0);
		setBlock(world, i + 8, j + 22, k + 10, Blocks.log, 0);
		setBlock(world, i + 8, j + 23, k + 6, Blocks.log, 0);
		setBlock(world, i + 8, j + 23, k + 7, Blocks.log, 0);
		setBlock(world, i + 8, j + 23, k + 8, Blocks.log, 0);
		setBlock(world, i + 8, j + 23, k + 9, Blocks.log, 0);
		setBlock(world, i + 8, j + 23, k + 10, Blocks.log, 0);
		setBlock(world, i + 8, j + 24, k + 6, Blocks.log, 0);
		setBlock(world, i + 8, j + 24, k + 7, Blocks.log, 0);
		setBlock(world, i + 8, j + 24, k + 8, Blocks.log, 0);
		setBlock(world, i + 8, j + 24, k + 9, Blocks.log, 0);
		setBlock(world, i + 8, j + 24, k + 10, Blocks.log, 0);
		setBlock(world, i + 8, j + 25, k + 6, Blocks.log, 0);
		setBlock(world, i + 8, j + 25, k + 7, Blocks.log, 0);
		setBlock(world, i + 8, j + 25, k + 8, Blocks.log, 0);
		setBlock(world, i + 8, j + 25, k + 9, Blocks.log, 0);
		setBlock(world, i + 8, j + 25, k + 10, Blocks.log, 0);
		setBlock(world, i + 8, j + 26, k + 6, Blocks.log, 0);
		setBlock(world, i + 8, j + 26, k + 7, Blocks.log, 0);
		setBlock(world, i + 8, j + 26, k + 8, Blocks.log, 0);
		setBlock(world, i + 8, j + 26, k + 9, Blocks.log, 0);
		setBlock(world, i + 8, j + 26, k + 10, Blocks.log, 0);
		setBlock(world, i + 8, j + 27, k + 7, Blocks.log, 0);
		setBlock(world, i + 8, j + 27, k + 8, Blocks.log, 0);
		setBlock(world, i + 8, j + 27, k + 9, Blocks.log, 0);
		setBlock(world, i + 8, j + 28, k + 7, Blocks.log, 0);
		setBlock(world, i + 8, j + 28, k + 8, Blocks.log, 0);
		setBlock(world, i + 8, j + 28, k + 9, Blocks.log, 0);
		setBlock(world, i + 8, j + 29, k + 7, Blocks.log, 0);
		setBlock(world, i + 8, j + 29, k + 8, Blocks.log, 0);
		setBlock(world, i + 8, j + 29, k + 9, Blocks.log, 0);
		setBlock(world, i + 8, j + 30, k + 7, Blocks.log, 0);
		setBlock(world, i + 8, j + 30, k + 8, Blocks.log, 0);
		setBlock(world, i + 8, j + 30, k + 9, Blocks.log, 0);
		setBlock(world, i + 8, j + 31, k + 7, Blocks.log, 0);
		setBlock(world, i + 8, j + 31, k + 8, Blocks.log, 0);
		setBlock(world, i + 8, j + 31, k + 9, Blocks.log, 0);
		setBlock(world, i + 8, j + 32, k + 7, Blocks.log, 0);
		setBlock(world, i + 8, j + 32, k + 8, Blocks.log, 0);
		setBlock(world, i + 8, j + 32, k + 9, Blocks.log, 0);
		setBlock(world, i + 8, j + 33, k + 7, Blocks.log, 0);
		setBlock(world, i + 8, j + 33, k + 8, Blocks.log, 0);
		setBlock(world, i + 8, j + 33, k + 9, Blocks.log, 0);
		setBlock(world, i + 8, j + 34, k + 0, Blocks.log, 0);
		setBlock(world, i + 8, j + 34, k + 7, Blocks.log, 0);
		setBlock(world, i + 8, j + 34, k + 8, Blocks.log, 0);
		setBlock(world, i + 8, j + 34, k + 9, Blocks.log, 0);
		setBlock(world, i + 8, j + 35, k + 8, Blocks.log, 0);
		setBlock(world, i + 8, j + 35, k + 9, Blocks.log, 0);
		setBlock(world, i + 8, j + 36, k + 8, Blocks.log, 0);
		setBlock(world, i + 8, j + 36, k + 9, Blocks.log, 0);
		setBlock(world, i + 8, j + 37, k + 7, Blocks.log, 0);
		setBlock(world, i + 8, j + 37, k + 8, Blocks.log, 0);
		setBlock(world, i + 8, j + 37, k + 9, Blocks.log, 0);
		setBlock(world, i + 8, j + 37, k + 10, Blocks.log, 0);
		setBlock(world, i + 8, j + 38, k + 7, Blocks.log, 0);
		setBlock(world, i + 8, j + 38, k + 8, Blocks.log, 0);
		setBlock(world, i + 8, j + 38, k + 10, Blocks.log, 0);
		setBlock(world, i + 8, j + 39, k + 7, Blocks.log, 0);
		setBlock(world, i + 8, j + 39, k + 8, Blocks.log, 0);
		setBlock(world, i + 8, j + 39, k + 10, Blocks.log, 0);
		setBlock(world, i + 8, j + 39, k + 11, Blocks.log, 0);
		setBlock(world, i + 8, j + 40, k + 6, Blocks.log, 0);
		setBlock(world, i + 8, j + 40, k + 7, Blocks.log, 0);
		setBlock(world, i + 8, j + 40, k + 8, Blocks.log, 0);
		setBlock(world, i + 8, j + 40, k + 10, Blocks.log, 0);
		setBlock(world, i + 8, j + 41, k + 3, Blocks.log, 0);
		setBlock(world, i + 8, j + 41, k + 6, Blocks.log, 0);
		setBlock(world, i + 8, j + 41, k + 7, Blocks.log, 0);
		setBlock(world, i + 8, j + 41, k + 11, Blocks.log, 0);
		setBlock(world, i + 8, j + 42, k + 5, Blocks.log, 0);
		setBlock(world, i + 8, j + 42, k + 7, Blocks.log, 0);
		setBlock(world, i + 8, j + 42, k + 11, Blocks.log, 0);
		setBlock(world, i + 8, j + 43, k + 5, Blocks.log, 0);
		setBlock(world, i + 8, j + 43, k + 6, Blocks.log, 0);
		setBlock(world, i + 8, j + 43, k + 7, Blocks.log, 0);
		setBlock(world, i + 8, j + 43, k + 11, Blocks.log, 0);
		setBlock(world, i + 8, j + 44, k + 5, Blocks.log, 0);
		setBlock(world, i + 8, j + 44, k + 6, Blocks.log, 0);
		setBlock(world, i + 8, j + 44, k + 7, Blocks.log, 0);
		setBlock(world, i + 8, j + 44, k + 12, Blocks.log, 0);
		setBlock(world, i + 8, j + 45, k + 4, Blocks.log, 0);
		setBlock(world, i + 8, j + 45, k + 6, Blocks.log, 0);
		setBlock(world, i + 8, j + 45, k + 7, Blocks.log, 0);
		setBlock(world, i + 8, j + 45, k + 12, Blocks.log, 0);
		setBlock(world, i + 8, j + 46, k + 4, Blocks.log, 0);
		setBlock(world, i + 8, j + 46, k + 6, Blocks.log, 0);
		setBlock(world, i + 8, j + 46, k + 7, Blocks.log, 0);
		setBlock(world, i + 8, j + 46, k + 12, Blocks.log, 0);
		setBlock(world, i + 8, j + 47, k + 12, Blocks.log, 0);
		setBlock(world, i + 9, j + 0, k + 4, Blocks.log, 0);
		setBlock(world, i + 9, j + 0, k + 5, Blocks.log, 0);
		setBlock(world, i + 9, j + 0, k + 6, Blocks.log, 0);
		setBlock(world, i + 9, j + 0, k + 7, Blocks.log, 0);
		setBlock(world, i + 9, j + 0, k + 8, Blocks.log, 0);
		setBlock(world, i + 9, j + 0, k + 9, Blocks.log, 0);
		setBlock(world, i + 9, j + 0, k + 10, Blocks.log, 0);
		setBlock(world, i + 9, j + 0, k + 11, Blocks.log, 0);
		setBlock(world, i + 9, j + 0, k + 12, Blocks.log, 0);
		setBlock(world, i + 9, j + 1, k + 5, Blocks.log, 0);
		setBlock(world, i + 9, j + 1, k + 6, Blocks.log, 0);
		setBlock(world, i + 9, j + 1, k + 7, Blocks.log, 0);
		setBlock(world, i + 9, j + 1, k + 8, Blocks.log, 0);
		setBlock(world, i + 9, j + 1, k + 9, Blocks.log, 0);
		setBlock(world, i + 9, j + 1, k + 10, Blocks.log, 0);
		setBlock(world, i + 9, j + 1, k + 11, Blocks.log, 0);
		setBlock(world, i + 9, j + 2, k + 5, Blocks.log, 0);
		setBlock(world, i + 9, j + 2, k + 6, Blocks.log, 0);
		setBlock(world, i + 9, j + 2, k + 7, Blocks.log, 0);
		setBlock(world, i + 9, j + 2, k + 8, Blocks.log, 0);
		setBlock(world, i + 9, j + 2, k + 9, Blocks.log, 0);
		setBlock(world, i + 9, j + 2, k + 10, Blocks.log, 0);
		setBlock(world, i + 9, j + 2, k + 11, Blocks.log, 0);
		setBlock(world, i + 9, j + 3, k + 3, Blocks.log, 0);
		setBlock(world, i + 9, j + 3, k + 4, Blocks.log, 0);
		setBlock(world, i + 9, j + 3, k + 5, Blocks.log, 0);
		setBlock(world, i + 9, j + 3, k + 6, Blocks.log, 0);
		setBlock(world, i + 9, j + 3, k + 7, Blocks.log, 0);
		setBlock(world, i + 9, j + 3, k + 8, Blocks.log, 0);
		setBlock(world, i + 9, j + 3, k + 9, Blocks.log, 0);
		setBlock(world, i + 9, j + 3, k + 10, Blocks.log, 0);
		setBlock(world, i + 9, j + 3, k + 11, Blocks.log, 0);
		setBlock(world, i + 9, j + 4, k + 1, Blocks.log, 0);
		setBlock(world, i + 9, j + 4, k + 2, Blocks.log, 0);
		setBlock(world, i + 9, j + 4, k + 5, Blocks.log, 0);
		setBlock(world, i + 9, j + 4, k + 6, Blocks.log, 0);
		setBlock(world, i + 9, j + 4, k + 7, Blocks.log, 0);
		setBlock(world, i + 9, j + 4, k + 8, Blocks.log, 0);
		setBlock(world, i + 9, j + 4, k + 9, Blocks.log, 0);
		setBlock(world, i + 9, j + 4, k + 10, Blocks.log, 0);
		setBlock(world, i + 9, j + 4, k + 11, Blocks.log, 0);
		setBlock(world, i + 9, j + 5, k + 5, Blocks.log, 0);
		setBlock(world, i + 9, j + 5, k + 6, Blocks.log, 0);
		setBlock(world, i + 9, j + 5, k + 7, Blocks.log, 0);
		setBlock(world, i + 9, j + 5, k + 8, Blocks.log, 0);
		setBlock(world, i + 9, j + 5, k + 9, Blocks.log, 0);
		setBlock(world, i + 9, j + 5, k + 10, Blocks.log, 0);
		setBlock(world, i + 9, j + 5, k + 11, Blocks.log, 0);
		setBlock(world, i + 9, j + 5, k + 14, Blocks.log, 0);
		setBlock(world, i + 9, j + 6, k + 5, Blocks.log, 0);
		setBlock(world, i + 9, j + 6, k + 6, Blocks.log, 0);
		setBlock(world, i + 9, j + 6, k + 7, Blocks.log, 0);
		setBlock(world, i + 9, j + 6, k + 8, Blocks.log, 0);
		setBlock(world, i + 9, j + 6, k + 9, Blocks.log, 0);
		setBlock(world, i + 9, j + 6, k + 10, Blocks.log, 0);
		setBlock(world, i + 9, j + 6, k + 11, Blocks.log, 0);
		setBlock(world, i + 9, j + 6, k + 13, Blocks.log, 0);
		setBlock(world, i + 9, j + 6, k + 14, Blocks.log, 0);
		setBlock(world, i + 9, j + 7, k + 5, Blocks.log, 0);
		setBlock(world, i + 9, j + 7, k + 6, Blocks.log, 0);
		setBlock(world, i + 9, j + 7, k + 7, Blocks.log, 0);
		setBlock(world, i + 9, j + 7, k + 8, Blocks.log, 0);
		setBlock(world, i + 9, j + 7, k + 9, Blocks.log, 0);
		setBlock(world, i + 9, j + 7, k + 10, Blocks.log, 0);
		setBlock(world, i + 9, j + 7, k + 11, Blocks.log, 0);
		setBlock(world, i + 9, j + 7, k + 12, Blocks.log, 0);
		setBlock(world, i + 9, j + 7, k + 13, Blocks.log, 0);
		setBlock(world, i + 9, j + 7, k + 14, Blocks.log, 0);
		setBlock(world, i + 9, j + 8, k + 5, Blocks.log, 0);
		setBlock(world, i + 9, j + 8, k + 6, Blocks.log, 0);
		setBlock(world, i + 9, j + 8, k + 7, Blocks.log, 0);
		setBlock(world, i + 9, j + 8, k + 8, Blocks.log, 0);
		setBlock(world, i + 9, j + 8, k + 9, Blocks.log, 0);
		setBlock(world, i + 9, j + 8, k + 10, Blocks.log, 0);
		setBlock(world, i + 9, j + 8, k + 11, Blocks.log, 0);
		setBlock(world, i + 9, j + 8, k + 12, Blocks.log, 0);
		setBlock(world, i + 9, j + 8, k + 13, Blocks.log, 0);
		setBlock(world, i + 9, j + 9, k + 5, Blocks.log, 0);
		setBlock(world, i + 9, j + 9, k + 6, Blocks.log, 0);
		setBlock(world, i + 9, j + 9, k + 7, Blocks.log, 0);
		setBlock(world, i + 9, j + 9, k + 8, Blocks.log, 0);
		setBlock(world, i + 9, j + 9, k + 9, Blocks.log, 0);
		setBlock(world, i + 9, j + 9, k + 10, Blocks.log, 0);
		setBlock(world, i + 9, j + 9, k + 11, Blocks.log, 0);
		setBlock(world, i + 9, j + 9, k + 12, Blocks.log, 0);
		setBlock(world, i + 9, j + 10, k + 5, Blocks.log, 0);
		setBlock(world, i + 9, j + 10, k + 6, Blocks.log, 0);
		setBlock(world, i + 9, j + 10, k + 7, Blocks.log, 0);
		setBlock(world, i + 9, j + 10, k + 8, Blocks.log, 0);
		setBlock(world, i + 9, j + 10, k + 9, Blocks.log, 0);
		setBlock(world, i + 9, j + 10, k + 10, Blocks.log, 0);
		setBlock(world, i + 9, j + 10, k + 11, Blocks.log, 0);
		setBlock(world, i + 9, j + 11, k + 5, Blocks.log, 0);
		setBlock(world, i + 9, j + 11, k + 6, Blocks.log, 0);
		setBlock(world, i + 9, j + 11, k + 7, Blocks.log, 0);
		setBlock(world, i + 9, j + 11, k + 8, Blocks.log, 0);
		setBlock(world, i + 9, j + 11, k + 9, Blocks.log, 0);
		setBlock(world, i + 9, j + 11, k + 10, Blocks.log, 0);
		setBlock(world, i + 9, j + 11, k + 11, Blocks.log, 0);
		setBlock(world, i + 9, j + 12, k + 5, Blocks.log, 0);
		setBlock(world, i + 9, j + 12, k + 6, Blocks.log, 0);
		setBlock(world, i + 9, j + 12, k + 7, Blocks.log, 0);
		setBlock(world, i + 9, j + 12, k + 8, Blocks.log, 0);
		setBlock(world, i + 9, j + 12, k + 9, Blocks.log, 0);
		setBlock(world, i + 9, j + 12, k + 10, Blocks.log, 0);
		setBlock(world, i + 9, j + 12, k + 11, Blocks.log, 0);
		setBlock(world, i + 9, j + 13, k + 6, Blocks.log, 0);
		setBlock(world, i + 9, j + 13, k + 7, Blocks.log, 0);
		setBlock(world, i + 9, j + 13, k + 8, Blocks.log, 0);
		setBlock(world, i + 9, j + 13, k + 9, Blocks.log, 0);
		setBlock(world, i + 9, j + 13, k + 10, Blocks.log, 0);
		setBlock(world, i + 9, j + 14, k + 6, Blocks.log, 0);
		setBlock(world, i + 9, j + 14, k + 7, Blocks.log, 0);
		setBlock(world, i + 9, j + 14, k + 8, Blocks.log, 0);
		setBlock(world, i + 9, j + 14, k + 9, Blocks.log, 0);
		setBlock(world, i + 9, j + 14, k + 10, Blocks.log, 0);
		setBlock(world, i + 9, j + 15, k + 6, Blocks.log, 0);
		setBlock(world, i + 9, j + 15, k + 7, Blocks.log, 0);
		setBlock(world, i + 9, j + 15, k + 8, Blocks.log, 0);
		setBlock(world, i + 9, j + 15, k + 9, Blocks.log, 0);
		setBlock(world, i + 9, j + 15, k + 10, Blocks.log, 0);
		setBlock(world, i + 9, j + 16, k + 6, Blocks.log, 0);
		setBlock(world, i + 9, j + 16, k + 7, Blocks.log, 0);
		setBlock(world, i + 9, j + 16, k + 8, Blocks.log, 0);
		setBlock(world, i + 9, j + 16, k + 9, Blocks.log, 0);
		setBlock(world, i + 9, j + 16, k + 10, Blocks.log, 0);
		setBlock(world, i + 9, j + 17, k + 6, Blocks.log, 0);
		setBlock(world, i + 9, j + 17, k + 7, Blocks.log, 0);
		setBlock(world, i + 9, j + 17, k + 8, Blocks.log, 0);
		setBlock(world, i + 9, j + 17, k + 9, Blocks.log, 0);
		setBlock(world, i + 9, j + 17, k + 10, Blocks.log, 0);
		setBlock(world, i + 9, j + 18, k + 6, Blocks.log, 0);
		setBlock(world, i + 9, j + 18, k + 7, Blocks.log, 0);
		setBlock(world, i + 9, j + 18, k + 8, Blocks.log, 0);
		setBlock(world, i + 9, j + 18, k + 9, Blocks.log, 0);
		setBlock(world, i + 9, j + 18, k + 10, Blocks.log, 0);
		setBlock(world, i + 9, j + 19, k + 6, Blocks.log, 0);
		setBlock(world, i + 9, j + 19, k + 7, Blocks.log, 0);
		setBlock(world, i + 9, j + 19, k + 8, Blocks.log, 0);
		setBlock(world, i + 9, j + 19, k + 9, Blocks.log, 0);
		setBlock(world, i + 9, j + 19, k + 10, Blocks.log, 0);
		setBlock(world, i + 9, j + 20, k + 6, Blocks.log, 0);
		setBlock(world, i + 9, j + 20, k + 7, Blocks.log, 0);
		setBlock(world, i + 9, j + 20, k + 8, Blocks.log, 0);
		setBlock(world, i + 9, j + 20, k + 9, Blocks.log, 0);
		setBlock(world, i + 9, j + 20, k + 10, Blocks.log, 0);
		setBlock(world, i + 9, j + 21, k + 6, Blocks.log, 0);
		setBlock(world, i + 9, j + 21, k + 7, Blocks.log, 0);
		setBlock(world, i + 9, j + 21, k + 8, Blocks.log, 0);
		setBlock(world, i + 9, j + 21, k + 9, Blocks.log, 0);
		setBlock(world, i + 9, j + 21, k + 10, Blocks.log, 0);
		setBlock(world, i + 9, j + 22, k + 6, Blocks.log, 0);
		setBlock(world, i + 9, j + 22, k + 7, Blocks.log, 0);
		setBlock(world, i + 9, j + 22, k + 8, Blocks.log, 0);
		setBlock(world, i + 9, j + 22, k + 9, Blocks.log, 0);
		setBlock(world, i + 9, j + 22, k + 10, Blocks.log, 0);
		setBlock(world, i + 9, j + 23, k + 7, Blocks.log, 0);
		setBlock(world, i + 9, j + 23, k + 8, Blocks.log, 0);
		setBlock(world, i + 9, j + 23, k + 9, Blocks.log, 0);
		setBlock(world, i + 9, j + 24, k + 7, Blocks.log, 0);
		setBlock(world, i + 9, j + 24, k + 8, Blocks.log, 0);
		setBlock(world, i + 9, j + 24, k + 9, Blocks.log, 0);
		setBlock(world, i + 9, j + 25, k + 5, Blocks.log, 0);
		setBlock(world, i + 9, j + 25, k + 7, Blocks.log, 0);
		setBlock(world, i + 9, j + 25, k + 8, Blocks.log, 0);
		setBlock(world, i + 9, j + 25, k + 9, Blocks.log, 0);
		setBlock(world, i + 9, j + 26, k + 5, Blocks.log, 0);
		setBlock(world, i + 9, j + 26, k + 7, Blocks.log, 0);
		setBlock(world, i + 9, j + 26, k + 8, Blocks.log, 0);
		setBlock(world, i + 9, j + 26, k + 9, Blocks.log, 0);
		setBlock(world, i + 9, j + 27, k + 5, Blocks.log, 0);
		setBlock(world, i + 9, j + 27, k + 7, Blocks.log, 0);
		setBlock(world, i + 9, j + 27, k + 8, Blocks.log, 0);
		setBlock(world, i + 9, j + 27, k + 9, Blocks.log, 0);
		setBlock(world, i + 9, j + 28, k + 7, Blocks.log, 0);
		setBlock(world, i + 9, j + 28, k + 8, Blocks.log, 0);
		setBlock(world, i + 9, j + 28, k + 9, Blocks.log, 0);
		setBlock(world, i + 9, j + 29, k + 7, Blocks.log, 0);
		setBlock(world, i + 9, j + 29, k + 8, Blocks.log, 0);
		setBlock(world, i + 9, j + 29, k + 9, Blocks.log, 0);
		setBlock(world, i + 9, j + 30, k + 7, Blocks.log, 0);
		setBlock(world, i + 9, j + 30, k + 8, Blocks.log, 0);
		setBlock(world, i + 9, j + 30, k + 9, Blocks.log, 0);
		setBlock(world, i + 9, j + 31, k + 8, Blocks.log, 0);
		setBlock(world, i + 9, j + 32, k + 8, Blocks.log, 0);
		setBlock(world, i + 9, j + 33, k + 8, Blocks.log, 0);
		setBlock(world, i + 9, j + 34, k + 7, Blocks.log, 0);
		setBlock(world, i + 9, j + 34, k + 8, Blocks.log, 0);
		setBlock(world, i + 9, j + 35, k + 7, Blocks.log, 0);
		setBlock(world, i + 9, j + 36, k + 6, Blocks.log, 0);
		setBlock(world, i + 9, j + 36, k + 7, Blocks.log, 0);
		setBlock(world, i + 9, j + 37, k + 5, Blocks.log, 0);
		setBlock(world, i + 9, j + 37, k + 6, Blocks.log, 0);
		setBlock(world, i + 9, j + 38, k + 5, Blocks.log, 0);
		setBlock(world, i + 9, j + 38, k + 6, Blocks.log, 0);
		setBlock(world, i + 9, j + 38, k + 9, Blocks.log, 0);
		setBlock(world, i + 9, j + 39, k + 7, Blocks.log, 0);
		setBlock(world, i + 9, j + 39, k + 10, Blocks.log, 0);
		setBlock(world, i + 9, j + 40, k + 7, Blocks.log, 0);
		setBlock(world, i + 9, j + 40, k + 10, Blocks.log, 0);
		setBlock(world, i + 9, j + 40, k + 11, Blocks.log, 0);
		setBlock(world, i + 9, j + 41, k + 6, Blocks.log, 0);
		setBlock(world, i + 9, j + 41, k + 11, Blocks.log, 0);
		setBlock(world, i + 9, j + 42, k + 6, Blocks.log, 0);
		setBlock(world, i + 9, j + 42, k + 12, Blocks.log, 0);
		setBlock(world, i + 9, j + 43, k + 6, Blocks.log, 0);
		setBlock(world, i + 9, j + 43, k + 12, Blocks.log, 0);
		setBlock(world, i + 9, j + 44, k + 13, Blocks.log, 0);
		setBlock(world, i + 9, j + 45, k + 13, Blocks.log, 0);
		setBlock(world, i + 9, j + 47, k + 3, Blocks.log, 0);
		setBlock(world, i + 9, j + 47, k + 5, Blocks.log, 0);
		setBlock(world, i + 9, j + 47, k + 6, Blocks.log, 0);
		setBlock(world, i + 10, j + 0, k + 5, Blocks.log, 0);
		setBlock(world, i + 10, j + 0, k + 6, Blocks.log, 0);
		setBlock(world, i + 10, j + 0, k + 7, Blocks.log, 0);
		setBlock(world, i + 10, j + 0, k + 8, Blocks.log, 0);
		setBlock(world, i + 10, j + 0, k + 9, Blocks.log, 0);
		setBlock(world, i + 10, j + 0, k + 10, Blocks.log, 0);
		setBlock(world, i + 10, j + 0, k + 11, Blocks.log, 0);
		setBlock(world, i + 10, j + 1, k + 5, Blocks.log, 0);
		setBlock(world, i + 10, j + 1, k + 6, Blocks.log, 0);
		setBlock(world, i + 10, j + 1, k + 7, Blocks.log, 0);
		setBlock(world, i + 10, j + 1, k + 8, Blocks.log, 0);
		setBlock(world, i + 10, j + 1, k + 9, Blocks.log, 0);
		setBlock(world, i + 10, j + 1, k + 10, Blocks.log, 0);
		setBlock(world, i + 10, j + 1, k + 11, Blocks.log, 0);
		setBlock(world, i + 10, j + 2, k + 5, Blocks.log, 0);
		setBlock(world, i + 10, j + 2, k + 6, Blocks.log, 0);
		setBlock(world, i + 10, j + 2, k + 7, Blocks.log, 0);
		setBlock(world, i + 10, j + 2, k + 8, Blocks.log, 0);
		setBlock(world, i + 10, j + 2, k + 9, Blocks.log, 0);
		setBlock(world, i + 10, j + 2, k + 10, Blocks.log, 0);
		setBlock(world, i + 10, j + 2, k + 11, Blocks.log, 0);
		setBlock(world, i + 10, j + 3, k + 5, Blocks.log, 0);
		setBlock(world, i + 10, j + 3, k + 6, Blocks.log, 0);
		setBlock(world, i + 10, j + 3, k + 7, Blocks.log, 0);
		setBlock(world, i + 10, j + 3, k + 8, Blocks.log, 0);
		setBlock(world, i + 10, j + 3, k + 9, Blocks.log, 0);
		setBlock(world, i + 10, j + 3, k + 10, Blocks.log, 0);
		setBlock(world, i + 10, j + 3, k + 11, Blocks.log, 0);
		setBlock(world, i + 10, j + 4, k + 5, Blocks.log, 0);
		setBlock(world, i + 10, j + 4, k + 6, Blocks.log, 0);
		setBlock(world, i + 10, j + 4, k + 7, Blocks.log, 0);
		setBlock(world, i + 10, j + 4, k + 8, Blocks.log, 0);
		setBlock(world, i + 10, j + 4, k + 9, Blocks.log, 0);
		setBlock(world, i + 10, j + 4, k + 10, Blocks.log, 0);
		setBlock(world, i + 10, j + 4, k + 11, Blocks.log, 0);
		setBlock(world, i + 10, j + 5, k + 0, Blocks.log, 0);
		setBlock(world, i + 10, j + 5, k + 5, Blocks.log, 0);
		setBlock(world, i + 10, j + 5, k + 6, Blocks.log, 0);
		setBlock(world, i + 10, j + 5, k + 7, Blocks.log, 0);
		setBlock(world, i + 10, j + 5, k + 8, Blocks.log, 0);
		setBlock(world, i + 10, j + 5, k + 9, Blocks.log, 0);
		setBlock(world, i + 10, j + 5, k + 10, Blocks.log, 0);
		setBlock(world, i + 10, j + 5, k + 11, Blocks.log, 0);
		setBlock(world, i + 10, j + 5, k + 14, Blocks.log, 0);
		setBlock(world, i + 10, j + 5, k + 15, Blocks.log, 0);
		setBlock(world, i + 10, j + 6, k + 5, Blocks.log, 0);
		setBlock(world, i + 10, j + 6, k + 6, Blocks.log, 0);
		setBlock(world, i + 10, j + 6, k + 7, Blocks.log, 0);
		setBlock(world, i + 10, j + 6, k + 8, Blocks.log, 0);
		setBlock(world, i + 10, j + 6, k + 9, Blocks.log, 0);
		setBlock(world, i + 10, j + 6, k + 10, Blocks.log, 0);
		setBlock(world, i + 10, j + 6, k + 11, Blocks.log, 0);
		setBlock(world, i + 10, j + 6, k + 13, Blocks.log, 0);
		setBlock(world, i + 10, j + 6, k + 14, Blocks.log, 0);
		setBlock(world, i + 10, j + 6, k + 15, Blocks.log, 0);
		setBlock(world, i + 10, j + 7, k + 6, Blocks.log, 0);
		setBlock(world, i + 10, j + 7, k + 7, Blocks.log, 0);
		setBlock(world, i + 10, j + 7, k + 8, Blocks.log, 0);
		setBlock(world, i + 10, j + 7, k + 9, Blocks.log, 0);
		setBlock(world, i + 10, j + 7, k + 10, Blocks.log, 0);
		setBlock(world, i + 10, j + 7, k + 12, Blocks.log, 0);
		setBlock(world, i + 10, j + 7, k + 13, Blocks.log, 0);
		setBlock(world, i + 10, j + 7, k + 14, Blocks.log, 0);
		setBlock(world, i + 10, j + 7, k + 15, Blocks.log, 0);
		setBlock(world, i + 10, j + 8, k + 6, Blocks.log, 0);
		setBlock(world, i + 10, j + 8, k + 7, Blocks.log, 0);
		setBlock(world, i + 10, j + 8, k + 8, Blocks.log, 0);
		setBlock(world, i + 10, j + 8, k + 9, Blocks.log, 0);
		setBlock(world, i + 10, j + 8, k + 10, Blocks.log, 0);
		setBlock(world, i + 10, j + 8, k + 11, Blocks.log, 0);
		setBlock(world, i + 10, j + 8, k + 12, Blocks.log, 0);
		setBlock(world, i + 10, j + 8, k + 13, Blocks.log, 0);
		setBlock(world, i + 10, j + 9, k + 6, Blocks.log, 0);
		setBlock(world, i + 10, j + 9, k + 7, Blocks.log, 0);
		setBlock(world, i + 10, j + 9, k + 8, Blocks.log, 0);
		setBlock(world, i + 10, j + 9, k + 9, Blocks.log, 0);
		setBlock(world, i + 10, j + 9, k + 10, Blocks.log, 0);
		setBlock(world, i + 10, j + 9, k + 11, Blocks.log, 0);
		setBlock(world, i + 10, j + 9, k + 12, Blocks.log, 0);
		setBlock(world, i + 10, j + 10, k + 6, Blocks.log, 0);
		setBlock(world, i + 10, j + 10, k + 7, Blocks.log, 0);
		setBlock(world, i + 10, j + 10, k + 8, Blocks.log, 0);
		setBlock(world, i + 10, j + 10, k + 9, Blocks.log, 0);
		setBlock(world, i + 10, j + 10, k + 10, Blocks.log, 0);
		setBlock(world, i + 10, j + 10, k + 11, Blocks.log, 0);
		setBlock(world, i + 10, j + 11, k + 6, Blocks.log, 0);
		setBlock(world, i + 10, j + 11, k + 7, Blocks.log, 0);
		setBlock(world, i + 10, j + 11, k + 8, Blocks.log, 0);
		setBlock(world, i + 10, j + 11, k + 9, Blocks.log, 0);
		setBlock(world, i + 10, j + 11, k + 10, Blocks.log, 0);
		setBlock(world, i + 10, j + 12, k + 6, Blocks.log, 0);
		setBlock(world, i + 10, j + 12, k + 7, Blocks.log, 0);
		setBlock(world, i + 10, j + 12, k + 8, Blocks.log, 0);
		setBlock(world, i + 10, j + 12, k + 9, Blocks.log, 0);
		setBlock(world, i + 10, j + 12, k + 10, Blocks.log, 0);
		setBlock(world, i + 10, j + 13, k + 6, Blocks.log, 0);
		setBlock(world, i + 10, j + 13, k + 7, Blocks.log, 0);
		setBlock(world, i + 10, j + 13, k + 8, Blocks.log, 0);
		setBlock(world, i + 10, j + 13, k + 9, Blocks.log, 0);
		setBlock(world, i + 10, j + 13, k + 10, Blocks.log, 0);
		setBlock(world, i + 10, j + 14, k + 6, Blocks.log, 0);
		setBlock(world, i + 10, j + 14, k + 7, Blocks.log, 0);
		setBlock(world, i + 10, j + 14, k + 8, Blocks.log, 0);
		setBlock(world, i + 10, j + 14, k + 9, Blocks.log, 0);
		setBlock(world, i + 10, j + 14, k + 10, Blocks.log, 0);
		setBlock(world, i + 10, j + 15, k + 6, Blocks.log, 0);
		setBlock(world, i + 10, j + 15, k + 7, Blocks.log, 0);
		setBlock(world, i + 10, j + 15, k + 8, Blocks.log, 0);
		setBlock(world, i + 10, j + 15, k + 9, Blocks.log, 0);
		setBlock(world, i + 10, j + 15, k + 10, Blocks.log, 0);
		setBlock(world, i + 10, j + 16, k + 7, Blocks.log, 0);
		setBlock(world, i + 10, j + 16, k + 8, Blocks.log, 0);
		setBlock(world, i + 10, j + 16, k + 9, Blocks.log, 0);
		setBlock(world, i + 10, j + 17, k + 7, Blocks.log, 0);
		setBlock(world, i + 10, j + 17, k + 8, Blocks.log, 0);
		setBlock(world, i + 10, j + 17, k + 9, Blocks.log, 0);
		setBlock(world, i + 10, j + 18, k + 7, Blocks.log, 0);
		setBlock(world, i + 10, j + 18, k + 8, Blocks.log, 0);
		setBlock(world, i + 10, j + 18, k + 9, Blocks.log, 0);
		setBlock(world, i + 10, j + 19, k + 7, Blocks.log, 0);
		setBlock(world, i + 10, j + 19, k + 8, Blocks.log, 0);
		setBlock(world, i + 10, j + 19, k + 9, Blocks.log, 0);
		setBlock(world, i + 10, j + 20, k + 7, Blocks.log, 0);
		setBlock(world, i + 10, j + 20, k + 8, Blocks.log, 0);
		setBlock(world, i + 10, j + 20, k + 9, Blocks.log, 0);
		setBlock(world, i + 10, j + 21, k + 7, Blocks.log, 0);
		setBlock(world, i + 10, j + 21, k + 8, Blocks.log, 0);
		setBlock(world, i + 10, j + 21, k + 9, Blocks.log, 0);
		setBlock(world, i + 10, j + 22, k + 7, Blocks.log, 0);
		setBlock(world, i + 10, j + 22, k + 8, Blocks.log, 0);
		setBlock(world, i + 10, j + 22, k + 9, Blocks.log, 0);
		setBlock(world, i + 10, j + 23, k + 8, Blocks.log, 0);
		setBlock(world, i + 10, j + 24, k + 8, Blocks.log, 0);
		setBlock(world, i + 10, j + 25, k + 8, Blocks.log, 0);
		setBlock(world, i + 10, j + 26, k + 4, Blocks.log, 0);
		setBlock(world, i + 10, j + 26, k + 5, Blocks.log, 0);
		setBlock(world, i + 10, j + 26, k + 8, Blocks.log, 0);
		setBlock(world, i + 10, j + 27, k + 4, Blocks.log, 0);
		setBlock(world, i + 10, j + 27, k + 5, Blocks.log, 0);
		setBlock(world, i + 10, j + 37, k + 5, Blocks.log, 0);
		setBlock(world, i + 10, j + 38, k + 5, Blocks.log, 0);
		setBlock(world, i + 10, j + 41, k + 10, Blocks.log, 0);
		setBlock(world, i + 10, j + 42, k + 10, Blocks.log, 0);
		setBlock(world, i + 10, j + 43, k + 11, Blocks.log, 0);
		setBlock(world, i + 10, j + 44, k + 5, Blocks.log, 0);
		setBlock(world, i + 10, j + 46, k + 4, Blocks.log, 0);
		setBlock(world, i + 10, j + 46, k + 5, Blocks.log, 0);
		setBlock(world, i + 10, j + 46, k + 13, Blocks.log, 0);
		setBlock(world, i + 11, j + 0, k + 6, Blocks.log, 0);
		setBlock(world, i + 11, j + 0, k + 7, Blocks.log, 0);
		setBlock(world, i + 11, j + 0, k + 8, Blocks.log, 0);
		setBlock(world, i + 11, j + 0, k + 9, Blocks.log, 0);
		setBlock(world, i + 11, j + 0, k + 10, Blocks.log, 0);
		setBlock(world, i + 11, j + 1, k + 6, Blocks.log, 0);
		setBlock(world, i + 11, j + 1, k + 7, Blocks.log, 0);
		setBlock(world, i + 11, j + 1, k + 8, Blocks.log, 0);
		setBlock(world, i + 11, j + 1, k + 9, Blocks.log, 0);
		setBlock(world, i + 11, j + 1, k + 10, Blocks.log, 0);
		setBlock(world, i + 11, j + 2, k + 6, Blocks.log, 0);
		setBlock(world, i + 11, j + 2, k + 7, Blocks.log, 0);
		setBlock(world, i + 11, j + 2, k + 8, Blocks.log, 0);
		setBlock(world, i + 11, j + 2, k + 9, Blocks.log, 0);
		setBlock(world, i + 11, j + 2, k + 10, Blocks.log, 0);
		setBlock(world, i + 11, j + 3, k + 6, Blocks.log, 0);
		setBlock(world, i + 11, j + 3, k + 7, Blocks.log, 0);
		setBlock(world, i + 11, j + 3, k + 8, Blocks.log, 0);
		setBlock(world, i + 11, j + 3, k + 9, Blocks.log, 0);
		setBlock(world, i + 11, j + 3, k + 10, Blocks.log, 0);
		setBlock(world, i + 11, j + 4, k + 6, Blocks.log, 0);
		setBlock(world, i + 11, j + 4, k + 7, Blocks.log, 0);
		setBlock(world, i + 11, j + 4, k + 8, Blocks.log, 0);
		setBlock(world, i + 11, j + 4, k + 9, Blocks.log, 0);
		setBlock(world, i + 11, j + 4, k + 10, Blocks.log, 0);
		setBlock(world, i + 11, j + 5, k + 6, Blocks.log, 0);
		setBlock(world, i + 11, j + 5, k + 7, Blocks.log, 0);
		setBlock(world, i + 11, j + 5, k + 8, Blocks.log, 0);
		setBlock(world, i + 11, j + 5, k + 9, Blocks.log, 0);
		setBlock(world, i + 11, j + 5, k + 10, Blocks.log, 0);
		setBlock(world, i + 11, j + 5, k + 14, Blocks.log, 0);
		setBlock(world, i + 11, j + 5, k + 15, Blocks.log, 0);
		setBlock(world, i + 11, j + 6, k + 6, Blocks.log, 0);
		setBlock(world, i + 11, j + 6, k + 7, Blocks.log, 0);
		setBlock(world, i + 11, j + 6, k + 8, Blocks.log, 0);
		setBlock(world, i + 11, j + 6, k + 9, Blocks.log, 0);
		setBlock(world, i + 11, j + 6, k + 10, Blocks.log, 0);
		setBlock(world, i + 11, j + 6, k + 13, Blocks.log, 0);
		setBlock(world, i + 11, j + 6, k + 14, Blocks.log, 0);
		setBlock(world, i + 11, j + 6, k + 15, Blocks.log, 0);
		setBlock(world, i + 11, j + 7, k + 7, Blocks.log, 0);
		setBlock(world, i + 11, j + 7, k + 8, Blocks.log, 0);
		setBlock(world, i + 11, j + 7, k + 9, Blocks.log, 0);
		setBlock(world, i + 11, j + 7, k + 10, Blocks.log, 0);
		setBlock(world, i + 11, j + 7, k + 13, Blocks.log, 0);
		setBlock(world, i + 11, j + 7, k + 14, Blocks.log, 0);
		setBlock(world, i + 11, j + 7, k + 15, Blocks.log, 0);
		setBlock(world, i + 11, j + 8, k + 6, Blocks.log, 0);
		setBlock(world, i + 11, j + 8, k + 7, Blocks.log, 0);
		setBlock(world, i + 11, j + 8, k + 8, Blocks.log, 0);
		setBlock(world, i + 11, j + 8, k + 9, Blocks.log, 0);
		setBlock(world, i + 11, j + 8, k + 13, Blocks.log, 0);
		setBlock(world, i + 11, j + 9, k + 6, Blocks.log, 0);
		setBlock(world, i + 11, j + 9, k + 7, Blocks.log, 0);
		setBlock(world, i + 11, j + 9, k + 8, Blocks.log, 0);
		setBlock(world, i + 11, j + 9, k + 9, Blocks.log, 0);
		setBlock(world, i + 11, j + 10, k + 6, Blocks.log, 0);
		setBlock(world, i + 11, j + 10, k + 7, Blocks.log, 0);
		setBlock(world, i + 11, j + 10, k + 8, Blocks.log, 0);
		setBlock(world, i + 11, j + 10, k + 9, Blocks.log, 0);
		setBlock(world, i + 11, j + 11, k + 7, Blocks.log, 0);
		setBlock(world, i + 11, j + 11, k + 8, Blocks.log, 0);
		setBlock(world, i + 11, j + 11, k + 9, Blocks.log, 0);
		setBlock(world, i + 11, j + 12, k + 7, Blocks.log, 0);
		setBlock(world, i + 11, j + 12, k + 8, Blocks.log, 0);
		setBlock(world, i + 11, j + 12, k + 9, Blocks.log, 0);
		setBlock(world, i + 11, j + 13, k + 8, Blocks.log, 0);
		setBlock(world, i + 11, j + 14, k + 8, Blocks.log, 0);
		setBlock(world, i + 11, j + 15, k + 8, Blocks.log, 0);
		setBlock(world, i + 11, j + 27, k + 3, Blocks.log, 0);
		setBlock(world, i + 11, j + 39, k + 5, Blocks.log, 0);
		setBlock(world, i + 11, j + 40, k + 4, Blocks.log, 0);
		setBlock(world, i + 11, j + 44, k + 11, Blocks.log, 0);
		setBlock(world, i + 11, j + 45, k + 11, Blocks.log, 0);
		setBlock(world, i + 11, j + 46, k + 11, Blocks.log, 0);
		setBlock(world, i + 12, j + 0, k + 7, Blocks.log, 0);
		setBlock(world, i + 12, j + 0, k + 8, Blocks.log, 0);
		setBlock(world, i + 12, j + 0, k + 9, Blocks.log, 0);
		setBlock(world, i + 12, j + 1, k + 8, Blocks.log, 0);
		setBlock(world, i + 12, j + 2, k + 8, Blocks.log, 0);
		setBlock(world, i + 12, j + 3, k + 8, Blocks.log, 0);
		setBlock(world, i + 12, j + 5, k + 15, Blocks.log, 0);
		setBlock(world, i + 12, j + 6, k + 15, Blocks.log, 0);
		setBlock(world, i + 12, j + 7, k + 5, Blocks.log, 0);
		setBlock(world, i + 12, j + 7, k + 6, Blocks.log, 0);
		setBlock(world, i + 12, j + 7, k + 7, Blocks.log, 0);
		setBlock(world, i + 12, j + 7, k + 8, Blocks.log, 0);
		setBlock(world, i + 12, j + 7, k + 15, Blocks.log, 0);
		setBlock(world, i + 12, j + 8, k + 5, Blocks.log, 0);
		setBlock(world, i + 12, j + 8, k + 6, Blocks.log, 0);
		setBlock(world, i + 12, j + 8, k + 7, Blocks.log, 0);
		setBlock(world, i + 12, j + 8, k + 8, Blocks.log, 0);
		setBlock(world, i + 12, j + 8, k + 9, Blocks.log, 0);
		setBlock(world, i + 12, j + 9, k + 5, Blocks.log, 0);
		setBlock(world, i + 12, j + 9, k + 6, Blocks.log, 0);
		setBlock(world, i + 12, j + 9, k + 7, Blocks.log, 0);
		setBlock(world, i + 12, j + 9, k + 8, Blocks.log, 0);
		setBlock(world, i + 12, j + 9, k + 9, Blocks.log, 0);
		setBlock(world, i + 12, j + 10, k + 7, Blocks.log, 0);
		setBlock(world, i + 12, j + 10, k + 8, Blocks.log, 0);
		setBlock(world, i + 12, j + 10, k + 9, Blocks.log, 0);
		setBlock(world, i + 12, j + 39, k + 2, Blocks.log, 0);
		setBlock(world, i + 12, j + 41, k + 3, Blocks.log, 0);
		setBlock(world, i + 12, j + 46, k + 11, Blocks.log, 0);
		setBlock(world, i + 12, j + 47, k + 3, Blocks.log, 0);
		setBlock(world, i + 12, j + 47, k + 11, Blocks.log, 0);
		setBlock(world, i + 13, j + 6, k + 5, Blocks.log, 0);
		setBlock(world, i + 13, j + 6, k + 6, Blocks.log, 0);
		setBlock(world, i + 13, j + 6, k + 7, Blocks.log, 0);
		setBlock(world, i + 13, j + 6, k + 8, Blocks.log, 0);
		setBlock(world, i + 13, j + 7, k + 5, Blocks.log, 0);
		setBlock(world, i + 13, j + 7, k + 6, Blocks.log, 0);
		setBlock(world, i + 13, j + 7, k + 7, Blocks.log, 0);
		setBlock(world, i + 13, j + 7, k + 8, Blocks.log, 0);
		setBlock(world, i + 13, j + 7, k + 9, Blocks.log, 0);
		setBlock(world, i + 13, j + 8, k + 5, Blocks.log, 0);
		setBlock(world, i + 13, j + 8, k + 6, Blocks.log, 0);
		setBlock(world, i + 13, j + 8, k + 7, Blocks.log, 0);
		setBlock(world, i + 13, j + 8, k + 8, Blocks.log, 0);
		setBlock(world, i + 13, j + 8, k + 9, Blocks.log, 0);
		setBlock(world, i + 13, j + 9, k + 7, Blocks.log, 0);
		setBlock(world, i + 13, j + 9, k + 8, Blocks.log, 0);
		setBlock(world, i + 13, j + 9, k + 9, Blocks.log, 0);
		setBlock(world, i + 13, j + 40, k + 1, Blocks.log, 0);
		setBlock(world, i + 13, j + 42, k + 2, Blocks.log, 0);
		setBlock(world, i + 13, j + 46, k + 1, Blocks.log, 0);
		setBlock(world, i + 13, j + 47, k + 11, Blocks.log, 0);
		setBlock(world, i + 14, j + 5, k + 4, Blocks.log, 0);
		setBlock(world, i + 14, j + 5, k + 5, Blocks.log, 0);
		setBlock(world, i + 14, j + 5, k + 6, Blocks.log, 0);
		setBlock(world, i + 14, j + 5, k + 7, Blocks.log, 0);
		setBlock(world, i + 14, j + 5, k + 8, Blocks.log, 0);
		setBlock(world, i + 14, j + 6, k + 4, Blocks.log, 0);
		setBlock(world, i + 14, j + 6, k + 5, Blocks.log, 0);
		setBlock(world, i + 14, j + 6, k + 6, Blocks.log, 0);
		setBlock(world, i + 14, j + 6, k + 7, Blocks.log, 0);
		setBlock(world, i + 14, j + 6, k + 8, Blocks.log, 0);
		setBlock(world, i + 14, j + 6, k + 9, Blocks.log, 0);
		setBlock(world, i + 14, j + 7, k + 4, Blocks.log, 0);
		setBlock(world, i + 14, j + 7, k + 5, Blocks.log, 0);
		setBlock(world, i + 14, j + 7, k + 6, Blocks.log, 0);
		setBlock(world, i + 14, j + 7, k + 7, Blocks.log, 0);
		setBlock(world, i + 14, j + 7, k + 8, Blocks.log, 0);
		setBlock(world, i + 14, j + 7, k + 9, Blocks.log, 0);
		setBlock(world, i + 14, j + 8, k + 7, Blocks.log, 0);
		setBlock(world, i + 14, j + 8, k + 8, Blocks.log, 0);
		setBlock(world, i + 14, j + 8, k + 9, Blocks.log, 0);
		setBlock(world, i + 14, j + 47, k + 3, Blocks.log, 0);
		setBlock(world, i + 14, j + 47, k + 10, Blocks.log, 0);
		setBlock(world, i + 15, j + 4, k + 4, Blocks.log, 0);
		setBlock(world, i + 15, j + 4, k + 5, Blocks.log, 0);
		setBlock(world, i + 15, j + 4, k + 6, Blocks.log, 0);
		setBlock(world, i + 15, j + 4, k + 7, Blocks.log, 0);
		setBlock(world, i + 15, j + 5, k + 4, Blocks.log, 0);
		setBlock(world, i + 15, j + 5, k + 5, Blocks.log, 0);
		setBlock(world, i + 15, j + 5, k + 6, Blocks.log, 0);
		setBlock(world, i + 15, j + 5, k + 7, Blocks.log, 0);
		setBlock(world, i + 15, j + 5, k + 8, Blocks.log, 0);
		setBlock(world, i + 15, j + 5, k + 9, Blocks.log, 0);
		setBlock(world, i + 15, j + 6, k + 4, Blocks.log, 0);
		setBlock(world, i + 15, j + 6, k + 5, Blocks.log, 0);
		setBlock(world, i + 15, j + 6, k + 6, Blocks.log, 0);
		setBlock(world, i + 15, j + 6, k + 7, Blocks.log, 0);
		setBlock(world, i + 15, j + 6, k + 8, Blocks.log, 0);
		setBlock(world, i + 15, j + 6, k + 9, Blocks.log, 0);
		setBlock(world, i + 15, j + 7, k + 7, Blocks.log, 0);
		setBlock(world, i + 15, j + 7, k + 8, Blocks.log, 0);
		setBlock(world, i + 15, j + 7, k + 9, Blocks.log, 0);
		setBlock(world, i + 0, j + 31, k + 0, Blocks.leaves, 4);
		world.setBlockMetadataWithNotify(i + 0, j + 31, k + 0, 4, 2);
		setBlock(world, i + 0, j + 31, k + 1, Blocks.leaves, 4);
		world.setBlockMetadataWithNotify(i + 0, j + 31, k + 1, 4, 2);
		setBlock(world, i + 0, j + 32, k + 0, Blocks.leaves, 4);
		world.setBlockMetadataWithNotify(i + 0, j + 32, k + 0, 4, 2);
		setBlock(world, i + 0, j + 32, k + 1, Blocks.leaves, 4);
		world.setBlockMetadataWithNotify(i + 0, j + 32, k + 1, 4, 2);
		setBlock(world, i + 0, j + 37, k + 2, Blocks.leaves, 4);
		world.setBlockMetadataWithNotify(i + 0, j + 37, k + 2, 4, 2);
		setBlock(world, i + 0, j + 38, k + 0, Blocks.leaves, 4);
		world.setBlockMetadataWithNotify(i + 0, j + 38, k + 0, 4, 2);
		setBlock(world, i + 0, j + 38, k + 1, Blocks.leaves, 4);
		world.setBlockMetadataWithNotify(i + 0, j + 38, k + 1, 4, 2);
		setBlock(world, i + 0, j + 38, k + 2, Blocks.leaves, 4);
		world.setBlockMetadataWithNotify(i + 0, j + 38, k + 2, 4, 2);
		setBlock(world, i + 0, j + 38, k + 3, Blocks.leaves, 4);
		world.setBlockMetadataWithNotify(i + 0, j + 38, k + 3, 4, 2);
		setBlock(world, i + 0, j + 38, k + 4, Blocks.leaves, 4);
		world.setBlockMetadataWithNotify(i + 0, j + 38, k + 4, 4, 2);
		setBlock(world, i + 0, j + 39, k + 0, Blocks.leaves, 4);
		world.setBlockMetadataWithNotify(i + 0, j + 39, k + 0, 4, 2);
		setBlock(world, i + 0, j + 39, k + 1, Blocks.leaves, 4);
		world.setBlockMetadataWithNotify(i + 0, j + 39, k + 1, 4, 2);
		setBlock(world, i + 0, j + 39, k + 2, Blocks.leaves, 4);
		world.setBlockMetadataWithNotify(i + 0, j + 39, k + 2, 4, 2);
		setBlock(world, i + 0, j + 39, k + 3, Blocks.leaves, 4);
		world.setBlockMetadataWithNotify(i + 0, j + 39, k + 3, 4, 2);
		setBlock(world, i + 0, j + 39, k + 4, Blocks.leaves, 4);
		world.setBlockMetadataWithNotify(i + 0, j + 39, k + 4, 4, 2);
		setBlock(world, i + 0, j + 40, k + 1, Blocks.leaves, 4);
		world.setBlockMetadataWithNotify(i + 0, j + 40, k + 1, 4, 2);
		setBlock(world, i + 0, j + 40, k + 2, Blocks.leaves, 4);
		world.setBlockMetadataWithNotify(i + 0, j + 40, k + 2, 4, 2);
		setBlock(world, i + 0, j + 40, k + 3, Blocks.leaves, 4);
		world.setBlockMetadataWithNotify(i + 0, j + 40, k + 3, 4, 2);
		setBlock(world, i + 0, j + 41, k + 2, Blocks.leaves, 4);
		world.setBlockMetadataWithNotify(i + 0, j + 41, k + 2, 4, 2);
		setBlock(world, i + 0, j + 43, k + 0, Blocks.leaves, 4);
		world.setBlockMetadataWithNotify(i + 0, j + 43, k + 0, 4, 2);
		setBlock(world, i + 0, j + 44, k + 0, Blocks.leaves, 4);
		world.setBlockMetadataWithNotify(i + 0, j + 44, k + 0, 4, 2);
		setBlock(world, i + 0, j + 44, k + 1, Blocks.leaves, 4);
		world.setBlockMetadataWithNotify(i + 0, j + 44, k + 1, 4, 2);
		setBlock(world, i + 0, j + 44, k + 2, Blocks.leaves, 4);
		world.setBlockMetadataWithNotify(i + 0, j + 44, k + 2, 4, 2);
		setBlock(world, i + 0, j + 44, k + 3, Blocks.leaves, 4);
		world.setBlockMetadataWithNotify(i + 0, j + 44, k + 3, 4, 2);
		setBlock(world, i + 0, j + 44, k + 4, Blocks.leaves, 4);
		world.setBlockMetadataWithNotify(i + 0, j + 44, k + 4, 4, 2);
		setBlock(world, i + 0, j + 44, k + 5, Blocks.leaves, 4);
		world.setBlockMetadataWithNotify(i + 0, j + 44, k + 5, 4, 2);
		setBlock(world, i + 0, j + 45, k + 0, Blocks.leaves, 4);
		world.setBlockMetadataWithNotify(i + 0, j + 45, k + 0, 4, 2);
		setBlock(world, i + 0, j + 45, k + 1, Blocks.leaves, 4);
		world.setBlockMetadataWithNotify(i + 0, j + 45, k + 1, 4, 2);
		setBlock(world, i + 0, j + 45, k + 2, Blocks.leaves, 4);
		world.setBlockMetadataWithNotify(i + 0, j + 45, k + 2, 4, 2);
		setBlock(world, i + 0, j + 45, k + 3, Blocks.leaves, 4);
		world.setBlockMetadataWithNotify(i + 0, j + 45, k + 3, 4, 2);
		setBlock(world, i + 0, j + 45, k + 4, Blocks.leaves, 4);
		world.setBlockMetadataWithNotify(i + 0, j + 45, k + 4, 4, 2);
		setBlock(world, i + 0, j + 45, k + 5, Blocks.leaves, 4);
		world.setBlockMetadataWithNotify(i + 0, j + 45, k + 5, 4, 2);
		setBlock(world, i + 0, j + 46, k + 0, Blocks.leaves, 4);
		world.setBlockMetadataWithNotify(i + 0, j + 46, k + 0, 4, 2);
		setBlock(world, i + 0, j + 46, k + 1, Blocks.leaves, 4);
		world.setBlockMetadataWithNotify(i + 0, j + 46, k + 1, 4, 2);
		setBlock(world, i + 0, j + 46, k + 2, Blocks.leaves, 4);
		world.setBlockMetadataWithNotify(i + 0, j + 46, k + 2, 4, 2);
		setBlock(world, i + 0, j + 46, k + 8, Blocks.leaves, 4);
		world.setBlockMetadataWithNotify(i + 0, j + 46, k + 8, 4, 2);
		setBlock(world, i + 0, j + 47, k + 0, Blocks.leaves, 4);
		world.setBlockMetadataWithNotify(i + 0, j + 47, k + 0, 4, 2);
		setBlock(world, i + 0, j + 47, k + 1, Blocks.leaves, 4);
		world.setBlockMetadataWithNotify(i + 0, j + 47, k + 1, 4, 2);
		setBlock(world, i + 0, j + 47, k + 2, Blocks.leaves, 4);
		world.setBlockMetadataWithNotify(i + 0, j + 47, k + 2, 4, 2);
		setBlock(world, i + 0, j + 47, k + 3, Blocks.leaves, 4);
		world.setBlockMetadataWithNotify(i + 0, j + 47, k + 3, 4, 2);
		setBlock(world, i + 0, j + 47, k + 4, Blocks.leaves, 4);
		world.setBlockMetadataWithNotify(i + 0, j + 47, k + 4, 4, 2);
		setBlock(world, i + 0, j + 47, k + 6, Blocks.leaves, 4);
		world.setBlockMetadataWithNotify(i + 0, j + 47, k + 6, 4, 2);
		setBlock(world, i + 0, j + 47, k + 7, Blocks.leaves, 4);
		world.setBlockMetadataWithNotify(i + 0, j + 47, k + 7, 4, 2);
		setBlock(world, i + 0, j + 47, k + 8, Blocks.leaves, 4);
		world.setBlockMetadataWithNotify(i + 0, j + 47, k + 8, 4, 2);
		setBlock(world, i + 0, j + 47, k + 9, Blocks.leaves, 4);
		world.setBlockMetadataWithNotify(i + 0, j + 47, k + 9, 4, 2);
		setBlock(world, i + 0, j + 47, k + 10, Blocks.leaves, 4);
		world.setBlockMetadataWithNotify(i + 0, j + 47, k + 10, 4, 2);
		setBlock(world, i + 0, j + 48, k + 2, Blocks.leaves, 4);
		world.setBlockMetadataWithNotify(i + 0, j + 48, k + 2, 4, 2);
		setBlock(world, i + 0, j + 48, k + 3, Blocks.leaves, 4);
		world.setBlockMetadataWithNotify(i + 0, j + 48, k + 3, 4, 2);
		setBlock(world, i + 0, j + 48, k + 4, Blocks.leaves, 4);
		world.setBlockMetadataWithNotify(i + 0, j + 48, k + 4, 4, 2);
		setBlock(world, i + 0, j + 48, k + 5, Blocks.leaves, 4);
		world.setBlockMetadataWithNotify(i + 0, j + 48, k + 5, 4, 2);
		setBlock(world, i + 0, j + 48, k + 6, Blocks.leaves, 4);
		world.setBlockMetadataWithNotify(i + 0, j + 48, k + 6, 4, 2);
		setBlock(world, i + 0, j + 48, k + 7, Blocks.leaves, 4);
		world.setBlockMetadataWithNotify(i + 0, j + 48, k + 7, 4, 2);
		setBlock(world, i + 0, j + 48, k + 8, Blocks.leaves, 4);
		world.setBlockMetadataWithNotify(i + 0, j + 48, k + 8, 4, 2);
		setBlock(world, i + 0, j + 48, k + 9, Blocks.leaves, 4);
		world.setBlockMetadataWithNotify(i + 0, j + 48, k + 9, 4, 2);
		setBlock(world, i + 0, j + 48, k + 10, Blocks.leaves, 4);
		world.setBlockMetadataWithNotify(i + 0, j + 48, k + 10, 4, 2);
		setBlock(world, i + 0, j + 49, k + 4, Blocks.leaves, 4);
		world.setBlockMetadataWithNotify(i + 0, j + 49, k + 4, 4, 2);
		setBlock(world, i + 0, j + 49, k + 5, Blocks.leaves, 4);
		world.setBlockMetadataWithNotify(i + 0, j + 49, k + 5, 4, 2);
		setBlock(world, i + 0, j + 49, k + 6, Blocks.leaves, 4);
		world.setBlockMetadataWithNotify(i + 0, j + 49, k + 6, 4, 2);
		setBlock(world, i + 0, j + 49, k + 7, Blocks.leaves, 4);
		world.setBlockMetadataWithNotify(i + 0, j + 49, k + 7, 4, 2);
		setBlock(world, i + 0, j + 49, k + 8, Blocks.leaves, 4);
		world.setBlockMetadataWithNotify(i + 0, j + 49, k + 8, 4, 2);
		setBlock(world, i + 0, j + 49, k + 9, Blocks.leaves, 4);
		world.setBlockMetadataWithNotify(i + 0, j + 49, k + 9, 4, 2);
		setBlock(world, i + 0, j + 49, k + 10, Blocks.leaves, 4);
		world.setBlockMetadataWithNotify(i + 0, j + 49, k + 10, 4, 2);
		setBlock(world, i + 0, j + 50, k + 5, Blocks.leaves, 4);
		world.setBlockMetadataWithNotify(i + 0, j + 50, k + 5, 4, 2);
		setBlock(world, i + 0, j + 50, k + 6, Blocks.leaves, 4);
		world.setBlockMetadataWithNotify(i + 0, j + 50, k + 6, 4, 2);
		setBlock(world, i + 0, j + 50, k + 7, Blocks.leaves, 4);
		world.setBlockMetadataWithNotify(i + 0, j + 50, k + 7, 4, 2);
		setBlock(world, i + 0, j + 50, k + 8, Blocks.leaves, 4);
		world.setBlockMetadataWithNotify(i + 0, j + 50, k + 8, 4, 2);
		setBlock(world, i + 0, j + 50, k + 9, Blocks.leaves, 4);
		world.setBlockMetadataWithNotify(i + 0, j + 50, k + 9, 4, 2);
		setBlock(world, i + 0, j + 51, k + 6, Blocks.leaves, 4);
		world.setBlockMetadataWithNotify(i + 0, j + 51, k + 6, 4, 2);
		setBlock(world, i + 0, j + 51, k + 7, Blocks.leaves, 4);
		world.setBlockMetadataWithNotify(i + 0, j + 51, k + 7, 4, 2);
		setBlock(world, i + 0, j + 51, k + 8, Blocks.leaves, 4);
		world.setBlockMetadataWithNotify(i + 0, j + 51, k + 8, 4, 2);
		setBlock(world, i + 1, j + 30, k + 0, Blocks.leaves, 4);
		world.setBlockMetadataWithNotify(i + 1, j + 30, k + 0, 4, 2);
		setBlock(world, i + 1, j + 31, k + 0, Blocks.leaves, 4);
		world.setBlockMetadataWithNotify(i + 1, j + 31, k + 0, 4, 2);
		setBlock(world, i + 1, j + 31, k + 1, Blocks.leaves, 4);
		world.setBlockMetadataWithNotify(i + 1, j + 31, k + 1, 4, 2);
		setBlock(world, i + 1, j + 31, k + 2, Blocks.leaves, 4);
		world.setBlockMetadataWithNotify(i + 1, j + 31, k + 2, 4, 2);
		setBlock(world, i + 1, j + 32, k + 0, Blocks.leaves, 4);
		world.setBlockMetadataWithNotify(i + 1, j + 32, k + 0, 4, 2);
		setBlock(world, i + 1, j + 32, k + 1, Blocks.leaves, 4);
		world.setBlockMetadataWithNotify(i + 1, j + 32, k + 1, 4, 2);
		setBlock(world, i + 1, j + 32, k + 2, Blocks.leaves, 4);
		world.setBlockMetadataWithNotify(i + 1, j + 32, k + 2, 4, 2);
		setBlock(world, i + 1, j + 33, k + 0, Blocks.leaves, 4);
		world.setBlockMetadataWithNotify(i + 1, j + 33, k + 0, 4, 2);
		setBlock(world, i + 1, j + 33, k + 1, Blocks.leaves, 4);
		world.setBlockMetadataWithNotify(i + 1, j + 33, k + 1, 4, 2);
		setBlock(world, i + 1, j + 34, k + 0, Blocks.leaves, 4);
		world.setBlockMetadataWithNotify(i + 1, j + 34, k + 0, 4, 2);
		setBlock(world, i + 1, j + 37, k + 1, Blocks.leaves, 4);
		world.setBlockMetadataWithNotify(i + 1, j + 37, k + 1, 4, 2);
		setBlock(world, i + 1, j + 37, k + 3, Blocks.leaves, 4);
		world.setBlockMetadataWithNotify(i + 1, j + 37, k + 3, 4, 2);
		setBlock(world, i + 1, j + 38, k + 0, Blocks.leaves, 4);
		world.setBlockMetadataWithNotify(i + 1, j + 38, k + 0, 4, 2);
		setBlock(world, i + 1, j + 38, k + 1, Blocks.leaves, 4);
		world.setBlockMetadataWithNotify(i + 1, j + 38, k + 1, 4, 2);
		setBlock(world, i + 1, j + 38, k + 2, Blocks.leaves, 4);
		world.setBlockMetadataWithNotify(i + 1, j + 38, k + 2, 4, 2);
		setBlock(world, i + 1, j + 38, k + 3, Blocks.leaves, 4);
		world.setBlockMetadataWithNotify(i + 1, j + 38, k + 3, 4, 2);
		setBlock(world, i + 1, j + 38, k + 4, Blocks.leaves, 4);
		world.setBlockMetadataWithNotify(i + 1, j + 38, k + 4, 4, 2);
		setBlock(world, i + 1, j + 39, k + 0, Blocks.leaves, 4);
		world.setBlockMetadataWithNotify(i + 1, j + 39, k + 0, 4, 2);
		setBlock(world, i + 1, j + 39, k + 1, Blocks.leaves, 4);
		world.setBlockMetadataWithNotify(i + 1, j + 39, k + 1, 4, 2);
		setBlock(world, i + 1, j + 39, k + 2, Blocks.leaves, 4);
		world.setBlockMetadataWithNotify(i + 1, j + 39, k + 2, 4, 2);
		setBlock(world, i + 1, j + 39, k + 3, Blocks.leaves, 4);
		world.setBlockMetadataWithNotify(i + 1, j + 39, k + 3, 4, 2);
		setBlock(world, i + 1, j + 39, k + 4, Blocks.leaves, 4);
		world.setBlockMetadataWithNotify(i + 1, j + 39, k + 4, 4, 2);
		setBlock(world, i + 1, j + 40, k + 1, Blocks.leaves, 4);
		world.setBlockMetadataWithNotify(i + 1, j + 40, k + 1, 4, 2);
		setBlock(world, i + 1, j + 40, k + 2, Blocks.leaves, 4);
		world.setBlockMetadataWithNotify(i + 1, j + 40, k + 2, 4, 2);
		setBlock(world, i + 1, j + 40, k + 3, Blocks.leaves, 4);
		world.setBlockMetadataWithNotify(i + 1, j + 40, k + 3, 4, 2);
		setBlock(world, i + 1, j + 41, k + 1, Blocks.leaves, 4);
		world.setBlockMetadataWithNotify(i + 1, j + 41, k + 1, 4, 2);

		generate2(world, rand, i, j, k);
		return true;
	}

	public boolean generate2(World world, Random rand, int i, int j, int k)
	{
		setBlock(world, i + 1, j + 41, k + 2, Blocks.leaves, 4);
		world.setBlockMetadataWithNotify(i + 1, j + 41, k + 2, 4, 2);
		setBlock(world, i + 1, j + 41, k + 3, Blocks.leaves, 4);
		world.setBlockMetadataWithNotify(i + 1, j + 41, k + 3, 4, 2);
		setBlock(world, i + 1, j + 41, k + 11, Blocks.leaves, 4);
		world.setBlockMetadataWithNotify(i + 1, j + 41, k + 11, 4, 2);
		setBlock(world, i + 1, j + 41, k + 12, Blocks.leaves, 4);
		world.setBlockMetadataWithNotify(i + 1, j + 41, k + 12, 4, 2);
		setBlock(world, i + 1, j + 41, k + 13, Blocks.leaves, 4);
		world.setBlockMetadataWithNotify(i + 1, j + 41, k + 13, 4, 2);
		setBlock(world, i + 1, j + 42, k + 11, Blocks.leaves, 4);
		world.setBlockMetadataWithNotify(i + 1, j + 42, k + 11, 4, 2);
		setBlock(world, i + 1, j + 42, k + 12, Blocks.leaves, 4);
		world.setBlockMetadataWithNotify(i + 1, j + 42, k + 12, 4, 2);
		setBlock(world, i + 1, j + 42, k + 13, Blocks.leaves, 4);
		world.setBlockMetadataWithNotify(i + 1, j + 42, k + 13, 4, 2);
		setBlock(world, i + 1, j + 43, k + 1, Blocks.leaves, 4);
		world.setBlockMetadataWithNotify(i + 1, j + 43, k + 1, 4, 2);
		setBlock(world, i + 1, j + 43, k + 4, Blocks.leaves, 4);
		world.setBlockMetadataWithNotify(i + 1, j + 43, k + 4, 4, 2);
		setBlock(world, i + 1, j + 43, k + 11, Blocks.leaves, 4);
		world.setBlockMetadataWithNotify(i + 1, j + 43, k + 11, 4, 2);
		setBlock(world, i + 1, j + 43, k + 12, Blocks.leaves, 4);
		world.setBlockMetadataWithNotify(i + 1, j + 43, k + 12, 4, 2);
		setBlock(world, i + 1, j + 43, k + 13, Blocks.leaves, 4);
		world.setBlockMetadataWithNotify(i + 1, j + 43, k + 13, 4, 2);
		setBlock(world, i + 1, j + 44, k + 0, Blocks.leaves, 4);
		world.setBlockMetadataWithNotify(i + 1, j + 44, k + 0, 4, 2);
		setBlock(world, i + 1, j + 44, k + 1, Blocks.leaves, 4);
		world.setBlockMetadataWithNotify(i + 1, j + 44, k + 1, 4, 2);
		setBlock(world, i + 1, j + 44, k + 2, Blocks.leaves, 4);
		world.setBlockMetadataWithNotify(i + 1, j + 44, k + 2, 4, 2);
		setBlock(world, i + 1, j + 44, k + 3, Blocks.leaves, 4);
		world.setBlockMetadataWithNotify(i + 1, j + 44, k + 3, 4, 2);
		setBlock(world, i + 1, j + 44, k + 4, Blocks.leaves, 4);
		world.setBlockMetadataWithNotify(i + 1, j + 44, k + 4, 4, 2);
		setBlock(world, i + 1, j + 44, k + 5, Blocks.leaves, 4);
		world.setBlockMetadataWithNotify(i + 1, j + 44, k + 5, 4, 2);
		setBlock(world, i + 1, j + 44, k + 6, Blocks.leaves, 4);
		world.setBlockMetadataWithNotify(i + 1, j + 44, k + 6, 4, 2);
		setBlock(world, i + 1, j + 45, k + 0, Blocks.leaves, 4);
		world.setBlockMetadataWithNotify(i + 1, j + 45, k + 0, 4, 2);
		setBlock(world, i + 1, j + 45, k + 1, Blocks.leaves, 4);
		world.setBlockMetadataWithNotify(i + 1, j + 45, k + 1, 4, 2);
		setBlock(world, i + 1, j + 45, k + 2, Blocks.leaves, 4);
		world.setBlockMetadataWithNotify(i + 1, j + 45, k + 2, 4, 2);
		setBlock(world, i + 1, j + 45, k + 3, Blocks.leaves, 4);
		world.setBlockMetadataWithNotify(i + 1, j + 45, k + 3, 4, 2);
		setBlock(world, i + 1, j + 45, k + 4, Blocks.leaves, 4);
		world.setBlockMetadataWithNotify(i + 1, j + 45, k + 4, 4, 2);
		setBlock(world, i + 1, j + 45, k + 5, Blocks.leaves, 4);
		world.setBlockMetadataWithNotify(i + 1, j + 45, k + 5, 4, 2);
		setBlock(world, i + 1, j + 45, k + 6, Blocks.leaves, 4);
		world.setBlockMetadataWithNotify(i + 1, j + 45, k + 6, 4, 2);
		setBlock(world, i + 1, j + 46, k + 0, Blocks.leaves, 4);
		world.setBlockMetadataWithNotify(i + 1, j + 46, k + 0, 4, 2);
		setBlock(world, i + 1, j + 46, k + 1, Blocks.leaves, 4);
		world.setBlockMetadataWithNotify(i + 1, j + 46, k + 1, 4, 2);
		setBlock(world, i + 1, j + 46, k + 2, Blocks.leaves, 4);
		world.setBlockMetadataWithNotify(i + 1, j + 46, k + 2, 4, 2);
		setBlock(world, i + 1, j + 46, k + 3, Blocks.leaves, 4);
		world.setBlockMetadataWithNotify(i + 1, j + 46, k + 3, 4, 2);
		setBlock(world, i + 1, j + 46, k + 4, Blocks.leaves, 4);
		world.setBlockMetadataWithNotify(i + 1, j + 46, k + 4, 4, 2);
		setBlock(world, i + 1, j + 46, k + 5, Blocks.leaves, 4);
		world.setBlockMetadataWithNotify(i + 1, j + 46, k + 5, 4, 2);
		setBlock(world, i + 1, j + 46, k + 7, Blocks.leaves, 4);
		world.setBlockMetadataWithNotify(i + 1, j + 46, k + 7, 4, 2);
		setBlock(world, i + 1, j + 46, k + 9, Blocks.leaves, 4);
		world.setBlockMetadataWithNotify(i + 1, j + 46, k + 9, 4, 2);
		setBlock(world, i + 1, j + 46, k + 12, Blocks.leaves, 4);
		world.setBlockMetadataWithNotify(i + 1, j + 46, k + 12, 4, 2);
		setBlock(world, i + 1, j + 46, k + 13, Blocks.leaves, 4);
		world.setBlockMetadataWithNotify(i + 1, j + 46, k + 13, 4, 2);
		setBlock(world, i + 1, j + 46, k + 14, Blocks.leaves, 4);
		world.setBlockMetadataWithNotify(i + 1, j + 46, k + 14, 4, 2);
		setBlock(world, i + 1, j + 47, k + 0, Blocks.leaves, 4);
		world.setBlockMetadataWithNotify(i + 1, j + 47, k + 0, 4, 2);
		setBlock(world, i + 1, j + 47, k + 1, Blocks.leaves, 4);
		world.setBlockMetadataWithNotify(i + 1, j + 47, k + 1, 4, 2);
		setBlock(world, i + 1, j + 47, k + 2, Blocks.leaves, 4);
		world.setBlockMetadataWithNotify(i + 1, j + 47, k + 2, 4, 2);
		setBlock(world, i + 1, j + 47, k + 3, Blocks.leaves, 4);
		world.setBlockMetadataWithNotify(i + 1, j + 47, k + 3, 4, 2);
		setBlock(world, i + 1, j + 47, k + 4, Blocks.leaves, 4);
		world.setBlockMetadataWithNotify(i + 1, j + 47, k + 4, 4, 2);
		setBlock(world, i + 1, j + 47, k + 5, Blocks.leaves, 4);
		world.setBlockMetadataWithNotify(i + 1, j + 47, k + 5, 4, 2);
		setBlock(world, i + 1, j + 47, k + 9, Blocks.leaves, 4);
		world.setBlockMetadataWithNotify(i + 1, j + 47, k + 9, 4, 2);
		setBlock(world, i + 1, j + 47, k + 10, Blocks.leaves, 4);
		world.setBlockMetadataWithNotify(i + 1, j + 47, k + 10, 4, 2);
		setBlock(world, i + 1, j + 47, k + 12, Blocks.leaves, 4);
		world.setBlockMetadataWithNotify(i + 1, j + 47, k + 12, 4, 2);
		setBlock(world, i + 1, j + 47, k + 13, Blocks.leaves, 4);
		world.setBlockMetadataWithNotify(i + 1, j + 47, k + 13, 4, 2);
		setBlock(world, i + 1, j + 47, k + 14, Blocks.leaves, 4);
		world.setBlockMetadataWithNotify(i + 1, j + 47, k + 14, 4, 2);
		setBlock(world, i + 1, j + 48, k + 0, Blocks.leaves, 4);
		world.setBlockMetadataWithNotify(i + 1, j + 48, k + 0, 4, 2);
		setBlock(world, i + 1, j + 48, k + 1, Blocks.leaves, 4);
		world.setBlockMetadataWithNotify(i + 1, j + 48, k + 1, 4, 2);
		setBlock(world, i + 1, j + 48, k + 2, Blocks.leaves, 4);
		world.setBlockMetadataWithNotify(i + 1, j + 48, k + 2, 4, 2);
		setBlock(world, i + 1, j + 48, k + 3, Blocks.leaves, 4);
		world.setBlockMetadataWithNotify(i + 1, j + 48, k + 3, 4, 2);
		setBlock(world, i + 1, j + 48, k + 4, Blocks.leaves, 4);
		world.setBlockMetadataWithNotify(i + 1, j + 48, k + 4, 4, 2);
		setBlock(world, i + 1, j + 48, k + 5, Blocks.leaves, 4);
		world.setBlockMetadataWithNotify(i + 1, j + 48, k + 5, 4, 2);
		setBlock(world, i + 1, j + 48, k + 6, Blocks.leaves, 4);
		world.setBlockMetadataWithNotify(i + 1, j + 48, k + 6, 4, 2);
		setBlock(world, i + 1, j + 48, k + 7, Blocks.leaves, 4);
		world.setBlockMetadataWithNotify(i + 1, j + 48, k + 7, 4, 2);
		setBlock(world, i + 1, j + 48, k + 8, Blocks.leaves, 4);
		world.setBlockMetadataWithNotify(i + 1, j + 48, k + 8, 4, 2);
		setBlock(world, i + 1, j + 48, k + 9, Blocks.leaves, 4);
		world.setBlockMetadataWithNotify(i + 1, j + 48, k + 9, 4, 2);
		setBlock(world, i + 1, j + 48, k + 10, Blocks.leaves, 4);
		world.setBlockMetadataWithNotify(i + 1, j + 48, k + 10, 4, 2);
		setBlock(world, i + 1, j + 49, k + 1, Blocks.leaves, 4);
		world.setBlockMetadataWithNotify(i + 1, j + 49, k + 1, 4, 2);
		setBlock(world, i + 1, j + 49, k + 2, Blocks.leaves, 4);
		world.setBlockMetadataWithNotify(i + 1, j + 49, k + 2, 4, 2);
		setBlock(world, i + 1, j + 49, k + 3, Blocks.leaves, 4);
		world.setBlockMetadataWithNotify(i + 1, j + 49, k + 3, 4, 2);
		setBlock(world, i + 1, j + 49, k + 4, Blocks.leaves, 4);
		world.setBlockMetadataWithNotify(i + 1, j + 49, k + 4, 4, 2);
		setBlock(world, i + 1, j + 49, k + 5, Blocks.leaves, 4);
		world.setBlockMetadataWithNotify(i + 1, j + 49, k + 5, 4, 2);
		setBlock(world, i + 1, j + 49, k + 6, Blocks.leaves, 4);
		world.setBlockMetadataWithNotify(i + 1, j + 49, k + 6, 4, 2);
		setBlock(world, i + 1, j + 49, k + 7, Blocks.leaves, 4);
		world.setBlockMetadataWithNotify(i + 1, j + 49, k + 7, 4, 2);
		setBlock(world, i + 1, j + 49, k + 8, Blocks.leaves, 4);
		world.setBlockMetadataWithNotify(i + 1, j + 49, k + 8, 4, 2);
		setBlock(world, i + 1, j + 49, k + 9, Blocks.leaves, 4);
		world.setBlockMetadataWithNotify(i + 1, j + 49, k + 9, 4, 2);
		setBlock(world, i + 1, j + 49, k + 10, Blocks.leaves, 4);
		world.setBlockMetadataWithNotify(i + 1, j + 49, k + 10, 4, 2);
		setBlock(world, i + 1, j + 50, k + 3, Blocks.leaves, 4);
		world.setBlockMetadataWithNotify(i + 1, j + 50, k + 3, 4, 2);
		setBlock(world, i + 1, j + 50, k + 5, Blocks.leaves, 4);
		world.setBlockMetadataWithNotify(i + 1, j + 50, k + 5, 4, 2);
		setBlock(world, i + 1, j + 50, k + 6, Blocks.leaves, 4);
		world.setBlockMetadataWithNotify(i + 1, j + 50, k + 6, 4, 2);
		setBlock(world, i + 1, j + 50, k + 7, Blocks.leaves, 4);
		world.setBlockMetadataWithNotify(i + 1, j + 50, k + 7, 4, 2);
		setBlock(world, i + 1, j + 50, k + 8, Blocks.leaves, 4);
		world.setBlockMetadataWithNotify(i + 1, j + 50, k + 8, 4, 2);
		setBlock(world, i + 1, j + 50, k + 9, Blocks.leaves, 4);
		world.setBlockMetadataWithNotify(i + 1, j + 50, k + 9, 4, 2);
		setBlock(world, i + 1, j + 51, k + 5, Blocks.leaves, 4);
		world.setBlockMetadataWithNotify(i + 1, j + 51, k + 5, 4, 2);
		setBlock(world, i + 1, j + 51, k + 6, Blocks.leaves, 4);
		world.setBlockMetadataWithNotify(i + 1, j + 51, k + 6, 4, 2);
		setBlock(world, i + 1, j + 51, k + 7, Blocks.leaves, 4);
		world.setBlockMetadataWithNotify(i + 1, j + 51, k + 7, 4, 2);
		setBlock(world, i + 1, j + 51, k + 8, Blocks.leaves, 4);
		world.setBlockMetadataWithNotify(i + 1, j + 51, k + 8, 4, 2);
		setBlock(world, i + 1, j + 51, k + 9, Blocks.leaves, 4);
		world.setBlockMetadataWithNotify(i + 1, j + 51, k + 9, 4, 2);
		setBlock(world, i + 2, j + 30, k + 1, Blocks.leaves, 4);
		world.setBlockMetadataWithNotify(i + 2, j + 30, k + 1, 4, 2);
		setBlock(world, i + 2, j + 31, k + 0, Blocks.leaves, 4);
		world.setBlockMetadataWithNotify(i + 2, j + 31, k + 0, 4, 2);
		setBlock(world, i + 2, j + 31, k + 1, Blocks.leaves, 4);
		world.setBlockMetadataWithNotify(i + 2, j + 31, k + 1, 4, 2);
		setBlock(world, i + 2, j + 31, k + 2, Blocks.leaves, 4);
		world.setBlockMetadataWithNotify(i + 2, j + 31, k + 2, 4, 2);
		setBlock(world, i + 2, j + 32, k + 0, Blocks.leaves, 4);
		world.setBlockMetadataWithNotify(i + 2, j + 32, k + 0, 4, 2);
		setBlock(world, i + 2, j + 32, k + 1, Blocks.leaves, 4);
		world.setBlockMetadataWithNotify(i + 2, j + 32, k + 1, 4, 2);
		setBlock(world, i + 2, j + 32, k + 2, Blocks.leaves, 4);
		world.setBlockMetadataWithNotify(i + 2, j + 32, k + 2, 4, 2);
		setBlock(world, i + 2, j + 33, k + 0, Blocks.leaves, 4);
		world.setBlockMetadataWithNotify(i + 2, j + 33, k + 0, 4, 2);
		setBlock(world, i + 2, j + 33, k + 1, Blocks.leaves, 4);
		world.setBlockMetadataWithNotify(i + 2, j + 33, k + 1, 4, 2);
		setBlock(world, i + 2, j + 34, k + 0, Blocks.leaves, 4);
		world.setBlockMetadataWithNotify(i + 2, j + 34, k + 0, 4, 2);
		setBlock(world, i + 2, j + 34, k + 1, Blocks.leaves, 4);
		world.setBlockMetadataWithNotify(i + 2, j + 34, k + 1, 4, 2);
		setBlock(world, i + 2, j + 37, k + 2, Blocks.leaves, 4);
		world.setBlockMetadataWithNotify(i + 2, j + 37, k + 2, 4, 2);
		setBlock(world, i + 2, j + 38, k + 0, Blocks.leaves, 4);
		world.setBlockMetadataWithNotify(i + 2, j + 38, k + 0, 4, 2);
		setBlock(world, i + 2, j + 38, k + 1, Blocks.leaves, 4);
		world.setBlockMetadataWithNotify(i + 2, j + 38, k + 1, 4, 2);
		setBlock(world, i + 2, j + 38, k + 2, Blocks.leaves, 4);
		world.setBlockMetadataWithNotify(i + 2, j + 38, k + 2, 4, 2);
		setBlock(world, i + 2, j + 38, k + 3, Blocks.leaves, 4);
		world.setBlockMetadataWithNotify(i + 2, j + 38, k + 3, 4, 2);
		setBlock(world, i + 2, j + 38, k + 4, Blocks.leaves, 4);
		world.setBlockMetadataWithNotify(i + 2, j + 38, k + 4, 4, 2);
		setBlock(world, i + 2, j + 39, k + 0, Blocks.leaves, 4);
		world.setBlockMetadataWithNotify(i + 2, j + 39, k + 0, 4, 2);
		setBlock(world, i + 2, j + 39, k + 1, Blocks.leaves, 4);
		world.setBlockMetadataWithNotify(i + 2, j + 39, k + 1, 4, 2);
		setBlock(world, i + 2, j + 39, k + 2, Blocks.leaves, 4);
		world.setBlockMetadataWithNotify(i + 2, j + 39, k + 2, 4, 2);
		setBlock(world, i + 2, j + 39, k + 3, Blocks.leaves, 4);
		world.setBlockMetadataWithNotify(i + 2, j + 39, k + 3, 4, 2);
		setBlock(world, i + 2, j + 39, k + 4, Blocks.leaves, 4);
		world.setBlockMetadataWithNotify(i + 2, j + 39, k + 4, 4, 2);
		setBlock(world, i + 2, j + 40, k + 1, Blocks.leaves, 4);
		world.setBlockMetadataWithNotify(i + 2, j + 40, k + 1, 4, 2);
		setBlock(world, i + 2, j + 40, k + 2, Blocks.leaves, 4);
		world.setBlockMetadataWithNotify(i + 2, j + 40, k + 2, 4, 2);
		setBlock(world, i + 2, j + 40, k + 3, Blocks.leaves, 4);
		world.setBlockMetadataWithNotify(i + 2, j + 40, k + 3, 4, 2);
		setBlock(world, i + 2, j + 40, k + 12, Blocks.leaves, 4);
		world.setBlockMetadataWithNotify(i + 2, j + 40, k + 12, 4, 2);
		setBlock(world, i + 2, j + 41, k + 2, Blocks.leaves, 4);
		world.setBlockMetadataWithNotify(i + 2, j + 41, k + 2, 4, 2);
		setBlock(world, i + 2, j + 41, k + 10, Blocks.leaves, 4);
		world.setBlockMetadataWithNotify(i + 2, j + 41, k + 10, 4, 2);
		setBlock(world, i + 2, j + 41, k + 11, Blocks.leaves, 4);
		world.setBlockMetadataWithNotify(i + 2, j + 41, k + 11, 4, 2);
		setBlock(world, i + 2, j + 41, k + 12, Blocks.leaves, 4);
		world.setBlockMetadataWithNotify(i + 2, j + 41, k + 12, 4, 2);
		setBlock(world, i + 2, j + 41, k + 13, Blocks.leaves, 4);
